Workbook

Sheet README
A1: Weekly Sales Report Automation – Reporting Automation Portfolio Project
A2: BZME Insights | Sector: Retail / Reporting automation | Tool: Excel (formula-driven; macro file included)
A4: BUSINESS PROBLEM
A5: Every Monday an analyst spends hours cleaning the point-of-sale export (mixed date formats, inconsistent branch and product names, text prices, duplicates and returns) before building the weekly sales report by hand. The work is slow and errors creep in.
A7: BUSINESS QUESTIONS
A8: 1. Can the cleaning and reporting be done by formulas, so a new export only needs to be pasted in?
A9: 2. How do sales compare with last week by branch, category, product and day?
A10: 3. Which rows were fixed, excluded or flagged, so the report can be trusted?
A11: 4. How much time and money does the automation save?
A13: HOW THE WORKBOOK IS BUILT
A14: Raw_Export: 2,221 rows exactly as a POS system might export them (messy on purpose). Paste a new export here each week.
A15: Maps: lookup tables that standardise branch, product and payment names. Add a new variant here and the next refresh picks it up.
... A33: Once stable, move the pipeline to Power Query or SQL so the refresh is fully hands-off.

Sheet Dashboard
A1: Weekly Sales Report: Automated from a Raw POS Export
A2: ="Fictional Kenyan convenience-store chain (5 branches) | Synthetic data | Week of "&TEXT(Assumptions!$B$4,"d mmm yyyy")&" vs week of "&TEXT(Assumptions!$B$5,"d mmm yyyy")&" | Prepared by BZME Insights" -> Fictional Kenyan convenience-store chain (5 branches) | Synthetic data | Week of 7 Sep 2026 vs week of 31 Aug 2026 | Prepared by BZME Insights
A4: NET SALES (KES) | C4: VS LAST WEEK | E4: SALES LINES | G4: AVG VALUE PER SALES LINE (KES) | I4: RETURNS (KES) | K4: M-PESA SHARE OF SALES
A5: =B23 -> 473309 | C5: =E23 -> -0.084482142 | E5: =COUNTIFS(Clean!$M$2:$M$3001,Assumptions!$B$4,Clean!$L$2:$L$3001,1) -> 1086 | G5: =IFERROR(A5/E5,0) -> 435.82781 | I5: =SUMIFS(Clean!$H$2:$H$3001,Clean!$M$2:$M$3001,Assumptions!$B$4,Clean!$K$2:$K$3001,"Return") -> -11902 | K5: =IFERROR(SUMIFS(Clean!$H$2:$H$3001,Clean!$M$2:$M$3001,Assumptions!$B$4,Clean!$L$2:$L$3001,1,Clean!$I$2:$I$3001,"M-Pesa")/A5,0) -> 0.52336423
A7: Key findings (update automatically)
A8: ="1. Net sales for the week were KES "&TEXT(B23/1000000,"0.00")&"M, "&TEXT(ABS(E23),"0.0%")&IF(E23>=0," up"," down")&" on the previous week." -> 1. Net sales for the week were KES 0.47M, 8.4% down on the previous week.
A9: ="2. "&INDEX(A18:A22,MATCH(MAX(B18:B22),B18:B22,0))&" is the biggest branch ("&TEXT(MAX(F18:F22),"0%")&" of sales); "&INDEX(A18:A22,MATCH(MIN(E18:E22),E18:E22,0))&" has the weakest growth ("&TEXT(MIN(E18:E22),"+0.0%;-0.0%")&")." -> 2. Nairobi CBD is the biggest branch (29% of sales); Mombasa has the weakest growth (-23.4%).
A10: ="3. "&INDEX(A27:A32,MATCH(MAX(E27:E32),E27:E32,0))&" grew fastest ("&TEXT(MAX(E27:E32),"+0.0%;-0.0%")&"); "&INDEX(A27:A32,MATCH(MIN(E27:E32),E27:E32,0))&" fell the most ("&TEXT(MIN(E27:E32),"+0.0%;-0.0%")&")." -> 3. Snacks grew fastest (+22.8%); Dairy & Eggs fell the most (-26.1%).
A11: ="4. Top product this week: "&A37&" (KES "&TEXT(D37,"#,##0")&")." -> 4. Top product this week: Cooking Oil 1L (KES 81,180).
A12: ="5. Busiest day: "&INDEX(A45:A51,MATCH(MAX(B45:B51),B45:B51,0))&" (KES "&TEXT(MAX(B45:B51),"#,##0")&")." -> 5. Busiest day: Sat (KES 93,388).
A13: ="6. Data quality: "&(B56+B57+B58)&" of "&TEXT(COUNTIF(Clean!$K$2:$K$3001,"?*"),"#,##0")&" raw rows ("&TEXT((B56+B57+B58)/COUNTIF(Clean!$K$2:$K$3001,"?*"),"0.0%")&") were excluded or flagged: "&B56&" duplicates, "&B57&" unknown names and "&B58&" blank quantities. Dates, prices and names were standardised on the rest." -> 6. Data quality: 82 of 2,221 raw rows (3.7%) were excluded or flagged: 43 duplicates, 19 unknown names and 20 blank quantities. Dates, prices and names were standardised on the rest.
A14: ="7. Automating this report saves about "&TEXT(B66,"#,##0")&" hours a year (KES "&TEXT(B67,"#,##0")&")." -> 7. Automating this report saves about 143 hours a year (KES 100,100).
A16: 1. Sales by branch
A17: Branch | B17: This week (KES) | C17: Last week (KES) | D17: Change (KES) | E17: Change % | F17: Share of sales
A18: Nairobi CBD | B18: =SUMIFS(Clean!$H$2:$H$3001,Clean!$M$2:$M$3001,Assumptions!$B$4,Clean!$L$2:$L$3001,1,Clean!$C$2:$C$3001,A18) -> 139577 | C18: =SUMIFS(Clean!$H$2:$H$3001,Clean!$M$2:$M$3001,Assumptions!$B$5,Clean!$L$2:$L$3001,1,Clean!$C$2:$C$3001,A18) -> 140736 | D18: =B18-C18 -> -1159 | E18: =IFERROR(D18/C18,0) -> -0.0082352774 | F18: =IFERROR(B18/B$23,0) -> 0.29489615
A19: Westlands | B19: =SUMIFS(Clean!$H$2:$H$3001,Clean!$M$2:$M$3001,Assumptions!$B$4,Clean!$L$2:$L$3001,1,Clean!$C$2:$C$3001,A19) -> 92023 | C19: =SUMIFS(Clean!$H$2:$H$3001,Clean!$M$2:$M$3001,Assumptions!$B$5,Clean!$L$2:$L$3001,1,Clean!$C$2:$C$3001,A19) -> 104369 | D19: =B19-C19 -> -12346 | E19: =IFERROR(D19/C19,0) -> -0.11829183 | F19: =IFERROR(B19/B$23,0) -> 0.19442478
A20: Mombasa | B20: =SUMIFS(Clean!$H$2:$H$3001,Clean!$M$2:$M$3001,Assumptions!$B$4,Clean!$L$2:$L$3001,1,Clean!$C$2:$C$3001,A20) -> 85567 | C20: =SUMIFS(Clean!$H$2:$H$3001,Clean!$M$2:$M$3001,Assumptions!$B$5,Clean!$L$2:$L$3001,1,Clean!$C$2:$C$3001,A20) -> 111676 | D20: =B20-C20 -> -26109 | E20: =IFERROR(D20/C20,0) -> -0.2337924 | F20: =IFERROR(B20/B$23,0) -> 0.18078465
A21: Kisumu | B21: =SUMIFS(Clean!$H$2:$H$3001,Clean!$M$2:$M$3001,Assumptions!$B$4,Clean!$L$2:$L$3001,1,Clean!$C$2:$C$3001,A21) -> 81212 | C21: =SUMIFS(Clean!$H$2:$H$3001,Clean!$M$2:$M$3001,Assumptions!$B$5,Clean!$L$2:$L$3001,1,Clean!$C$2:$C$3001,A21) -> 78732 | D21: =B21-C21 -> 2480 | E21: =IFERROR(D21/C21,0) -> 0.031499263 | F21: =IFERROR(B21/B$23,0) -> 0.17158347
A22: Nakuru | B22: =SUMIFS(Clean!$H$2:$H$3001,Clean!$M$2:$M$3001,Assumptions!$B$4,Clean!$L$2:$L$3001,1,Clean!$C$2:$C$3001,A22) -> 74930 | C22: =SUMIFS(Clean!$H$2:$H$3001,Clean!$M$2:$M$3001,Assumptions!$B$5,Clean!$L$2:$L$3001,1,Clean!$C$2:$C$3001,A22) -> 81472 | D22: =B22-C22 -> -6542 | E22: =IFERROR(D22/C22,0) -> -0.080297526 | F22: =IFERROR(B22/B$23,0) -> 0.15831096
A23: All branches | B23: =SUM(B18:B22) -> 473309 | C23: =SUM(C18:C22) -> 516985 | D23: =B23-C23 -> -43676 | E23: =IFERROR(D23/C23,0) -> -0.084482142 | F23: =SUM(F18:F22) -> 1
A25: 2. Sales by category
A26: Category | B26: This week (KES) | C26: Last week (KES) | D26: Change (KES) | E26: Change % | F26: Share of sales
A27: Staples | B27: =SUMIFS(Clean!$H$2:$H$3001,Clean!$M$2:$M$3001,Assumptions!$B$4,Clean!$L$2:$L$3001,1,Clean!$E$2:$E$3001,A27) -> 159826 | C27: =SUMIFS(Clean!$H$2:$H$3001,Clean!$M$2:$M$3001,Assumptions!$B$5,Clean!$L$2:$L$3001,1,Clean!$E$2:$E$3001,A27) -> 177969 | D27: =B27-C27 -> -18143 | E27: =IFERROR(D27/C27,0) -> -0.10194472 | F27: =IFERROR(B27/B$33,0) -> 0.33767792
A28: Dairy & Eggs | B28: =SUMIFS(Clean!$H$2:$H$3001,Clean!$M$2:$M$3001,Assumptions!$B$4,Clean!$L$2:$L$3001,1,Clean!$E$2:$E$3001,A28) -> 78213 | C28: =SUMIFS(Clean!$H$2:$H$3001,Clean!$M$2:$M$3001,Assumptions!$B$5,Clean!$L$2:$L$3001,1,Clean!$E$2:$E$3001,A28) -> 105895 | D28: =B28-C28 -> -27682 | E28: =IFERROR(D28/C28,0) -> -0.26140989 | F28: =IFERROR(B28/B$33,0) -> 0.16524723
A29: Beverages | B29: =SUMIFS(Clean!$H$2:$H$3001,Clean!$M$2:$M$3001,Assumptions!$B$4,Clean!$L$2:$L$3001,1,Clean!$E$2:$E$3001,A29) -> 67587 | C29: =SUMIFS(Clean!$H$2:$H$3001,Clean!$M$2:$M$3001,Assumptions!$B$5,Clean!$L$2:$L$3001,1,Clean!$E$2:$E$3001,A29) -> 60741 | D29: =B29-C29 -> 6846 | E29: =IFERROR(D29/C29,0) -> 0.11270806 | F29: =IFERROR(B29/B$33,0) -> 0.14279678
A30: Household | B30: =SUMIFS(Clean!$H$2:$H$3001,Clean!$M$2:$M$3001,Assumptions!$B$4,Clean!$L$2:$L$3001,1,Clean!$E$2:$E$3001,A30) -> 57299 | C30: =SUMIFS(Clean!$H$2:$H$3001,Clean!$M$2:$M$3001,Assumptions!$B$5,Clean!$L$2:$L$3001,1,Clean!$E$2:$E$3001,A30) -> 67488 | D30: =B30-C30 -> -10189 | E30: =IFERROR(D30/C30,0) -> -0.15097499 | F30: =IFERROR(B30/B$33,0) -> 0.12106045
A31: Personal Care | B31: =SUMIFS(Clean!$H$2:$H$3001,Clean!$M$2:$M$3001,Assumptions!$B$4,Clean!$L$2:$L$3001,1,Clean!$E$2:$E$3001,A31) -> 72423 | C31: =SUMIFS(Clean!$H$2:$H$3001,Clean!$M$2:$M$3001,Assumptions!$B$5,Clean!$L$2:$L$3001,1,Clean!$E$2:$E$3001,A31) -> 73980 | D31: =B31-C31 -> -1557 | E31: =IFERROR(D31/C31,0) -> -0.021046229 | F31: =IFERROR(B31/B$33,0) -> 0.1530142
A32: Snacks | B32: =SUMIFS(Clean!$H$2:$H$3001,Clean!$M$2:$M$3001,Assumptions!$B$4,Clean!$L$2:$L$3001,1,Clean!$E$2:$E$3001,A32) -> 37961 | C32: =SUMIFS(Clean!$H$2:$H$3001,Clean!$M$2:$M$3001,Assumptions!$B$5,Clean!$L$2:$L$3001,1,Clean!$E$2:$E$3001,A32) -> 30912 | D32: =B32-C32 -> 7049 | E32: =IFERROR(D32/C32,0) -> 0.22803442 | F32: =IFERROR(B32/B$33,0) -> 0.080203419
A33: All categories | B33: =SUM(B27:B32) -> 473309 | C33: =SUM(C27:C32) -> 516985 | D33: =B33-C33 -> -43676 | E33: =IFERROR(D33/C33,0) -> -0.084482142 | F33: =SUM(F27:F32) -> 1
A35: 3. Top 5 products this week
A36: Product | B36: Category | C36: Units | D36: Sales (KES)
A37: =INDEX(Maps!$K$2:$K$32,MATCH(D37,Maps!$N$2:$N$32,0)) -> Cooking Oil 1L | B37: =INDEX(Maps!$L$2:$L$32,MATCH(D37,Maps!$N$2:$N$32,0)) -> Staples | C37: =INDEX(Maps!$M$2:$M$32,MATCH(D37,Maps!$N$2:$N$32,0)) -> 250 | D37: =LARGE(Maps!$N$2:$N$32,1) -> 81180
A38: =INDEX(Maps!$K$2:$K$32,MATCH(D38,Maps!$N$2:$N$32,0)) -> Eggs Tray 30 | B38: =INDEX(Maps!$L$2:$L$32,MATCH(D38,Maps!$N$2:$N$32,0)) -> Dairy & Eggs | C38: =INDEX(Maps!$M$2:$M$32,MATCH(D38,Maps!$N$2:$N$32,0)) -> 93 | D38: =LARGE(Maps!$N$2:$N$32,2) -> 41355
A39: =INDEX(Maps!$K$2:$K$32,MATCH(D39,Maps!$N$2:$N$32,0)) -> Deodorant 150ml | B39: =INDEX(Maps!$L$2:$L$32,MATCH(D39,Maps!$N$2:$N$32,0)) -> Personal Care | C39: =INDEX(Maps!$M$2:$M$32,MATCH(D39,Maps!$N$2:$N$32,0)) -> 79 | D39: =LARGE(Maps!$N$2:$N$32,3) -> 27405
A40: =INDEX(Maps!$K$2:$K$32,MATCH(D40,Maps!$N$2:$N$32,0)) -> Sugar 2kg | B40: =INDEX(Maps!$L$2:$L$32,MATCH(D40,Maps!$N$2:$N$32,0)) -> Staples | C40: =INDEX(Maps!$M$2:$M$32,MATCH(D40,Maps!$N$2:$N$32,0)) -> 80 | D40: =LARGE(Maps!$N$2:$N$32,4) -> 26466
A41: =INDEX(Maps!$K$2:$K$32,MATCH(D41,Maps!$N$2:$N$32,0)) -> Rice Pishori 2kg | B41: =INDEX(Maps!$L$2:$L$32,MATCH(D41,Maps!$N$2:$N$32,0)) -> Staples | C41: =INDEX(Maps!$M$2:$M$32,MATCH(D41,Maps!$N$2:$N$32,0)) -> 54 | D41: =LARGE(Maps!$N$2:$N$32,5) -> 22428
A43: 4. Daily trend (Monday to Sunday)
A44: Day | B44: This week (KES) | C44: Last week (KES)
A45: Mon | B45: =SUMIFS(Clean!$H$2:$H$3001,Clean!$B$2:$B$3001,Assumptions!$B$4+0,Clean!$L$2:$L$3001,1) -> 59099 | C45: =SUMIFS(Clean!$H$2:$H$3001,Clean!$B$2:$B$3001,Assumptions!$B$5+0,Clean!$L$2:$L$3001,1) -> 73483
A46: Tue | B46: =SUMIFS(Clean!$H$2:$H$3001,Clean!$B$2:$B$3001,Assumptions!$B$4+1,Clean!$L$2:$L$3001,1) -> 52905 | C46: =SUMIFS(Clean!$H$2:$H$3001,Clean!$B$2:$B$3001,Assumptions!$B$5+1,Clean!$L$2:$L$3001,1) -> 55995
...

Sheet Assumptions
A1: Assumptions & Parameters
A2: Blue cells are editable inputs. Everything else recalculates from them.
A3: Assumption | B3: Value | C3: Comment
A4: Report week starts (Monday) | B4: 46272 | C4: Pick any Monday in the data. The report compares it with the week before.
A5: Previous week starts | B5: =B4-7 -> 46265 | C5: Calculated.
A6: Manual effort per run (minutes) | B6: 180 | C6: Time an analyst spends cleaning the export and building the report by hand.
A7: Automated effort per run (minutes) | B7: 15 | C7: Paste the new export, refresh, check the data-quality log and send.
A8: Runs per year | B8: 52 | C8: One report each week.
A9: Analyst cost per hour (KES) | B9: 700 | C9: Illustrative loaded cost.

Sheet Clean
A1: Txn ID | B1: Date | C1: Branch | D1: Product | E1: Category | F1: Qty | G1: Unit price (KES) | H1: Amount (KES) | I1: Payment | J1: Duplicate? | K1: Status | L1: Include | M1: Week start
A2: =IF(Raw_Export!$A2="","",TRIM(Raw_Export!A2)) -> TXN-100001 | B2: =IF(Raw_Export!$A2="","",IF(ISNUMBER(Raw_Export!B2),Raw_Export!B2,IF(MID(TRIM(Raw_Export!B2),5,1)="-",DATE(LEFT(TRIM(Raw_Export!B2),4),MID(TRIM(Raw_Export!B2),6,2),RIGHT(TRIM(Raw_Export!B2),2)),DATE(RIGHT(TRIM(Raw_Export!B2),4),MATCH(MID(TRIM(Raw_Export!B2),4,3),{"Jan","Feb","Mar","Apr","May","Jun","Jul","Aug","Sep","Oct","Nov","Dec"},0),LEFT(TRIM(Raw_Export!B2),2))))) -> 46265 | C2: =IF(Raw_Export!$A2="","",IFERROR(VLOOKUP(LOWER(TRIM(Raw_Export!C2)),Maps!$A$2:$B$20,2,FALSE()),"UNMAPPED")) -> Nairobi CBD | D2: =IF(Raw_Export!$A2="","",IFERROR(VLOOKUP(LOWER(TRIM(Raw_Export!D2)),Maps!$G$2:$I$80,2,FALSE()),"UNMAPPED")) -> Cheddar 200g | E2: =IF(Raw_Export!$A2="","",IFERROR(VLOOKUP(LOWER(TRIM(Raw_Export!D2)),Maps!$G$2:$I$80,3,FALSE()),"UNMAPPED")) -> Dairy & Eggs | F2: =IF(Raw_Export!$A2="","",IFERROR(VALUE(TRIM(Raw_Export!E2)),0)) -> 6 | G2: =IF(Raw_Export!$A2="","",IFERROR(VALUE(SUBSTITUTE(SUBSTITUTE(UPPER(TRIM(Raw_Export!F2)),"KES",""),",","")),0)) -> 380 | H2: =IF(Raw_Export!$A2="","",F2*G2) -> 2280 | I2: =IF(Raw_Export!$A2="","",IFERROR(VLOOKUP(LOWER(TRIM(Raw_Export!H2)),Maps!$D$2:$E$12,2,FALSE()),"Other")) -> Cash | J2: =IF(Raw_Export!$A2="","",IF(COUNTIF($A$2:A2,A2)>1,"Duplicate","")) | K2: =IF(Raw_Export!$A2="","",IF(J2="Duplicate","Duplicate",IF(OR(C2="UNMAPPED",D2="UNMAPPED"),"Unmapped",IF(F2=0,"Blank qty",IF(F2<0,"Return","OK"))))) -> OK | L2: =IF(Raw_Export!$A2="","",IF(OR(K2="OK",K2="Return"),1,0)) -> 1 | M2: =IF(Raw_Export!$A2="","",B2-WEEKDAY(B2,2)+1) -> 46265
A3: =IF(Raw_Export!$A3="","",TRIM(Raw_Export!A3)) -> TXN-100002 | B3: =IF(Raw_Export!$A3="","",IF(ISNUMBER(Raw_Export!B3),Raw_Export!B3,IF(MID(TRIM(Raw_Export!B3),5,1)="-",DATE(LEFT(TRIM(Raw_Export!B3),4),MID(TRIM(Raw_Export!B3),6,2),RIGHT(TRIM(Raw_Export!B3),2)),DATE(RIGHT(TRIM(Raw_Export!B3),4),MATCH(MID(TRIM(Raw_Export!B3),4,3),{"Jan","Feb","Mar","Apr","May","Jun","Jul","Aug","Sep","Oct","Nov","Dec"},0),LEFT(TRIM(Raw_Export!B3),2))))) -> 46265 | C3: =IF(Raw_Export!$A3="","",IFERROR(VLOOKUP(LOWER(TRIM(Raw_Export!C3)),Maps!$A$2:$B$20,2,FALSE()),"UNMAPPED")) -> Nairobi CBD | D3: =IF(Raw_Export!$A3="","",IFERROR(VLOOKUP(LOWER(TRIM(Raw_Export!D3)),Maps!$G$2:$I$80,2,FALSE()),"UNMAPPED")) -> Spaghetti 400g | E3: =IF(Raw_Export!$A3="","",IFERROR(VLOOKUP(LOWER(TRIM(Raw_Export!D3)),Maps!$G$2:$I$80,3,FALSE()),"UNMAPPED")) -> Staples | F3: =IF(Raw_Export!$A3="","",IFERROR(VALUE(TRIM(Raw_Export!E3)),0)) -> 1 | G3: =IF(Raw_Export!$A3="","",IFERROR(VALUE(SUBSTITUTE(SUBSTITUTE(UPPER(TRIM(Raw_Export!F3)),"KES",""),",","")),0)) -> 110 | H3: =IF(Raw_Export!$A3="","",F3*G3) -> 110 | I3: =IF(Raw_Export!$A3="","",IFERROR(VLOOKUP(LOWER(TRIM(Raw_Export!H3)),Maps!$D$2:$E$12,2,FALSE()),"Other")) -> M-Pesa | J3: =IF(Raw_Export!$A3="","",IF(COUNTIF($A$2:A3,A3)>1,"Duplicate","")) | K3: =IF(Raw_Export!$A3="","",IF(J3="Duplicate","Duplicate",IF(OR(C3="UNMAPPED",D3="UNMAPPED"),"Unmapped",IF(F3=0,"Blank qty",IF(F3<0,"Return","OK"))))) -> OK | L3: =IF(Raw_Export!$A3="","",IF(OR(K3="OK",K3="Return"),1,0)) -> 1 | M3: =IF(Raw_Export!$A3="","",B3-WEEKDAY(B3,2)+1) -> 46265
A4: =IF(Raw_Export!$A4="","",TRIM(Raw_Export!A4)) -> TXN-100003 | B4: =IF(Raw_Export!$A4="","",IF(ISNUMBER(Raw_Export!B4),Raw_Export!B4,IF(MID(TRIM(Raw_Export!B4),5,1)="-",DATE(LEFT(TRIM(Raw_Export!B4),4),MID(TRIM(Raw_Export!B4),6,2),RIGHT(TRIM(Raw_Export!B4),2)),DATE(RIGHT(TRIM(Raw_Export!B4),4),MATCH(MID(TRIM(Raw_Export!B4),4,3),{"Jan","Feb","Mar","Apr","May","Jun","Jul","Aug","Sep","Oct","Nov","Dec"},0),LEFT(TRIM(Raw_Export!B4),2))))) -> 46265 | C4: =IF(Raw_Export!$A4="","",IFERROR(VLOOKUP(LOWER(TRIM(Raw_Export!C4)),Maps!$A$2:$B$20,2,FALSE()),"UNMAPPED")) -> Nairobi CBD | D4: =IF(Raw_Export!$A4="","",IFERROR(VLOOKUP(LOWER(TRIM(Raw_Export!D4)),Maps!$G$2:$I$80,2,FALSE()),"UNMAPPED")) -> Juice 1L | E4: =IF(Raw_Export!$A4="","",IFERROR(VLOOKUP(LOWER(TRIM(Raw_Export!D4)),Maps!$G$2:$I$80,3,FALSE()),"UNMAPPED")) -> Beverages | F4: =IF(Raw_Export!$A4="","",IFERROR(VALUE(TRIM(Raw_Export!E4)),0)) -> 1 | G4: =IF(Raw_Export!$A4="","",IFERROR(VALUE(SUBSTITUTE(SUBSTITUTE(UPPER(TRIM(Raw_Export!F4)),"KES",""),",","")),0)) -> 210 | H4: =IF(Raw_Export!$A4="","",F4*G4) -> 210 | I4: =IF(Raw_Export!$A4="","",IFERROR(VLOOKUP(LOWER(TRIM(Raw_Export!H4)),Maps!$D$2:$E$12,2,FALSE()),"Other")) -> Cash | J4: =IF(Raw_Export!$A4="","",IF(COUNTIF($A$2:A4,A4)>1,"Duplicate","")) | K4: =IF(Raw_Export!$A4="","",IF(J4="Duplicate","Duplicate",IF(OR(C4="UNMAPPED",D4="UNMAPPED"),"Unmapped",IF(F4=0,"Blank qty",IF(F4<0,"Return","OK"))))) -> OK | L4: =IF(Raw_Export!$A4="","",IF(OR(K4="OK",K4="Return"),1,0)) -> 1 | M4: =IF(Raw_Export!$A4="","",B4-WEEKDAY(B4,2)+1) -> 46265
A5: =IF(Raw_Export!$A5="","",TRIM(Raw_Export!A5)) -> TXN-100004 | B5: =IF(Raw_Export!$A5="","",IF(ISNUMBER(Raw_Export!B5),Raw_Export!B5,IF(MID(TRIM(Raw_Export!B5),5,1)="-",DATE(LEFT(TRIM(Raw_Export!B5),4),MID(TRIM(Raw_Export!B5),6,2),RIGHT(TRIM(Raw_Export!B5),2)),DATE(RIGHT(TRIM(Raw_Export!B5),4),MATCH(MID(TRIM(Raw_Export!B5),4,3),{"Jan","Feb","Mar","Apr","May","Jun","Jul","Aug","Sep","Oct","Nov","Dec"},0),LEFT(TRIM(Raw_Export!B5),2))))) -> 46265 | C5: =IF(Raw_Export!$A5="","",IFERROR(VLOOKUP(LOWER(TRIM(Raw_Export!C5)),Maps!$A$2:$B$20,2,FALSE()),"UNMAPPED")) -> Nairobi CBD | D5: =IF(Raw_Export!$A5="","",IFERROR(VLOOKUP(LOWER(TRIM(Raw_Export!D5)),Maps!$G$2:$I$80,2,FALSE()),"UNMAPPED")) -> Peanuts 250g | E5: =IF(Raw_Export!$A5="","",IFERROR(VLOOKUP(LOWER(TRIM(Raw_Export!D5)),Maps!$G$2:$I$80,3,FALSE()),"UNMAPPED")) -> Snacks | F5: =IF(Raw_Export!$A5="","",IFERROR(VALUE(TRIM(Raw_Export!E5)),0)) -> 2 | G5: =IF(Raw_Export!$A5="","",IFERROR(VALUE(SUBSTITUTE(SUBSTITUTE(UPPER(TRIM(Raw_Export!F5)),"KES",""),",","")),0)) -> 130 | H5: =IF(Raw_Export!$A5="","",F5*G5) -> 260 | I5: =IF(Raw_Export!$A5="","",IFERROR(VLOOKUP(LOWER(TRIM(Raw_Export!H5)),Maps!$D$2:$E$12,2,FALSE()),"Other")) -> Cash | J5: =IF(Raw_Export!$A5="","",IF(COUNTIF($A$2:A5,A5)>1,"Duplicate","")) | K5: =IF(Raw_Export!$A5="","",IF(J5="Duplicate","Duplicate",IF(OR(C5="UNMAPPED",D5="UNMAPPED"),"Unmapped",IF(F5=0,"Blank qty",IF(F5<0,"Return","OK"))))) -> OK | L5: =IF(Raw_Export!$A5="","",IF(OR(K5="OK",K5="Return"),1,0)) -> 1 | M5: =IF(Raw_Export!$A5="","",B5-WEEKDAY(B5,2)+1) -> 46265
A6: =IF(Raw_Export!$A6="","",TRIM(Raw_Export!A6)) -> TXN-100005 | B6: =IF(Raw_Export!$A6="","",IF(ISNUMBER(Raw_Export!B6),Raw_Export!B6,IF(MID(TRIM(Raw_Export!B6),5,1)="-",DATE(LEFT(TRIM(Raw_Export!B6),4),MID(TRIM(Raw_Export!B6),6,2),RIGHT(TRIM(Raw_Export!B6),2)),DATE(RIGHT(TRIM(Raw_Export!B6),4),MATCH(MID(TRIM(Raw_Export!B6),4,3),{"Jan","Feb","Mar","Apr","May","Jun","Jul","Aug","Sep","Oct","Nov","Dec"},0),LEFT(TRIM(Raw_Export!B6),2))))) -> 46265 | C6: =IF(Raw_Export!$A6="","",IFERROR(VLOOKUP(LOWER(TRIM(Raw_Export!C6)),Maps!$A$2:$B$20,2,FALSE()),"UNMAPPED")) -> Nairobi CBD | D6: =IF(Raw_Export!$A6="","",IFERROR(VLOOKUP(LOWER(TRIM(Raw_Export!D6)),Maps!$G$2:$I$80,2,FALSE()),"UNMAPPED")) -> Body Lotion 400ml | E6: =IF(Raw_Export!$A6="","",IFERROR(VLOOKUP(LOWER(TRIM(Raw_Export!D6)),Maps!$G$2:$I$80,3,FALSE()),"UNMAPPED")) -> Personal Care | F6: =IF(Raw_Export!$A6="","",IFERROR(VALUE(TRIM(Raw_Export!E6)),0)) -> 4 | G6: =IF(Raw_Export!$A6="","",IFERROR(VALUE(SUBSTITUTE(SUBSTITUTE(UPPER(TRIM(Raw_Export!F6)),"KES",""),",","")),0)) -> 420 | H6: =IF(Raw_Export!$A6="","",F6*G6) -> 1680 | I6: =IF(Raw_Export!$A6="","",IFERROR(VLOOKUP(LOWER(TRIM(Raw_Export!H6)),Maps!$D$2:$E$12,2,FALSE()),"Other")) -> Cash | J6: =IF(Raw_Export!$A6="","",IF(COUNTIF($A$2:A6,A6)>1,"Duplicate","")) | K6: =IF(Raw_Export!$A6="","",IF(J6="Duplicate","Duplicate",IF(OR(C6="UNMAPPED",D6="UNMAPPED"),"Unmapped",IF(F6=0,"Blank qty",IF(F6<0,"Return","OK"))))) -> OK | L6: =IF(Raw_Export!$A6="","",IF(OR(K6="OK",K6="Return"),1,0)) -> 1 | M6: =IF(Raw_Export!$A6="","",B6-WEEKDAY(B6,2)+1) -> 46265
A7: =IF(Raw_Export!$A7="","",TRIM(Raw_Export!A7)) -> TXN-100006 | B7: =IF(Raw_Export!$A7="","",IF(ISNUMBER(Raw_Export!B7),Raw_Export!B7,IF(MID(TRIM(Raw_Export!B7),5,1)="-",DATE(LEFT(TRIM(Raw_Export!B7),4),MID(TRIM(Raw_Export!B7),6,2),RIGHT(TRIM(Raw_Export!B7),2)),DATE(RIGHT(TRIM(Raw_Export!B7),4),MATCH(MID(TRIM(Raw_Export!B7),4,3),{"Jan","Feb","Mar","Apr","May","Jun","Jul","Aug","Sep","Oct","Nov","Dec"},0),LEFT(TRIM(Raw_Export!B7),2))))) -> 46265 | C7: =IF(Raw_Export!$A7="","",IFERROR(VLOOKUP(LOWER(TRIM(Raw_Export!C7)),Maps!$A$2:$B$20,2,FALSE()),"UNMAPPED")) -> Nairobi CBD | D7: =IF(Raw_Export!$A7="","",IFERROR(VLOOKUP(LOWER(TRIM(Raw_Export!D7)),Maps!$G$2:$I$80,2,FALSE()),"UNMAPPED")) -> Toothpaste 100g | E7: =IF(Raw_Export!$A7="","",IFERROR(VLOOKUP(LOWER(TRIM(Raw_Export!D7)),Maps!$G$2:$I$80,3,FALSE()),"UNMAPPED")) -> Personal Care | F7: =IF(Raw_Export!$A7="","",IFERROR(VALUE(TRIM(Raw_Export!E7)),0)) -> 2 | G7: =IF(Raw_Export!$A7="","",IFERROR(VALUE(SUBSTITUTE(SUBSTITUTE(UPPER(TRIM(Raw_Export!F7)),"KES",""),",","")),0)) -> 176 | H7: =IF(Raw_Export!$A7="","",F7*G7) -> 352 | I7: =IF(Raw_Export!$A7="","",IFERROR(VLOOKUP(LOWER(TRIM(Raw_Export!H7)),Maps!$D$2:$E$12,2,FALSE()),"Other")) -> Cash | J7: =IF(Raw_Export!$A7="","",IF(COUNTIF($A$2:A7,A7)>1,"Duplicate","")) | K7: =IF(Raw_Export!$A7="","",IF(J7="Duplicate","Duplicate",IF(OR(C7="UNMAPPED",D7="UNMAPPED"),"Unmapped",IF(F7=0,"Blank qty",IF(F7<0,"Return","OK"))))) -> OK | L7: =IF(Raw_Export!$A7="","",IF(OR(K7="OK",K7="Return"),1,0)) -> 1 | M7: =IF(Raw_Export!$A7="","",B7-WEEKDAY(B7,2)+1) -> 46265
A8: =IF(Raw_Export!$A8="","",TRIM(Raw_Export!A8)) -> TXN-100007 | B8: =IF(Raw_Export!$A8="","",IF(ISNUMBER(Raw_Export!B8),Raw_Export!B8,IF(MID(TRIM(Raw_Export!B8),5,1)="-",DATE(LEFT(TRIM(Raw_Export!B8),4),MID(TRIM(Raw_Export!B8),6,2),RIGHT(TRIM(Raw_Export!B8),2)),DATE(RIGHT(TRIM(Raw_Export!B8),4),MATCH(MID(TRIM(Raw_Export!B8),4,3),{"Jan","Feb","Mar","Apr","May","Jun","Jul","Aug","Sep","Oct","Nov","Dec"},0),LEFT(TRIM(Raw_Export!B8),2))))) -> 46265 | C8: =IF(Raw_Export!$A8="","",IFERROR(VLOOKUP(LOWER(TRIM(Raw_Export!C8)),Maps!$A$2:$B$20,2,FALSE()),"UNMAPPED")) -> Nairobi CBD | D8: =IF(Raw_Export!$A8="","",IFERROR(VLOOKUP(LOWER(TRIM(Raw_Export!D8)),Maps!$G$2:$I$80,2,FALSE()),"UNMAPPED")) -> Biscuits 200g | E8: =IF(Raw_Export!$A8="","",IFERROR(VLOOKUP(LOWER(TRIM(Raw_Export!D8)),Maps!$G$2:$I$80,3,FALSE()),"UNMAPPED")) -> Snacks | F8: =IF(Raw_Export!$A8="","",IFERROR(VALUE(TRIM(Raw_Export!E8)),0)) -> 1 | G8: =IF(Raw_Export!$A8="","",IFERROR(VALUE(SUBSTITUTE(SUBSTITUTE(UPPER(TRIM(Raw_Export!F8)),"KES",""),",","")),0)) -> 95 | H8: =IF(Raw_Export!$A8="","",F8*G8) -> 95 | I8: =IF(Raw_Export!$A8="","",IFERROR(VLOOKUP(LOWER(TRIM(Raw_Export!H8)),Maps!$D$2:$E$12,2,FALSE()),"Other")) -> M-Pesa | J8: =IF(Raw_Export!$A8="","",IF(COUNTIF($A$2:A8,A8)>1,"Duplicate","")) | K8: =IF(Raw_Export!$A8="","",IF(J8="Duplicate","Duplicate",IF(OR(C8="UNMAPPED",D8="UNMAPPED"),"Unmapped",IF(F8=0,"Blank qty",IF(F8<0,"Return","OK"))))) -> OK | L8: =IF(Raw_Export!$A8="","",IF(OR(K8="OK",K8="Return"),1,0)) -> 1 | M8: =IF(Raw_Export!$A8="","",B8-WEEKDAY(B8,2)+1) -> 46265
A9: =IF(Raw_Export!$A9="","",TRIM(Raw_Export!A9)) -> TXN-100008 | B9: =IF(Raw_Export!$A9="","",IF(ISNUMBER(Raw_Export!B9),Raw_Export!B9,IF(MID(TRIM(Raw_Export!B9),5,1)="-",DATE(LEFT(TRIM(Raw_Export!B9),4),MID(TRIM(Raw_Export!B9),6,2),RIGHT(TRIM(Raw_Export!B9),2)),DATE(RIGHT(TRIM(Raw_Export!B9),4),MATCH(MID(TRIM(Raw_Export!B9),4,3),{"Jan","Feb","Mar","Apr","May","Jun","Jul","Aug","Sep","Oct","Nov","Dec"},0),LEFT(TRIM(Raw_Export!B9),2))))) -> 46265 | C9: =IF(Raw_Export!$A9="","",IFERROR(VLOOKUP(LOWER(TRIM(Raw_Export!C9)),Maps!$A$2:$B$20,2,FALSE()),"UNMAPPED")) -> Nairobi CBD | D9: =IF(Raw_Export!$A9="","",IFERROR(VLOOKUP(LOWER(TRIM(Raw_Export!D9)),Maps!$G$2:$I$80,2,FALSE()),"UNMAPPED")) -> Cooking Oil 1L | E9: =IF(Raw_Export!$A9="","",IFERROR(VLOOKUP(LOWER(TRIM(Raw_Export!D9)),Maps!$G$2:$I$80,3,FALSE()),"UNMAPPED")) -> Staples | F9: =IF(Raw_Export!$A9="","",IFERROR(VALUE(TRIM(Raw_Export!E9)),0)) -> 1 | G9: =IF(Raw_Export!$A9="","",IFERROR(VALUE(SUBSTITUTE(SUBSTITUTE(UPPER(TRIM(Raw_Export!F9)),"KES",""),",","")),0)) -> 330 | H9: =IF(Raw_Export!$A9="","",F9*G9) -> 330 | I9: =IF(Raw_Export!$A9="","",IFERROR(VLOOKUP(LOWER(TRIM(Raw_Export!H9)),Maps!$D$2:$E$12,2,FALSE()),"Other")) -> Cash | J9: =IF(Raw_Export!$A9="","",IF(COUNTIF($A$2:A9,A9)>1,"Duplicate","")) | K9: =IF(Raw_Export!$A9="","",IF(J9="Duplicate","Duplicate",IF(OR(C9="UNMAPPED",D9="UNMAPPED"),"Unmapped",IF(F9=0,"Blank qty",IF(F9<0,"Return","OK"))))) -> OK | L9: =IF(Raw_Export!$A9="","",IF(OR(K9="OK",K9="Return"),1,0)) -> 1 | M9: =IF(Raw_Export!$A9="","",B9-WEEKDAY(B9,2)+1) -> 46265
A10: =IF(Raw_Export!$A10="","",TRIM(Raw_Export!A10)) -> TXN-100009 | B10: =IF(Raw_Export!$A10="","",IF(ISNUMBER(Raw_Export!B10),Raw_Export!B10,IF(MID(TRIM(Raw_Export!B10),5,1)="-",DATE(LEFT(TRIM(Raw_Export!B10),4),MID(TRIM(Raw_Export!B10),6,2),RIGHT(TRIM(Raw_Export!B10),2)),DATE(RIGHT(TRIM(Raw_Export!B10),4),MATCH(MID(TRIM(Raw_Export!B10),4,3),{"Jan","Feb","Mar","Apr","May","Jun","Jul","Aug","Sep","Oct","Nov","Dec"},0),LEFT(TRIM(Raw_Export!B10),2))))) -> 46265 | C10: =IF(Raw_Export!$A10="","",IFERROR(VLOOKUP(LOWER(TRIM(Raw_Export!C10)),Maps!$A$2:$B$20,2,FALSE()),"UNMAPPED")) -> Nairobi CBD | D10: =IF(Raw_Export!$A10="","",IFERROR(VLOOKUP(LOWER(TRIM(Raw_Export!D10)),Maps!$G$2:$I$80,2,FALSE()),"UNMAPPED")) -> Toilet Paper 10pk | E10: =IF(Raw_Export!$A10="","",IFERROR(VLOOKUP(LOWER(TRIM(Raw_Export!D10)),Maps!$G$2:$I$80,3,FALSE()),"UNMAPPED")) -> Household | F10: =IF(Raw_Export!$A10="","",IFERROR(VALUE(TRIM(Raw_Export!E10)),0)) -> 1 | G10: =IF(Raw_Export!$A10="","",IFERROR(VALUE(SUBSTITUTE(SUBSTITUTE(UPPER(TRIM(Raw_Export!F10)),"KES",""),",","")),0)) -> 380 | H10: =IF(Raw_Export!$A10="","",F10*G10) -> 380 | I10: =IF(Raw_Export!$A10="","",IFERROR(VLOOKUP(LOWER(TRIM(Raw_Export!H10)),Maps!$D$2:$E$12,2,FALSE()),"Other")) -> M-Pesa | J10: =IF(Raw_Export!$A10="","",IF(COUNTIF($A$2:A10,A10)>1,"Duplicate","")) | K10: =IF(Raw_Export!$A10="","",IF(J10="Duplicate","Duplicate",IF(OR(C10="UNMAPPED",D10="UNMAPPED"),"Unmapped",IF(F10=0,"Blank qty",IF(F10<0,"Return","OK"))))) -> OK | L10: =IF(Raw_Export!$A10="","",IF(OR(K10="OK",K10="Return"),1,0)) -> 1 | M10: =IF(Raw_Export!$A10="","",B10-WEEKDAY(B10,2)+1) -> 46265
A11: =IF(Raw_Export!$A11="","",TRIM(Raw_Export!A11)) -> TXN-100010 | B11: =IF(Raw_Export!$A11="","",IF(ISNUMBER(Raw_Export!B11),Raw_Export!B11,IF(MID(TRIM(Raw_Export!B11),5,1)="-",DATE(LEFT(TRIM(Raw_Export!B11),4),MID(TRIM(Raw_Export!B11),6,2),RIGHT(TRIM(Raw_Export!B11),2)),DATE(RIGHT(TRIM(Raw_Export!B11),4),MATCH(MID(TRIM(Raw_Export!B11),4,3),{"Jan","Feb","Mar","Apr","May","Jun","Jul","Aug","Sep","Oct","Nov","Dec"},0),LEFT(TRIM(Raw_Export!B11),2))))) -> 46265 | C11: =IF(Raw_Export!$A11="","",IFERROR(VLOOKUP(LOWER(TRIM(Raw_Export!C11)),Maps!$A$2:$B$20,2,FALSE()),"UNMAPPED")) -> Nairobi CBD | D11: =IF(Raw_Export!$A11="","",IFERROR(VLOOKUP(LOWER(TRIM(Raw_Export!D11)),Maps!$G$2:$I$80,2,FALSE()),"UNMAPPED")) -> Toothpaste 100g | E11: =IF(Raw_Export!$A11="","",IFERROR(VLOOKUP(LOWER(TRIM(Raw_Export!D11)),Maps!$G$2:$I$80,3,FALSE()),"UNMAPPED")) -> Personal Care | F11: =IF(Raw_Export!$A11="","",IFERROR(VALUE(TRIM(Raw_Export!E11)),0)) -> 2 | G11: =IF(Raw_Export!$A11="","",IFERROR(VALUE(SUBSTITUTE(SUBSTITUTE(UPPER(TRIM(Raw_Export!F11)),"KES",""),",","")),0)) -> 195 | H11: =IF(Raw_Export!$A11="","",F11*G11) -> 390 | I11: =IF(Raw_Export!$A11="","",IFERROR(VLOOKUP(LOWER(TRIM(Raw_Export!H11)),Maps!$D$2:$E$12,2,FALSE()),"Other")) -> M-Pesa | J11: =IF(Raw_Export!$A11="","",IF(COUNTIF($A$2:A11,A11)>1,"Duplicate","")) | K11: =IF(Raw_Export!$A11="","",IF(J11="Duplicate","Duplicate",IF(OR(C11="UNMAPPED",D11="UNMAPPED"),"Unmapped",IF(F11=0,"Blank qty",IF(F11<0,"Return","OK"))))) -> OK | L11: =IF(Raw_Export!$A11="","",IF(OR(K11="OK",K11="Return"),1,0)) -> 1 | M11: =IF(Raw_Export!$A11="","",B11-WEEKDAY(B11,2)+1) -> 46265
A12: =IF(Raw_Export!$A12="","",TRIM(Raw_Export!A12)) -> TXN-100011 | B12: =IF(Raw_Export!$A12="","",IF(ISNUMBER(Raw_Export!B12),Raw_Export!B12,IF(MID(TRIM(Raw_Export!B12),5,1)="-",DATE(LEFT(TRIM(Raw_Export!B12),4),MID(TRIM(Raw_Export!B12),6,2),RIGHT(TRIM(Raw_Export!B12),2)),DATE(RIGHT(TRIM(Raw_Export!B12),4),MATCH(MID(TRIM(Raw_Export!B12),4,3),{"Jan","Feb","Mar","Apr","May","Jun","Jul","Aug","Sep","Oct","Nov","Dec"},0),LEFT(TRIM(Raw_Export!B12),2))))) -> 46265 | C12: =IF(Raw_Export!$A12="","",IFERROR(VLOOKUP(LOWER(TRIM(Raw_Export!C12)),Maps!$A$2:$B$20,2,FALSE()),"UNMAPPED")) -> Nairobi CBD | D12: =IF(Raw_Export!$A12="","",IFERROR(VLOOKUP(LOWER(TRIM(Raw_Export!D12)),Maps!$G$2:$I$80,2,FALSE()),"UNMAPPED")) -> Tea Leaves 250g | E12: =IF(Raw_Export!$A12="","",IFERROR(VLOOKUP(LOWER(TRIM(Raw_Export!D12)),Maps!$G$2:$I$80,3,FALSE()),"UNMAPPED")) -> Beverages | F12: =IF(Raw_Export!$A12="","",IFERROR(VALUE(TRIM(Raw_Export!E12)),0)) -> 4 | G12: =IF(Raw_Export!$A12="","",IFERROR(VALUE(SUBSTITUTE(SUBSTITUTE(UPPER(TRIM(Raw_Export!F12)),"KES",""),",","")),0)) -> 150 | H12: =IF(Raw_Export!$A12="","",F12*G12) -> 600 | I12: =IF(Raw_Export!$A12="","",IFERROR(VLOOKUP(LOWER(TRIM(Raw_Export!H12)),Maps!$D$2:$E$12,2,FALSE()),"Other")) -> Cash | J12: =IF(Raw_Export!$A12="","",IF(COUNTIF($A$2:A12,A12)>1,"Duplicate","")) | K12: =IF(Raw_Export!$A12="","",IF(J12="Duplicate","Duplicate",IF(OR(C12="UNMAPPED",D12="UNMAPPED"),"Unmapped",IF(F12=0,"Blank qty",IF(F12<0,"Return","OK"))))) -> OK | L12: =IF(Raw_Export!$A12="","",IF(OR(K12="OK",K12="Return"),1,0)) -> 1 | M12: =IF(Raw_Export!$A12="","",B12-WEEKDAY(B12,2)+1) -> 46265
A13: =IF(Raw_Export!$A13="","",TRIM(Raw_Export!A13)) -> TXN-100012 | B13: =IF(Raw_Export!$A13="","",IF(ISNUMBER(Raw_Export!B13),Raw_Export!B13,IF(MID(TRIM(Raw_Export!B13),5,1)="-",DATE(LEFT(TRIM(Raw_Export!B13),4),MID(TRIM(Raw_Export!B13),6,2),RIGHT(TRIM(Raw_Export!B13),2)),DATE(RIGHT(TRIM(Raw_Export!B13),4),MATCH(MID(TRIM(Raw_Export!B13),4,3),{"Jan","Feb","Mar","Apr","May","Jun","Jul","Aug","Sep","Oct","Nov","Dec"},0),LEFT(TRIM(Raw_Export!B13),2))))) -> 46265 | C13: =IF(Raw_Export!$A13="","",IFERROR(VLOOKUP(LOWER(TRIM(Raw_Export!C13)),Maps!$A$2:$B$20,2,FALSE()),"UNMAPPED")) -> Nairobi CBD | D13: =IF(Raw_Export!$A13="","",IFERROR(VLOOKUP(LOWER(TRIM(Raw_Export!D13)),Maps!$G$2:$I$80,2,FALSE()),"UNMAPPED")) -> Sugar 2kg | E13: =IF(Raw_Export!$A13="","",IFERROR(VLOOKUP(LOWER(TRIM(Raw_Export!D13)),Maps!$G$2:$I$80,3,FALSE()),"UNMAPPED")) -> Staples | F13: =IF(Raw_Export!$A13="","",IFERROR(VALUE(TRIM(Raw_Export!E13)),0)) -> 1 | G13: =IF(Raw_Export!$A13="","",IFERROR(VALUE(SUBSTITUTE(SUBSTITUTE(UPPER(TRIM(Raw_Export!F13)),"KES",""),",","")),0)) -> 330 | H13: =IF(Raw_Export!$A13="","",F13*G13) -> 330 | I13: =IF(Raw_Export!$A13="","",IFERROR(VLOOKUP(LOWER(TRIM(Raw_Export!H13)),Maps!$D$2:$E$12,2,FALSE()),"Other")) -> Cash | J13: =IF(Raw_Export!$A13="","",IF(COUNTIF($A$2:A13,A13)>1,"Duplicate","")) | K13: =IF(Raw_Export!$A13="","",IF(J13="Duplicate","Duplicate",IF(OR(C13="UNMAPPED",D13="UNMAPPED"),"Unmapped",IF(F13=0,"Blank qty",IF(F13<0,"Return","OK"))))) -> OK | L13: =IF(Raw_Export!$A13="","",IF(OR(K13="OK",K13="Return"),1,0)) -> 1 | M13: =IF(Raw_Export!$A13="","",B13-WEEKDAY(B13,2)+1) -> 46265
... A3001: =IF(Raw_Export!$A3001="","",TRIM(Raw_Export!A3001)) | B3001: =IF(Raw_Export!$A3001="","",IF(ISNUMBER(Raw_Export!B3001),Raw_Export!B3001,IF(MID(TRIM(Raw_Export!B3001),5,1)="-",DATE(LEFT(TRIM(Raw_Export!B3001),4),MID(TRIM(Raw_Export!B3001),6,2),RIGHT(TRIM(Raw_Export!B3001),2)),DATE(RIGHT(TRIM(Raw_Export!B3001),4),MATCH(MID(TRIM(Raw_Export!B3001),4,3),{"Jan","Feb","Mar","Apr","May","Jun","Jul","Aug","Sep","Oct","Nov","Dec"},0),LEFT(TRIM(Raw_Export!B3001),2))))) | C3001: =IF(Raw_Export!$A3001="","",IFERROR(VLOOKUP(LOWER(TRIM(Raw_Export!C3001)),Maps!$A$2:$B$20,2,FALSE()),"UNMAPPED")) | D3001: =IF(Raw_Export!$A3001="","",IFERROR(VLOOKUP(LOWER(TRIM(Raw_Export!D3001)),Maps!$G$2:$I$80,2,FALSE()),"UNMAPPED")) | E3001: =IF(Raw_Export!$A3001="","",IFERROR(VLOOKUP(LOWER(TRIM(Raw_Export!D3001)),Maps!$G$2:$I$80,3,FALSE()),"UNMAPPED")) | F3001: =IF(Raw_Export!$A3001="","",IFERROR(VALUE(TRIM(Raw_Export!E3001)),0)) | G3001: =IF(Raw_Export!$A3001="","",IFERROR(VALUE(SUBSTITUTE(SUBSTITUTE(UPPER(TRIM(Raw_Export!F3001)),"KES",""),",","")),0)) | H3001: =IF(Raw_Export!$A3001="","",F3001*G3001) | I3001: =IF(Raw_Export!$A3001="","",IFERROR(VLOOKUP(LOWER(TRIM(Raw_Export!H3001)),Maps!$D$2:$E$12,2,FALSE()),"Other")) | J3001: =IF(Raw_Export!$A3001="","",IF(COUNTIF($A$2:A3001,A3001)>1,"Duplicate","")) | K3001: =IF(Raw_Export!$A3001="","",IF(J3001="Duplicate","Duplicate",IF(OR(C3001="UNMAPPED",D3001="UNMAPPED"),"Unmapped",IF(F3001=0,"Blank qty",IF(F3001<0,"Return","OK"))))) | L3001: =IF(Raw_Export!$A3001="","",IF(OR(K3001="OK",K3001="Return"),1,0)) | M3001: =IF(Raw_Export!$A3001="","",B3001-WEEKDAY(B3001,2)+1)

Sheet Maps
A1: Branch variant (lowercase) | B1: Standard branch | D1: Payment variant (lowercase) | E1: Standard payment | G1: Product variant (lowercase) | H1: Standard product | I1: Category | K1: Product list | L1: Category | M1: Units (report week) | N1: Sales (report week, KES)
A2: nairobi cbd | B2: Nairobi CBD | D2: m-pesa | E2: M-Pesa | G2: unga pembe 2kg | H2: Unga Pembe 2kg | I2: Staples | K2: Unga Pembe 2kg | L2: Staples | M2: =SUMIFS(Clean!$F$2:$F$3001,Clean!$D$2:$D$3001,K2,Clean!$M$2:$M$3001,Assumptions!$B$4,Clean!$L$2:$L$3001,1) -> 79 | N2: =SUMIFS(Clean!$H$2:$H$3001,Clean!$D$2:$D$3001,K2,Clean!$M$2:$M$3001,Assumptions!$B$4,Clean!$L$2:$L$3001,1) -> 14934
A3: nbi cbd | B3: Nairobi CBD | D3: mpesa | E3: M-Pesa | G3: unga pembe 2 kg | H3: Unga Pembe 2kg | I3: Staples | K3: Rice Pishori 2kg | L3: Staples | M3: =SUMIFS(Clean!$F$2:$F$3001,Clean!$D$2:$D$3001,K3,Clean!$M$2:$M$3001,Assumptions!$B$4,Clean!$L$2:$L$3001,1) -> 54 | N3: =SUMIFS(Clean!$H$2:$H$3001,Clean!$D$2:$D$3001,K3,Clean!$M$2:$M$3001,Assumptions!$B$4,Clean!$L$2:$L$3001,1) -> 22428
A4: westlands | B4: Westlands | D4: cash | E4: Cash | G4: rice pishori 2kg | H4: Rice Pishori 2kg | I4: Staples | K4: Sugar 2kg | L4: Staples | M4: =SUMIFS(Clean!$F$2:$F$3001,Clean!$D$2:$D$3001,K4,Clean!$M$2:$M$3001,Assumptions!$B$4,Clean!$L$2:$L$3001,1) -> 80 | N4: =SUMIFS(Clean!$H$2:$H$3001,Clean!$D$2:$D$3001,K4,Clean!$M$2:$M$3001,Assumptions!$B$4,Clean!$L$2:$L$3001,1) -> 26466
A5: mombasa | B5: Mombasa | D5: card | E5: Card | G5: rice pishori 2 kg | H5: Rice Pishori 2kg | I5: Staples | K5: Cooking Oil 1L | L5: Staples | M5: =SUMIFS(Clean!$F$2:$F$3001,Clean!$D$2:$D$3001,K5,Clean!$M$2:$M$3001,Assumptions!$B$4,Clean!$L$2:$L$3001,1) -> 250 | N5: =SUMIFS(Clean!$H$2:$H$3001,Clean!$D$2:$D$3001,K5,Clean!$M$2:$M$3001,Assumptions!$B$4,Clean!$L$2:$L$3001,1) -> 81180
A6: msa | B6: Mombasa | D6: visa | E6: Card | G6: sugar 2kg | H6: Sugar 2kg | I6: Staples | K6: Salt 500g | L6: Staples | M6: =SUMIFS(Clean!$F$2:$F$3001,Clean!$D$2:$D$3001,K6,Clean!$M$2:$M$3001,Assumptions!$B$4,Clean!$L$2:$L$3001,1) -> 109 | N6: =SUMIFS(Clean!$H$2:$H$3001,Clean!$D$2:$D$3001,K6,Clean!$M$2:$M$3001,Assumptions!$B$4,Clean!$L$2:$L$3001,1) -> 4324
A7: kisumu | B7: Kisumu | G7: sugar 2 kg | H7: Sugar 2kg | I7: Staples | K7: Spaghetti 400g | L7: Staples | M7: =SUMIFS(Clean!$F$2:$F$3001,Clean!$D$2:$D$3001,K7,Clean!$M$2:$M$3001,Assumptions!$B$4,Clean!$L$2:$L$3001,1) -> 96 | N7: =SUMIFS(Clean!$H$2:$H$3001,Clean!$D$2:$D$3001,K7,Clean!$M$2:$M$3001,Assumptions!$B$4,Clean!$L$2:$L$3001,1) -> 10494
A8: nakuru | B8: Nakuru | G8: cooking oil 1l | H8: Cooking Oil 1L | I8: Staples | K8: Fresh Milk 500ml | L8: Dairy & Eggs | M8: =SUMIFS(Clean!$F$2:$F$3001,Clean!$D$2:$D$3001,K8,Clean!$M$2:$M$3001,Assumptions!$B$4,Clean!$L$2:$L$3001,1) -> 120 | N8: =SUMIFS(Clean!$H$2:$H$3001,Clean!$D$2:$D$3001,K8,Clean!$M$2:$M$3001,Assumptions!$B$4,Clean!$L$2:$L$3001,1) -> 7772
G9: cooking oil 1 l | H9: Cooking Oil 1L | I9: Staples | K9: Yoghurt 500ml | L9: Dairy & Eggs | M9: =SUMIFS(Clean!$F$2:$F$3001,Clean!$D$2:$D$3001,K9,Clean!$M$2:$M$3001,Assumptions!$B$4,Clean!$L$2:$L$3001,1) -> 82 | N9: =SUMIFS(Clean!$H$2:$H$3001,Clean!$D$2:$D$3001,K9,Clean!$M$2:$M$3001,Assumptions!$B$4,Clean!$L$2:$L$3001,1) -> 9804
G10: salt 500g | H10: Salt 500g | I10: Staples | K10: Butter 250g | L10: Dairy & Eggs | M10: =SUMIFS(Clean!$F$2:$F$3001,Clean!$D$2:$D$3001,K10,Clean!$M$2:$M$3001,Assumptions!$B$4,Clean!$L$2:$L$3001,1) -> 32 | N10: =SUMIFS(Clean!$H$2:$H$3001,Clean!$D$2:$D$3001,K10,Clean!$M$2:$M$3001,Assumptions!$B$4,Clean!$L$2:$L$3001,1) -> 9858
G11: salt 500 g | H11: Salt 500g | I11: Staples | K11: Eggs Tray 30 | L11: Dairy & Eggs | M11: =SUMIFS(Clean!$F$2:$F$3001,Clean!$D$2:$D$3001,K11,Clean!$M$2:$M$3001,Assumptions!$B$4,Clean!$L$2:$L$3001,1) -> 93 | N11: =SUMIFS(Clean!$H$2:$H$3001,Clean!$D$2:$D$3001,K11,Clean!$M$2:$M$3001,Assumptions!$B$4,Clean!$L$2:$L$3001,1) -> 41355
G12: spaghetti 400g | H12: Spaghetti 400g | I12: Staples | K12: Cheddar 200g | L12: Dairy & Eggs | M12: =SUMIFS(Clean!$F$2:$F$3001,Clean!$D$2:$D$3001,K12,Clean!$M$2:$M$3001,Assumptions!$B$4,Clean!$L$2:$L$3001,1) -> 25 | N12: =SUMIFS(Clean!$H$2:$H$3001,Clean!$D$2:$D$3001,K12,Clean!$M$2:$M$3001,Assumptions!$B$4,Clean!$L$2:$L$3001,1) -> 9424
G13: spaghetti 400 g | H13: Spaghetti 400g | I13: Staples | K13: Tea Leaves 250g | L13: Beverages | M13: =SUMIFS(Clean!$F$2:$F$3001,Clean!$D$2:$D$3001,K13,Clean!$M$2:$M$3001,Assumptions!$B$4,Clean!$L$2:$L$3001,1) -> 101 | N13: =SUMIFS(Clean!$H$2:$H$3001,Clean!$D$2:$D$3001,K13,Clean!$M$2:$M$3001,Assumptions!$B$4,Clean!$L$2:$L$3001,1) -> 15120
G14: fresh milk 500ml | H14: Fresh Milk 500ml | I14: Dairy & Eggs | K14: Coffee 100g | L14: Beverages | M14: =SUMIFS(Clean!$F$2:$F$3001,Clean!$D$2:$D$3001,K14,Clean!$M$2:$M$3001,Assumptions!$B$4,Clean!$L$2:$L$3001,1) -> 48 | N14: =SUMIFS(Clean!$H$2:$H$3001,Clean!$D$2:$D$3001,K14,Clean!$M$2:$M$3001,Assumptions!$B$4,Clean!$L$2:$L$3001,1) -> 17136
G15: fresh milk 500 ml | H15: Fresh Milk 500ml | I15: Dairy & Eggs | K15: Soda 500ml | L15: Beverages | M15: =SUMIFS(Clean!$F$2:$F$3001,Clean!$D$2:$D$3001,K15,Clean!$M$2:$M$3001,Assumptions!$B$4,Clean!$L$2:$L$3001,1) -> 235 | N15: =SUMIFS(Clean!$H$2:$H$3001,Clean!$D$2:$D$3001,K15,Clean!$M$2:$M$3001,Assumptions!$B$4,Clean!$L$2:$L$3001,1) -> 13878
G16: yoghurt 500ml | H16: Yoghurt 500ml | I16: Dairy & Eggs | K16: Juice 1L | L16: Beverages | M16: =SUMIFS(Clean!$F$2:$F$3001,Clean!$D$2:$D$3001,K16,Clean!$M$2:$M$3001,Assumptions!$B$4,Clean!$L$2:$L$3001,1) -> 60 | N16: =SUMIFS(Clean!$H$2:$H$3001,Clean!$D$2:$D$3001,K16,Clean!$M$2:$M$3001,Assumptions!$B$4,Clean!$L$2:$L$3001,1) -> 12453
G17: yoghurt 500 ml | H17: Yoghurt 500ml | I17: Dairy & Eggs | K17: Bottled Water 1.5L | L17: Beverages | M17: =SUMIFS(Clean!$F$2:$F$3001,Clean!$D$2:$D$3001,K17,Clean!$M$2:$M$3001,Assumptions!$B$4,Clean!$L$2:$L$3001,1) -> 100 | N17: =SUMIFS(Clean!$H$2:$H$3001,Clean!$D$2:$D$3001,K17,Clean!$M$2:$M$3001,Assumptions!$B$4,Clean!$L$2:$L$3001,1) -> 9000
G18: butter 250g | H18: Butter 250g | I18: Dairy & Eggs | K18: Washing Powder 1kg | L18: Household | M18: =SUMIFS(Clean!$F$2:$F$3001,Clean!$D$2:$D$3001,K18,Clean!$M$2:$M$3001,Assumptions!$B$4,Clean!$L$2:$L$3001,1) -> 66 | N18: =SUMIFS(Clean!$H$2:$H$3001,Clean!$D$2:$D$3001,K18,Clean!$M$2:$M$3001,Assumptions!$B$4,Clean!$L$2:$L$3001,1) -> 18144
G19: butter 250 g | H19: Butter 250g | I19: Dairy & Eggs | K19: Dish Soap 750ml | L19: Household | M19: =SUMIFS(Clean!$F$2:$F$3001,Clean!$D$2:$D$3001,K19,Clean!$M$2:$M$3001,Assumptions!$B$4,Clean!$L$2:$L$3001,1) -> 54 | N19: =SUMIFS(Clean!$H$2:$H$3001,Clean!$D$2:$D$3001,K19,Clean!$M$2:$M$3001,Assumptions!$B$4,Clean!$L$2:$L$3001,1) -> 10260
G20: eggs tray 30 | H20: Eggs Tray 30 | I20: Dairy & Eggs | K20: Toilet Paper 10pk | L20: Household | M20: =SUMIFS(Clean!$F$2:$F$3001,Clean!$D$2:$D$3001,K20,Clean!$M$2:$M$3001,Assumptions!$B$4,Clean!$L$2:$L$3001,1) -> 38 | N20: =SUMIFS(Clean!$H$2:$H$3001,Clean!$D$2:$D$3001,K20,Clean!$M$2:$M$3001,Assumptions!$B$4,Clean!$L$2:$L$3001,1) -> 14136
... G32: bottled water 1.5 l | H32: Bottled Water 1.5L | I32: Beverages | K32: Bread Loaf 400g | L32: Snacks | M32: =SUMIFS(Clean!$F$2:$F$3001,Clean!$D$2:$D$3001,K32,Clean!$M$2:$M$3001,Assumptions!$B$4,Clean!$L$2:$L$3001,1) -> 67 | N32: =SUMIFS(Clean!$H$2:$H$3001,Clean!$D$2:$D$3001,K32,Clean!$M$2:$M$3001,Assumptions!$B$4,Clean!$L$2:$L$3001,1) -> 4355
G33: washing powder 1kg | H33: Washing Powder 1kg | I33: Household
G34: washing powder 1 kg | H34: Washing Powder 1kg | I34: Household
G35: dish soap 750ml | H35: Dish Soap 750ml | I35: Household
G36: dish soap 750 ml | H36: Dish Soap 750ml | I36: Household
G37: toilet paper 10pk | H37: Toilet Paper 10pk | I37: Household
G38: toilet paper 10 pk | H38: Toilet Paper 10pk | I38: Household
G39: bleach 1l | H39: Bleach 1L | I39: Household
G40: bleach 1 l | H40: Bleach 1L | I40: Household
G41: matches 10pk | H41: Matches 10pk | I41: Household
G42: matches 10 pk | H42: Matches 10pk | I42: Household
G43: bath soap 175g | H43: Bath Soap 175g | I43: Personal Care
G44: bath soap 175 g | H44: Bath Soap 175g | I44: Personal Care
... G62: bread loaf 400 g | H62: Bread Loaf 400g | I62: Snacks

Sheet Raw_Export
A1: Txn ID | B1: Date | C1: Branch | D1: Product | E1: Qty | F1: Unit price | G1: Cashier | H1: Payment
A2: TXN-100001 | B2: 2026-08-31 | C2: NBI CBD | D2: Cheddar 200g | E2: 6 | F2: 380 | G2: C04 | H2: Cash
A3: TXN-100002 | B3: 2026-08-31 | C3: NBI CBD | D3: spaghetti 400 g | E3: 1 | F3: KES 110 | G3: C07 | H3: Mpesa
A4: TXN-100003 | B4: 2026-08-31 | C4: NAIROBI CBD | D4: Juice 1L | E4: 1 | F4: 210 | G4: C03 | H4: Cash
A5: TXN-100004 | B5: 31-Aug-2026 | C5: Nairobi Cbd | D5: Peanuts 250g | E5: 2 | F5: KES 130 | G5: C08 | H5: Cash
A6: TXN-100005 | B6: 46265 | C6: Nairobi CBD | D6: Body Lotion 400ml | E6: 4 | F6: 420 | G6: C05 | H6: Cash
A7: TXN-100006 | B7: 2026-08-31 | C7: NAIROBI CBD | D7: Toothpaste 100g | E7: 2 | F7: KES 176 | G7: C01 | H7: Cash
A8: TXN-100007 | B8: 2026-08-31 | C8: NAIROBI CBD | D8: BISCUITS 200G | E8: 1 | F8: 95 | G8: C08 | H8: m-pesa
A9: TXN-100008 | B9: 31-Aug-2026 | C9: Nairobi CBD | D9: Cooking Oil 1L | E9: 1 | F9: 330 | G9: C02 | H9: Cash
A10: TXN-100009 | B10: 2026-08-31 | C10: Nairobi Cbd | D10: Toilet Paper 10pk | E10: 1 | F10: KES 380 | G10: C06 | H10: Mpesa
A11: TXN-100010 | B11: 31-Aug-2026 | C11: nairobi cbd | D11: toothpaste 100g | E11: 2 | F11: KES 195 | G11: C06 | H11: Mpesa
A12: TXN-100011 | B12: 46265 | C12: NAIROBI CBD | D12: tea leaves 250 g | E12: 4 | F12: 150 | G12: C02 | H12: Cash
A13: TXN-100012 | B13: 2026-08-31 | C13: NAIROBI CBD | D13: Sugar 2kg | E13: 1 | F13: 330 | G13: C04 | H13: Cash
A14: TXN-100013 | B14: 31-Aug-2026 | C14: Nairobi Cbd | D14: DEODORANT 150ML | E14: 3 | F14: 350 | G14: C05 | H14: Cash
A15: TXN-100014 | B15: 46265 | C15: NBI CBD | D15: bread loaf 400g | E15: 1 | F15: 65 | G15: C04 | H15: Cash
A16: TXN-100015 | B16: 46265 | C16: Nairobi Cbd | D16: Cooking Oil 1L | E16: 1 | F16: 330 | G16: C05 | H16: M-Pesa
A17: TXN-100016 | B17: 46265 | C17: Nairobi Cbd | D17: butter 250 g | E17: 2 | F17: KES 310 | G17: C05 | H17: Card
A18: TXN-100017 | B18: 31-Aug-2026 | C18: NAIROBI CBD | D18: Deodorant 150ml | E18: 1 | F18: 315 | G18: C02 | H18: Mpesa
A19: TXN-100018 | B19: 2026-08-31 | C19: NAIROBI CBD | D19: Cheddar 200g | E19: 6 | F19: 380 | G19: C04 | H19: Mpesa
A20: TXN-100019 | B20: 2026-08-31 | C20: Nairobi CBD | D20: Chocolate Bar 90g | E20: 1 | F20: 140 | G20: C07 | H20: Cash
A21: TXN-100020 | B21: 2026-08-31 | C21: nairobi cbd | D21: Salt 500g | E21: 4 | F21: 36 | G21: C07 | H21: Cash
A22: TXN-100021 | B22: 2026-08-31 | C22: nairobi cbd | D22: Spaghetti 400g | E22: 6 | F22: 110 | G22: C04 | H22: Mpesa
A23: TXN-100022 | B23: 2026-08-31 | C23: Nairobi CBD | D23: Tea Leaves 250g | E23: 6 | F23: 150 | G23: C05 | H23: M-Pesa
A24: TXN-100023 | B24: 2026-08-31 | C24: nairobi cbd | D24: BUTTER 250G | E24: 6 | F24: 310 | G24: C05 | H24: M-Pesa
A25: TXN-100024 | B25: 2026-08-31 | C25: Nairobi CBD | D25: SODA 500ML | E25: 4 | F25: 60 | G25: C04 | H25: M-Pesa
A26: TXN-100025 | B26: 2026-08-31 | C26: nairobi cbd | D26: bottled water 1.5l x | E26: 1 | F26: 90 | G26: C07 | H26: Card
A27: TXN-100026 | B27: 31-Aug-2026 | C27: nairobi cbd | D27: Unga Pembe 2kg | E27: 3 | F27: 190 | G27: C02 | H27: M-Pesa
A28: TXN-100027 | B28: 2026-08-31 | C28: Nairobi CBD | D28: Coffee 100g | E28: 6 | F28: 360 | G28: C01 | H28: CARD
A29: TXN-100028 | B29: 2026-08-31 | C29: NBI CBD | D29: Cooking Oil 1L | E29: 6 | F29: 330 | G29: C03 | H29: CASH
A30: TXN-100029 | B30: 2026-08-31 | C30: Nairobi Cbd | D30: Coffee 100g | E30: 6 | F30: 360 | G30: C02 | H30: m-pesa
A31: TXN-100030 | B31: 31-Aug-2026 | C31: Nairobi Cbd | D31: Bath Soap 175g | E31: 1 | F31: KES 85 | G31: C03 | H31: Card
A32: TXN-100031 | B32: 31-Aug-2026 | C32: nairobi cbd | D32: Eggs Tray 30 | E32: 2 | F32: 450 | G32: C02 | H32: Card
A33: TXN-100032 | B33: 31-Aug-2026 | C33: NAIROBI CBD | D33: Bleach 1L | E33: 4 | F33: 160 | G33: C06 | H33: CASH
A34: TXN-100033 | B34: 2026-08-31 | C34: Nairobi CBD | D34: Soda 500ml | E34: 1 | F34: KES 60 | G34: C08 | H34: Cash
A35: TXN-100034 | B35: 2026-08-31 | C35: Nairobi CBD | D35: Peanuts 250g | E35: 2 | F35: KES 130 | G35: C06 | H35: M-PESA
A36: TXN-100035 | B36: 2026-08-31 | C36: Nairobi Cbd | D36: body lotion 400 ml | E36: 1 | F36: KES 420 | G36: C07 | H36: Cash
A37: TXN-100036 | B37: 2026-08-31 | C37: Westlands | D37: Biscuits 200g | E37: 3 | F37: 95 | G37: C06 | H37: CARD
A38: TXN-100037 | B38: 2026-08-31 | C38: Westlands | D38: Yoghurt 500ml | E38: 3 | F38: 120 | G38: C01 | H38: Cash
A39: TXN-100038 | B39: 31-Aug-2026 | C39: Westlands | D39: EGGS TRAY 30 | E39: 6 | F39: 450 | G39: C03 | H39: M-PESA
A40: TXN-100039 | B40: 31-Aug-2026 | C40: westlands | D40: tea leaves 250 g | E40: 2 | F40: KES 150 | G40: C06 | H40: M-Pesa
...
