Workbook

Sheet README
A1: Customer Support Performance & SLA – Operations Analytics Portfolio Project
A2: BZME Insights | Sector: Customer Support / BPO / Operations | Tool: Excel (formula-driven)
A4: BUSINESS PROBLEM
A5: A support centre handles thousands of tickets across chat, WhatsApp, email and phone. Management needs to see whether service-level targets are being met, where delays and reopened tickets come from, and which agents need coaching.
A7: BUSINESS QUESTIONS
A8: 1. Are first-response and resolution SLAs being met, by priority, channel and category?
A9: 2. What is customer satisfaction (CSAT) and what drives it down?
A10: 3. Which categories have the lowest resolution SLA and the highest reopen rate?
A11: 4. What is the open backlog and how much of it is aged?
A12: 5. Which days are busiest, and which agents need coaching?
A14: HOW THE WORKBOOK IS BUILT
A15: Tickets: 6,918 synthetic tickets (Jul-Sep 2026) with channel, category, priority, agent, response and resolution times, status, CSAT and reopen flag.
... A35: Clear aged backlog first and set an escalation rule to reduce escalations, which lower CSAT.

Sheet Dashboard
A1: Customer Support Performance & SLA Dashboard
A2: ="Fictional Kenyan e-commerce and delivery company | Synthetic data | "&TEXT(Assumptions!B5,"d mmm yyyy")&" to "&TEXT(Assumptions!B4,"d mmm yyyy")&" | Prepared by BZME Insights" -> Fictional Kenyan e-commerce and delivery company | Synthetic data | 1 Jul 2026 to 30 Sep 2026 | Prepared by BZME Insights
A4: TICKETS | C4: RESPONSE SLA MET | E4: RESOLUTION SLA MET | G4: AVG RESOLUTION (HRS) | I4: AVG CSAT (1-5) | K4: OPEN TICKETS (BACKLOG)
A5: =COUNTA(Tickets!$A$2:$A$6919) -> 6918 | C5: =COUNTIF(Tickets!$N$2:$N$6919,"Yes")/COUNTA(Tickets!$A$2:$A$6919) -> 0.87901127 | E5: =COUNTIF(Tickets!$O$2:$O$6919,"Yes")/(COUNTIF(Tickets!$O$2:$O$6919,"Yes")+COUNTIF(Tickets!$O$2:$O$6919,"No")) -> 0.8147439 | G5: =AVERAGE(Tickets!$H$2:$H$6919) -> 16.121254 | I5: =AVERAGE(Tickets!$J$2:$J$6919) -> 4.1381733 | K5: =COUNTIF(Tickets!$I$2:$I$6919,"Open") -> 651
A7: Key findings (update automatically)
A8: ="1. The team handled "&TEXT(A5,"#,##0")&" tickets in "&Assumptions!B6&" months. Response SLA is "&TEXT(C5,"0.0%")&" (target "&TEXT(Assumptions!B7,"0%")&"), resolution SLA "&TEXT(E5,"0.0%")&" (target "&TEXT(Assumptions!B8,"0%")&"), CSAT "&TEXT(I5,"0.00")&" (target "&TEXT(Assumptions!B9,"0.0")&")." -> 1. The team handled 6,918 tickets in 3 months. Response SLA is 87.9% (target 90%), resolution SLA 81.5% (target 85%), CSAT 4.14 (target 4.2).
A9: ="2. "&INDEX(A26:A29,MATCH(MIN(F26:F29),F26:F29,0))&" tickets have the weakest resolution SLA ("&TEXT(MIN(F26:F29),"0%")&"), while "&INDEX(A26:A29,MATCH(MAX(F26:F29),F26:F29,0))&" tickets reach "&TEXT(MAX(F26:F29),"0%")&"." -> 2. Urgent tickets have the weakest resolution SLA (57%), while Low tickets reach 95%.
A10: ="3. "&INDEX(A35:A38,MATCH(MAX(C35:C38),C35:C38,0))&" is the slowest channel for first response (average "&TEXT(MAX(C35:C38),"0")&" minutes) and "&INDEX(A35:A38,MATCH(MIN(C35:C38),C35:C38,0))&" the fastest ("&TEXT(MIN(C35:C38),"0")&")." -> 3. Email is the slowest channel for first response (average 103 minutes) and Phone the fastest (3).
A11: ="4. "&INDEX(A51:A55,MATCH(MIN(D51:D55),D51:D55,0))&" has the lowest resolution SLA ("&TEXT(MIN(D51:D55),"0%")&"); "&INDEX(A51:A55,MATCH(MAX(E51:E55),E51:E55,0))&" has the highest reopen rate ("&TEXT(MAX(E51:E55),"0.0%")&")." -> 4. Refund has the lowest resolution SLA (56%); Account has the highest reopen rate (8.8%).
A12: ="5. "&K5&" tickets are open, and "&COUNTIFS(Tickets!$I$2:$I$6919,"Open",Tickets!$B$2:$B$6919,"<"&(Assumptions!B4-Assumptions!B11))&" of them are older than "&Assumptions!B11&" days (aged backlog)." -> 5. 651 tickets are open, and 415 of them are older than 3 days (aged backlog).
A13: ="6. "&INDEX(A67:A73,MATCH(MAX(B67:B73),B67:B73,0))&" is the busiest day ("&TEXT(MAX(C67:C73),"0")&" tickets per day on average) - schedule extra cover." -> 6. Monday is the busiest day (98 tickets per day on average) - schedule extra cover.
A14: ="7. "&B93&" of "&COUNTA(Agents!$A$2:$A$19)&" agents miss all three targets and need coaching, and "&B92&" are on watch. Top performer: "&B84&"." -> 7. 6 of 18 agents miss all three targets and need coaching, and 7 are on watch. Top performer: AG11.
A15: ="8. Escalated tickets average CSAT "&TEXT(IFERROR(AVERAGEIFS(Tickets!$J$2:$J$6919,Tickets!$I$2:$I$6919,"Escalated"),0),"0.00")&" versus "&TEXT(IFERROR(AVERAGEIFS(Tickets!$J$2:$J$6919,Tickets!$I$2:$I$6919,"Resolved"),0),"0.00")&" for resolved tickets - escalation hurts satisfaction." -> 8. Escalated tickets average CSAT 3.15 versus 4.20 for resolved tickets - escalation hurts satisfaction.
A17: 1. Monthly trend
A18: Month start | B18: Month | C18: Tickets | D18: Response SLA % | E18: Resolution SLA % | F18: Avg CSAT | G18: Avg Resolution (hrs)
A19: =DATE(YEAR(Assumptions!$B$5),MONTH(Assumptions!$B$5),1) -> 46204 | B19: =TEXT(A19,"mmm") -> Jul | C19: =COUNTIFS(Tickets!$L$2:$L$6919,A19) -> 2251 | D19: =IFERROR(COUNTIFS(Tickets!$L$2:$L$6919,A19,Tickets!$N$2:$N$6919,"Yes")/C19,0) -> 0.87872057 | E19: =IFERROR(COUNTIFS(Tickets!$L$2:$L$6919,A19,Tickets!$O$2:$O$6919,"Yes")/(COUNTIFS(Tickets!$L$2:$L$6919,A19,Tickets!$O$2:$O$6919,"Yes")+COUNTIFS(Tickets!$L$2:$L$6919,A19,Tickets!$O$2:$O$6919,"No")),0) -> 0.82201087 | F19: =IFERROR(AVERAGEIFS(Tickets!$J$2:$J$6919,Tickets!$L$2:$L$6919,A19),0) -> 4.1267723 | G19: =IFERROR(AVERAGEIFS(Tickets!$H$2:$H$6919,Tickets!$L$2:$L$6919,A19),0) -> 15.838089
A20: =EDATE(A19,1) -> 46235 | B20: =TEXT(A20,"mmm") -> Aug | C20: =COUNTIFS(Tickets!$L$2:$L$6919,A20) -> 2239 | D20: =IFERROR(COUNTIFS(Tickets!$L$2:$L$6919,A20,Tickets!$N$2:$N$6919,"Yes")/C20,0) -> 0.87449754 | E20: =IFERROR(COUNTIFS(Tickets!$L$2:$L$6919,A20,Tickets!$O$2:$O$6919,"Yes")/(COUNTIFS(Tickets!$L$2:$L$6919,A20,Tickets!$O$2:$O$6919,"Yes")+COUNTIFS(Tickets!$L$2:$L$6919,A20,Tickets!$O$2:$O$6919,"No")),0) -> 0.80594966 | F20: =IFERROR(AVERAGEIFS(Tickets!$J$2:$J$6919,Tickets!$L$2:$L$6919,A20),0) -> 4.1531842 | G20: =IFERROR(AVERAGEIFS(Tickets!$H$2:$H$6919,Tickets!$L$2:$L$6919,A20),0) -> 16.140503
A21: =EDATE(A20,1) -> 46266 | B21: =TEXT(A21,"mmm") -> Sep | C21: =COUNTIFS(Tickets!$L$2:$L$6919,A21) -> 2428 | D21: =IFERROR(COUNTIFS(Tickets!$L$2:$L$6919,A21,Tickets!$N$2:$N$6919,"Yes")/C21,0) -> 0.88344316 | E21: =IFERROR(COUNTIFS(Tickets!$L$2:$L$6919,A21,Tickets!$O$2:$O$6919,"Yes")/(COUNTIFS(Tickets!$L$2:$L$6919,A21,Tickets!$O$2:$O$6919,"Yes")+COUNTIFS(Tickets!$L$2:$L$6919,A21,Tickets!$O$2:$O$6919,"No")),0) -> 0.81643543 | F21: =IFERROR(AVERAGEIFS(Tickets!$J$2:$J$6919,Tickets!$L$2:$L$6919,A21),0) -> 4.1345972 | G21: =IFERROR(AVERAGEIFS(Tickets!$H$2:$H$6919,Tickets!$L$2:$L$6919,A21),0) -> 16.432444
A24: 2. SLA performance by priority
A25: Priority | B25: Tickets | C25: Response target (min) | D25: Response SLA % | E25: Resolution target (hrs) | F25: Resolution SLA % | G25: Avg CSAT
A26: Urgent | B26: =COUNTIFS(Tickets!$E$2:$E$6919,A26) -> 413 | C26: =INDEX(Assumptions!$B$15:$B$18,MATCH(A26,Assumptions!$A$15:$A$18,0)) -> 15 | D26: =IFERROR(COUNTIFS(Tickets!$E$2:$E$6919,A26,Tickets!$N$2:$N$6919,"Yes")/B26,0) -> 0.74576271 | E26: =INDEX(Assumptions!$C$15:$C$18,MATCH(A26,Assumptions!$A$15:$A$18,0)) -> 4 | F26: =IFERROR(COUNTIFS(Tickets!$E$2:$E$6919,A26,Tickets!$O$2:$O$6919,"Yes")/(COUNTIFS(Tickets!$E$2:$E$6919,A26,Tickets!$O$2:$O$6919,"Yes")+COUNTIFS(Tickets!$E$2:$E$6919,A26,Tickets!$O$2:$O$6919,"No")),0) -> 0.57180851 | G26: =IFERROR(AVERAGEIFS(Tickets!$J$2:$J$6919,Tickets!$E$2:$E$6919,A26),0) -> 3.9575472
A27: High | B27: =COUNTIFS(Tickets!$E$2:$E$6919,A27) -> 1239 | C27: =INDEX(Assumptions!$B$15:$B$18,MATCH(A27,Assumptions!$A$15:$A$18,0)) -> 30 | D27: =IFERROR(COUNTIFS(Tickets!$E$2:$E$6919,A27,Tickets!$N$2:$N$6919,"Yes")/B27,0) -> 0.80468119 | E27: =INDEX(Assumptions!$C$15:$C$18,MATCH(A27,Assumptions!$A$15:$A$18,0)) -> 8 | F27: =IFERROR(COUNTIFS(Tickets!$E$2:$E$6919,A27,Tickets!$O$2:$O$6919,"Yes")/(COUNTIFS(Tickets!$E$2:$E$6919,A27,Tickets!$O$2:$O$6919,"Yes")+COUNTIFS(Tickets!$E$2:$E$6919,A27,Tickets!$O$2:$O$6919,"No")),0) -> 0.65572316 | G27: =IFERROR(AVERAGEIFS(Tickets!$J$2:$J$6919,Tickets!$E$2:$E$6919,A27),0) -> 4.0016584
A28: Medium | B28: =COUNTIFS(Tickets!$E$2:$E$6919,A28) -> 3231 | C28: =INDEX(Assumptions!$B$15:$B$18,MATCH(A28,Assumptions!$A$15:$A$18,0)) -> 60 | D28: =IFERROR(COUNTIFS(Tickets!$E$2:$E$6919,A28,Tickets!$N$2:$N$6919,"Yes")/B28,0) -> 0.86412875 | E28: =INDEX(Assumptions!$C$15:$C$18,MATCH(A28,Assumptions!$A$15:$A$18,0)) -> 24 | F28: =IFERROR(COUNTIFS(Tickets!$E$2:$E$6919,A28,Tickets!$O$2:$O$6919,"Yes")/(COUNTIFS(Tickets!$E$2:$E$6919,A28,Tickets!$O$2:$O$6919,"Yes")+COUNTIFS(Tickets!$E$2:$E$6919,A28,Tickets!$O$2:$O$6919,"No")),0) -> 0.8248974 | G28: =IFERROR(AVERAGEIFS(Tickets!$J$2:$J$6919,Tickets!$E$2:$E$6919,A28),0) -> 4.1378245
A29: Low | B29: =COUNTIFS(Tickets!$E$2:$E$6919,A29) -> 2035 | C29: =INDEX(Assumptions!$B$15:$B$18,MATCH(A29,Assumptions!$A$15:$A$18,0)) -> 240 | D29: =IFERROR(COUNTIFS(Tickets!$E$2:$E$6919,A29,Tickets!$N$2:$N$6919,"Yes")/B29,0) -> 0.97493857 | E29: =INDEX(Assumptions!$C$15:$C$18,MATCH(A29,Assumptions!$A$15:$A$18,0)) -> 72 | F29: =IFERROR(COUNTIFS(Tickets!$E$2:$E$6919,A29,Tickets!$O$2:$O$6919,"Yes")/(COUNTIFS(Tickets!$E$2:$E$6919,A29,Tickets!$O$2:$O$6919,"Yes")+COUNTIFS(Tickets!$E$2:$E$6919,A29,Tickets!$O$2:$O$6919,"No")),0) -> 0.94565217 | G29: =IFERROR(AVERAGEIFS(Tickets!$J$2:$J$6919,Tickets!$E$2:$E$6919,A29),0) -> 4.2614446
A30: Total | B30: =SUM(B26:B29) -> 6918 | D30: =C5 -> 0.87901127 | F30: =E5 -> 0.8147439 | G30: =I5 -> 4.1381733
A33: 3. Channel performance
A34: Channel | B34: Tickets | C34: Avg First Response (min) | D34: Response SLA % | E34: Avg Resolution (hrs) | F34: Avg CSAT
A35: Chat | B35: =COUNTIFS(Tickets!$C$2:$C$6919,A35) -> 2057 | C35: =IFERROR(AVERAGEIFS(Tickets!$G$2:$G$6919,Tickets!$C$2:$C$6919,A35),0) -> 5.6315022 | D35: =IFERROR(COUNTIFS(Tickets!$C$2:$C$6919,A35,Tickets!$N$2:$N$6919,"Yes")/B35,0) -> 0.99854157 | E35: =IFERROR(AVERAGEIFS(Tickets!$H$2:$H$6919,Tickets!$C$2:$C$6919,A35),0) -> 16.159017 | F35: =IFERROR(AVERAGEIFS(Tickets!$J$2:$J$6919,Tickets!$C$2:$C$6919,A35),0) -> 4.1732926
A36: WhatsApp | B36: =COUNTIFS(Tickets!$C$2:$C$6919,A36) -> 1895 | C36: =IFERROR(AVERAGEIFS(Tickets!$G$2:$G$6919,Tickets!$C$2:$C$6919,A36),0) -> 14.861214 | D36: =IFERROR(COUNTIFS(Tickets!$C$2:$C$6919,A36,Tickets!$N$2:$N$6919,"Yes")/B36,0) -> 0.98047493 | E36: =IFERROR(AVERAGEIFS(Tickets!$H$2:$H$6919,Tickets!$C$2:$C$6919,A36),0) -> 16.167723 | F36: =IFERROR(AVERAGEIFS(Tickets!$J$2:$J$6919,Tickets!$C$2:$C$6919,A36),0) -> 4.1675338
A37: Email | B37: =COUNTIFS(Tickets!$C$2:$C$6919,A37) -> 1556 | C37: =IFERROR(AVERAGEIFS(Tickets!$G$2:$G$6919,Tickets!$C$2:$C$6919,A37),0) -> 102.75193 | D37: =IFERROR(COUNTIFS(Tickets!$C$2:$C$6919,A37,Tickets!$N$2:$N$6919,"Yes")/B37,0) -> 0.4877892 | E37: =IFERROR(AVERAGEIFS(Tickets!$H$2:$H$6919,Tickets!$C$2:$C$6919,A37),0) -> 16.254284 | F37: =IFERROR(AVERAGEIFS(Tickets!$J$2:$J$6919,Tickets!$C$2:$C$6919,A37),0) -> 3.9910828
A38: Phone | B38: =COUNTIFS(Tickets!$C$2:$C$6919,A38) -> 1410 | C38: =IFERROR(AVERAGEIFS(Tickets!$G$2:$G$6919,Tickets!$C$2:$C$6919,A38),0) -> 2.912766 | D38: =IFERROR(COUNTIFS(Tickets!$C$2:$C$6919,A38,Tickets!$N$2:$N$6919,"Yes")/B38,0) -> 1 | E38: =IFERROR(AVERAGEIFS(Tickets!$H$2:$H$6919,Tickets!$C$2:$C$6919,A38),0) -> 15.858197 | F38: =IFERROR(AVERAGEIFS(Tickets!$J$2:$J$6919,Tickets!$C$2:$C$6919,A38),0) -> 4.2148041
A39: Total | B39: =SUM(B35:B38) -> 6918 | C39: =AVERAGE(Tickets!$G$2:$G$6919) -> 29.449986 | D39: =C5 -> 0.87901127 | E39: =G5 -> 16.121254 | F39: =I5 -> 4.1381733
A49: 4. Category performance
A50: Category | B50: Tickets | C50: Avg Resolution (hrs) | D50: Resolution SLA % | E50: Reopen Rate | F50: Avg CSAT | G50: Escalated
A51: Technical | B51: =COUNTIFS(Tickets!$D$2:$D$6919,A51) -> 2053 | C51: =IFERROR(AVERAGEIFS(Tickets!$H$2:$H$6919,Tickets!$D$2:$D$6919,A51),0) -> 16.330479 | D51: =IFERROR(COUNTIFS(Tickets!$D$2:$D$6919,A51,Tickets!$O$2:$O$6919,"Yes")/(COUNTIFS(Tickets!$D$2:$D$6919,A51,Tickets!$O$2:$O$6919,"Yes")+COUNTIFS(Tickets!$D$2:$D$6919,A51,Tickets!$O$2:$O$6919,"No")),0) -> 0.8143617 | E51: =IFERROR(COUNTIFS(Tickets!$D$2:$D$6919,A51,Tickets!$K$2:$K$6919,"Yes")/COUNTIFS(Tickets!$D$2:$D$6919,A51,Tickets!$I$2:$I$6919,"<>Open"),0) -> 0.070212766 | F51: =IFERROR(AVERAGEIFS(Tickets!$J$2:$J$6919,Tickets!$D$2:$D$6919,A51),0) -> 4.1282565 | G51: =COUNTIFS(Tickets!$D$2:$D$6919,A51,Tickets!$I$2:$I$6919,"Escalated") -> 124
A52: Billing | B52: =COUNTIFS(Tickets!$D$2:$D$6919,A52) -> 1717 | C52: =IFERROR(AVERAGEIFS(Tickets!$H$2:$H$6919,Tickets!$D$2:$D$6919,A52),0) -> 8.1386113 | D52: =IFERROR(COUNTIFS(Tickets!$D$2:$D$6919,A52,Tickets!$O$2:$O$6919,"Yes")/(COUNTIFS(Tickets!$D$2:$D$6919,A52,Tickets!$O$2:$O$6919,"Yes")+COUNTIFS(Tickets!$D$2:$D$6919,A52,Tickets!$O$2:$O$6919,"No")),0) -> 0.94484101 | E52: =IFERROR(COUNTIFS(Tickets!$D$2:$D$6919,A52,Tickets!$K$2:$K$6919,"Yes")/COUNTIFS(Tickets!$D$2:$D$6919,A52,Tickets!$I$2:$I$6919,"<>Open"),0) -> 0.073329007 | F52: =IFERROR(AVERAGEIFS(Tickets!$J$2:$J$6919,Tickets!$D$2:$D$6919,A52),0) -> 4.2485549 | G52: =COUNTIFS(Tickets!$D$2:$D$6919,A52,Tickets!$I$2:$I$6919,"Escalated") -> 87
A53: Delivery | B53: =COUNTIFS(Tickets!$D$2:$D$6919,A53) -> 1405 | C53: =IFERROR(AVERAGEIFS(Tickets!$H$2:$H$6919,Tickets!$D$2:$D$6919,A53),0) -> 21.953084 | D53: =IFERROR(COUNTIFS(Tickets!$D$2:$D$6919,A53,Tickets!$O$2:$O$6919,"Yes")/(COUNTIFS(Tickets!$D$2:$D$6919,A53,Tickets!$O$2:$O$6919,"Yes")+COUNTIFS(Tickets!$D$2:$D$6919,A53,Tickets!$O$2:$O$6919,"No")),0) -> 0.69476971 | E53: =IFERROR(COUNTIFS(Tickets!$D$2:$D$6919,A53,Tickets!$K$2:$K$6919,"Yes")/COUNTIFS(Tickets!$D$2:$D$6919,A53,Tickets!$I$2:$I$6919,"<>Open"),0) -> 0.071818891 | F53: =IFERROR(AVERAGEIFS(Tickets!$J$2:$J$6919,Tickets!$D$2:$D$6919,A53),0) -> 4.0472779 | G53: =COUNTIFS(Tickets!$D$2:$D$6919,A53,Tickets!$I$2:$I$6919,"Escalated") -> 73
A54: Account | B54: =COUNTIFS(Tickets!$D$2:$D$6919,A54) -> 955 | C54: =IFERROR(AVERAGEIFS(Tickets!$H$2:$H$6919,Tickets!$D$2:$D$6919,A54),0) -> 6.3614302 | D54: =IFERROR(COUNTIFS(Tickets!$D$2:$D$6919,A54,Tickets!$O$2:$O$6919,"Yes")/(COUNTIFS(Tickets!$D$2:$D$6919,A54,Tickets!$O$2:$O$6919,"Yes")+COUNTIFS(Tickets!$D$2:$D$6919,A54,Tickets!$O$2:$O$6919,"No")),0) -> 0.97420868 | E54: =IFERROR(COUNTIFS(Tickets!$D$2:$D$6919,A54,Tickets!$K$2:$K$6919,"Yes")/COUNTIFS(Tickets!$D$2:$D$6919,A54,Tickets!$I$2:$I$6919,"<>Open"),0) -> 0.087924971 | F54: =IFERROR(AVERAGEIFS(Tickets!$J$2:$J$6919,Tickets!$D$2:$D$6919,A54),0) -> 4.251073 | G54: =COUNTIFS(Tickets!$D$2:$D$6919,A54,Tickets!$I$2:$I$6919,"Escalated") -> 58
A55: Refund | B55: =COUNTIFS(Tickets!$D$2:$D$6919,A55) -> 788 | C55: =IFERROR(AVERAGEIFS(Tickets!$H$2:$H$6919,Tickets!$D$2:$D$6919,A55),0) -> 34.046067 | D55: =IFERROR(COUNTIFS(Tickets!$D$2:$D$6919,A55,Tickets!$O$2:$O$6919,"Yes")/(COUNTIFS(Tickets!$D$2:$D$6919,A55,Tickets!$O$2:$O$6919,"Yes")+COUNTIFS(Tickets!$D$2:$D$6919,A55,Tickets!$O$2:$O$6919,"No")),0) -> 0.55898876 | E55: =IFERROR(COUNTIFS(Tickets!$D$2:$D$6919,A55,Tickets!$K$2:$K$6919,"Yes")/COUNTIFS(Tickets!$D$2:$D$6919,A55,Tickets!$I$2:$I$6919,"<>Open"),0) -> 0.073033708 | F55: =IFERROR(AVERAGEIFS(Tickets!$J$2:$J$6919,Tickets!$D$2:$D$6919,A55),0) -> 3.9460154 | G55: =COUNTIFS(Tickets!$D$2:$D$6919,A55,Tickets!$I$2:$I$6919,"Escalated") -> 41
A56: Total | B56: =SUM(B51:B55) -> 6918 | C56: =G5 -> 16.121254 | D56: =E5 -> 0.8147439 | E56: =IFERROR(COUNTIF(Tickets!$K$2:$K$6919,"Yes")/COUNTIF(Tickets!$I$2:$I$6919,"<>Open"),0) -> 0.074038615 | F56: =I5 -> 4.1381733 | G56: =SUM(G51:G55) -> 383
...

Sheet Assumptions
A1: Assumptions & Parameters
A2: Blue cells are editable inputs. Everything else recalculates from them.
A4: As-of date | B4: 46295 | C4: Last day of data.
A5: Period start | B5: 46204 | C5: First day of data.
A6: Months in period | B6: =(YEAR(B4)-YEAR(B5))*12+MONTH(B4)-MONTH(B5)+1 -> 3 | C6: Calculated.
A7: Response SLA target (% of tickets) | B7: 0.9 | C7: Share of tickets answered within the priority's first-response target.
A8: Resolution SLA target (% of tickets) | B8: 0.85 | C8: Share of tickets resolved within the priority's resolution target.
A9: CSAT target (1-5) | B9: 4.2 | C9: Average customer satisfaction score.
A10: Maximum reopen rate | B10: 0.08 | C10: Share of tickets reopened after resolution.
A11: Aged backlog: open longer than (days) | B11: 3 | C11: Open tickets older than this count as aged backlog.
A13: SLA targets by priority
A14: Priority | B14: First response target (minutes) | C14: Resolution target (hours)
A15: Urgent | B15: 15 | C15: 4
A16: High | B16: 30 | C16: 8
A17: Medium | B17: 60 | C17: 24
A18: Low | B18: 240 | C18: 72

Sheet Agents
A1: AgentID | B1: Team | C1: Tickets | D1: Closed Tickets | E1: Avg First Response (min) | F1: Avg Resolution (hrs) | G1: Response SLA % | H1: Resolution SLA % | I1: Avg CSAT | J1: Reopen Rate | K1: Targets Missed | L1: Performance Flag | M1: Resolution SLA Rank
A2: AG01 | B2: Team Alpha | C2: =COUNTIFS(Tickets!$F$2:$F$6919,A2) -> 369 | D2: =COUNTIFS(Tickets!$F$2:$F$6919,A2,Tickets!$I$2:$I$6919,"<>Open") -> 340 | E2: =IFERROR(AVERAGEIFS(Tickets!$G$2:$G$6919,Tickets!$F$2:$F$6919,A2),0) -> 21.826558 | F2: =IFERROR(AVERAGEIFS(Tickets!$H$2:$H$6919,Tickets!$F$2:$F$6919,A2),0) -> 12.451176 | G2: =IFERROR(COUNTIFS(Tickets!$F$2:$F$6919,A2,Tickets!$N$2:$N$6919,"Yes")/C2,0) -> 0.89430894 | H2: =IFERROR(COUNTIFS(Tickets!$F$2:$F$6919,A2,Tickets!$O$2:$O$6919,"Yes")/(COUNTIFS(Tickets!$F$2:$F$6919,A2,Tickets!$O$2:$O$6919,"Yes")+COUNTIFS(Tickets!$F$2:$F$6919,A2,Tickets!$O$2:$O$6919,"No")),0) -> 0.90294118 | I2: =IFERROR(AVERAGEIFS(Tickets!$J$2:$J$6919,Tickets!$F$2:$F$6919,A2),0) -> 4.3791209 | J2: =IFERROR(COUNTIFS(Tickets!$F$2:$F$6919,A2,Tickets!$K$2:$K$6919,"Yes")/D2,0) -> 0.047058824 | K2: =(H2<Assumptions!$B$8)+(I2<Assumptions!$B$9)+(J2>Assumptions!$B$10) -> 0 | L2: =IF(K2>=3,"Coaching needed",IF(K2>=1,"Watch","On track")) -> On track | M2: =RANK(H2,$H$2:$H$19)+COUNTIF($H$2:H2,H2)-1 -> 2
A3: AG02 | B3: Team Alpha | C3: =COUNTIFS(Tickets!$F$2:$F$6919,A3) -> 355 | D3: =COUNTIFS(Tickets!$F$2:$F$6919,A3,Tickets!$I$2:$I$6919,"<>Open") -> 320 | E3: =IFERROR(AVERAGEIFS(Tickets!$G$2:$G$6919,Tickets!$F$2:$F$6919,A3),0) -> 21.977465 | F3: =IFERROR(AVERAGEIFS(Tickets!$H$2:$H$6919,Tickets!$F$2:$F$6919,A3),0) -> 14.898438 | G3: =IFERROR(COUNTIFS(Tickets!$F$2:$F$6919,A3,Tickets!$N$2:$N$6919,"Yes")/C3,0) -> 0.90985915 | H3: =IFERROR(COUNTIFS(Tickets!$F$2:$F$6919,A3,Tickets!$O$2:$O$6919,"Yes")/(COUNTIFS(Tickets!$F$2:$F$6919,A3,Tickets!$O$2:$O$6919,"Yes")+COUNTIFS(Tickets!$F$2:$F$6919,A3,Tickets!$O$2:$O$6919,"No")),0) -> 0.828125 | I3: =IFERROR(AVERAGEIFS(Tickets!$J$2:$J$6919,Tickets!$F$2:$F$6919,A3),0) -> 4.1349693 | J3: =IFERROR(COUNTIFS(Tickets!$F$2:$F$6919,A3,Tickets!$K$2:$K$6919,"Yes")/D3,0) -> 0.05625 | K3: =(H3<Assumptions!$B$8)+(I3<Assumptions!$B$9)+(J3>Assumptions!$B$10) -> 2 | L3: =IF(K3>=3,"Coaching needed",IF(K3>=1,"Watch","On track")) -> Watch | M3: =RANK(H3,$H$2:$H$19)+COUNTIF($H$2:H3,H3)-1 -> 11
A4: AG03 | B4: Team Alpha | C4: =COUNTIFS(Tickets!$F$2:$F$6919,A4) -> 393 | D4: =COUNTIFS(Tickets!$F$2:$F$6919,A4,Tickets!$I$2:$I$6919,"<>Open") -> 346 | E4: =IFERROR(AVERAGEIFS(Tickets!$G$2:$G$6919,Tickets!$F$2:$F$6919,A4),0) -> 33.035623 | F4: =IFERROR(AVERAGEIFS(Tickets!$H$2:$H$6919,Tickets!$F$2:$F$6919,A4),0) -> 23.627746 | G4: =IFERROR(COUNTIFS(Tickets!$F$2:$F$6919,A4,Tickets!$N$2:$N$6919,"Yes")/C4,0) -> 0.86005089 | H4: =IFERROR(COUNTIFS(Tickets!$F$2:$F$6919,A4,Tickets!$O$2:$O$6919,"Yes")/(COUNTIFS(Tickets!$F$2:$F$6919,A4,Tickets!$O$2:$O$6919,"Yes")+COUNTIFS(Tickets!$F$2:$F$6919,A4,Tickets!$O$2:$O$6919,"No")),0) -> 0.70231214 | I4: =IFERROR(AVERAGEIFS(Tickets!$J$2:$J$6919,Tickets!$F$2:$F$6919,A4),0) -> 3.6372093 | J4: =IFERROR(COUNTIFS(Tickets!$F$2:$F$6919,A4,Tickets!$K$2:$K$6919,"Yes")/D4,0) -> 0.11849711 | K4: =(H4<Assumptions!$B$8)+(I4<Assumptions!$B$9)+(J4>Assumptions!$B$10) -> 3 | L4: =IF(K4>=3,"Coaching needed",IF(K4>=1,"Watch","On track")) -> Coaching needed | M4: =RANK(H4,$H$2:$H$19)+COUNTIF($H$2:H4,H4)-1 -> 17
A5: AG04 | B5: Team Alpha | C5: =COUNTIFS(Tickets!$F$2:$F$6919,A5) -> 373 | D5: =COUNTIFS(Tickets!$F$2:$F$6919,A5,Tickets!$I$2:$I$6919,"<>Open") -> 335 | E5: =IFERROR(AVERAGEIFS(Tickets!$G$2:$G$6919,Tickets!$F$2:$F$6919,A5),0) -> 36.477212 | F5: =IFERROR(AVERAGEIFS(Tickets!$H$2:$H$6919,Tickets!$F$2:$F$6919,A5),0) -> 19.664478 | G5: =IFERROR(COUNTIFS(Tickets!$F$2:$F$6919,A5,Tickets!$N$2:$N$6919,"Yes")/C5,0) -> 0.84718499 | H5: =IFERROR(COUNTIFS(Tickets!$F$2:$F$6919,A5,Tickets!$O$2:$O$6919,"Yes")/(COUNTIFS(Tickets!$F$2:$F$6919,A5,Tickets!$O$2:$O$6919,"Yes")+COUNTIFS(Tickets!$F$2:$F$6919,A5,Tickets!$O$2:$O$6919,"No")),0) -> 0.7761194 | I5: =IFERROR(AVERAGEIFS(Tickets!$J$2:$J$6919,Tickets!$F$2:$F$6919,A5),0) -> 3.9388889 | J5: =IFERROR(COUNTIFS(Tickets!$F$2:$F$6919,A5,Tickets!$K$2:$K$6919,"Yes")/D5,0) -> 0.095522388 | K5: =(H5<Assumptions!$B$8)+(I5<Assumptions!$B$9)+(J5>Assumptions!$B$10) -> 3 | L5: =IF(K5>=3,"Coaching needed",IF(K5>=1,"Watch","On track")) -> Coaching needed | M5: =RANK(H5,$H$2:$H$19)+COUNTIF($H$2:H5,H5)-1 -> 14
A6: AG05 | B6: Team Alpha | C6: =COUNTIFS(Tickets!$F$2:$F$6919,A6) -> 365 | D6: =COUNTIFS(Tickets!$F$2:$F$6919,A6,Tickets!$I$2:$I$6919,"<>Open") -> 334 | E6: =IFERROR(AVERAGEIFS(Tickets!$G$2:$G$6919,Tickets!$F$2:$F$6919,A6),0) -> 28.945205 | F6: =IFERROR(AVERAGEIFS(Tickets!$H$2:$H$6919,Tickets!$F$2:$F$6919,A6),0) -> 14.910778 | G6: =IFERROR(COUNTIFS(Tickets!$F$2:$F$6919,A6,Tickets!$N$2:$N$6919,"Yes")/C6,0) -> 0.87671233 | H6: =IFERROR(COUNTIFS(Tickets!$F$2:$F$6919,A6,Tickets!$O$2:$O$6919,"Yes")/(COUNTIFS(Tickets!$F$2:$F$6919,A6,Tickets!$O$2:$O$6919,"Yes")+COUNTIFS(Tickets!$F$2:$F$6919,A6,Tickets!$O$2:$O$6919,"No")),0) -> 0.86826347 | I6: =IFERROR(AVERAGEIFS(Tickets!$J$2:$J$6919,Tickets!$F$2:$F$6919,A6),0) -> 4.3011364 | J6: =IFERROR(COUNTIFS(Tickets!$F$2:$F$6919,A6,Tickets!$K$2:$K$6919,"Yes")/D6,0) -> 0.065868263 | K6: =(H6<Assumptions!$B$8)+(I6<Assumptions!$B$9)+(J6>Assumptions!$B$10) -> 0 | L6: =IF(K6>=3,"Coaching needed",IF(K6>=1,"Watch","On track")) -> On track | M6: =RANK(H6,$H$2:$H$19)+COUNTIF($H$2:H6,H6)-1 -> 4
A7: AG06 | B7: Team Alpha | C7: =COUNTIFS(Tickets!$F$2:$F$6919,A7) -> 400 | D7: =COUNTIFS(Tickets!$F$2:$F$6919,A7,Tickets!$I$2:$I$6919,"<>Open") -> 372 | E7: =IFERROR(AVERAGEIFS(Tickets!$G$2:$G$6919,Tickets!$F$2:$F$6919,A7),0) -> 27.675 | F7: =IFERROR(AVERAGEIFS(Tickets!$H$2:$H$6919,Tickets!$F$2:$F$6919,A7),0) -> 13.778226 | G7: =IFERROR(COUNTIFS(Tickets!$F$2:$F$6919,A7,Tickets!$N$2:$N$6919,"Yes")/C7,0) -> 0.8875 | H7: =IFERROR(COUNTIFS(Tickets!$F$2:$F$6919,A7,Tickets!$O$2:$O$6919,"Yes")/(COUNTIFS(Tickets!$F$2:$F$6919,A7,Tickets!$O$2:$O$6919,"Yes")+COUNTIFS(Tickets!$F$2:$F$6919,A7,Tickets!$O$2:$O$6919,"No")),0) -> 0.83333333 | I7: =IFERROR(AVERAGEIFS(Tickets!$J$2:$J$6919,Tickets!$F$2:$F$6919,A7),0) -> 4.1469194 | J7: =IFERROR(COUNTIFS(Tickets!$F$2:$F$6919,A7,Tickets!$K$2:$K$6919,"Yes")/D7,0) -> 0.069892473 | K7: =(H7<Assumptions!$B$8)+(I7<Assumptions!$B$9)+(J7>Assumptions!$B$10) -> 2 | L7: =IF(K7>=3,"Coaching needed",IF(K7>=1,"Watch","On track")) -> Watch | M7: =RANK(H7,$H$2:$H$19)+COUNTIF($H$2:H7,H7)-1 -> 10
A8: AG07 | B8: Team Bravo | C8: =COUNTIFS(Tickets!$F$2:$F$6919,A8) -> 394 | D8: =COUNTIFS(Tickets!$F$2:$F$6919,A8,Tickets!$I$2:$I$6919,"<>Open") -> 364 | E8: =IFERROR(AVERAGEIFS(Tickets!$G$2:$G$6919,Tickets!$F$2:$F$6919,A8),0) -> 20.28934 | F8: =IFERROR(AVERAGEIFS(Tickets!$H$2:$H$6919,Tickets!$F$2:$F$6919,A8),0) -> 14.207143 | G8: =IFERROR(COUNTIFS(Tickets!$F$2:$F$6919,A8,Tickets!$N$2:$N$6919,"Yes")/C8,0) -> 0.92893401 | H8: =IFERROR(COUNTIFS(Tickets!$F$2:$F$6919,A8,Tickets!$O$2:$O$6919,"Yes")/(COUNTIFS(Tickets!$F$2:$F$6919,A8,Tickets!$O$2:$O$6919,"Yes")+COUNTIFS(Tickets!$F$2:$F$6919,A8,Tickets!$O$2:$O$6919,"No")),0) -> 0.82692308 | I8: =IFERROR(AVERAGEIFS(Tickets!$J$2:$J$6919,Tickets!$F$2:$F$6919,A8),0) -> 4.3152174 | J8: =IFERROR(COUNTIFS(Tickets!$F$2:$F$6919,A8,Tickets!$K$2:$K$6919,"Yes")/D8,0) -> 0.082417582 | K8: =(H8<Assumptions!$B$8)+(I8<Assumptions!$B$9)+(J8>Assumptions!$B$10) -> 2 | L8: =IF(K8>=3,"Coaching needed",IF(K8>=1,"Watch","On track")) -> Watch | M8: =RANK(H8,$H$2:$H$19)+COUNTIF($H$2:H8,H8)-1 -> 12
A9: AG08 | B9: Team Bravo | C9: =COUNTIFS(Tickets!$F$2:$F$6919,A9) -> 379 | D9: =COUNTIFS(Tickets!$F$2:$F$6919,A9,Tickets!$I$2:$I$6919,"<>Open") -> 343 | E9: =IFERROR(AVERAGEIFS(Tickets!$G$2:$G$6919,Tickets!$F$2:$F$6919,A9),0) -> 22.604222 | F9: =IFERROR(AVERAGEIFS(Tickets!$H$2:$H$6919,Tickets!$F$2:$F$6919,A9),0) -> 11.949854 | G9: =IFERROR(COUNTIFS(Tickets!$F$2:$F$6919,A9,Tickets!$N$2:$N$6919,"Yes")/C9,0) -> 0.8707124 | H9: =IFERROR(COUNTIFS(Tickets!$F$2:$F$6919,A9,Tickets!$O$2:$O$6919,"Yes")/(COUNTIFS(Tickets!$F$2:$F$6919,A9,Tickets!$O$2:$O$6919,"Yes")+COUNTIFS(Tickets!$F$2:$F$6919,A9,Tickets!$O$2:$O$6919,"No")),0) -> 0.85714286 | I9: =IFERROR(AVERAGEIFS(Tickets!$J$2:$J$6919,Tickets!$F$2:$F$6919,A9),0) -> 4.4034091 | J9: =IFERROR(COUNTIFS(Tickets!$F$2:$F$6919,A9,Tickets!$K$2:$K$6919,"Yes")/D9,0) -> 0.049562682 | K9: =(H9<Assumptions!$B$8)+(I9<Assumptions!$B$9)+(J9>Assumptions!$B$10) -> 0 | L9: =IF(K9>=3,"Coaching needed",IF(K9>=1,"Watch","On track")) -> On track | M9: =RANK(H9,$H$2:$H$19)+COUNTIF($H$2:H9,H9)-1 -> 5
A10: AG09 | B10: Team Bravo | C10: =COUNTIFS(Tickets!$F$2:$F$6919,A10) -> 381 | D10: =COUNTIFS(Tickets!$F$2:$F$6919,A10,Tickets!$I$2:$I$6919,"<>Open") -> 352 | E10: =IFERROR(AVERAGEIFS(Tickets!$G$2:$G$6919,Tickets!$F$2:$F$6919,A10),0) -> 21.144357 | F10: =IFERROR(AVERAGEIFS(Tickets!$H$2:$H$6919,Tickets!$F$2:$F$6919,A10),0) -> 12.740909 | G10: =IFERROR(COUNTIFS(Tickets!$F$2:$F$6919,A10,Tickets!$N$2:$N$6919,"Yes")/C10,0) -> 0.91076115 | H10: =IFERROR(COUNTIFS(Tickets!$F$2:$F$6919,A10,Tickets!$O$2:$O$6919,"Yes")/(COUNTIFS(Tickets!$F$2:$F$6919,A10,Tickets!$O$2:$O$6919,"Yes")+COUNTIFS(Tickets!$F$2:$F$6919,A10,Tickets!$O$2:$O$6919,"No")),0) -> 0.84943182 | I10: =IFERROR(AVERAGEIFS(Tickets!$J$2:$J$6919,Tickets!$F$2:$F$6919,A10),0) -> 4.3399015 | J10: =IFERROR(COUNTIFS(Tickets!$F$2:$F$6919,A10,Tickets!$K$2:$K$6919,"Yes")/D10,0) -> 0.071022727 | K10: =(H10<Assumptions!$B$8)+(I10<Assumptions!$B$9)+(J10>Assumptions!$B$10) -> 1 | L10: =IF(K10>=3,"Coaching needed",IF(K10>=1,"Watch","On track")) -> Watch | M10: =RANK(H10,$H$2:$H$19)+COUNTIF($H$2:H10,H10)-1 -> 7
A11: AG10 | B11: Team Bravo | C11: =COUNTIFS(Tickets!$F$2:$F$6919,A11) -> 411 | D11: =COUNTIFS(Tickets!$F$2:$F$6919,A11,Tickets!$I$2:$I$6919,"<>Open") -> 368 | E11: =IFERROR(AVERAGEIFS(Tickets!$G$2:$G$6919,Tickets!$F$2:$F$6919,A11),0) -> 50.729927 | F11: =IFERROR(AVERAGEIFS(Tickets!$H$2:$H$6919,Tickets!$F$2:$F$6919,A11),0) -> 23.680435 | G11: =IFERROR(COUNTIFS(Tickets!$F$2:$F$6919,A11,Tickets!$N$2:$N$6919,"Yes")/C11,0) -> 0.83454988 | H11: =IFERROR(COUNTIFS(Tickets!$F$2:$F$6919,A11,Tickets!$O$2:$O$6919,"Yes")/(COUNTIFS(Tickets!$F$2:$F$6919,A11,Tickets!$O$2:$O$6919,"Yes")+COUNTIFS(Tickets!$F$2:$F$6919,A11,Tickets!$O$2:$O$6919,"No")),0) -> 0.73369565 | I11: =IFERROR(AVERAGEIFS(Tickets!$J$2:$J$6919,Tickets!$F$2:$F$6919,A11),0) -> 3.735 | J11: =IFERROR(COUNTIFS(Tickets!$F$2:$F$6919,A11,Tickets!$K$2:$K$6919,"Yes")/D11,0) -> 0.125 | K11: =(H11<Assumptions!$B$8)+(I11<Assumptions!$B$9)+(J11>Assumptions!$B$10) -> 3 | L11: =IF(K11>=3,"Coaching needed",IF(K11>=1,"Watch","On track")) -> Coaching needed | M11: =RANK(H11,$H$2:$H$19)+COUNTIF($H$2:H11,H11)-1 -> 15
A12: AG11 | B12: Team Bravo | C12: =COUNTIFS(Tickets!$F$2:$F$6919,A12) -> 369 | D12: =COUNTIFS(Tickets!$F$2:$F$6919,A12,Tickets!$I$2:$I$6919,"<>Open") -> 343 | E12: =IFERROR(AVERAGEIFS(Tickets!$G$2:$G$6919,Tickets!$F$2:$F$6919,A12),0) -> 21.663957 | F12: =IFERROR(AVERAGEIFS(Tickets!$H$2:$H$6919,Tickets!$F$2:$F$6919,A12),0) -> 12.177843 | G12: =IFERROR(COUNTIFS(Tickets!$F$2:$F$6919,A12,Tickets!$N$2:$N$6919,"Yes")/C12,0) -> 0.90514905 | H12: =IFERROR(COUNTIFS(Tickets!$F$2:$F$6919,A12,Tickets!$O$2:$O$6919,"Yes")/(COUNTIFS(Tickets!$F$2:$F$6919,A12,Tickets!$O$2:$O$6919,"Yes")+COUNTIFS(Tickets!$F$2:$F$6919,A12,Tickets!$O$2:$O$6919,"No")),0) -> 0.90962099 | I12: =IFERROR(AVERAGEIFS(Tickets!$J$2:$J$6919,Tickets!$F$2:$F$6919,A12),0) -> 4.5139665 | J12: =IFERROR(COUNTIFS(Tickets!$F$2:$F$6919,A12,Tickets!$K$2:$K$6919,"Yes")/D12,0) -> 0.043731778 | K12: =(H12<Assumptions!$B$8)+(I12<Assumptions!$B$9)+(J12>Assumptions!$B$10) -> 0 | L12: =IF(K12>=3,"Coaching needed",IF(K12>=1,"Watch","On track")) -> On track | M12: =RANK(H12,$H$2:$H$19)+COUNTIF($H$2:H12,H12)-1 -> 1
A13: AG12 | B13: Team Bravo | C13: =COUNTIFS(Tickets!$F$2:$F$6919,A13) -> 396 | D13: =COUNTIFS(Tickets!$F$2:$F$6919,A13,Tickets!$I$2:$I$6919,"<>Open") -> 346 | E13: =IFERROR(AVERAGEIFS(Tickets!$G$2:$G$6919,Tickets!$F$2:$F$6919,A13),0) -> 23.199495 | F13: =IFERROR(AVERAGEIFS(Tickets!$H$2:$H$6919,Tickets!$F$2:$F$6919,A13),0) -> 13.74422 | G13: =IFERROR(COUNTIFS(Tickets!$F$2:$F$6919,A13,Tickets!$N$2:$N$6919,"Yes")/C13,0) -> 0.90151515 | H13: =IFERROR(COUNTIFS(Tickets!$F$2:$F$6919,A13,Tickets!$O$2:$O$6919,"Yes")/(COUNTIFS(Tickets!$F$2:$F$6919,A13,Tickets!$O$2:$O$6919,"Yes")+COUNTIFS(Tickets!$F$2:$F$6919,A13,Tickets!$O$2:$O$6919,"No")),0) -> 0.84971098 | I13: =IFERROR(AVERAGEIFS(Tickets!$J$2:$J$6919,Tickets!$F$2:$F$6919,A13),0) -> 4.3701923 | J13: =IFERROR(COUNTIFS(Tickets!$F$2:$F$6919,A13,Tickets!$K$2:$K$6919,"Yes")/D13,0) -> 0.052023121 | K13: =(H13<Assumptions!$B$8)+(I13<Assumptions!$B$9)+(J13>Assumptions!$B$10) -> 1 | L13: =IF(K13>=3,"Coaching needed",IF(K13>=1,"Watch","On track")) -> Watch | M13: =RANK(H13,$H$2:$H$19)+COUNTIF($H$2:H13,H13)-1 -> 6
... A19: AG18 | B19: Team Charlie | C19: =COUNTIFS(Tickets!$F$2:$F$6919,A19) -> 378 | D19: =COUNTIFS(Tickets!$F$2:$F$6919,A19,Tickets!$I$2:$I$6919,"<>Open") -> 338 | E19: =IFERROR(AVERAGEIFS(Tickets!$G$2:$G$6919,Tickets!$F$2:$F$6919,A19),0) -> 31.179894 | F19: =IFERROR(AVERAGEIFS(Tickets!$H$2:$H$6919,Tickets!$F$2:$F$6919,A19),0) -> 17.176036 | G19: =IFERROR(COUNTIFS(Tickets!$F$2:$F$6919,A19,Tickets!$N$2:$N$6919,"Yes")/C19,0) -> 0.85978836 | H19: =IFERROR(COUNTIFS(Tickets!$F$2:$F$6919,A19,Tickets!$O$2:$O$6919,"Yes")/(COUNTIFS(Tickets!$F$2:$F$6919,A19,Tickets!$O$2:$O$6919,"Yes")+COUNTIFS(Tickets!$F$2:$F$6919,A19,Tickets!$O$2:$O$6919,"No")),0) -> 0.78698225 | I19: =IFERROR(AVERAGEIFS(Tickets!$J$2:$J$6919,Tickets!$F$2:$F$6919,A19),0) -> 3.9521277 | J19: =IFERROR(COUNTIFS(Tickets!$F$2:$F$6919,A19,Tickets!$K$2:$K$6919,"Yes")/D19,0) -> 0.091715976 | K19: =(H19<Assumptions!$B$8)+(I19<Assumptions!$B$9)+(J19>Assumptions!$B$10) -> 3 | L19: =IF(K19>=3,"Coaching needed",IF(K19>=1,"Watch","On track")) -> Coaching needed | M19: =RANK(H19,$H$2:$H$19)+COUNTIF($H$2:H19,H19)-1 -> 13

Sheet Tickets
A1: TicketID | B1: Created Date | C1: Channel | D1: Category | E1: Priority | F1: AgentID | G1: First Response (min) | H1: Resolution Time (hrs) | I1: Status | J1: CSAT (1-5) | K1: Reopened | L1: Month | M1: Weekday (1=Mon) | N1: Response SLA Met | O1: Resolution SLA Met
A2: TK-00001 | B2: 46204 | C2: Email | D2: Billing | E2: Medium | F2: AG04 | G2: 42 | H2: 5.6 | I2: Resolved | K2: No | L2: =DATE(YEAR(B2),MONTH(B2),1) -> 46204 | M2: =WEEKDAY(B2,2) -> 3 | N2: =IF(G2<=INDEX(Assumptions!$B$15:$B$18,MATCH(E2,Assumptions!$A$15:$A$18,0)),"Yes","No") -> Yes | O2: =IF(H2="","Open",IF(H2<=INDEX(Assumptions!$C$15:$C$18,MATCH(E2,Assumptions!$A$15:$A$18,0)),"Yes","No")) -> Yes
A3: TK-00002 | B3: 46204 | C3: Email | D3: Delivery | E3: High | F3: AG06 | G3: 113 | H3: 9.3 | I3: Resolved | K3: No | L3: =DATE(YEAR(B3),MONTH(B3),1) -> 46204 | M3: =WEEKDAY(B3,2) -> 3 | N3: =IF(G3<=INDEX(Assumptions!$B$15:$B$18,MATCH(E3,Assumptions!$A$15:$A$18,0)),"Yes","No") -> No | O3: =IF(H3="","Open",IF(H3<=INDEX(Assumptions!$C$15:$C$18,MATCH(E3,Assumptions!$A$15:$A$18,0)),"Yes","No")) -> No
A4: TK-00003 | B4: 46204 | C4: Phone | D4: Refund | E4: Medium | F4: AG03 | G4: 10 | H4: 36.6 | I4: Resolved | K4: Yes | L4: =DATE(YEAR(B4),MONTH(B4),1) -> 46204 | M4: =WEEKDAY(B4,2) -> 3 | N4: =IF(G4<=INDEX(Assumptions!$B$15:$B$18,MATCH(E4,Assumptions!$A$15:$A$18,0)),"Yes","No") -> Yes | O4: =IF(H4="","Open",IF(H4<=INDEX(Assumptions!$C$15:$C$18,MATCH(E4,Assumptions!$A$15:$A$18,0)),"Yes","No")) -> No
A5: TK-00004 | B5: 46204 | C5: Chat | D5: Technical | E5: Medium | F5: AG09 | G5: 5 | H5: 17.9 | I5: Resolved | J5: 5 | K5: No | L5: =DATE(YEAR(B5),MONTH(B5),1) -> 46204 | M5: =WEEKDAY(B5,2) -> 3 | N5: =IF(G5<=INDEX(Assumptions!$B$15:$B$18,MATCH(E5,Assumptions!$A$15:$A$18,0)),"Yes","No") -> Yes | O5: =IF(H5="","Open",IF(H5<=INDEX(Assumptions!$C$15:$C$18,MATCH(E5,Assumptions!$A$15:$A$18,0)),"Yes","No")) -> Yes
A6: TK-00005 | B6: 46204 | C6: WhatsApp | D6: Account | E6: Medium | F6: AG18 | G6: 6 | H6: 3.2 | I6: Resolved | K6: No | L6: =DATE(YEAR(B6),MONTH(B6),1) -> 46204 | M6: =WEEKDAY(B6,2) -> 3 | N6: =IF(G6<=INDEX(Assumptions!$B$15:$B$18,MATCH(E6,Assumptions!$A$15:$A$18,0)),"Yes","No") -> Yes | O6: =IF(H6="","Open",IF(H6<=INDEX(Assumptions!$C$15:$C$18,MATCH(E6,Assumptions!$A$15:$A$18,0)),"Yes","No")) -> Yes
A7: TK-00006 | B7: 46204 | C7: Email | D7: Delivery | E7: Medium | F7: AG06 | G7: 181 | H7: 34.7 | I7: Resolved | K7: Yes | L7: =DATE(YEAR(B7),MONTH(B7),1) -> 46204 | M7: =WEEKDAY(B7,2) -> 3 | N7: =IF(G7<=INDEX(Assumptions!$B$15:$B$18,MATCH(E7,Assumptions!$A$15:$A$18,0)),"Yes","No") -> No | O7: =IF(H7="","Open",IF(H7<=INDEX(Assumptions!$C$15:$C$18,MATCH(E7,Assumptions!$A$15:$A$18,0)),"Yes","No")) -> No
A8: TK-00007 | B8: 46204 | C8: Email | D8: Billing | E8: Low | F8: AG11 | G8: 86 | I8: Open | K8: No | L8: =DATE(YEAR(B8),MONTH(B8),1) -> 46204 | M8: =WEEKDAY(B8,2) -> 3 | N8: =IF(G8<=INDEX(Assumptions!$B$15:$B$18,MATCH(E8,Assumptions!$A$15:$A$18,0)),"Yes","No") -> Yes | O8: =IF(H8="","Open",IF(H8<=INDEX(Assumptions!$C$15:$C$18,MATCH(E8,Assumptions!$A$15:$A$18,0)),"Yes","No")) -> Open
A9: TK-00008 | B9: 46204 | C9: WhatsApp | D9: Technical | E9: Medium | F9: AG05 | G9: 6 | H9: 14.3 | I9: Resolved | J9: 5 | K9: No | L9: =DATE(YEAR(B9),MONTH(B9),1) -> 46204 | M9: =WEEKDAY(B9,2) -> 3 | N9: =IF(G9<=INDEX(Assumptions!$B$15:$B$18,MATCH(E9,Assumptions!$A$15:$A$18,0)),"Yes","No") -> Yes | O9: =IF(H9="","Open",IF(H9<=INDEX(Assumptions!$C$15:$C$18,MATCH(E9,Assumptions!$A$15:$A$18,0)),"Yes","No")) -> Yes
A10: TK-00009 | B10: 46204 | C10: Chat | D10: Billing | E10: Medium | F10: AG13 | G10: 5 | H10: 3.4 | I10: Resolved | J10: 5 | K10: No | L10: =DATE(YEAR(B10),MONTH(B10),1) -> 46204 | M10: =WEEKDAY(B10,2) -> 3 | N10: =IF(G10<=INDEX(Assumptions!$B$15:$B$18,MATCH(E10,Assumptions!$A$15:$A$18,0)),"Yes","No") -> Yes | O10: =IF(H10="","Open",IF(H10<=INDEX(Assumptions!$C$15:$C$18,MATCH(E10,Assumptions!$A$15:$A$18,0)),"Yes","No")) -> Yes
A11: TK-00010 | B11: 46204 | C11: WhatsApp | D11: Billing | E11: Medium | F11: AG02 | G11: 14 | H11: 14.1 | I11: Resolved | K11: No | L11: =DATE(YEAR(B11),MONTH(B11),1) -> 46204 | M11: =WEEKDAY(B11,2) -> 3 | N11: =IF(G11<=INDEX(Assumptions!$B$15:$B$18,MATCH(E11,Assumptions!$A$15:$A$18,0)),"Yes","No") -> Yes | O11: =IF(H11="","Open",IF(H11<=INDEX(Assumptions!$C$15:$C$18,MATCH(E11,Assumptions!$A$15:$A$18,0)),"Yes","No")) -> Yes
A12: TK-00011 | B12: 46204 | C12: Chat | D12: Billing | E12: High | F12: AG11 | G12: 2 | H12: 2.2 | I12: Resolved | K12: No | L12: =DATE(YEAR(B12),MONTH(B12),1) -> 46204 | M12: =WEEKDAY(B12,2) -> 3 | N12: =IF(G12<=INDEX(Assumptions!$B$15:$B$18,MATCH(E12,Assumptions!$A$15:$A$18,0)),"Yes","No") -> Yes | O12: =IF(H12="","Open",IF(H12<=INDEX(Assumptions!$C$15:$C$18,MATCH(E12,Assumptions!$A$15:$A$18,0)),"Yes","No")) -> Yes
A13: TK-00012 | B13: 46204 | C13: WhatsApp | D13: Billing | E13: High | F13: AG06 | G13: 12 | H13: 0.8 | I13: Resolved | J13: 4 | K13: No | L13: =DATE(YEAR(B13),MONTH(B13),1) -> 46204 | M13: =WEEKDAY(B13,2) -> 3 | N13: =IF(G13<=INDEX(Assumptions!$B$15:$B$18,MATCH(E13,Assumptions!$A$15:$A$18,0)),"Yes","No") -> Yes | O13: =IF(H13="","Open",IF(H13<=INDEX(Assumptions!$C$15:$C$18,MATCH(E13,Assumptions!$A$15:$A$18,0)),"Yes","No")) -> Yes
A14: TK-00013 | B14: 46204 | C14: Email | D14: Delivery | E14: Low | F14: AG02 | G14: 181 | H14: 47 | I14: Resolved | J14: 5 | K14: No | L14: =DATE(YEAR(B14),MONTH(B14),1) -> 46204 | M14: =WEEKDAY(B14,2) -> 3 | N14: =IF(G14<=INDEX(Assumptions!$B$15:$B$18,MATCH(E14,Assumptions!$A$15:$A$18,0)),"Yes","No") -> Yes | O14: =IF(H14="","Open",IF(H14<=INDEX(Assumptions!$C$15:$C$18,MATCH(E14,Assumptions!$A$15:$A$18,0)),"Yes","No")) -> Yes
A15: TK-00014 | B15: 46204 | C15: WhatsApp | D15: Delivery | E15: Urgent | F15: AG09 | G15: 7 | H15: 5.2 | I15: Resolved | J15: 4 | K15: No | L15: =DATE(YEAR(B15),MONTH(B15),1) -> 46204 | M15: =WEEKDAY(B15,2) -> 3 | N15: =IF(G15<=INDEX(Assumptions!$B$15:$B$18,MATCH(E15,Assumptions!$A$15:$A$18,0)),"Yes","No") -> Yes | O15: =IF(H15="","Open",IF(H15<=INDEX(Assumptions!$C$15:$C$18,MATCH(E15,Assumptions!$A$15:$A$18,0)),"Yes","No")) -> No
A16: TK-00015 | B16: 46204 | C16: WhatsApp | D16: Technical | E16: Medium | F16: AG17 | G16: 11 | H16: 2.7 | I16: Resolved | J16: 5 | K16: No | L16: =DATE(YEAR(B16),MONTH(B16),1) -> 46204 | M16: =WEEKDAY(B16,2) -> 3 | N16: =IF(G16<=INDEX(Assumptions!$B$15:$B$18,MATCH(E16,Assumptions!$A$15:$A$18,0)),"Yes","No") -> Yes | O16: =IF(H16="","Open",IF(H16<=INDEX(Assumptions!$C$15:$C$18,MATCH(E16,Assumptions!$A$15:$A$18,0)),"Yes","No")) -> Yes
A17: TK-00016 | B17: 46204 | C17: Email | D17: Account | E17: High | F17: AG16 | G17: 79 | H17: 2.4 | I17: Resolved | J17: 5 | K17: No | L17: =DATE(YEAR(B17),MONTH(B17),1) -> 46204 | M17: =WEEKDAY(B17,2) -> 3 | N17: =IF(G17<=INDEX(Assumptions!$B$15:$B$18,MATCH(E17,Assumptions!$A$15:$A$18,0)),"Yes","No") -> No | O17: =IF(H17="","Open",IF(H17<=INDEX(Assumptions!$C$15:$C$18,MATCH(E17,Assumptions!$A$15:$A$18,0)),"Yes","No")) -> Yes
A18: TK-00017 | B18: 46204 | C18: Phone | D18: Billing | E18: Medium | F18: AG09 | G18: 1 | H18: 6.8 | I18: Resolved | J18: 5 | K18: No | L18: =DATE(YEAR(B18),MONTH(B18),1) -> 46204 | M18: =WEEKDAY(B18,2) -> 3 | N18: =IF(G18<=INDEX(Assumptions!$B$15:$B$18,MATCH(E18,Assumptions!$A$15:$A$18,0)),"Yes","No") -> Yes | O18: =IF(H18="","Open",IF(H18<=INDEX(Assumptions!$C$15:$C$18,MATCH(E18,Assumptions!$A$15:$A$18,0)),"Yes","No")) -> Yes
A19: TK-00018 | B19: 46204 | C19: Email | D19: Billing | E19: Low | F19: AG16 | G19: 113 | H19: 11.3 | I19: Escalated | K19: No | L19: =DATE(YEAR(B19),MONTH(B19),1) -> 46204 | M19: =WEEKDAY(B19,2) -> 3 | N19: =IF(G19<=INDEX(Assumptions!$B$15:$B$18,MATCH(E19,Assumptions!$A$15:$A$18,0)),"Yes","No") -> Yes | O19: =IF(H19="","Open",IF(H19<=INDEX(Assumptions!$C$15:$C$18,MATCH(E19,Assumptions!$A$15:$A$18,0)),"Yes","No")) -> Yes
A20: TK-00019 | B20: 46204 | C20: WhatsApp | D20: Technical | E20: Medium | F20: AG06 | G20: 5 | H20: 4.5 | I20: Resolved | J20: 5 | K20: No | L20: =DATE(YEAR(B20),MONTH(B20),1) -> 46204 | M20: =WEEKDAY(B20,2) -> 3 | N20: =IF(G20<=INDEX(Assumptions!$B$15:$B$18,MATCH(E20,Assumptions!$A$15:$A$18,0)),"Yes","No") -> Yes | O20: =IF(H20="","Open",IF(H20<=INDEX(Assumptions!$C$15:$C$18,MATCH(E20,Assumptions!$A$15:$A$18,0)),"Yes","No")) -> Yes
A21: TK-00020 | B21: 46204 | C21: Chat | D21: Technical | E21: High | F21: AG12 | G21: 1 | H21: 5.1 | I21: Resolved | J21: 5 | K21: No | L21: =DATE(YEAR(B21),MONTH(B21),1) -> 46204 | M21: =WEEKDAY(B21,2) -> 3 | N21: =IF(G21<=INDEX(Assumptions!$B$15:$B$18,MATCH(E21,Assumptions!$A$15:$A$18,0)),"Yes","No") -> Yes | O21: =IF(H21="","Open",IF(H21<=INDEX(Assumptions!$C$15:$C$18,MATCH(E21,Assumptions!$A$15:$A$18,0)),"Yes","No")) -> Yes
A22: TK-00021 | B22: 46204 | C22: Phone | D22: Delivery | E22: Medium | F22: AG07 | G22: 4 | H22: 19.6 | I22: Resolved | K22: No | L22: =DATE(YEAR(B22),MONTH(B22),1) -> 46204 | M22: =WEEKDAY(B22,2) -> 3 | N22: =IF(G22<=INDEX(Assumptions!$B$15:$B$18,MATCH(E22,Assumptions!$A$15:$A$18,0)),"Yes","No") -> Yes | O22: =IF(H22="","Open",IF(H22<=INDEX(Assumptions!$C$15:$C$18,MATCH(E22,Assumptions!$A$15:$A$18,0)),"Yes","No")) -> Yes
A23: TK-00022 | B23: 46204 | C23: Email | D23: Refund | E23: Low | F23: AG07 | G23: 211 | H23: 12.5 | I23: Resolved | J23: 4 | K23: No | L23: =DATE(YEAR(B23),MONTH(B23),1) -> 46204 | M23: =WEEKDAY(B23,2) -> 3 | N23: =IF(G23<=INDEX(Assumptions!$B$15:$B$18,MATCH(E23,Assumptions!$A$15:$A$18,0)),"Yes","No") -> Yes | O23: =IF(H23="","Open",IF(H23<=INDEX(Assumptions!$C$15:$C$18,MATCH(E23,Assumptions!$A$15:$A$18,0)),"Yes","No")) -> Yes
A24: TK-00023 | B24: 46204 | C24: Email | D24: Account | E24: High | F24: AG04 | G24: 146 | H24: 6.2 | I24: Resolved | K24: No | L24: =DATE(YEAR(B24),MONTH(B24),1) -> 46204 | M24: =WEEKDAY(B24,2) -> 3 | N24: =IF(G24<=INDEX(Assumptions!$B$15:$B$18,MATCH(E24,Assumptions!$A$15:$A$18,0)),"Yes","No") -> No | O24: =IF(H24="","Open",IF(H24<=INDEX(Assumptions!$C$15:$C$18,MATCH(E24,Assumptions!$A$15:$A$18,0)),"Yes","No")) -> Yes
A25: TK-00024 | B25: 46204 | C25: WhatsApp | D25: Account | E25: Medium | F25: AG16 | G25: 45 | H25: 1.6 | I25: Resolved | J25: 4 | K25: No | L25: =DATE(YEAR(B25),MONTH(B25),1) -> 46204 | M25: =WEEKDAY(B25,2) -> 3 | N25: =IF(G25<=INDEX(Assumptions!$B$15:$B$18,MATCH(E25,Assumptions!$A$15:$A$18,0)),"Yes","No") -> Yes | O25: =IF(H25="","Open",IF(H25<=INDEX(Assumptions!$C$15:$C$18,MATCH(E25,Assumptions!$A$15:$A$18,0)),"Yes","No")) -> Yes
A26: TK-00025 | B26: 46204 | C26: Phone | D26: Technical | E26: Low | F26: AG11 | G26: 3 | H26: 8.5 | I26: Resolved | J26: 3 | K26: No | L26: =DATE(YEAR(B26),MONTH(B26),1) -> 46204 | M26: =WEEKDAY(B26,2) -> 3 | N26: =IF(G26<=INDEX(Assumptions!$B$15:$B$18,MATCH(E26,Assumptions!$A$15:$A$18,0)),"Yes","No") -> Yes | O26: =IF(H26="","Open",IF(H26<=INDEX(Assumptions!$C$15:$C$18,MATCH(E26,Assumptions!$A$15:$A$18,0)),"Yes","No")) -> Yes
A27: TK-00026 | B27: 46204 | C27: Phone | D27: Account | E27: Medium | F27: AG06 | G27: 1 | H27: 2.8 | I27: Resolved | K27: No | L27: =DATE(YEAR(B27),MONTH(B27),1) -> 46204 | M27: =WEEKDAY(B27,2) -> 3 | N27: =IF(G27<=INDEX(Assumptions!$B$15:$B$18,MATCH(E27,Assumptions!$A$15:$A$18,0)),"Yes","No") -> Yes | O27: =IF(H27="","Open",IF(H27<=INDEX(Assumptions!$C$15:$C$18,MATCH(E27,Assumptions!$A$15:$A$18,0)),"Yes","No")) -> Yes
A28: TK-00027 | B28: 46204 | C28: WhatsApp | D28: Account | E28: Medium | F28: AG14 | G28: 48 | H28: 2 | I28: Resolved | K28: No | L28: =DATE(YEAR(B28),MONTH(B28),1) -> 46204 | M28: =WEEKDAY(B28,2) -> 3 | N28: =IF(G28<=INDEX(Assumptions!$B$15:$B$18,MATCH(E28,Assumptions!$A$15:$A$18,0)),"Yes","No") -> Yes | O28: =IF(H28="","Open",IF(H28<=INDEX(Assumptions!$C$15:$C$18,MATCH(E28,Assumptions!$A$15:$A$18,0)),"Yes","No")) -> Yes
A29: TK-00028 | B29: 46204 | C29: Chat | D29: Account | E29: Low | F29: AG14 | G29: 1 | H29: 17.1 | I29: Resolved | K29: No | L29: =DATE(YEAR(B29),MONTH(B29),1) -> 46204 | M29: =WEEKDAY(B29,2) -> 3 | N29: =IF(G29<=INDEX(Assumptions!$B$15:$B$18,MATCH(E29,Assumptions!$A$15:$A$18,0)),"Yes","No") -> Yes | O29: =IF(H29="","Open",IF(H29<=INDEX(Assumptions!$C$15:$C$18,MATCH(E29,Assumptions!$A$15:$A$18,0)),"Yes","No")) -> Yes
A30: TK-00029 | B30: 46204 | C30: Email | D30: Billing | E30: High | F30: AG17 | G30: 60 | H30: 6.5 | I30: Resolved | J30: 4 | K30: No | L30: =DATE(YEAR(B30),MONTH(B30),1) -> 46204 | M30: =WEEKDAY(B30,2) -> 3 | N30: =IF(G30<=INDEX(Assumptions!$B$15:$B$18,MATCH(E30,Assumptions!$A$15:$A$18,0)),"Yes","No") -> No | O30: =IF(H30="","Open",IF(H30<=INDEX(Assumptions!$C$15:$C$18,MATCH(E30,Assumptions!$A$15:$A$18,0)),"Yes","No")) -> Yes
A31: TK-00030 | B31: 46204 | C31: Chat | D31: Billing | E31: High | F31: AG17 | G31: 5 | H31: 7.9 | I31: Resolved | K31: No | L31: =DATE(YEAR(B31),MONTH(B31),1) -> 46204 | M31: =WEEKDAY(B31,2) -> 3 | N31: =IF(G31<=INDEX(Assumptions!$B$15:$B$18,MATCH(E31,Assumptions!$A$15:$A$18,0)),"Yes","No") -> Yes | O31: =IF(H31="","Open",IF(H31<=INDEX(Assumptions!$C$15:$C$18,MATCH(E31,Assumptions!$A$15:$A$18,0)),"Yes","No")) -> Yes
A32: TK-00031 | B32: 46204 | C32: WhatsApp | D32: Account | E32: Medium | F32: AG02 | G32: 3 | H32: 4.2 | I32: Resolved | J32: 4 | K32: No | L32: =DATE(YEAR(B32),MONTH(B32),1) -> 46204 | M32: =WEEKDAY(B32,2) -> 3 | N32: =IF(G32<=INDEX(Assumptions!$B$15:$B$18,MATCH(E32,Assumptions!$A$15:$A$18,0)),"Yes","No") -> Yes | O32: =IF(H32="","Open",IF(H32<=INDEX(Assumptions!$C$15:$C$18,MATCH(E32,Assumptions!$A$15:$A$18,0)),"Yes","No")) -> Yes
A33: TK-00032 | B33: 46204 | C33: WhatsApp | D33: Delivery | E33: High | F33: AG10 | G33: 7 | H33: 4.9 | I33: Resolved | J33: 4 | K33: No | L33: =DATE(YEAR(B33),MONTH(B33),1) -> 46204 | M33: =WEEKDAY(B33,2) -> 3 | N33: =IF(G33<=INDEX(Assumptions!$B$15:$B$18,MATCH(E33,Assumptions!$A$15:$A$18,0)),"Yes","No") -> Yes | O33: =IF(H33="","Open",IF(H33<=INDEX(Assumptions!$C$15:$C$18,MATCH(E33,Assumptions!$A$15:$A$18,0)),"Yes","No")) -> Yes
A34: TK-00033 | B34: 46204 | C34: WhatsApp | D34: Account | E34: Low | F34: AG12 | G34: 12 | H34: 19.3 | I34: Resolved | J34: 5 | K34: Yes | L34: =DATE(YEAR(B34),MONTH(B34),1) -> 46204 | M34: =WEEKDAY(B34,2) -> 3 | N34: =IF(G34<=INDEX(Assumptions!$B$15:$B$18,MATCH(E34,Assumptions!$A$15:$A$18,0)),"Yes","No") -> Yes | O34: =IF(H34="","Open",IF(H34<=INDEX(Assumptions!$C$15:$C$18,MATCH(E34,Assumptions!$A$15:$A$18,0)),"Yes","No")) -> Yes
A35: TK-00034 | B35: 46204 | C35: Phone | D35: Delivery | E35: Low | F35: AG02 | G35: 6 | H35: 12 | I35: Resolved | J35: 5 | K35: No | L35: =DATE(YEAR(B35),MONTH(B35),1) -> 46204 | M35: =WEEKDAY(B35,2) -> 3 | N35: =IF(G35<=INDEX(Assumptions!$B$15:$B$18,MATCH(E35,Assumptions!$A$15:$A$18,0)),"Yes","No") -> Yes | O35: =IF(H35="","Open",IF(H35<=INDEX(Assumptions!$C$15:$C$18,MATCH(E35,Assumptions!$A$15:$A$18,0)),"Yes","No")) -> Yes
A36: TK-00035 | B36: 46204 | C36: Email | D36: Delivery | E36: Medium | F36: AG02 | G36: 40 | H36: 26.2 | I36: Resolved | J36: 4 | K36: No | L36: =DATE(YEAR(B36),MONTH(B36),1) -> 46204 | M36: =WEEKDAY(B36,2) -> 3 | N36: =IF(G36<=INDEX(Assumptions!$B$15:$B$18,MATCH(E36,Assumptions!$A$15:$A$18,0)),"Yes","No") -> Yes | O36: =IF(H36="","Open",IF(H36<=INDEX(Assumptions!$C$15:$C$18,MATCH(E36,Assumptions!$A$15:$A$18,0)),"Yes","No")) -> No
A37: TK-00036 | B37: 46204 | C37: WhatsApp | D37: Billing | E37: Low | F37: AG06 | G37: 3 | H37: 14 | I37: Resolved | K37: Yes | L37: =DATE(YEAR(B37),MONTH(B37),1) -> 46204 | M37: =WEEKDAY(B37,2) -> 3 | N37: =IF(G37<=INDEX(Assumptions!$B$15:$B$18,MATCH(E37,Assumptions!$A$15:$A$18,0)),"Yes","No") -> Yes | O37: =IF(H37="","Open",IF(H37<=INDEX(Assumptions!$C$15:$C$18,MATCH(E37,Assumptions!$A$15:$A$18,0)),"Yes","No")) -> Yes
A38: TK-00037 | B38: 46204 | C38: Email | D38: Delivery | E38: Medium | F38: AG08 | G38: 37 | H38: 25.7 | I38: Resolved | K38: No | L38: =DATE(YEAR(B38),MONTH(B38),1) -> 46204 | M38: =WEEKDAY(B38,2) -> 3 | N38: =IF(G38<=INDEX(Assumptions!$B$15:$B$18,MATCH(E38,Assumptions!$A$15:$A$18,0)),"Yes","No") -> Yes | O38: =IF(H38="","Open",IF(H38<=INDEX(Assumptions!$C$15:$C$18,MATCH(E38,Assumptions!$A$15:$A$18,0)),"Yes","No")) -> No
A39: TK-00038 | B39: 46204 | C39: Phone | D39: Delivery | E39: Medium | F39: AG04 | G39: 2 | H39: 27.2 | I39: Resolved | K39: No | L39: =DATE(YEAR(B39),MONTH(B39),1) -> 46204 | M39: =WEEKDAY(B39,2) -> 3 | N39: =IF(G39<=INDEX(Assumptions!$B$15:$B$18,MATCH(E39,Assumptions!$A$15:$A$18,0)),"Yes","No") -> Yes | O39: =IF(H39="","Open",IF(H39<=INDEX(Assumptions!$C$15:$C$18,MATCH(E39,Assumptions!$A$15:$A$18,0)),"Yes","No")) -> No
A40: TK-00039 | B40: 46204 | C40: Chat | D40: Billing | E40: High | F40: AG06 | G40: 5 | H40: 2.6 | I40: Resolved | J40: 5 | K40: No | L40: =DATE(YEAR(B40),MONTH(B40),1) -> 46204 | M40: =WEEKDAY(B40,2) -> 3 | N40: =IF(G40<=INDEX(Assumptions!$B$15:$B$18,MATCH(E40,Assumptions!$A$15:$A$18,0)),"Yes","No") -> Yes | O40: =IF(H40="","Open",IF(H40<=INDEX(Assumptions!$C$15:$C$18,MATCH(E40,Assumptions!$A$15:$A$18,0)),"Yes","No")) -> Yes
...
