Workbook

Sheet README
A1: Logistics & Supplier Delivery Performance
A3: Business scenario | B3: A distributor in Kenya orders goods from six suppliers and delivers to six regions. Management wants to know which suppliers deliver on time and in full (OTIF), what late and damaged deliveries cost, and whether performance is improving.
A5: Sheets | B5: Assumptions: lateness tolerance, late-penalty rate, OTIF target, minimum acceptable OTIF and damage tolerance.
B6: Deliveries: 500 synthetic deliveries (inputs) plus formula columns for days late, on-time, in-full, OTIF, penalty, cost per km and damage rate.
B7: Dashboard: OTIF KPIs, supplier scorecard with A/B/C grade, regional table, monthly trend, and charts.
A9: Colour legend | B9: Blue text on yellow = editable input (Assumptions sheet).
B10: Blue header on Data sheet = raw input columns; green header = formula columns (do not overwrite).
B11: Black text = formula. Everything on the Dashboard recalculates when Assumptions or Data change.
A13: Data note | B13: All data is SYNTHETIC, generated for portfolio demonstration. Targets and thresholds are illustrative. Not client data.
A15: Skills demonstrated | B15: Supply-chain KPIs (OTIF, fill rate, cost per km)
B16: Supplier scorecarding
B17: Date arithmetic and flags
B18: SUMIFS / COUNTIFS / INDEX-MATCH
B19: Dashboard design

Sheet Dashboard
A1: Logistics & Supplier Delivery Dashboard
A2: Synthetic data | KES | Jan-Sep 2026
A4: Key metrics
A5: Deliveries | B5: =COUNTA(Deliveries!$A$2:$A$501) -> 500
A6: OTIF % | B6: =SUM(Deliveries!$O$2:$O$501)/COUNTA(Deliveries!$A$2:$A$501) -> 0.75
A7: On-time % | B7: =SUM(Deliveries!$M$2:$M$501)/COUNTA(Deliveries!$A$2:$A$501) -> 0.854
A8: In-full % | B8: =SUM(Deliveries!$N$2:$N$501)/COUNTA(Deliveries!$A$2:$A$501) -> 0.87
A9: OTIF vs target | B9: =IF(B6>=Assumptions!$B$7,"On target","Below target") -> Below target
A10: Avg days late (all deliveries) | B10: =AVERAGE(Deliveries!$L$2:$L$501) -> 0.45
A11: Total freight cost (KES) | B11: =SUM(Deliveries!$J$2:$J$501) -> 10722578
A12: Late penalty cost (KES) | B12: =SUM(Deliveries!$P$2:$P$501) -> 337500
A13: Overall damage rate | B13: =SUM(Deliveries!$K$2:$K$501)/SUM(Deliveries!$H$2:$H$501) -> 0.020205172
A14: Freight cost per km (KES) | B14: =SUM(Deliveries!$J$2:$J$501)/SUM(Deliveries!$I$2:$I$501) -> 95.243229
A16: Insights (auto-updating)
A17: Best supplier (OTIF) | B17: =INDEX(A23:A28,MATCH(MAX(E23:E28),E23:E28,0)) -> Highland Foods Ltd
A18: Weakest supplier (OTIF) | B18: =INDEX(A23:A28,MATCH(MIN(E23:E28),E23:E28,0)) -> Lakeside Hardware
A19: Weakest region (OTIF) | B19: =INDEX(A33:A38,MATCH(MIN(E33:E38),E33:E38,0)) -> Bomet
A20: Suppliers graded C | B20: =COUNTIF(J23:J28,"C") -> 3
A21: Supplier scorecard
A22: Supplier | B22: Deliveries | C22: On-time % | D22: In-full % | E22: OTIF % | F22: Avg days late | G22: Damage rate | H22: Freight (KES) | I22: Late penalty (KES) | J22: Grade | K22: Damage flag
A23: Rift Agro Supplies | B23: =COUNTIFS(Deliveries!$B$2:$B$501,$A23) -> 68 | C23: =IF(B23=0,0,SUMIFS(Deliveries!$M$2:$M$501,Deliveries!$B$2:$B$501,$A23)/B23) -> 0.95588235 | D23: =IF(B23=0,0,SUMIFS(Deliveries!$N$2:$N$501,Deliveries!$B$2:$B$501,$A23)/B23) -> 0.94117647 | E23: =IF(B23=0,0,SUMIFS(Deliveries!$O$2:$O$501,Deliveries!$B$2:$B$501,$A23)/B23) -> 0.89705882 | F23: =IF(B23=0,0,SUMIFS(Deliveries!$L$2:$L$501,Deliveries!$B$2:$B$501,$A23)/B23) -> 0.14705882 | G23: =IFERROR(SUMIFS(Deliveries!$K$2:$K$501,Deliveries!$B$2:$B$501,$A23)/SUMIFS(Deliveries!$H$2:$H$501,Deliveries!$B$2:$B$501,$A23),0) -> 0.0095688456 | H23: =SUMIFS(Deliveries!$J$2:$J$501,Deliveries!$B$2:$B$501,$A23) -> 1331271 | I23: =SUMIFS(Deliveries!$P$2:$P$501,Deliveries!$B$2:$B$501,$A23) -> 15000 | J23: =IF(E23>=Assumptions!$B$7,"A",IF(E23>=Assumptions!$B$8,"B","C")) -> B | K23: =IF(G23>Assumptions!$B$9,"Above tolerance","OK") -> OK
A24: Savanna Packaging | B24: =COUNTIFS(Deliveries!$B$2:$B$501,$A24) -> 90 | C24: =IF(B24=0,0,SUMIFS(Deliveries!$M$2:$M$501,Deliveries!$B$2:$B$501,$A24)/B24) -> 0.86666667 | D24: =IF(B24=0,0,SUMIFS(Deliveries!$N$2:$N$501,Deliveries!$B$2:$B$501,$A24)/B24) -> 0.93333333 | E24: =IF(B24=0,0,SUMIFS(Deliveries!$O$2:$O$501,Deliveries!$B$2:$B$501,$A24)/B24) -> 0.81111111 | F24: =IF(B24=0,0,SUMIFS(Deliveries!$L$2:$L$501,Deliveries!$B$2:$B$501,$A24)/B24) -> 0.4 | G24: =IFERROR(SUMIFS(Deliveries!$K$2:$K$501,Deliveries!$B$2:$B$501,$A24)/SUMIFS(Deliveries!$H$2:$H$501,Deliveries!$B$2:$B$501,$A24),0) -> 0.018078425 | H24: =SUMIFS(Deliveries!$J$2:$J$501,Deliveries!$B$2:$B$501,$A24) -> 1993450 | I24: =SUMIFS(Deliveries!$P$2:$P$501,Deliveries!$B$2:$B$501,$A24) -> 54000 | J24: =IF(E24>=Assumptions!$B$7,"A",IF(E24>=Assumptions!$B$8,"B","C")) -> B | K24: =IF(G24>Assumptions!$B$9,"Above tolerance","OK") -> OK
A25: Lakeside Hardware | B25: =COUNTIFS(Deliveries!$B$2:$B$501,$A25) -> 87 | C25: =IF(B25=0,0,SUMIFS(Deliveries!$M$2:$M$501,Deliveries!$B$2:$B$501,$A25)/B25) -> 0.67816092 | D25: =IF(B25=0,0,SUMIFS(Deliveries!$N$2:$N$501,Deliveries!$B$2:$B$501,$A25)/B25) -> 0.68965517 | E25: =IF(B25=0,0,SUMIFS(Deliveries!$O$2:$O$501,Deliveries!$B$2:$B$501,$A25)/B25) -> 0.44827586 | F25: =IF(B25=0,0,SUMIFS(Deliveries!$L$2:$L$501,Deliveries!$B$2:$B$501,$A25)/B25) -> 1.0804598 | G25: =IFERROR(SUMIFS(Deliveries!$K$2:$K$501,Deliveries!$B$2:$B$501,$A25)/SUMIFS(Deliveries!$H$2:$H$501,Deliveries!$B$2:$B$501,$A25),0) -> 0.036844837 | H25: =SUMIFS(Deliveries!$J$2:$J$501,Deliveries!$B$2:$B$501,$A25) -> 2008153 | I25: =SUMIFS(Deliveries!$P$2:$P$501,Deliveries!$B$2:$B$501,$A25) -> 141000 | J25: =IF(E25>=Assumptions!$B$7,"A",IF(E25>=Assumptions!$B$8,"B","C")) -> C | K25: =IF(G25>Assumptions!$B$9,"Above tolerance","OK") -> Above tolerance
A26: Coastal Freight Goods | B26: =COUNTIFS(Deliveries!$B$2:$B$501,$A26) -> 88 | C26: =IF(B26=0,0,SUMIFS(Deliveries!$M$2:$M$501,Deliveries!$B$2:$B$501,$A26)/B26) -> 0.85227273 | D26: =IF(B26=0,0,SUMIFS(Deliveries!$N$2:$N$501,Deliveries!$B$2:$B$501,$A26)/B26) -> 0.78409091 | E26: =IF(B26=0,0,SUMIFS(Deliveries!$O$2:$O$501,Deliveries!$B$2:$B$501,$A26)/B26) -> 0.65909091 | F26: =IF(B26=0,0,SUMIFS(Deliveries!$L$2:$L$501,Deliveries!$B$2:$B$501,$A26)/B26) -> 0.48863636 | G26: =IFERROR(SUMIFS(Deliveries!$K$2:$K$501,Deliveries!$B$2:$B$501,$A26)/SUMIFS(Deliveries!$H$2:$H$501,Deliveries!$B$2:$B$501,$A26),0) -> 0.029870673 | H26: =SUMIFS(Deliveries!$J$2:$J$501,Deliveries!$B$2:$B$501,$A26) -> 1993145 | I26: =SUMIFS(Deliveries!$P$2:$P$501,Deliveries!$B$2:$B$501,$A26) -> 64500 | J26: =IF(E26>=Assumptions!$B$7,"A",IF(E26>=Assumptions!$B$8,"B","C")) -> C | K26: =IF(G26>Assumptions!$B$9,"Above tolerance","OK") -> Above tolerance
A27: Highland Foods Ltd | B27: =COUNTIFS(Deliveries!$B$2:$B$501,$A27) -> 89 | C27: =IF(B27=0,0,SUMIFS(Deliveries!$M$2:$M$501,Deliveries!$B$2:$B$501,$A27)/B27) -> 0.97752809 | D27: =IF(B27=0,0,SUMIFS(Deliveries!$N$2:$N$501,Deliveries!$B$2:$B$501,$A27)/B27) -> 1 | E27: =IF(B27=0,0,SUMIFS(Deliveries!$O$2:$O$501,Deliveries!$B$2:$B$501,$A27)/B27) -> 0.97752809 | F27: =IF(B27=0,0,SUMIFS(Deliveries!$L$2:$L$501,Deliveries!$B$2:$B$501,$A27)/B27) -> 0.02247191 | G27: =IFERROR(SUMIFS(Deliveries!$K$2:$K$501,Deliveries!$B$2:$B$501,$A27)/SUMIFS(Deliveries!$H$2:$H$501,Deliveries!$B$2:$B$501,$A27),0) -> 0.0069674067 | H27: =SUMIFS(Deliveries!$J$2:$J$501,Deliveries!$B$2:$B$501,$A27) -> 1883031 | I27: =SUMIFS(Deliveries!$P$2:$P$501,Deliveries!$B$2:$B$501,$A27) -> 3000 | J27: =IF(E27>=Assumptions!$B$7,"A",IF(E27>=Assumptions!$B$8,"B","C")) -> A | K27: =IF(G27>Assumptions!$B$9,"Above tolerance","OK") -> OK
A28: Unity Stationers | B28: =COUNTIFS(Deliveries!$B$2:$B$501,$A28) -> 78 | C28: =IF(B28=0,0,SUMIFS(Deliveries!$M$2:$M$501,Deliveries!$B$2:$B$501,$A28)/B28) -> 0.80769231 | D28: =IF(B28=0,0,SUMIFS(Deliveries!$N$2:$N$501,Deliveries!$B$2:$B$501,$A28)/B28) -> 0.88461538 | E28: =IF(B28=0,0,SUMIFS(Deliveries!$O$2:$O$501,Deliveries!$B$2:$B$501,$A28)/B28) -> 0.73076923 | F28: =IF(B28=0,0,SUMIFS(Deliveries!$L$2:$L$501,Deliveries!$B$2:$B$501,$A28)/B28) -> 0.51282051 | G28: =IFERROR(SUMIFS(Deliveries!$K$2:$K$501,Deliveries!$B$2:$B$501,$A28)/SUMIFS(Deliveries!$H$2:$H$501,Deliveries!$B$2:$B$501,$A28),0) -> 0.013368719 | H28: =SUMIFS(Deliveries!$J$2:$J$501,Deliveries!$B$2:$B$501,$A28) -> 1513528 | I28: =SUMIFS(Deliveries!$P$2:$P$501,Deliveries!$B$2:$B$501,$A28) -> 60000 | J28: =IF(E28>=Assumptions!$B$7,"A",IF(E28>=Assumptions!$B$8,"B","C")) -> C | K28: =IF(G28>Assumptions!$B$9,"Above tolerance","OK") -> OK
A31: Performance by region
A32: Region | B32: Deliveries | C32: On-time % | D32: In-full % | E32: OTIF % | F32: Avg days late | G32: Damage rate | H32: Freight (KES) | I32: Late penalty (KES)
A33: Nairobi | B33: =COUNTIFS(Deliveries!$C$2:$C$501,$A33) -> 138 | C33: =IF(B33=0,0,SUMIFS(Deliveries!$M$2:$M$501,Deliveries!$C$2:$C$501,$A33)/B33) -> 0.85507246 | D33: =IF(B33=0,0,SUMIFS(Deliveries!$N$2:$N$501,Deliveries!$C$2:$C$501,$A33)/B33) -> 0.86956522 | E33: =IF(B33=0,0,SUMIFS(Deliveries!$O$2:$O$501,Deliveries!$C$2:$C$501,$A33)/B33) -> 0.76086957 | F33: =IF(B33=0,0,SUMIFS(Deliveries!$L$2:$L$501,Deliveries!$C$2:$C$501,$A33)/B33) -> 0.38405797 | G33: =IFERROR(SUMIFS(Deliveries!$K$2:$K$501,Deliveries!$C$2:$C$501,$A33)/SUMIFS(Deliveries!$H$2:$H$501,Deliveries!$C$2:$C$501,$A33),0) -> 0.020172833 | H33: =SUMIFS(Deliveries!$J$2:$J$501,Deliveries!$C$2:$C$501,$A33) -> 766297 | I33: =SUMIFS(Deliveries!$P$2:$P$501,Deliveries!$C$2:$C$501,$A33) -> 79500
A34: Mombasa | B34: =COUNTIFS(Deliveries!$C$2:$C$501,$A34) -> 71 | C34: =IF(B34=0,0,SUMIFS(Deliveries!$M$2:$M$501,Deliveries!$C$2:$C$501,$A34)/B34) -> 0.85915493 | D34: =IF(B34=0,0,SUMIFS(Deliveries!$N$2:$N$501,Deliveries!$C$2:$C$501,$A34)/B34) -> 0.84507042 | E34: =IF(B34=0,0,SUMIFS(Deliveries!$O$2:$O$501,Deliveries!$C$2:$C$501,$A34)/B34) -> 0.71830986 | F34: =IF(B34=0,0,SUMIFS(Deliveries!$L$2:$L$501,Deliveries!$C$2:$C$501,$A34)/B34) -> 0.50704225 | G34: =IFERROR(SUMIFS(Deliveries!$K$2:$K$501,Deliveries!$C$2:$C$501,$A34)/SUMIFS(Deliveries!$H$2:$H$501,Deliveries!$C$2:$C$501,$A34),0) -> 0.021441446 | H34: =SUMIFS(Deliveries!$J$2:$J$501,Deliveries!$C$2:$C$501,$A34) -> 2955637 | I34: =SUMIFS(Deliveries!$P$2:$P$501,Deliveries!$C$2:$C$501,$A34) -> 54000
A35: Kisumu | B35: =COUNTIFS(Deliveries!$C$2:$C$501,$A35) -> 68 | C35: =IF(B35=0,0,SUMIFS(Deliveries!$M$2:$M$501,Deliveries!$C$2:$C$501,$A35)/B35) -> 0.82352941 | D35: =IF(B35=0,0,SUMIFS(Deliveries!$N$2:$N$501,Deliveries!$C$2:$C$501,$A35)/B35) -> 0.89705882 | E35: =IF(B35=0,0,SUMIFS(Deliveries!$O$2:$O$501,Deliveries!$C$2:$C$501,$A35)/B35) -> 0.73529412 | F35: =IF(B35=0,0,SUMIFS(Deliveries!$L$2:$L$501,Deliveries!$C$2:$C$501,$A35)/B35) -> 0.64705882 | G35: =IFERROR(SUMIFS(Deliveries!$K$2:$K$501,Deliveries!$C$2:$C$501,$A35)/SUMIFS(Deliveries!$H$2:$H$501,Deliveries!$C$2:$C$501,$A35),0) -> 0.02255118 | H35: =SUMIFS(Deliveries!$J$2:$J$501,Deliveries!$C$2:$C$501,$A35) -> 2012918 | I35: =SUMIFS(Deliveries!$P$2:$P$501,Deliveries!$C$2:$C$501,$A35) -> 66000
A36: Nakuru | B36: =COUNTIFS(Deliveries!$C$2:$C$501,$A36) -> 76 | C36: =IF(B36=0,0,SUMIFS(Deliveries!$M$2:$M$501,Deliveries!$C$2:$C$501,$A36)/B36) -> 0.90789474 | D36: =IF(B36=0,0,SUMIFS(Deliveries!$N$2:$N$501,Deliveries!$C$2:$C$501,$A36)/B36) -> 0.90789474 | E36: =IF(B36=0,0,SUMIFS(Deliveries!$O$2:$O$501,Deliveries!$C$2:$C$501,$A36)/B36) -> 0.82894737 | F36: =IF(B36=0,0,SUMIFS(Deliveries!$L$2:$L$501,Deliveries!$C$2:$C$501,$A36)/B36) -> 0.28947368 | G36: =IFERROR(SUMIFS(Deliveries!$K$2:$K$501,Deliveries!$C$2:$C$501,$A36)/SUMIFS(Deliveries!$H$2:$H$501,Deliveries!$C$2:$C$501,$A36),0) -> 0.018531178 | H36: =SUMIFS(Deliveries!$J$2:$J$501,Deliveries!$C$2:$C$501,$A36) -> 1315984 | I36: =SUMIFS(Deliveries!$P$2:$P$501,Deliveries!$C$2:$C$501,$A36) -> 33000
A37: Eldoret | B37: =COUNTIFS(Deliveries!$C$2:$C$501,$A37) -> 90 | C37: =IF(B37=0,0,SUMIFS(Deliveries!$M$2:$M$501,Deliveries!$C$2:$C$501,$A37)/B37) -> 0.83333333 | D37: =IF(B37=0,0,SUMIFS(Deliveries!$N$2:$N$501,Deliveries!$C$2:$C$501,$A37)/B37) -> 0.9 | E37: =IF(B37=0,0,SUMIFS(Deliveries!$O$2:$O$501,Deliveries!$C$2:$C$501,$A37)/B37) -> 0.78888889 | F37: =IF(B37=0,0,SUMIFS(Deliveries!$L$2:$L$501,Deliveries!$C$2:$C$501,$A37)/B37) -> 0.54444444 | G37: =IFERROR(SUMIFS(Deliveries!$K$2:$K$501,Deliveries!$C$2:$C$501,$A37)/SUMIFS(Deliveries!$H$2:$H$501,Deliveries!$C$2:$C$501,$A37),0) -> 0.018592805 | H37: =SUMIFS(Deliveries!$J$2:$J$501,Deliveries!$C$2:$C$501,$A37) -> 2408516 | I37: =SUMIFS(Deliveries!$P$2:$P$501,Deliveries!$C$2:$C$501,$A37) -> 73500
A38: Bomet | B38: =COUNTIFS(Deliveries!$C$2:$C$501,$A38) -> 57 | C38: =IF(B38=0,0,SUMIFS(Deliveries!$M$2:$M$501,Deliveries!$C$2:$C$501,$A38)/B38) -> 0.84210526 | D38: =IF(B38=0,0,SUMIFS(Deliveries!$N$2:$N$501,Deliveries!$C$2:$C$501,$A38)/B38) -> 0.77192982 | E38: =IF(B38=0,0,SUMIFS(Deliveries!$O$2:$O$501,Deliveries!$C$2:$C$501,$A38)/B38) -> 0.61403509 | F38: =IF(B38=0,0,SUMIFS(Deliveries!$L$2:$L$501,Deliveries!$C$2:$C$501,$A38)/B38) -> 0.36842105 | G38: =IFERROR(SUMIFS(Deliveries!$K$2:$K$501,Deliveries!$C$2:$C$501,$A38)/SUMIFS(Deliveries!$H$2:$H$501,Deliveries!$C$2:$C$501,$A38),0) -> 0.020440729 | H38: =SUMIFS(Deliveries!$J$2:$J$501,Deliveries!$C$2:$C$501,$A38) -> 1263226 | I38: =SUMIFS(Deliveries!$P$2:$P$501,Deliveries!$C$2:$C$501,$A38) -> 31500
A41: Monthly trend (by order month)
A42: Month | B42: Month # | C42: Deliveries | D42: OTIF % | E42: Late penalty (KES)
A43: Jan | B43: 1 | C43: =COUNTIFS(Deliveries!$S$2:$S$501,$B43) -> 44 | D43: =IF(C43=0,0,SUMIFS(Deliveries!$O$2:$O$501,Deliveries!$S$2:$S$501,$B43)/C43) -> 0.72727273 | E43: =SUMIFS(Deliveries!$P$2:$P$501,Deliveries!$S$2:$S$501,$B43) -> 58500
A44: Feb | B44: 2 | C44: =COUNTIFS(Deliveries!$S$2:$S$501,$B44) -> 49 | D44: =IF(C44=0,0,SUMIFS(Deliveries!$O$2:$O$501,Deliveries!$S$2:$S$501,$B44)/C44) -> 0.79591837 | E44: =SUMIFS(Deliveries!$P$2:$P$501,Deliveries!$S$2:$S$501,$B44) -> 18000
A45: Mar | B45: 3 | C45: =COUNTIFS(Deliveries!$S$2:$S$501,$B45) -> 75 | D45: =IF(C45=0,0,SUMIFS(Deliveries!$O$2:$O$501,Deliveries!$S$2:$S$501,$B45)/C45) -> 0.76 | E45: =SUMIFS(Deliveries!$P$2:$P$501,Deliveries!$S$2:$S$501,$B45) -> 57000
A46: Apr | B46: 4 | C46: =COUNTIFS(Deliveries!$S$2:$S$501,$B46) -> 55 | D46: =IF(C46=0,0,SUMIFS(Deliveries!$O$2:$O$501,Deliveries!$S$2:$S$501,$B46)/C46) -> 0.76363636 | E46: =SUMIFS(Deliveries!$P$2:$P$501,Deliveries!$S$2:$S$501,$B46) -> 43500
...

Sheet Assumptions
A1: Assumptions (edit the yellow cells)
A4: Parameter | B4: Value | C4: Note
A5: On-time tolerance (days late allowed) | B5: 0 | C5: 0 = delivery must arrive on or before the promised date.
A6: Late penalty cost (KES per day late) | B6: 1500 | C6: Illustrative internal cost of a late delivery (stock-outs, rework).
A7: OTIF target | B7: 0.9 | C7: Illustrative target; grade A at or above.
A8: Minimum acceptable OTIF | B8: 0.8 | C8: Grade B at or above; below this is grade C.
A9: Damage tolerance (% of units) | B9: 0.02 | C9: Suppliers above this are flagged.

Sheet Deliveries
A1: Delivery ID | B1: Supplier | C1: Region | D1: Order date | E1: Promised date | F1: Delivered date | G1: Qty ordered | H1: Qty delivered | I1: Distance (km) | J1: Freight cost (KES) | K1: Damaged units | L1: Days late | M1: On time | N1: In full | O1: OTIF | P1: Late penalty (KES) | Q1: Freight cost per km (KES) | R1: Damage rate | S1: Month #
A2: DL3001 | B2: Highland Foods Ltd | C2: Nairobi | D2: 46086 | E2: 46093 | F2: 46093 | G2: 880 | H2: 880 | I2: 52 | J2: 8132 | K2: 6 | L2: =MAX(0,F2-E2) -> 0 | M2: =IF(L2<=Assumptions!$B$5,1,0) -> 1 | N2: =IF(H2>=G2,1,0) -> 1 | O2: =M2*N2 -> 1 | P2: =L2*Assumptions!$B$6 -> 0 | Q2: =IF(I2=0,0,J2/I2) -> 156.38462 | R2: =IF(H2=0,0,K2/H2) -> 0.0068181818 | S2: =MONTH(D2) -> 3
A3: DL3002 | B3: Lakeside Hardware | C3: Bomet | D3: 46189 | E3: 46193 | F3: 46193 | G3: 710 | H3: 710 | I3: 223 | J3: 25527 | K3: 38 | L3: =MAX(0,F3-E3) -> 0 | M3: =IF(L3<=Assumptions!$B$5,1,0) -> 1 | N3: =IF(H3>=G3,1,0) -> 1 | O3: =M3*N3 -> 1 | P3: =L3*Assumptions!$B$6 -> 0 | Q3: =IF(I3=0,0,J3/I3) -> 114.47085 | R3: =IF(H3=0,0,K3/H3) -> 0.053521127 | S3: =MONTH(D3) -> 6
A4: DL3003 | B4: Lakeside Hardware | C4: Bomet | D4: 46169 | E4: 46175 | F4: 46175 | G4: 450 | H4: 381 | I4: 233 | J4: 26538 | K4: 11 | L4: =MAX(0,F4-E4) -> 0 | M4: =IF(L4<=Assumptions!$B$5,1,0) -> 1 | N4: =IF(H4>=G4,1,0) -> 0 | O4: =M4*N4 -> 0 | P4: =L4*Assumptions!$B$6 -> 0 | Q4: =IF(I4=0,0,J4/I4) -> 113.897 | R4: =IF(H4=0,0,K4/H4) -> 0.028871391 | S4: =MONTH(D4) -> 5
A5: DL3004 | B5: Unity Stationers | C5: Mombasa | D5: 46089 | E5: 46096 | F5: 46096 | G5: 720 | H5: 720 | I5: 471 | J5: 39517 | K5: 2 | L5: =MAX(0,F5-E5) -> 0 | M5: =IF(L5<=Assumptions!$B$5,1,0) -> 1 | N5: =IF(H5>=G5,1,0) -> 1 | O5: =M5*N5 -> 1 | P5: =L5*Assumptions!$B$6 -> 0 | Q5: =IF(I5=0,0,J5/I5) -> 83.900212 | R5: =IF(H5=0,0,K5/H5) -> 0.0027777778 | S5: =MONTH(D5) -> 3
A6: DL3005 | B6: Rift Agro Supplies | C6: Mombasa | D6: 46187 | E6: 46191 | F6: 46191 | G6: 200 | H6: 200 | I6: 400 | J6: 25772 | K6: 0 | L6: =MAX(0,F6-E6) -> 0 | M6: =IF(L6<=Assumptions!$B$5,1,0) -> 1 | N6: =IF(H6>=G6,1,0) -> 1 | O6: =M6*N6 -> 1 | P6: =L6*Assumptions!$B$6 -> 0 | Q6: =IF(I6=0,0,J6/I6) -> 64.43 | R6: =IF(H6=0,0,K6/H6) -> 0 | S6: =MONTH(D6) -> 6
A7: DL3006 | B7: Savanna Packaging | C7: Nakuru | D7: 46126 | E7: 46136 | F7: 46136 | G7: 800 | H7: 800 | I7: 200 | J7: 23764 | K7: 0 | L7: =MAX(0,F7-E7) -> 0 | M7: =IF(L7<=Assumptions!$B$5,1,0) -> 1 | N7: =IF(H7>=G7,1,0) -> 1 | O7: =M7*N7 -> 1 | P7: =L7*Assumptions!$B$6 -> 0 | Q7: =IF(I7=0,0,J7/I7) -> 118.82 | R7: =IF(H7=0,0,K7/H7) -> 0 | S7: =MONTH(D7) -> 4
A8: DL3007 | B8: Coastal Freight Goods | C8: Mombasa | D8: 46226 | E8: 46234 | F8: 46234 | G8: 60 | H8: 54 | I8: 492 | J8: 37610 | K8: 2 | L8: =MAX(0,F8-E8) -> 0 | M8: =IF(L8<=Assumptions!$B$5,1,0) -> 1 | N8: =IF(H8>=G8,1,0) -> 0 | O8: =M8*N8 -> 0 | P8: =L8*Assumptions!$B$6 -> 0 | Q8: =IF(I8=0,0,J8/I8) -> 76.443089 | R8: =IF(H8=0,0,K8/H8) -> 0.037037037 | S8: =MONTH(D8) -> 7
A9: DL3008 | B9: Savanna Packaging | C9: Bomet | D9: 46213 | E9: 46223 | F9: 46223 | G9: 820 | H9: 695 | I9: 237 | J9: 22524 | K9: 7 | L9: =MAX(0,F9-E9) -> 0 | M9: =IF(L9<=Assumptions!$B$5,1,0) -> 1 | N9: =IF(H9>=G9,1,0) -> 0 | O9: =M9*N9 -> 0 | P9: =L9*Assumptions!$B$6 -> 0 | Q9: =IF(I9=0,0,J9/I9) -> 95.037975 | R9: =IF(H9=0,0,K9/H9) -> 0.010071942 | S9: =MONTH(D9) -> 7
A10: DL3009 | B10: Highland Foods Ltd | C10: Bomet | D10: 46150 | E10: 46159 | F10: 46158 | G10: 450 | H10: 450 | I10: 240 | J10: 19036 | K10: 6 | L10: =MAX(0,F10-E10) -> 0 | M10: =IF(L10<=Assumptions!$B$5,1,0) -> 1 | N10: =IF(H10>=G10,1,0) -> 1 | O10: =M10*N10 -> 1 | P10: =L10*Assumptions!$B$6 -> 0 | Q10: =IF(I10=0,0,J10/I10) -> 79.316667 | R10: =IF(H10=0,0,K10/H10) -> 0.013333333 | S10: =MONTH(D10) -> 5
A11: DL3010 | B11: Lakeside Hardware | C11: Nakuru | D11: 46100 | E11: 46105 | F11: 46108 | G11: 590 | H11: 590 | I11: 171 | J11: 21402 | K11: 35 | L11: =MAX(0,F11-E11) -> 3 | M11: =IF(L11<=Assumptions!$B$5,1,0) -> 0 | N11: =IF(H11>=G11,1,0) -> 1 | O11: =M11*N11 -> 0 | P11: =L11*Assumptions!$B$6 -> 4500 | Q11: =IF(I11=0,0,J11/I11) -> 125.15789 | R11: =IF(H11=0,0,K11/H11) -> 0.059322034 | S11: =MONTH(D11) -> 3
A12: DL3011 | B12: Highland Foods Ltd | C12: Nakuru | D12: 46035 | E12: 46038 | F12: 46038 | G12: 390 | H12: 390 | I12: 155 | J12: 14830 | K12: 1 | L12: =MAX(0,F12-E12) -> 0 | M12: =IF(L12<=Assumptions!$B$5,1,0) -> 1 | N12: =IF(H12>=G12,1,0) -> 1 | O12: =M12*N12 -> 1 | P12: =L12*Assumptions!$B$6 -> 0 | Q12: =IF(I12=0,0,J12/I12) -> 95.677419 | R12: =IF(H12=0,0,K12/H12) -> 0.0025641026 | S12: =MONTH(D12) -> 1
A13: DL3012 | B13: Highland Foods Ltd | C13: Nairobi | D13: 46264 | E13: 46267 | F13: 46267 | G13: 50 | H13: 50 | I13: 29 | J13: 2622 | K13: 0 | L13: =MAX(0,F13-E13) -> 0 | M13: =IF(L13<=Assumptions!$B$5,1,0) -> 1 | N13: =IF(H13>=G13,1,0) -> 1 | O13: =M13*N13 -> 1 | P13: =L13*Assumptions!$B$6 -> 0 | Q13: =IF(I13=0,0,J13/I13) -> 90.413793 | R13: =IF(H13=0,0,K13/H13) -> 0 | S13: =MONTH(D13) -> 8
... A501: DL3500 | B501: Savanna Packaging | C501: Bomet | D501: 46038 | E501: 46041 | F501: 46041 | G501: 290 | H501: 290 | I501: 250 | J501: 16565 | K501: 2 | L501: =MAX(0,F501-E501) -> 0 | M501: =IF(L501<=Assumptions!$B$5,1,0) -> 1 | N501: =IF(H501>=G501,1,0) -> 1 | O501: =M501*N501 -> 1 | P501: =L501*Assumptions!$B$6 -> 0 | Q501: =IF(I501=0,0,J501/I501) -> 66.26 | R501: =IF(H501=0,0,K501/H501) -> 0.0068965517 | S501: =MONTH(D501) -> 1
