Workbook

Sheet README
A1: Monthly Management Reporting Pack – Finance Reporting Portfolio Project
A2: BZME Insights | Sector: Finance / Management reporting | Tool: Excel (formula-driven)
A4: BUSINESS PROBLEM
A5: A distributor's managers receive a late, hand-built spreadsheet each month. They cannot quickly see how revenue, margin and costs compare with budget, or which variances matter. This workbook produces a consistent monthly pack from the ledger and budget.
A7: BUSINESS QUESTIONS
A8: 1. How did the month and the year to date perform against budget (revenue, gross profit, operating profit)?
A9: 2. Which accounts drive the biggest favourable and adverse variances?
A10: 3. Which variances are material enough to need an explanation?
A11: 4. Is the margin, cost or volume trend moving in the right direction?
A13: HOW THE WORKBOOK IS BUILT
A14: Ledger: 1,284 transactions (Jan to Sep 2026) across 16 accounts. Budget: monthly budget by account.
A15: Monthly_PL: formulas turn the ledger and budget into actual and budget by month, year to date, month variance and a materiality flag.
... A33: Reforecast the full year once three or more months show the same adverse trend.

Sheet Dashboard
A1: Monthly Management Reporting Pack
A2: ="Fictional Kenyan FMCG distributor | Synthetic data | Reporting month: "&TEXT(Assumptions!B4,"mmmm yyyy")&" | Variances shown as favourable (+) or adverse (-) | Prepared by BZME Insights" -> Fictional Kenyan FMCG distributor | Synthetic data | Reporting month: September 2026 | Variances shown as favourable (+) or adverse (-) | Prepared by BZME Insights
A4: REVENUE (MONTH, KES) | C4: REVENUE VS BUDGET | E4: GROSS MARGIN | G4: OPERATING PROFIT (MONTH, KES) | I4: OP. PROFIT VS BUDGET (KES) | K4: OPERATING PROFIT YTD (KES)
A5: =B23 -> 27293500 | C5: =E23 -> -0.0038868613 | E5: =B26 -> 0.16496602 | G5: =B36 -> 612700 | I5: =D36 -> -664300 | K5: =G36 -> 8497900
A7: Key findings (update automatically)
A8: ="1. "&TEXT(Assumptions!B4,"mmmm")&" revenue was KES "&TEXT(B23/1000000,"0.0")&"M, "&TEXT(ABS(E23),"0.0%")&IF(D23>=0," above"," below")&" budget; year to date is "&TEXT(ABS(J23),"0.0%")&IF(I23>=0," above"," below")&" budget." -> 1. September revenue was KES 27.3M, 0.4% below budget; year to date is 1.3% above budget.
A9: ="2. Gross margin was "&TEXT(B26,"0.0%")&" against a budget of "&TEXT(C26,"0.0%")&" ("&TEXT((B26-C26)*100,"+0.0;-0.0")&" pts)." -> 2. Gross margin was 16.5% against a budget of 18.0% (-1.5 pts).
A10: ="3. Operating profit was KES "&TEXT(B36/1000000,"0.00")&"M against a budget of KES "&TEXT(C36/1000000,"0.00")&"M; year to date KES "&TEXT(G36/1000000,"0.0")&"M against KES "&TEXT(H36/1000000,"0.0")&"M." -> 3. Operating profit was KES 0.61M against a budget of KES 1.28M; year to date KES 8.5M against KES 9.9M.
A11: ="4. Largest adverse variance this month: "&A55&" (KES "&TEXT(B55,"#,##0")&", "&TEXT(C55,"0%")&" of budget)." -> 4. Largest adverse variance this month: Sales: Beverages (KES -876,300, -16% of budget).
A12: ="5. Largest favourable variance this month: "&A59&" (KES +"&TEXT(B59,"#,##0")&", +"&TEXT(C59,"0%")&" of budget)." -> 5. Largest favourable variance this month: Sales: Cooking oil & fats (KES +866,900, +9% of budget).
A13: ="6. Biggest year-to-date cost overrun: "&INDEX(A27:A34,MATCH(MIN(I27:I34),I27:I34,0))&" (KES "&TEXT(-MIN(I27:I34),"#,##0")&" over budget)." -> 6. Biggest year-to-date cost overrun: Transport & fuel (KES 705,600 over budget).
A14: ="7. "&COUNTIF(Monthly_PL!$AC$2:$AC$17,"Material")&" of 16 lines have a material variance this month (at least KES "&TEXT(Assumptions!B5,"#,##0")&" and "&TEXT(Assumptions!B6,"0%")&" of budget)." -> 7. 3 of 16 lines have a material variance this month (at least KES 50,000 and 10% of budget).
A17: 1. Profit and loss: month and year to date vs budget
A18: Line | B18: Month actual | C18: Month budget | D18: Variance (KES) | E18: Var % | F18: F / A | G18: YTD actual | H18: YTD budget | I18: Variance (KES) | J18: Var % | K18: F / A
A19: Sales: Cooking oil & fats | B19: =Monthly_PL!W2 -> 10730900 | C19: =Monthly_PL!X2 -> 9864000 | D19: =(B19-C19) -> 866900 | E19: =IFERROR(D19/C19,0) -> 0.087885239 | F19: =IF(D19>=0,"F","A") -> F | G19: =Monthly_PL!U2 -> 91170800 | H19: =Monthly_PL!V2 -> 84888000 | I19: =(G19-H19) -> 6282800 | J19: =IFERROR(I19/H19,0) -> 0.074012817 | K19: =IF(I19>=0,"F","A") -> F
A20: Sales: Flour & grains | B20: =Monthly_PL!W3 -> 7877200 | C20: =Monthly_PL!X3 -> 8220000 | D20: =(B20-C20) -> -342800 | E20: =IFERROR(D20/C20,0) -> -0.041703163 | F20: =IF(D20>=0,"F","A") -> A | G20: =Monthly_PL!U3 -> 68599400 | H20: =Monthly_PL!V3 -> 70740000 | I20: =(G20-H20) -> -2140600 | J20: =IFERROR(I20/H20,0) -> -0.030260107 | K20: =IF(I20>=0,"F","A") -> A
A21: Sales: Beverages | B21: =Monthly_PL!W4 -> 4603700 | C21: =Monthly_PL!X4 -> 5480000 | D21: =(B21-C21) -> -876300 | E21: =IFERROR(D21/C21,0) -> -0.15990876 | F21: =IF(D21>=0,"F","A") -> A | G21: =Monthly_PL!U4 -> 44356100 | H21: =Monthly_PL!V4 -> 47160000 | I21: =(G21-H21) -> -2803900 | J21: =IFERROR(I21/H21,0) -> -0.059455047 | K21: =IF(I21>=0,"F","A") -> A
A22: Sales: Household goods | B22: =Monthly_PL!W5 -> 4081700 | C22: =Monthly_PL!X5 -> 3836000 | D22: =(B22-C22) -> 245700 | E22: =IFERROR(D22/C22,0) -> 0.064051095 | F22: =IF(D22>=0,"F","A") -> F | G22: =Monthly_PL!U5 -> 34840600 | H22: =Monthly_PL!V5 -> 33012000 | I22: =(G22-H22) -> 1828600 | J22: =IFERROR(I22/H22,0) -> 0.055391979 | K22: =IF(I22>=0,"F","A") -> F
A23: Total revenue | B23: =SUM(B19:B22) -> 27293500 | C23: =SUM(C19:C22) -> 27400000 | D23: =(B23-C23) -> -106500 | E23: =IFERROR(D23/C23,0) -> -0.0038868613 | F23: =IF(D23>=0,"F","A") -> A | G23: =SUM(G19:G22) -> 238966900 | H23: =SUM(H19:H22) -> 235800000 | I23: =(G23-H23) -> 3166900 | J23: =IFERROR(I23/H23,0) -> 0.01343045 | K23: =IF(I23>=0,"F","A") -> F
A24: Total cost of sales | B24: =Monthly_PL!W20 -> 22791000 | C24: =Monthly_PL!X20 -> 22468000 | D24: =-(B24-C24) -> -323000 | E24: =IFERROR(D24/C24,0) -> -0.014376001 | F24: =IF(D24>=0,"F","A") -> A | G24: =Monthly_PL!U20 -> 197358400 | H24: =Monthly_PL!V20 -> 193355000 | I24: =-(G24-H24) -> -4003400 | J24: =IFERROR(I24/H24,0) -> -0.020704921 | K24: =IF(I24>=0,"F","A") -> A
A25: Gross profit | B25: =B23-B24 -> 4502500 | C25: =C23-C24 -> 4932000 | D25: =(B25-C25) -> -429500 | E25: =IFERROR(D25/C25,0) -> -0.087084347 | F25: =IF(D25>=0,"F","A") -> A | G25: =G23-G24 -> 41608500 | H25: =H23-H24 -> 42445000 | I25: =(G25-H25) -> -836500 | J25: =IFERROR(I25/H25,0) -> -0.019707857 | K25: =IF(I25>=0,"F","A") -> A
A26: Gross margin % | B26: =IFERROR(B25/B23,0) -> 0.16496602 | C26: =IFERROR(C25/C23,0) -> 0.18 | D26: =(B26-C26)*100 -> -1.5033982 | F26: =IF(D26>=0,"F","A") -> A | G26: =IFERROR(G25/G23,0) -> 0.17411826 | H26: =IFERROR(H25/H23,0) -> 0.18000424 | I26: =(G26-H26)*100 -> -0.58859843 | K26: =IF(I26>=0,"F","A") -> A
A27: Salaries & wages | B27: =Monthly_PL!W10 -> 1719000 | C27: =Monthly_PL!X10 -> 1638000 | D27: =-(B27-C27) -> -81000 | E27: =IFERROR(D27/C27,0) -> -0.049450549 | F27: =IF(D27>=0,"F","A") -> A | G27: =Monthly_PL!U10 -> 14882400 | H27: =Monthly_PL!V10 -> 14573000 | I27: =-(G27-H27) -> -309400 | J27: =IFERROR(I27/H27,0) -> -0.021231044 | K27: =IF(I27>=0,"F","A") -> A
A28: Rent | B28: =Monthly_PL!W11 -> 569200 | C28: =Monthly_PL!X11 -> 563000 | D28: =-(B28-C28) -> -6200 | E28: =IFERROR(D28/C28,0) -> -0.011012433 | F28: =IF(D28>=0,"F","A") -> A | G28: =Monthly_PL!U11 -> 5028500 | H28: =Monthly_PL!V11 -> 5010000 | I28: =-(G28-H28) -> -18500 | J28: =IFERROR(I28/H28,0) -> -0.0036926148 | K28: =IF(I28>=0,"F","A") -> A
A29: Utilities | B29: =Monthly_PL!W12 -> 159300 | C29: =Monthly_PL!X12 -> 154000 | D29: =-(B29-C29) -> -5300 | E29: =IFERROR(D29/C29,0) -> -0.034415584 | F29: =IF(D29>=0,"F","A") -> A | G29: =Monthly_PL!U12 -> 1400900 | H29: =Monthly_PL!V12 -> 1366000 | I29: =-(G29-H29) -> -34900 | J29: =IFERROR(I29/H29,0) -> -0.025549048 | K29: =IF(I29>=0,"F","A") -> A
A30: Transport & fuel | B30: =Monthly_PL!W13 -> 911700 | C30: =Monthly_PL!X13 -> 717000 | D30: =-(B30-C30) -> -194700 | E30: =IFERROR(D30/C30,0) -> -0.27154812 | F30: =IF(D30>=0,"F","A") -> A | G30: =Monthly_PL!U13 -> 7080600 | H30: =Monthly_PL!V13 -> 6375000 | I30: =-(G30-H30) -> -705600 | J30: =IFERROR(I30/H30,0) -> -0.11068235 | K30: =IF(I30>=0,"F","A") -> A
A31: Marketing | B31: =Monthly_PL!W14 -> 222100 | C31: =Monthly_PL!X14 -> 307000 | D31: =-(B31-C31) -> 84900 | E31: =IFERROR(D31/C31,0) -> 0.27654723 | F31: =IF(D31>=0,"F","A") -> F | G31: =Monthly_PL!U14 -> 2138900 | H31: =Monthly_PL!V14 -> 2732000 | I31: =-(G31-H31) -> 593100 | J31: =IFERROR(I31/H31,0) -> 0.2170937 | K31: =IF(I31>=0,"F","A") -> F
A32: Insurance & licences | B32: =Monthly_PL!W15 -> 91500 | C32: =Monthly_PL!X15 -> 92000 | D32: =-(B32-C32) -> 500 | E32: =IFERROR(D32/C32,0) -> 0.0054347826 | F32: =IF(D32>=0,"F","A") -> F | G32: =Monthly_PL!U15 -> 825500 | H32: =Monthly_PL!V15 -> 820000 | I32: =-(G32-H32) -> -5500 | J32: =IFERROR(I32/H32,0) -> -0.0067073171 | K32: =IF(I32>=0,"F","A") -> A
A33: Bank charges | B33: =Monthly_PL!W16 -> 71600 | C33: =Monthly_PL!X16 -> 61000 | D33: =-(B33-C33) -> -10600 | E33: =IFERROR(D33/C33,0) -> -0.17377049 | F33: =IF(D33>=0,"F","A") -> A | G33: =Monthly_PL!U16 -> 605600 | H33: =Monthly_PL!V16 -> 546000 | I33: =-(G33-H33) -> -59600 | J33: =IFERROR(I33/H33,0) -> -0.10915751 | K33: =IF(I33>=0,"F","A") -> A
A34: Repairs & maintenance | B34: =Monthly_PL!W17 -> 145400 | C34: =Monthly_PL!X17 -> 123000 | D34: =-(B34-C34) -> -22400 | E34: =IFERROR(D34/C34,0) -> -0.18211382 | F34: =IF(D34>=0,"F","A") -> A | G34: =Monthly_PL!U17 -> 1148200 | H34: =Monthly_PL!V17 -> 1093000 | I34: =-(G34-H34) -> -55200 | J34: =IFERROR(I34/H34,0) -> -0.050503202 | K34: =IF(I34>=0,"F","A") -> A
A35: Total operating expenses | B35: =SUM(B27:B34) -> 3889800 | C35: =SUM(C27:C34) -> 3655000 | D35: =-(B35-C35) -> -234800 | E35: =IFERROR(D35/C35,0) -> -0.064240766 | F35: =IF(D35>=0,"F","A") -> A | G35: =SUM(G27:G34) -> 33110600 | H35: =SUM(H27:H34) -> 32515000 | I35: =-(G35-H35) -> -595600 | J35: =IFERROR(I35/H35,0) -> -0.0183177 | K35: =IF(I35>=0,"F","A") -> A
A36: Operating profit | B36: =B25-B35 -> 612700 | C36: =C25-C35 -> 1277000 | D36: =(B36-C36) -> -664300 | E36: =IFERROR(D36/C36,0) -> -0.5202036 | F36: =IF(D36>=0,"F","A") -> A | G36: =G25-G35 -> 8497900 | H36: =H25-H35 -> 9930000 | I36: =(G36-H36) -> -1432100 | J36: =IFERROR(I36/H36,0) -> -0.14421954 | K36: =IF(I36>=0,"F","A") -> A
A37: Operating margin % | B37: =IFERROR(B36/B23,0) -> 0.022448568 | C37: =IFERROR(C36/C23,0) -> 0.046605839 | D37: =(B37-C37)*100 -> -2.4157271 | F37: =IF(D37>=0,"F","A") -> A | G37: =IFERROR(G36/G23,0) -> 0.035560992 | H37: =IFERROR(H36/H23,0) -> 0.042111959 | I37: =(G37-H37)*100 -> -0.65509674 | K37: =IF(I37>=0,"F","A") -> A
A38: F = favourable, A = adverse. Variance is actual minus budget for revenue and profit lines, and budget minus actual for cost lines, so a positive number is always good news.
A40: 2. Monthly trend
A41: Month | B41: Revenue actual | C41: Revenue budget | D41: Gross margin actual | E41: Gross margin budget | F41: Operating profit actual | G41: Operating profit budget
A42: =DATE(2026,1,1) -> 46023 | B42: =INDEX(Monthly_PL!$C$19:$K$19,1) -> 25538600 | C42: =INDEX(Monthly_PL!$L$19:$T$19,1) -> 25000000 | D42: =INDEX(Monthly_PL!$C$24:$K$24,1) -> 0.17864722 | E42: =INDEX(Monthly_PL!$L$24:$T$24,1) -> 0.18 | F42: =INDEX(Monthly_PL!$C$23:$K$23,1) -> 1010300 | G42: =INDEX(Monthly_PL!$L$23:$T$23,1) -> 930000
A43: =DATE(2026,2,1) -> 46054 | B43: =INDEX(Monthly_PL!$C$19:$K$19,2) -> 25829500 | C43: =INDEX(Monthly_PL!$L$19:$T$19,2) -> 25300000 | D43: =INDEX(Monthly_PL!$C$24:$K$24,2) -> 0.1813895 | E43: =INDEX(Monthly_PL!$L$24:$T$24,2) -> 0.18 | F43: =INDEX(Monthly_PL!$C$23:$K$23,2) -> 1117600 | G43: =INDEX(Monthly_PL!$L$23:$T$23,2) -> 974000
A44: =DATE(2026,3,1) -> 46082 | B44: =INDEX(Monthly_PL!$C$19:$K$19,3) -> 26000500 | C44: =INDEX(Monthly_PL!$L$19:$T$19,3) -> 25600000 | D44: =INDEX(Monthly_PL!$C$24:$K$24,3) -> 0.18105421 | E44: =INDEX(Monthly_PL!$L$24:$T$24,3) -> 0.18 | F44: =INDEX(Monthly_PL!$C$23:$K$23,3) -> 1204000 | G44: =INDEX(Monthly_PL!$L$23:$T$23,3) -> 1016000
A45: =DATE(2026,4,1) -> 46113 | B45: =INDEX(Monthly_PL!$C$19:$K$19,4) -> 26671500 | C45: =INDEX(Monthly_PL!$L$19:$T$19,4) -> 25900000 | D45: =INDEX(Monthly_PL!$C$24:$K$24,4) -> 0.17743284 | E45: =INDEX(Monthly_PL!$L$24:$T$24,4) -> 0.18003861 | F45: =INDEX(Monthly_PL!$C$23:$K$23,4) -> 1138000 | G45: =INDEX(Monthly_PL!$L$23:$T$23,4) -> 1061000
...

Sheet Assumptions
A1: Assumptions & Parameters
A2: Blue cells are editable inputs. Everything else recalculates from them.
A3: Assumption | B3: Value | C3: Comment
A4: Reporting month | B4: 46266 | C4: First day of the month to report on (Jan to Sep 2026 available). Change it to roll the whole pack.
A5: Materiality: amount (KES) | B5: 50000 | C5: A variance is flagged material only if it is at least this large in KES...
A6: Materiality: percentage | B6: 0.1 | C6: ...and at least this large as a share of budget.
A7: Months included year to date | B7: =MONTH(B4) -> 9 | C7: Calculated from the reporting month (calendar fiscal year).

Sheet Monthly_PL
A1: Account | B1: Type | C1: 46023 | D1: 46054 | E1: 46082 | F1: 46113 | G1: 46143 | H1: 46174 | I1: 46204 | J1: 46235 | K1: 46266 | L1: 46023 | M1: 46054 | N1: 46082 | O1: 46113 | P1: 46143 | Q1: 46174 | R1: 46204 | S1: 46235 | T1: 46266 | U1: YTD actual | V1: YTD budget | W1: Month actual | X1: Month budget | Y1: Month fav. variance | Z1: Month var % of budget | AA1: YTD fav. variance | AB1: YTD var % of budget | AC1: Material?
A2: Sales: Cooking oil & fats | B2: Revenue | C2: =SUMIFS(Ledger!$E$2:$E$1285,Ledger!$B$2:$B$1285,$A2,Ledger!$A$2:$A$1285,">="&C$1,Ledger!$A$2:$A$1285,"<"&EDATE(C$1,1)) -> 9408000 | D2: =SUMIFS(Ledger!$E$2:$E$1285,Ledger!$B$2:$B$1285,$A2,Ledger!$A$2:$A$1285,">="&D$1,Ledger!$A$2:$A$1285,"<"&EDATE(D$1,1)) -> 9666200 | E2: =SUMIFS(Ledger!$E$2:$E$1285,Ledger!$B$2:$B$1285,$A2,Ledger!$A$2:$A$1285,">="&E$1,Ledger!$A$2:$A$1285,"<"&EDATE(E$1,1)) -> 9684500 | F2: =SUMIFS(Ledger!$E$2:$E$1285,Ledger!$B$2:$B$1285,$A2,Ledger!$A$2:$A$1285,">="&F$1,Ledger!$A$2:$A$1285,"<"&EDATE(F$1,1)) -> 10155800 | G2: =SUMIFS(Ledger!$E$2:$E$1285,Ledger!$B$2:$B$1285,$A2,Ledger!$A$2:$A$1285,">="&G$1,Ledger!$A$2:$A$1285,"<"&EDATE(G$1,1)) -> 9976400 | H2: =SUMIFS(Ledger!$E$2:$E$1285,Ledger!$B$2:$B$1285,$A2,Ledger!$A$2:$A$1285,">="&H$1,Ledger!$A$2:$A$1285,"<"&EDATE(H$1,1)) -> 10438300 | I2: =SUMIFS(Ledger!$E$2:$E$1285,Ledger!$B$2:$B$1285,$A2,Ledger!$A$2:$A$1285,">="&I$1,Ledger!$A$2:$A$1285,"<"&EDATE(I$1,1)) -> 10669100 | J2: =SUMIFS(Ledger!$E$2:$E$1285,Ledger!$B$2:$B$1285,$A2,Ledger!$A$2:$A$1285,">="&J$1,Ledger!$A$2:$A$1285,"<"&EDATE(J$1,1)) -> 10441600 | K2: =SUMIFS(Ledger!$E$2:$E$1285,Ledger!$B$2:$B$1285,$A2,Ledger!$A$2:$A$1285,">="&K$1,Ledger!$A$2:$A$1285,"<"&EDATE(K$1,1)) -> 10730900 | L2: =SUMIFS(Budget!$C$2:$C$145,Budget!$B$2:$B$145,$A2,Budget!$A$2:$A$145,L$1) -> 9000000 | M2: =SUMIFS(Budget!$C$2:$C$145,Budget!$B$2:$B$145,$A2,Budget!$A$2:$A$145,M$1) -> 9108000 | N2: =SUMIFS(Budget!$C$2:$C$145,Budget!$B$2:$B$145,$A2,Budget!$A$2:$A$145,N$1) -> 9216000 | O2: =SUMIFS(Budget!$C$2:$C$145,Budget!$B$2:$B$145,$A2,Budget!$A$2:$A$145,O$1) -> 9324000 | P2: =SUMIFS(Budget!$C$2:$C$145,Budget!$B$2:$B$145,$A2,Budget!$A$2:$A$145,P$1) -> 9432000 | Q2: =SUMIFS(Budget!$C$2:$C$145,Budget!$B$2:$B$145,$A2,Budget!$A$2:$A$145,Q$1) -> 9540000 | R2: =SUMIFS(Budget!$C$2:$C$145,Budget!$B$2:$B$145,$A2,Budget!$A$2:$A$145,R$1) -> 9648000 | S2: =SUMIFS(Budget!$C$2:$C$145,Budget!$B$2:$B$145,$A2,Budget!$A$2:$A$145,S$1) -> 9756000 | T2: =SUMIFS(Budget!$C$2:$C$145,Budget!$B$2:$B$145,$A2,Budget!$A$2:$A$145,T$1) -> 9864000 | U2: =SUMIFS(C2:K2,$C$1:$K$1,"<="&Assumptions!$B$4) -> 91170800 | V2: =SUMIFS(L2:T2,$L$1:$T$1,"<="&Assumptions!$B$4) -> 84888000 | W2: =SUMIFS(C2:K2,$C$1:$K$1,Assumptions!$B$4) -> 10730900 | X2: =SUMIFS(L2:T2,$L$1:$T$1,Assumptions!$B$4) -> 9864000 | Y2: =IF($B2="Revenue",W2-X2,X2-W2) -> 866900 | Z2: =IFERROR(Y2/X2,0) -> 0.087885239 | AA2: =IF($B2="Revenue",U2-V2,V2-U2) -> 6282800 | AB2: =IFERROR(AA2/V2,0) -> 0.074012817 | AC2: =IF(AND(ABS(Y2)>=Assumptions!$B$5,ABS(Z2)>=Assumptions!$B$6),"Material","")
A3: Sales: Flour & grains | B3: Revenue | C3: =SUMIFS(Ledger!$E$2:$E$1285,Ledger!$B$2:$B$1285,$A3,Ledger!$A$2:$A$1285,">="&C$1,Ledger!$A$2:$A$1285,"<"&EDATE(C$1,1)) -> 7500700 | D3: =SUMIFS(Ledger!$E$2:$E$1285,Ledger!$B$2:$B$1285,$A3,Ledger!$A$2:$A$1285,">="&D$1,Ledger!$A$2:$A$1285,"<"&EDATE(D$1,1)) -> 7395300 | E3: =SUMIFS(Ledger!$E$2:$E$1285,Ledger!$B$2:$B$1285,$A3,Ledger!$A$2:$A$1285,">="&E$1,Ledger!$A$2:$A$1285,"<"&EDATE(E$1,1)) -> 7367200 | F3: =SUMIFS(Ledger!$E$2:$E$1285,Ledger!$B$2:$B$1285,$A3,Ledger!$A$2:$A$1285,">="&F$1,Ledger!$A$2:$A$1285,"<"&EDATE(F$1,1)) -> 7554300 | G3: =SUMIFS(Ledger!$E$2:$E$1285,Ledger!$B$2:$B$1285,$A3,Ledger!$A$2:$A$1285,">="&G$1,Ledger!$A$2:$A$1285,"<"&EDATE(G$1,1)) -> 7668500 | H3: =SUMIFS(Ledger!$E$2:$E$1285,Ledger!$B$2:$B$1285,$A3,Ledger!$A$2:$A$1285,">="&H$1,Ledger!$A$2:$A$1285,"<"&EDATE(H$1,1)) -> 7692400 | I3: =SUMIFS(Ledger!$E$2:$E$1285,Ledger!$B$2:$B$1285,$A3,Ledger!$A$2:$A$1285,">="&I$1,Ledger!$A$2:$A$1285,"<"&EDATE(I$1,1)) -> 7827000 | J3: =SUMIFS(Ledger!$E$2:$E$1285,Ledger!$B$2:$B$1285,$A3,Ledger!$A$2:$A$1285,">="&J$1,Ledger!$A$2:$A$1285,"<"&EDATE(J$1,1)) -> 7716800 | K3: =SUMIFS(Ledger!$E$2:$E$1285,Ledger!$B$2:$B$1285,$A3,Ledger!$A$2:$A$1285,">="&K$1,Ledger!$A$2:$A$1285,"<"&EDATE(K$1,1)) -> 7877200 | L3: =SUMIFS(Budget!$C$2:$C$145,Budget!$B$2:$B$145,$A3,Budget!$A$2:$A$145,L$1) -> 7500000 | M3: =SUMIFS(Budget!$C$2:$C$145,Budget!$B$2:$B$145,$A3,Budget!$A$2:$A$145,M$1) -> 7590000 | N3: =SUMIFS(Budget!$C$2:$C$145,Budget!$B$2:$B$145,$A3,Budget!$A$2:$A$145,N$1) -> 7680000 | O3: =SUMIFS(Budget!$C$2:$C$145,Budget!$B$2:$B$145,$A3,Budget!$A$2:$A$145,O$1) -> 7770000 | P3: =SUMIFS(Budget!$C$2:$C$145,Budget!$B$2:$B$145,$A3,Budget!$A$2:$A$145,P$1) -> 7860000 | Q3: =SUMIFS(Budget!$C$2:$C$145,Budget!$B$2:$B$145,$A3,Budget!$A$2:$A$145,Q$1) -> 7950000 | R3: =SUMIFS(Budget!$C$2:$C$145,Budget!$B$2:$B$145,$A3,Budget!$A$2:$A$145,R$1) -> 8040000 | S3: =SUMIFS(Budget!$C$2:$C$145,Budget!$B$2:$B$145,$A3,Budget!$A$2:$A$145,S$1) -> 8130000 | T3: =SUMIFS(Budget!$C$2:$C$145,Budget!$B$2:$B$145,$A3,Budget!$A$2:$A$145,T$1) -> 8220000 | U3: =SUMIFS(C3:K3,$C$1:$K$1,"<="&Assumptions!$B$4) -> 68599400 | V3: =SUMIFS(L3:T3,$L$1:$T$1,"<="&Assumptions!$B$4) -> 70740000 | W3: =SUMIFS(C3:K3,$C$1:$K$1,Assumptions!$B$4) -> 7877200 | X3: =SUMIFS(L3:T3,$L$1:$T$1,Assumptions!$B$4) -> 8220000 | Y3: =IF($B3="Revenue",W3-X3,X3-W3) -> -342800 | Z3: =IFERROR(Y3/X3,0) -> -0.041703163 | AA3: =IF($B3="Revenue",U3-V3,V3-U3) -> -2140600 | AB3: =IFERROR(AA3/V3,0) -> -0.030260107 | AC3: =IF(AND(ABS(Y3)>=Assumptions!$B$5,ABS(Z3)>=Assumptions!$B$6),"Material","")
A4: Sales: Beverages | B4: Revenue | C4: =SUMIFS(Ledger!$E$2:$E$1285,Ledger!$B$2:$B$1285,$A4,Ledger!$A$2:$A$1285,">="&C$1,Ledger!$A$2:$A$1285,"<"&EDATE(C$1,1)) -> 4977300 | D4: =SUMIFS(Ledger!$E$2:$E$1285,Ledger!$B$2:$B$1285,$A4,Ledger!$A$2:$A$1285,">="&D$1,Ledger!$A$2:$A$1285,"<"&EDATE(D$1,1)) -> 5091100 | E4: =SUMIFS(Ledger!$E$2:$E$1285,Ledger!$B$2:$B$1285,$A4,Ledger!$A$2:$A$1285,">="&E$1,Ledger!$A$2:$A$1285,"<"&EDATE(E$1,1)) -> 5232600 | F4: =SUMIFS(Ledger!$E$2:$E$1285,Ledger!$B$2:$B$1285,$A4,Ledger!$A$2:$A$1285,">="&F$1,Ledger!$A$2:$A$1285,"<"&EDATE(F$1,1)) -> 5114100 | G4: =SUMIFS(Ledger!$E$2:$E$1285,Ledger!$B$2:$B$1285,$A4,Ledger!$A$2:$A$1285,">="&G$1,Ledger!$A$2:$A$1285,"<"&EDATE(G$1,1)) -> 5065400 | H4: =SUMIFS(Ledger!$E$2:$E$1285,Ledger!$B$2:$B$1285,$A4,Ledger!$A$2:$A$1285,">="&H$1,Ledger!$A$2:$A$1285,"<"&EDATE(H$1,1)) -> 4953300 | I4: =SUMIFS(Ledger!$E$2:$E$1285,Ledger!$B$2:$B$1285,$A4,Ledger!$A$2:$A$1285,">="&I$1,Ledger!$A$2:$A$1285,"<"&EDATE(I$1,1)) -> 4745600 | J4: =SUMIFS(Ledger!$E$2:$E$1285,Ledger!$B$2:$B$1285,$A4,Ledger!$A$2:$A$1285,">="&J$1,Ledger!$A$2:$A$1285,"<"&EDATE(J$1,1)) -> 4573000 | K4: =SUMIFS(Ledger!$E$2:$E$1285,Ledger!$B$2:$B$1285,$A4,Ledger!$A$2:$A$1285,">="&K$1,Ledger!$A$2:$A$1285,"<"&EDATE(K$1,1)) -> 4603700 | L4: =SUMIFS(Budget!$C$2:$C$145,Budget!$B$2:$B$145,$A4,Budget!$A$2:$A$145,L$1) -> 5000000 | M4: =SUMIFS(Budget!$C$2:$C$145,Budget!$B$2:$B$145,$A4,Budget!$A$2:$A$145,M$1) -> 5060000 | N4: =SUMIFS(Budget!$C$2:$C$145,Budget!$B$2:$B$145,$A4,Budget!$A$2:$A$145,N$1) -> 5120000 | O4: =SUMIFS(Budget!$C$2:$C$145,Budget!$B$2:$B$145,$A4,Budget!$A$2:$A$145,O$1) -> 5180000 | P4: =SUMIFS(Budget!$C$2:$C$145,Budget!$B$2:$B$145,$A4,Budget!$A$2:$A$145,P$1) -> 5240000 | Q4: =SUMIFS(Budget!$C$2:$C$145,Budget!$B$2:$B$145,$A4,Budget!$A$2:$A$145,Q$1) -> 5300000 | R4: =SUMIFS(Budget!$C$2:$C$145,Budget!$B$2:$B$145,$A4,Budget!$A$2:$A$145,R$1) -> 5360000 | S4: =SUMIFS(Budget!$C$2:$C$145,Budget!$B$2:$B$145,$A4,Budget!$A$2:$A$145,S$1) -> 5420000 | T4: =SUMIFS(Budget!$C$2:$C$145,Budget!$B$2:$B$145,$A4,Budget!$A$2:$A$145,T$1) -> 5480000 | U4: =SUMIFS(C4:K4,$C$1:$K$1,"<="&Assumptions!$B$4) -> 44356100 | V4: =SUMIFS(L4:T4,$L$1:$T$1,"<="&Assumptions!$B$4) -> 47160000 | W4: =SUMIFS(C4:K4,$C$1:$K$1,Assumptions!$B$4) -> 4603700 | X4: =SUMIFS(L4:T4,$L$1:$T$1,Assumptions!$B$4) -> 5480000 | Y4: =IF($B4="Revenue",W4-X4,X4-W4) -> -876300 | Z4: =IFERROR(Y4/X4,0) -> -0.15990876 | AA4: =IF($B4="Revenue",U4-V4,V4-U4) -> -2803900 | AB4: =IFERROR(AA4/V4,0) -> -0.059455047 | AC4: =IF(AND(ABS(Y4)>=Assumptions!$B$5,ABS(Z4)>=Assumptions!$B$6),"Material","") -> Material
A5: Sales: Household goods | B5: Revenue | C5: =SUMIFS(Ledger!$E$2:$E$1285,Ledger!$B$2:$B$1285,$A5,Ledger!$A$2:$A$1285,">="&C$1,Ledger!$A$2:$A$1285,"<"&EDATE(C$1,1)) -> 3652600 | D5: =SUMIFS(Ledger!$E$2:$E$1285,Ledger!$B$2:$B$1285,$A5,Ledger!$A$2:$A$1285,">="&D$1,Ledger!$A$2:$A$1285,"<"&EDATE(D$1,1)) -> 3676900 | E5: =SUMIFS(Ledger!$E$2:$E$1285,Ledger!$B$2:$B$1285,$A5,Ledger!$A$2:$A$1285,">="&E$1,Ledger!$A$2:$A$1285,"<"&EDATE(E$1,1)) -> 3716200 | F5: =SUMIFS(Ledger!$E$2:$E$1285,Ledger!$B$2:$B$1285,$A5,Ledger!$A$2:$A$1285,">="&F$1,Ledger!$A$2:$A$1285,"<"&EDATE(F$1,1)) -> 3847300 | G5: =SUMIFS(Ledger!$E$2:$E$1285,Ledger!$B$2:$B$1285,$A5,Ledger!$A$2:$A$1285,">="&G$1,Ledger!$A$2:$A$1285,"<"&EDATE(G$1,1)) -> 3867500 | H5: =SUMIFS(Ledger!$E$2:$E$1285,Ledger!$B$2:$B$1285,$A5,Ledger!$A$2:$A$1285,">="&H$1,Ledger!$A$2:$A$1285,"<"&EDATE(H$1,1)) -> 3910200 | I5: =SUMIFS(Ledger!$E$2:$E$1285,Ledger!$B$2:$B$1285,$A5,Ledger!$A$2:$A$1285,">="&I$1,Ledger!$A$2:$A$1285,"<"&EDATE(I$1,1)) -> 4012000 | J5: =SUMIFS(Ledger!$E$2:$E$1285,Ledger!$B$2:$B$1285,$A5,Ledger!$A$2:$A$1285,">="&J$1,Ledger!$A$2:$A$1285,"<"&EDATE(J$1,1)) -> 4076200 | K5: =SUMIFS(Ledger!$E$2:$E$1285,Ledger!$B$2:$B$1285,$A5,Ledger!$A$2:$A$1285,">="&K$1,Ledger!$A$2:$A$1285,"<"&EDATE(K$1,1)) -> 4081700 | L5: =SUMIFS(Budget!$C$2:$C$145,Budget!$B$2:$B$145,$A5,Budget!$A$2:$A$145,L$1) -> 3500000 | M5: =SUMIFS(Budget!$C$2:$C$145,Budget!$B$2:$B$145,$A5,Budget!$A$2:$A$145,M$1) -> 3542000 | N5: =SUMIFS(Budget!$C$2:$C$145,Budget!$B$2:$B$145,$A5,Budget!$A$2:$A$145,N$1) -> 3584000 | O5: =SUMIFS(Budget!$C$2:$C$145,Budget!$B$2:$B$145,$A5,Budget!$A$2:$A$145,O$1) -> 3626000 | P5: =SUMIFS(Budget!$C$2:$C$145,Budget!$B$2:$B$145,$A5,Budget!$A$2:$A$145,P$1) -> 3668000 | Q5: =SUMIFS(Budget!$C$2:$C$145,Budget!$B$2:$B$145,$A5,Budget!$A$2:$A$145,Q$1) -> 3710000 | R5: =SUMIFS(Budget!$C$2:$C$145,Budget!$B$2:$B$145,$A5,Budget!$A$2:$A$145,R$1) -> 3752000 | S5: =SUMIFS(Budget!$C$2:$C$145,Budget!$B$2:$B$145,$A5,Budget!$A$2:$A$145,S$1) -> 3794000 | T5: =SUMIFS(Budget!$C$2:$C$145,Budget!$B$2:$B$145,$A5,Budget!$A$2:$A$145,T$1) -> 3836000 | U5: =SUMIFS(C5:K5,$C$1:$K$1,"<="&Assumptions!$B$4) -> 34840600 | V5: =SUMIFS(L5:T5,$L$1:$T$1,"<="&Assumptions!$B$4) -> 33012000 | W5: =SUMIFS(C5:K5,$C$1:$K$1,Assumptions!$B$4) -> 4081700 | X5: =SUMIFS(L5:T5,$L$1:$T$1,Assumptions!$B$4) -> 3836000 | Y5: =IF($B5="Revenue",W5-X5,X5-W5) -> 245700 | Z5: =IFERROR(Y5/X5,0) -> 0.064051095 | AA5: =IF($B5="Revenue",U5-V5,V5-U5) -> 1828600 | AB5: =IFERROR(AA5/V5,0) -> 0.055391979 | AC5: =IF(AND(ABS(Y5)>=Assumptions!$B$5,ABS(Z5)>=Assumptions!$B$6),"Material","")
A6: Cost of sales: Cooking oil & fats | B6: Cost of sales | C6: =SUMIFS(Ledger!$E$2:$E$1285,Ledger!$B$2:$B$1285,$A6,Ledger!$A$2:$A$1285,">="&C$1,Ledger!$A$2:$A$1285,"<"&EDATE(C$1,1)) -> 7931300 | D6: =SUMIFS(Ledger!$E$2:$E$1285,Ledger!$B$2:$B$1285,$A6,Ledger!$A$2:$A$1285,">="&D$1,Ledger!$A$2:$A$1285,"<"&EDATE(D$1,1)) -> 8110100 | E6: =SUMIFS(Ledger!$E$2:$E$1285,Ledger!$B$2:$B$1285,$A6,Ledger!$A$2:$A$1285,">="&E$1,Ledger!$A$2:$A$1285,"<"&EDATE(E$1,1)) -> 8116600 | F6: =SUMIFS(Ledger!$E$2:$E$1285,Ledger!$B$2:$B$1285,$A6,Ledger!$A$2:$A$1285,">="&F$1,Ledger!$A$2:$A$1285,"<"&EDATE(F$1,1)) -> 8597500 | G6: =SUMIFS(Ledger!$E$2:$E$1285,Ledger!$B$2:$B$1285,$A6,Ledger!$A$2:$A$1285,">="&G$1,Ledger!$A$2:$A$1285,"<"&EDATE(G$1,1)) -> 8497600 | H6: =SUMIFS(Ledger!$E$2:$E$1285,Ledger!$B$2:$B$1285,$A6,Ledger!$A$2:$A$1285,">="&H$1,Ledger!$A$2:$A$1285,"<"&EDATE(H$1,1)) -> 8947000 | I6: =SUMIFS(Ledger!$E$2:$E$1285,Ledger!$B$2:$B$1285,$A6,Ledger!$A$2:$A$1285,">="&I$1,Ledger!$A$2:$A$1285,"<"&EDATE(I$1,1)) -> 9241400 | J6: =SUMIFS(Ledger!$E$2:$E$1285,Ledger!$B$2:$B$1285,$A6,Ledger!$A$2:$A$1285,">="&J$1,Ledger!$A$2:$A$1285,"<"&EDATE(J$1,1)) -> 9108300 | K6: =SUMIFS(Ledger!$E$2:$E$1285,Ledger!$B$2:$B$1285,$A6,Ledger!$A$2:$A$1285,">="&K$1,Ledger!$A$2:$A$1285,"<"&EDATE(K$1,1)) -> 9421800 | L6: =SUMIFS(Budget!$C$2:$C$145,Budget!$B$2:$B$145,$A6,Budget!$A$2:$A$145,L$1) -> 7560000 | M6: =SUMIFS(Budget!$C$2:$C$145,Budget!$B$2:$B$145,$A6,Budget!$A$2:$A$145,M$1) -> 7651000 | N6: =SUMIFS(Budget!$C$2:$C$145,Budget!$B$2:$B$145,$A6,Budget!$A$2:$A$145,N$1) -> 7741000 | O6: =SUMIFS(Budget!$C$2:$C$145,Budget!$B$2:$B$145,$A6,Budget!$A$2:$A$145,O$1) -> 7832000 | P6: =SUMIFS(Budget!$C$2:$C$145,Budget!$B$2:$B$145,$A6,Budget!$A$2:$A$145,P$1) -> 7923000 | Q6: =SUMIFS(Budget!$C$2:$C$145,Budget!$B$2:$B$145,$A6,Budget!$A$2:$A$145,Q$1) -> 8014000 | R6: =SUMIFS(Budget!$C$2:$C$145,Budget!$B$2:$B$145,$A6,Budget!$A$2:$A$145,R$1) -> 8104000 | S6: =SUMIFS(Budget!$C$2:$C$145,Budget!$B$2:$B$145,$A6,Budget!$A$2:$A$145,S$1) -> 8195000 | T6: =SUMIFS(Budget!$C$2:$C$145,Budget!$B$2:$B$145,$A6,Budget!$A$2:$A$145,T$1) -> 8286000 | U6: =SUMIFS(C6:K6,$C$1:$K$1,"<="&Assumptions!$B$4) -> 77971600 | V6: =SUMIFS(L6:T6,$L$1:$T$1,"<="&Assumptions!$B$4) -> 71306000 | W6: =SUMIFS(C6:K6,$C$1:$K$1,Assumptions!$B$4) -> 9421800 | X6: =SUMIFS(L6:T6,$L$1:$T$1,Assumptions!$B$4) -> 8286000 | Y6: =X6/X2*W2-W6 -> -407582.91 | Z6: =IFERROR(Y6/(X6/X2*W2),0) -> -0.045215564 | AA6: =V6/V2*U2-U6 -> -1388042.1 | AB6: =IFERROR(AA6/(V6/V2*U2),0) -> -0.018124544 | AC6: =IF(AND(ABS(Y6)>=Assumptions!$B$5,ABS(Z6)>=Assumptions!$B$6),"Material","")
A7: Cost of sales: Flour & grains | B7: Cost of sales | C7: =SUMIFS(Ledger!$E$2:$E$1285,Ledger!$B$2:$B$1285,$A7,Ledger!$A$2:$A$1285,">="&C$1,Ledger!$A$2:$A$1285,"<"&EDATE(C$1,1)) -> 6450200 | D7: =SUMIFS(Ledger!$E$2:$E$1285,Ledger!$B$2:$B$1285,$A7,Ledger!$A$2:$A$1285,">="&D$1,Ledger!$A$2:$A$1285,"<"&EDATE(D$1,1)) -> 6365000 | E7: =SUMIFS(Ledger!$E$2:$E$1285,Ledger!$B$2:$B$1285,$A7,Ledger!$A$2:$A$1285,">="&E$1,Ledger!$A$2:$A$1285,"<"&EDATE(E$1,1)) -> 6345100 | F7: =SUMIFS(Ledger!$E$2:$E$1285,Ledger!$B$2:$B$1285,$A7,Ledger!$A$2:$A$1285,">="&F$1,Ledger!$A$2:$A$1285,"<"&EDATE(F$1,1)) -> 6518700 | G7: =SUMIFS(Ledger!$E$2:$E$1285,Ledger!$B$2:$B$1285,$A7,Ledger!$A$2:$A$1285,">="&G$1,Ledger!$A$2:$A$1285,"<"&EDATE(G$1,1)) -> 6608300 | H7: =SUMIFS(Ledger!$E$2:$E$1285,Ledger!$B$2:$B$1285,$A7,Ledger!$A$2:$A$1285,">="&H$1,Ledger!$A$2:$A$1285,"<"&EDATE(H$1,1)) -> 6630700 | I7: =SUMIFS(Ledger!$E$2:$E$1285,Ledger!$B$2:$B$1285,$A7,Ledger!$A$2:$A$1285,">="&I$1,Ledger!$A$2:$A$1285,"<"&EDATE(I$1,1)) -> 6744300 | J7: =SUMIFS(Ledger!$E$2:$E$1285,Ledger!$B$2:$B$1285,$A7,Ledger!$A$2:$A$1285,">="&J$1,Ledger!$A$2:$A$1285,"<"&EDATE(J$1,1)) -> 6638100 | K7: =SUMIFS(Ledger!$E$2:$E$1285,Ledger!$B$2:$B$1285,$A7,Ledger!$A$2:$A$1285,">="&K$1,Ledger!$A$2:$A$1285,"<"&EDATE(K$1,1)) -> 6765700 | L7: =SUMIFS(Budget!$C$2:$C$145,Budget!$B$2:$B$145,$A7,Budget!$A$2:$A$145,L$1) -> 6450000 | M7: =SUMIFS(Budget!$C$2:$C$145,Budget!$B$2:$B$145,$A7,Budget!$A$2:$A$145,M$1) -> 6527000 | N7: =SUMIFS(Budget!$C$2:$C$145,Budget!$B$2:$B$145,$A7,Budget!$A$2:$A$145,N$1) -> 6605000 | O7: =SUMIFS(Budget!$C$2:$C$145,Budget!$B$2:$B$145,$A7,Budget!$A$2:$A$145,O$1) -> 6682000 | P7: =SUMIFS(Budget!$C$2:$C$145,Budget!$B$2:$B$145,$A7,Budget!$A$2:$A$145,P$1) -> 6760000 | Q7: =SUMIFS(Budget!$C$2:$C$145,Budget!$B$2:$B$145,$A7,Budget!$A$2:$A$145,Q$1) -> 6837000 | R7: =SUMIFS(Budget!$C$2:$C$145,Budget!$B$2:$B$145,$A7,Budget!$A$2:$A$145,R$1) -> 6914000 | S7: =SUMIFS(Budget!$C$2:$C$145,Budget!$B$2:$B$145,$A7,Budget!$A$2:$A$145,S$1) -> 6992000 | T7: =SUMIFS(Budget!$C$2:$C$145,Budget!$B$2:$B$145,$A7,Budget!$A$2:$A$145,T$1) -> 7069000 | U7: =SUMIFS(C7:K7,$C$1:$K$1,"<="&Assumptions!$B$4) -> 59066100 | V7: =SUMIFS(L7:T7,$L$1:$T$1,"<="&Assumptions!$B$4) -> 60836000 | W7: =SUMIFS(C7:K7,$C$1:$K$1,Assumptions!$B$4) -> 6765700 | X7: =SUMIFS(L7:T7,$L$1:$T$1,Assumptions!$B$4) -> 7069000 | Y7: =X7/X3*W3-W7 -> 8500.3406 | Z7: =IFERROR(Y7/(X7/X3*W3),0) -> 0.0012548109 | AA7: =V7/V3*U3-U7 -> -71003.896 | AB7: =IFERROR(AA7/(V7/V3*U3),0) -> -0.0012035559 | AC7: =IF(AND(ABS(Y7)>=Assumptions!$B$5,ABS(Z7)>=Assumptions!$B$6),"Material","")
A8: Cost of sales: Beverages | B8: Cost of sales | C8: =SUMIFS(Ledger!$E$2:$E$1285,Ledger!$B$2:$B$1285,$A8,Ledger!$A$2:$A$1285,">="&C$1,Ledger!$A$2:$A$1285,"<"&EDATE(C$1,1)) -> 3900300 | D8: =SUMIFS(Ledger!$E$2:$E$1285,Ledger!$B$2:$B$1285,$A8,Ledger!$A$2:$A$1285,">="&D$1,Ledger!$A$2:$A$1285,"<"&EDATE(D$1,1)) -> 3960900 | E8: =SUMIFS(Ledger!$E$2:$E$1285,Ledger!$B$2:$B$1285,$A8,Ledger!$A$2:$A$1285,">="&E$1,Ledger!$A$2:$A$1285,"<"&EDATE(E$1,1)) -> 4073800 | F8: =SUMIFS(Ledger!$E$2:$E$1285,Ledger!$B$2:$B$1285,$A8,Ledger!$A$2:$A$1285,">="&F$1,Ledger!$A$2:$A$1285,"<"&EDATE(F$1,1)) -> 3986600 | G8: =SUMIFS(Ledger!$E$2:$E$1285,Ledger!$B$2:$B$1285,$A8,Ledger!$A$2:$A$1285,">="&G$1,Ledger!$A$2:$A$1285,"<"&EDATE(G$1,1)) -> 3961000 | H8: =SUMIFS(Ledger!$E$2:$E$1285,Ledger!$B$2:$B$1285,$A8,Ledger!$A$2:$A$1285,">="&H$1,Ledger!$A$2:$A$1285,"<"&EDATE(H$1,1)) -> 3849200 | I8: =SUMIFS(Ledger!$E$2:$E$1285,Ledger!$B$2:$B$1285,$A8,Ledger!$A$2:$A$1285,">="&I$1,Ledger!$A$2:$A$1285,"<"&EDATE(I$1,1)) -> 3697000 | J8: =SUMIFS(Ledger!$E$2:$E$1285,Ledger!$B$2:$B$1285,$A8,Ledger!$A$2:$A$1285,">="&J$1,Ledger!$A$2:$A$1285,"<"&EDATE(J$1,1)) -> 3575800 | K8: =SUMIFS(Ledger!$E$2:$E$1285,Ledger!$B$2:$B$1285,$A8,Ledger!$A$2:$A$1285,">="&K$1,Ledger!$A$2:$A$1285,"<"&EDATE(K$1,1)) -> 3582700 | L8: =SUMIFS(Budget!$C$2:$C$145,Budget!$B$2:$B$145,$A8,Budget!$A$2:$A$145,L$1) -> 3900000 | M8: =SUMIFS(Budget!$C$2:$C$145,Budget!$B$2:$B$145,$A8,Budget!$A$2:$A$145,M$1) -> 3947000 | N8: =SUMIFS(Budget!$C$2:$C$145,Budget!$B$2:$B$145,$A8,Budget!$A$2:$A$145,N$1) -> 3994000 | O8: =SUMIFS(Budget!$C$2:$C$145,Budget!$B$2:$B$145,$A8,Budget!$A$2:$A$145,O$1) -> 4040000 | P8: =SUMIFS(Budget!$C$2:$C$145,Budget!$B$2:$B$145,$A8,Budget!$A$2:$A$145,P$1) -> 4087000 | Q8: =SUMIFS(Budget!$C$2:$C$145,Budget!$B$2:$B$145,$A8,Budget!$A$2:$A$145,Q$1) -> 4134000 | R8: =SUMIFS(Budget!$C$2:$C$145,Budget!$B$2:$B$145,$A8,Budget!$A$2:$A$145,R$1) -> 4181000 | S8: =SUMIFS(Budget!$C$2:$C$145,Budget!$B$2:$B$145,$A8,Budget!$A$2:$A$145,S$1) -> 4228000 | T8: =SUMIFS(Budget!$C$2:$C$145,Budget!$B$2:$B$145,$A8,Budget!$A$2:$A$145,T$1) -> 4274000 | U8: =SUMIFS(C8:K8,$C$1:$K$1,"<="&Assumptions!$B$4) -> 34587300 | V8: =SUMIFS(L8:T8,$L$1:$T$1,"<="&Assumptions!$B$4) -> 36785000 | W8: =SUMIFS(C8:K8,$C$1:$K$1,Assumptions!$B$4) -> 3582700 | X8: =SUMIFS(L8:T8,$L$1:$T$1,Assumptions!$B$4) -> 4274000 | Y8: =X8/X4*W4-W8 -> 7849.9635 | Z8: =IFERROR(Y8/(X8/X4*W4),0) -> 0.0021862844 | AA8: =V8/V4*U4-U8 -> 10646.109 | AB8: =IFERROR(AA8/(V8/V4*U4),0) -> 0.00030770928 | AC8: =IF(AND(ABS(Y8)>=Assumptions!$B$5,ABS(Z8)>=Assumptions!$B$6),"Material","")
A9: Cost of sales: Household goods | B9: Cost of sales | C9: =SUMIFS(Ledger!$E$2:$E$1285,Ledger!$B$2:$B$1285,$A9,Ledger!$A$2:$A$1285,">="&C$1,Ledger!$A$2:$A$1285,"<"&EDATE(C$1,1)) -> 2694400 | D9: =SUMIFS(Ledger!$E$2:$E$1285,Ledger!$B$2:$B$1285,$A9,Ledger!$A$2:$A$1285,">="&D$1,Ledger!$A$2:$A$1285,"<"&EDATE(D$1,1)) -> 2708300 | E9: =SUMIFS(Ledger!$E$2:$E$1285,Ledger!$B$2:$B$1285,$A9,Ledger!$A$2:$A$1285,">="&E$1,Ledger!$A$2:$A$1285,"<"&EDATE(E$1,1)) -> 2757500 | F9: =SUMIFS(Ledger!$E$2:$E$1285,Ledger!$B$2:$B$1285,$A9,Ledger!$A$2:$A$1285,">="&F$1,Ledger!$A$2:$A$1285,"<"&EDATE(F$1,1)) -> 2836300 | G9: =SUMIFS(Ledger!$E$2:$E$1285,Ledger!$B$2:$B$1285,$A9,Ledger!$A$2:$A$1285,">="&G$1,Ledger!$A$2:$A$1285,"<"&EDATE(G$1,1)) -> 2852100 | H9: =SUMIFS(Ledger!$E$2:$E$1285,Ledger!$B$2:$B$1285,$A9,Ledger!$A$2:$A$1285,">="&H$1,Ledger!$A$2:$A$1285,"<"&EDATE(H$1,1)) -> 2897600 | I9: =SUMIFS(Ledger!$E$2:$E$1285,Ledger!$B$2:$B$1285,$A9,Ledger!$A$2:$A$1285,">="&I$1,Ledger!$A$2:$A$1285,"<"&EDATE(I$1,1)) -> 2965000 | J9: =SUMIFS(Ledger!$E$2:$E$1285,Ledger!$B$2:$B$1285,$A9,Ledger!$A$2:$A$1285,">="&J$1,Ledger!$A$2:$A$1285,"<"&EDATE(J$1,1)) -> 3001400 | K9: =SUMIFS(Ledger!$E$2:$E$1285,Ledger!$B$2:$B$1285,$A9,Ledger!$A$2:$A$1285,">="&K$1,Ledger!$A$2:$A$1285,"<"&EDATE(K$1,1)) -> 3020800 | L9: =SUMIFS(Budget!$C$2:$C$145,Budget!$B$2:$B$145,$A9,Budget!$A$2:$A$145,L$1) -> 2590000 | M9: =SUMIFS(Budget!$C$2:$C$145,Budget!$B$2:$B$145,$A9,Budget!$A$2:$A$145,M$1) -> 2621000 | N9: =SUMIFS(Budget!$C$2:$C$145,Budget!$B$2:$B$145,$A9,Budget!$A$2:$A$145,N$1) -> 2652000 | O9: =SUMIFS(Budget!$C$2:$C$145,Budget!$B$2:$B$145,$A9,Budget!$A$2:$A$145,O$1) -> 2683000 | P9: =SUMIFS(Budget!$C$2:$C$145,Budget!$B$2:$B$145,$A9,Budget!$A$2:$A$145,P$1) -> 2714000 | Q9: =SUMIFS(Budget!$C$2:$C$145,Budget!$B$2:$B$145,$A9,Budget!$A$2:$A$145,Q$1) -> 2745000 | R9: =SUMIFS(Budget!$C$2:$C$145,Budget!$B$2:$B$145,$A9,Budget!$A$2:$A$145,R$1) -> 2776000 | S9: =SUMIFS(Budget!$C$2:$C$145,Budget!$B$2:$B$145,$A9,Budget!$A$2:$A$145,S$1) -> 2808000 | T9: =SUMIFS(Budget!$C$2:$C$145,Budget!$B$2:$B$145,$A9,Budget!$A$2:$A$145,T$1) -> 2839000 | U9: =SUMIFS(C9:K9,$C$1:$K$1,"<="&Assumptions!$B$4) -> 25733400 | V9: =SUMIFS(L9:T9,$L$1:$T$1,"<="&Assumptions!$B$4) -> 24428000 | W9: =SUMIFS(C9:K9,$C$1:$K$1,Assumptions!$B$4) -> 3020800 | X9: =SUMIFS(L9:T9,$L$1:$T$1,Assumptions!$B$4) -> 2839000 | Y9: =X9/X5*W5-W9 -> 41.058394 | Z9: =IFERROR(Y9/(X9/X5*W5),0) -> 1.359171e-05 | AA9: =V9/V5*U5-U9 -> 47715.255 | AB9: =IFERROR(AA9/(V9/V5*U5),0) -> 0.0018507832 | AC9: =IF(AND(ABS(Y9)>=Assumptions!$B$5,ABS(Z9)>=Assumptions!$B$6),"Material","")
A10: Salaries & wages | B10: Operating expense | C10: =SUMIFS(Ledger!$E$2:$E$1285,Ledger!$B$2:$B$1285,$A10,Ledger!$A$2:$A$1285,">="&C$1,Ledger!$A$2:$A$1285,"<"&EDATE(C$1,1)) -> 1626000 | D10: =SUMIFS(Ledger!$E$2:$E$1285,Ledger!$B$2:$B$1285,$A10,Ledger!$A$2:$A$1285,">="&D$1,Ledger!$A$2:$A$1285,"<"&EDATE(D$1,1)) -> 1632600 | E10: =SUMIFS(Ledger!$E$2:$E$1285,Ledger!$B$2:$B$1285,$A10,Ledger!$A$2:$A$1285,">="&E$1,Ledger!$A$2:$A$1285,"<"&EDATE(E$1,1)) -> 1604000 | F10: =SUMIFS(Ledger!$E$2:$E$1285,Ledger!$B$2:$B$1285,$A10,Ledger!$A$2:$A$1285,">="&F$1,Ledger!$A$2:$A$1285,"<"&EDATE(F$1,1)) -> 1629800 | G10: =SUMIFS(Ledger!$E$2:$E$1285,Ledger!$B$2:$B$1285,$A10,Ledger!$A$2:$A$1285,">="&G$1,Ledger!$A$2:$A$1285,"<"&EDATE(G$1,1)) -> 1623500 | H10: =SUMIFS(Ledger!$E$2:$E$1285,Ledger!$B$2:$B$1285,$A10,Ledger!$A$2:$A$1285,">="&H$1,Ledger!$A$2:$A$1285,"<"&EDATE(H$1,1)) -> 1667200 | I10: =SUMIFS(Ledger!$E$2:$E$1285,Ledger!$B$2:$B$1285,$A10,Ledger!$A$2:$A$1285,">="&I$1,Ledger!$A$2:$A$1285,"<"&EDATE(I$1,1)) -> 1671400 | J10: =SUMIFS(Ledger!$E$2:$E$1285,Ledger!$B$2:$B$1285,$A10,Ledger!$A$2:$A$1285,">="&J$1,Ledger!$A$2:$A$1285,"<"&EDATE(J$1,1)) -> 1708900 | K10: =SUMIFS(Ledger!$E$2:$E$1285,Ledger!$B$2:$B$1285,$A10,Ledger!$A$2:$A$1285,">="&K$1,Ledger!$A$2:$A$1285,"<"&EDATE(K$1,1)) -> 1719000 | L10: =SUMIFS(Budget!$C$2:$C$145,Budget!$B$2:$B$145,$A10,Budget!$A$2:$A$145,L$1) -> 1600000 | M10: =SUMIFS(Budget!$C$2:$C$145,Budget!$B$2:$B$145,$A10,Budget!$A$2:$A$145,M$1) -> 1605000 | N10: =SUMIFS(Budget!$C$2:$C$145,Budget!$B$2:$B$145,$A10,Budget!$A$2:$A$145,N$1) -> 1610000 | O10: =SUMIFS(Budget!$C$2:$C$145,Budget!$B$2:$B$145,$A10,Budget!$A$2:$A$145,O$1) -> 1614000 | P10: =SUMIFS(Budget!$C$2:$C$145,Budget!$B$2:$B$145,$A10,Budget!$A$2:$A$145,P$1) -> 1619000 | Q10: =SUMIFS(Budget!$C$2:$C$145,Budget!$B$2:$B$145,$A10,Budget!$A$2:$A$145,Q$1) -> 1624000 | R10: =SUMIFS(Budget!$C$2:$C$145,Budget!$B$2:$B$145,$A10,Budget!$A$2:$A$145,R$1) -> 1629000 | S10: =SUMIFS(Budget!$C$2:$C$145,Budget!$B$2:$B$145,$A10,Budget!$A$2:$A$145,S$1) -> 1634000 | T10: =SUMIFS(Budget!$C$2:$C$145,Budget!$B$2:$B$145,$A10,Budget!$A$2:$A$145,T$1) -> 1638000 | U10: =SUMIFS(C10:K10,$C$1:$K$1,"<="&Assumptions!$B$4) -> 14882400 | V10: =SUMIFS(L10:T10,$L$1:$T$1,"<="&Assumptions!$B$4) -> 14573000 | W10: =SUMIFS(C10:K10,$C$1:$K$1,Assumptions!$B$4) -> 1719000 | X10: =SUMIFS(L10:T10,$L$1:$T$1,Assumptions!$B$4) -> 1638000 | Y10: =IF($B10="Revenue",W10-X10,X10-W10) -> -81000 | Z10: =IFERROR(Y10/X10,0) -> -0.049450549 | AA10: =IF($B10="Revenue",U10-V10,V10-U10) -> -309400 | AB10: =IFERROR(AA10/V10,0) -> -0.021231044 | AC10: =IF(AND(ABS(Y10)>=Assumptions!$B$5,ABS(Z10)>=Assumptions!$B$6),"Material","")
A11: Rent | B11: Operating expense | C11: =SUMIFS(Ledger!$E$2:$E$1285,Ledger!$B$2:$B$1285,$A11,Ledger!$A$2:$A$1285,">="&C$1,Ledger!$A$2:$A$1285,"<"&EDATE(C$1,1)) -> 558600 | D11: =SUMIFS(Ledger!$E$2:$E$1285,Ledger!$B$2:$B$1285,$A11,Ledger!$A$2:$A$1285,">="&D$1,Ledger!$A$2:$A$1285,"<"&EDATE(D$1,1)) -> 562600 | E11: =SUMIFS(Ledger!$E$2:$E$1285,Ledger!$B$2:$B$1285,$A11,Ledger!$A$2:$A$1285,">="&E$1,Ledger!$A$2:$A$1285,"<"&EDATE(E$1,1)) -> 560600 | F11: =SUMIFS(Ledger!$E$2:$E$1285,Ledger!$B$2:$B$1285,$A11,Ledger!$A$2:$A$1285,">="&F$1,Ledger!$A$2:$A$1285,"<"&EDATE(F$1,1)) -> 544500 | G11: =SUMIFS(Ledger!$E$2:$E$1285,Ledger!$B$2:$B$1285,$A11,Ledger!$A$2:$A$1285,">="&G$1,Ledger!$A$2:$A$1285,"<"&EDATE(G$1,1)) -> 555300 | H11: =SUMIFS(Ledger!$E$2:$E$1285,Ledger!$B$2:$B$1285,$A11,Ledger!$A$2:$A$1285,">="&H$1,Ledger!$A$2:$A$1285,"<"&EDATE(H$1,1)) -> 554200 | I11: =SUMIFS(Ledger!$E$2:$E$1285,Ledger!$B$2:$B$1285,$A11,Ledger!$A$2:$A$1285,">="&I$1,Ledger!$A$2:$A$1285,"<"&EDATE(I$1,1)) -> 570700 | J11: =SUMIFS(Ledger!$E$2:$E$1285,Ledger!$B$2:$B$1285,$A11,Ledger!$A$2:$A$1285,">="&J$1,Ledger!$A$2:$A$1285,"<"&EDATE(J$1,1)) -> 552800 | K11: =SUMIFS(Ledger!$E$2:$E$1285,Ledger!$B$2:$B$1285,$A11,Ledger!$A$2:$A$1285,">="&K$1,Ledger!$A$2:$A$1285,"<"&EDATE(K$1,1)) -> 569200 | L11: =SUMIFS(Budget!$C$2:$C$145,Budget!$B$2:$B$145,$A11,Budget!$A$2:$A$145,L$1) -> 550000 | M11: =SUMIFS(Budget!$C$2:$C$145,Budget!$B$2:$B$145,$A11,Budget!$A$2:$A$145,M$1) -> 552000 | N11: =SUMIFS(Budget!$C$2:$C$145,Budget!$B$2:$B$145,$A11,Budget!$A$2:$A$145,N$1) -> 553000 | O11: =SUMIFS(Budget!$C$2:$C$145,Budget!$B$2:$B$145,$A11,Budget!$A$2:$A$145,O$1) -> 555000 | P11: =SUMIFS(Budget!$C$2:$C$145,Budget!$B$2:$B$145,$A11,Budget!$A$2:$A$145,P$1) -> 557000 | Q11: =SUMIFS(Budget!$C$2:$C$145,Budget!$B$2:$B$145,$A11,Budget!$A$2:$A$145,Q$1) -> 558000 | R11: =SUMIFS(Budget!$C$2:$C$145,Budget!$B$2:$B$145,$A11,Budget!$A$2:$A$145,R$1) -> 560000 | S11: =SUMIFS(Budget!$C$2:$C$145,Budget!$B$2:$B$145,$A11,Budget!$A$2:$A$145,S$1) -> 562000 | T11: =SUMIFS(Budget!$C$2:$C$145,Budget!$B$2:$B$145,$A11,Budget!$A$2:$A$145,T$1) -> 563000 | U11: =SUMIFS(C11:K11,$C$1:$K$1,"<="&Assumptions!$B$4) -> 5028500 | V11: =SUMIFS(L11:T11,$L$1:$T$1,"<="&Assumptions!$B$4) -> 5010000 | W11: =SUMIFS(C11:K11,$C$1:$K$1,Assumptions!$B$4) -> 569200 | X11: =SUMIFS(L11:T11,$L$1:$T$1,Assumptions!$B$4) -> 563000 | Y11: =IF($B11="Revenue",W11-X11,X11-W11) -> -6200 | Z11: =IFERROR(Y11/X11,0) -> -0.011012433 | AA11: =IF($B11="Revenue",U11-V11,V11-U11) -> -18500 | AB11: =IFERROR(AA11/V11,0) -> -0.0036926148 | AC11: =IF(AND(ABS(Y11)>=Assumptions!$B$5,ABS(Z11)>=Assumptions!$B$6),"Material","")
A12: Utilities | B12: Operating expense | C12: =SUMIFS(Ledger!$E$2:$E$1285,Ledger!$B$2:$B$1285,$A12,Ledger!$A$2:$A$1285,">="&C$1,Ledger!$A$2:$A$1285,"<"&EDATE(C$1,1)) -> 148800 | D12: =SUMIFS(Ledger!$E$2:$E$1285,Ledger!$B$2:$B$1285,$A12,Ledger!$A$2:$A$1285,">="&D$1,Ledger!$A$2:$A$1285,"<"&EDATE(D$1,1)) -> 147500 | E12: =SUMIFS(Ledger!$E$2:$E$1285,Ledger!$B$2:$B$1285,$A12,Ledger!$A$2:$A$1285,">="&E$1,Ledger!$A$2:$A$1285,"<"&EDATE(E$1,1)) -> 154400 | F12: =SUMIFS(Ledger!$E$2:$E$1285,Ledger!$B$2:$B$1285,$A12,Ledger!$A$2:$A$1285,">="&F$1,Ledger!$A$2:$A$1285,"<"&EDATE(F$1,1)) -> 157300 | G12: =SUMIFS(Ledger!$E$2:$E$1285,Ledger!$B$2:$B$1285,$A12,Ledger!$A$2:$A$1285,">="&G$1,Ledger!$A$2:$A$1285,"<"&EDATE(G$1,1)) -> 157900 | H12: =SUMIFS(Ledger!$E$2:$E$1285,Ledger!$B$2:$B$1285,$A12,Ledger!$A$2:$A$1285,">="&H$1,Ledger!$A$2:$A$1285,"<"&EDATE(H$1,1)) -> 157300 | I12: =SUMIFS(Ledger!$E$2:$E$1285,Ledger!$B$2:$B$1285,$A12,Ledger!$A$2:$A$1285,">="&I$1,Ledger!$A$2:$A$1285,"<"&EDATE(I$1,1)) -> 159400 | J12: =SUMIFS(Ledger!$E$2:$E$1285,Ledger!$B$2:$B$1285,$A12,Ledger!$A$2:$A$1285,">="&J$1,Ledger!$A$2:$A$1285,"<"&EDATE(J$1,1)) -> 159000 | K12: =SUMIFS(Ledger!$E$2:$E$1285,Ledger!$B$2:$B$1285,$A12,Ledger!$A$2:$A$1285,">="&K$1,Ledger!$A$2:$A$1285,"<"&EDATE(K$1,1)) -> 159300 | L12: =SUMIFS(Budget!$C$2:$C$145,Budget!$B$2:$B$145,$A12,Budget!$A$2:$A$145,L$1) -> 150000 | M12: =SUMIFS(Budget!$C$2:$C$145,Budget!$B$2:$B$145,$A12,Budget!$A$2:$A$145,M$1) -> 150000 | N12: =SUMIFS(Budget!$C$2:$C$145,Budget!$B$2:$B$145,$A12,Budget!$A$2:$A$145,N$1) -> 151000 | O12: =SUMIFS(Budget!$C$2:$C$145,Budget!$B$2:$B$145,$A12,Budget!$A$2:$A$145,O$1) -> 151000 | P12: =SUMIFS(Budget!$C$2:$C$145,Budget!$B$2:$B$145,$A12,Budget!$A$2:$A$145,P$1) -> 152000 | Q12: =SUMIFS(Budget!$C$2:$C$145,Budget!$B$2:$B$145,$A12,Budget!$A$2:$A$145,Q$1) -> 152000 | R12: =SUMIFS(Budget!$C$2:$C$145,Budget!$B$2:$B$145,$A12,Budget!$A$2:$A$145,R$1) -> 153000 | S12: =SUMIFS(Budget!$C$2:$C$145,Budget!$B$2:$B$145,$A12,Budget!$A$2:$A$145,S$1) -> 153000 | T12: =SUMIFS(Budget!$C$2:$C$145,Budget!$B$2:$B$145,$A12,Budget!$A$2:$A$145,T$1) -> 154000 | U12: =SUMIFS(C12:K12,$C$1:$K$1,"<="&Assumptions!$B$4) -> 1400900 | V12: =SUMIFS(L12:T12,$L$1:$T$1,"<="&Assumptions!$B$4) -> 1366000 | W12: =SUMIFS(C12:K12,$C$1:$K$1,Assumptions!$B$4) -> 159300 | X12: =SUMIFS(L12:T12,$L$1:$T$1,Assumptions!$B$4) -> 154000 | Y12: =IF($B12="Revenue",W12-X12,X12-W12) -> -5300 | Z12: =IFERROR(Y12/X12,0) -> -0.034415584 | AA12: =IF($B12="Revenue",U12-V12,V12-U12) -> -34900 | AB12: =IFERROR(AA12/V12,0) -> -0.025549048 | AC12: =IF(AND(ABS(Y12)>=Assumptions!$B$5,ABS(Z12)>=Assumptions!$B$6),"Material","")
A13: Transport & fuel | B13: Operating expense | C13: =SUMIFS(Ledger!$E$2:$E$1285,Ledger!$B$2:$B$1285,$A13,Ledger!$A$2:$A$1285,">="&C$1,Ledger!$A$2:$A$1285,"<"&EDATE(C$1,1)) -> 700700 | D13: =SUMIFS(Ledger!$E$2:$E$1285,Ledger!$B$2:$B$1285,$A13,Ledger!$A$2:$A$1285,">="&D$1,Ledger!$A$2:$A$1285,"<"&EDATE(D$1,1)) -> 711700 | E13: =SUMIFS(Ledger!$E$2:$E$1285,Ledger!$B$2:$B$1285,$A13,Ledger!$A$2:$A$1285,">="&E$1,Ledger!$A$2:$A$1285,"<"&EDATE(E$1,1)) -> 704700 | F13: =SUMIFS(Ledger!$E$2:$E$1285,Ledger!$B$2:$B$1285,$A13,Ledger!$A$2:$A$1285,">="&F$1,Ledger!$A$2:$A$1285,"<"&EDATE(F$1,1)) -> 743900 | G13: =SUMIFS(Ledger!$E$2:$E$1285,Ledger!$B$2:$B$1285,$A13,Ledger!$A$2:$A$1285,">="&G$1,Ledger!$A$2:$A$1285,"<"&EDATE(G$1,1)) -> 759900 | H13: =SUMIFS(Ledger!$E$2:$E$1285,Ledger!$B$2:$B$1285,$A13,Ledger!$A$2:$A$1285,">="&H$1,Ledger!$A$2:$A$1285,"<"&EDATE(H$1,1)) -> 811600 | I13: =SUMIFS(Ledger!$E$2:$E$1285,Ledger!$B$2:$B$1285,$A13,Ledger!$A$2:$A$1285,">="&I$1,Ledger!$A$2:$A$1285,"<"&EDATE(I$1,1)) -> 843600 | J13: =SUMIFS(Ledger!$E$2:$E$1285,Ledger!$B$2:$B$1285,$A13,Ledger!$A$2:$A$1285,">="&J$1,Ledger!$A$2:$A$1285,"<"&EDATE(J$1,1)) -> 892800 | K13: =SUMIFS(Ledger!$E$2:$E$1285,Ledger!$B$2:$B$1285,$A13,Ledger!$A$2:$A$1285,">="&K$1,Ledger!$A$2:$A$1285,"<"&EDATE(K$1,1)) -> 911700 | L13: =SUMIFS(Budget!$C$2:$C$145,Budget!$B$2:$B$145,$A13,Budget!$A$2:$A$145,L$1) -> 700000 | M13: =SUMIFS(Budget!$C$2:$C$145,Budget!$B$2:$B$145,$A13,Budget!$A$2:$A$145,M$1) -> 702000 | N13: =SUMIFS(Budget!$C$2:$C$145,Budget!$B$2:$B$145,$A13,Budget!$A$2:$A$145,N$1) -> 704000 | O13: =SUMIFS(Budget!$C$2:$C$145,Budget!$B$2:$B$145,$A13,Budget!$A$2:$A$145,O$1) -> 706000 | P13: =SUMIFS(Budget!$C$2:$C$145,Budget!$B$2:$B$145,$A13,Budget!$A$2:$A$145,P$1) -> 708000 | Q13: =SUMIFS(Budget!$C$2:$C$145,Budget!$B$2:$B$145,$A13,Budget!$A$2:$A$145,Q$1) -> 710000 | R13: =SUMIFS(Budget!$C$2:$C$145,Budget!$B$2:$B$145,$A13,Budget!$A$2:$A$145,R$1) -> 713000 | S13: =SUMIFS(Budget!$C$2:$C$145,Budget!$B$2:$B$145,$A13,Budget!$A$2:$A$145,S$1) -> 715000 | T13: =SUMIFS(Budget!$C$2:$C$145,Budget!$B$2:$B$145,$A13,Budget!$A$2:$A$145,T$1) -> 717000 | U13: =SUMIFS(C13:K13,$C$1:$K$1,"<="&Assumptions!$B$4) -> 7080600 | V13: =SUMIFS(L13:T13,$L$1:$T$1,"<="&Assumptions!$B$4) -> 6375000 | W13: =SUMIFS(C13:K13,$C$1:$K$1,Assumptions!$B$4) -> 911700 | X13: =SUMIFS(L13:T13,$L$1:$T$1,Assumptions!$B$4) -> 717000 | Y13: =IF($B13="Revenue",W13-X13,X13-W13) -> -194700 | Z13: =IFERROR(Y13/X13,0) -> -0.27154812 | AA13: =IF($B13="Revenue",U13-V13,V13-U13) -> -705600 | AB13: =IFERROR(AA13/V13,0) -> -0.11068235 | AC13: =IF(AND(ABS(Y13)>=Assumptions!$B$5,ABS(Z13)>=Assumptions!$B$6),"Material","") -> Material
A14: Marketing | B14: Operating expense | C14: =SUMIFS(Ledger!$E$2:$E$1285,Ledger!$B$2:$B$1285,$A14,Ledger!$A$2:$A$1285,">="&C$1,Ledger!$A$2:$A$1285,"<"&EDATE(C$1,1)) -> 268100 | D14: =SUMIFS(Ledger!$E$2:$E$1285,Ledger!$B$2:$B$1285,$A14,Ledger!$A$2:$A$1285,">="&D$1,Ledger!$A$2:$A$1285,"<"&EDATE(D$1,1)) -> 251900 | E14: =SUMIFS(Ledger!$E$2:$E$1285,Ledger!$B$2:$B$1285,$A14,Ledger!$A$2:$A$1285,">="&E$1,Ledger!$A$2:$A$1285,"<"&EDATE(E$1,1)) -> 238100 | F14: =SUMIFS(Ledger!$E$2:$E$1285,Ledger!$B$2:$B$1285,$A14,Ledger!$A$2:$A$1285,">="&F$1,Ledger!$A$2:$A$1285,"<"&EDATE(F$1,1)) -> 239100 | G14: =SUMIFS(Ledger!$E$2:$E$1285,Ledger!$B$2:$B$1285,$A14,Ledger!$A$2:$A$1285,">="&G$1,Ledger!$A$2:$A$1285,"<"&EDATE(G$1,1)) -> 241500 | H14: =SUMIFS(Ledger!$E$2:$E$1285,Ledger!$B$2:$B$1285,$A14,Ledger!$A$2:$A$1285,">="&H$1,Ledger!$A$2:$A$1285,"<"&EDATE(H$1,1)) -> 231300 | I14: =SUMIFS(Ledger!$E$2:$E$1285,Ledger!$B$2:$B$1285,$A14,Ledger!$A$2:$A$1285,">="&I$1,Ledger!$A$2:$A$1285,"<"&EDATE(I$1,1)) -> 228800 | J14: =SUMIFS(Ledger!$E$2:$E$1285,Ledger!$B$2:$B$1285,$A14,Ledger!$A$2:$A$1285,">="&J$1,Ledger!$A$2:$A$1285,"<"&EDATE(J$1,1)) -> 218000 | K14: =SUMIFS(Ledger!$E$2:$E$1285,Ledger!$B$2:$B$1285,$A14,Ledger!$A$2:$A$1285,">="&K$1,Ledger!$A$2:$A$1285,"<"&EDATE(K$1,1)) -> 222100 | L14: =SUMIFS(Budget!$C$2:$C$145,Budget!$B$2:$B$145,$A14,Budget!$A$2:$A$145,L$1) -> 300000 | M14: =SUMIFS(Budget!$C$2:$C$145,Budget!$B$2:$B$145,$A14,Budget!$A$2:$A$145,M$1) -> 301000 | N14: =SUMIFS(Budget!$C$2:$C$145,Budget!$B$2:$B$145,$A14,Budget!$A$2:$A$145,N$1) -> 302000 | O14: =SUMIFS(Budget!$C$2:$C$145,Budget!$B$2:$B$145,$A14,Budget!$A$2:$A$145,O$1) -> 303000 | P14: =SUMIFS(Budget!$C$2:$C$145,Budget!$B$2:$B$145,$A14,Budget!$A$2:$A$145,P$1) -> 304000 | Q14: =SUMIFS(Budget!$C$2:$C$145,Budget!$B$2:$B$145,$A14,Budget!$A$2:$A$145,Q$1) -> 304000 | R14: =SUMIFS(Budget!$C$2:$C$145,Budget!$B$2:$B$145,$A14,Budget!$A$2:$A$145,R$1) -> 305000 | S14: =SUMIFS(Budget!$C$2:$C$145,Budget!$B$2:$B$145,$A14,Budget!$A$2:$A$145,S$1) -> 306000 | T14: =SUMIFS(Budget!$C$2:$C$145,Budget!$B$2:$B$145,$A14,Budget!$A$2:$A$145,T$1) -> 307000 | U14: =SUMIFS(C14:K14,$C$1:$K$1,"<="&Assumptions!$B$4) -> 2138900 | V14: =SUMIFS(L14:T14,$L$1:$T$1,"<="&Assumptions!$B$4) -> 2732000 | W14: =SUMIFS(C14:K14,$C$1:$K$1,Assumptions!$B$4) -> 222100 | X14: =SUMIFS(L14:T14,$L$1:$T$1,Assumptions!$B$4) -> 307000 | Y14: =IF($B14="Revenue",W14-X14,X14-W14) -> 84900 | Z14: =IFERROR(Y14/X14,0) -> 0.27654723 | AA14: =IF($B14="Revenue",U14-V14,V14-U14) -> 593100 | AB14: =IFERROR(AA14/V14,0) -> 0.2170937 | AC14: =IF(AND(ABS(Y14)>=Assumptions!$B$5,ABS(Z14)>=Assumptions!$B$6),"Material","") -> Material
A15: Insurance & licences | B15: Operating expense | C15: =SUMIFS(Ledger!$E$2:$E$1285,Ledger!$B$2:$B$1285,$A15,Ledger!$A$2:$A$1285,">="&C$1,Ledger!$A$2:$A$1285,"<"&EDATE(C$1,1)) -> 91600 | D15: =SUMIFS(Ledger!$E$2:$E$1285,Ledger!$B$2:$B$1285,$A15,Ledger!$A$2:$A$1285,">="&D$1,Ledger!$A$2:$A$1285,"<"&EDATE(D$1,1)) -> 91400 | E15: =SUMIFS(Ledger!$E$2:$E$1285,Ledger!$B$2:$B$1285,$A15,Ledger!$A$2:$A$1285,">="&E$1,Ledger!$A$2:$A$1285,"<"&EDATE(E$1,1)) -> 92700 | F15: =SUMIFS(Ledger!$E$2:$E$1285,Ledger!$B$2:$B$1285,$A15,Ledger!$A$2:$A$1285,">="&F$1,Ledger!$A$2:$A$1285,"<"&EDATE(F$1,1)) -> 91300 | G15: =SUMIFS(Ledger!$E$2:$E$1285,Ledger!$B$2:$B$1285,$A15,Ledger!$A$2:$A$1285,">="&G$1,Ledger!$A$2:$A$1285,"<"&EDATE(G$1,1)) -> 91200 | H15: =SUMIFS(Ledger!$E$2:$E$1285,Ledger!$B$2:$B$1285,$A15,Ledger!$A$2:$A$1285,">="&H$1,Ledger!$A$2:$A$1285,"<"&EDATE(H$1,1)) -> 89300 | I15: =SUMIFS(Ledger!$E$2:$E$1285,Ledger!$B$2:$B$1285,$A15,Ledger!$A$2:$A$1285,">="&I$1,Ledger!$A$2:$A$1285,"<"&EDATE(I$1,1)) -> 93600 | J15: =SUMIFS(Ledger!$E$2:$E$1285,Ledger!$B$2:$B$1285,$A15,Ledger!$A$2:$A$1285,">="&J$1,Ledger!$A$2:$A$1285,"<"&EDATE(J$1,1)) -> 92900 | K15: =SUMIFS(Ledger!$E$2:$E$1285,Ledger!$B$2:$B$1285,$A15,Ledger!$A$2:$A$1285,">="&K$1,Ledger!$A$2:$A$1285,"<"&EDATE(K$1,1)) -> 91500 | L15: =SUMIFS(Budget!$C$2:$C$145,Budget!$B$2:$B$145,$A15,Budget!$A$2:$A$145,L$1) -> 90000 | M15: =SUMIFS(Budget!$C$2:$C$145,Budget!$B$2:$B$145,$A15,Budget!$A$2:$A$145,M$1) -> 90000 | N15: =SUMIFS(Budget!$C$2:$C$145,Budget!$B$2:$B$145,$A15,Budget!$A$2:$A$145,N$1) -> 91000 | O15: =SUMIFS(Budget!$C$2:$C$145,Budget!$B$2:$B$145,$A15,Budget!$A$2:$A$145,O$1) -> 91000 | P15: =SUMIFS(Budget!$C$2:$C$145,Budget!$B$2:$B$145,$A15,Budget!$A$2:$A$145,P$1) -> 91000 | Q15: =SUMIFS(Budget!$C$2:$C$145,Budget!$B$2:$B$145,$A15,Budget!$A$2:$A$145,Q$1) -> 91000 | R15: =SUMIFS(Budget!$C$2:$C$145,Budget!$B$2:$B$145,$A15,Budget!$A$2:$A$145,R$1) -> 92000 | S15: =SUMIFS(Budget!$C$2:$C$145,Budget!$B$2:$B$145,$A15,Budget!$A$2:$A$145,S$1) -> 92000 | T15: =SUMIFS(Budget!$C$2:$C$145,Budget!$B$2:$B$145,$A15,Budget!$A$2:$A$145,T$1) -> 92000 | U15: =SUMIFS(C15:K15,$C$1:$K$1,"<="&Assumptions!$B$4) -> 825500 | V15: =SUMIFS(L15:T15,$L$1:$T$1,"<="&Assumptions!$B$4) -> 820000 | W15: =SUMIFS(C15:K15,$C$1:$K$1,Assumptions!$B$4) -> 91500 | X15: =SUMIFS(L15:T15,$L$1:$T$1,Assumptions!$B$4) -> 92000 | Y15: =IF($B15="Revenue",W15-X15,X15-W15) -> 500 | Z15: =IFERROR(Y15/X15,0) -> 0.0054347826 | AA15: =IF($B15="Revenue",U15-V15,V15-U15) -> -5500 | AB15: =IFERROR(AA15/V15,0) -> -0.0067073171 | AC15: =IF(AND(ABS(Y15)>=Assumptions!$B$5,ABS(Z15)>=Assumptions!$B$6),"Material","")
A16: Bank charges | B16: Operating expense | C16: =SUMIFS(Ledger!$E$2:$E$1285,Ledger!$B$2:$B$1285,$A16,Ledger!$A$2:$A$1285,">="&C$1,Ledger!$A$2:$A$1285,"<"&EDATE(C$1,1)) -> 63200 | D16: =SUMIFS(Ledger!$E$2:$E$1285,Ledger!$B$2:$B$1285,$A16,Ledger!$A$2:$A$1285,">="&D$1,Ledger!$A$2:$A$1285,"<"&EDATE(D$1,1)) -> 63000 | E16: =SUMIFS(Ledger!$E$2:$E$1285,Ledger!$B$2:$B$1285,$A16,Ledger!$A$2:$A$1285,">="&E$1,Ledger!$A$2:$A$1285,"<"&EDATE(E$1,1)) -> 65000 | F16: =SUMIFS(Ledger!$E$2:$E$1285,Ledger!$B$2:$B$1285,$A16,Ledger!$A$2:$A$1285,">="&F$1,Ledger!$A$2:$A$1285,"<"&EDATE(F$1,1)) -> 68400 | G16: =SUMIFS(Ledger!$E$2:$E$1285,Ledger!$B$2:$B$1285,$A16,Ledger!$A$2:$A$1285,">="&G$1,Ledger!$A$2:$A$1285,"<"&EDATE(G$1,1)) -> 67300 | H16: =SUMIFS(Ledger!$E$2:$E$1285,Ledger!$B$2:$B$1285,$A16,Ledger!$A$2:$A$1285,">="&H$1,Ledger!$A$2:$A$1285,"<"&EDATE(H$1,1)) -> 68900 | I16: =SUMIFS(Ledger!$E$2:$E$1285,Ledger!$B$2:$B$1285,$A16,Ledger!$A$2:$A$1285,">="&I$1,Ledger!$A$2:$A$1285,"<"&EDATE(I$1,1)) -> 69000 | J16: =SUMIFS(Ledger!$E$2:$E$1285,Ledger!$B$2:$B$1285,$A16,Ledger!$A$2:$A$1285,">="&J$1,Ledger!$A$2:$A$1285,"<"&EDATE(J$1,1)) -> 69200 | K16: =SUMIFS(Ledger!$E$2:$E$1285,Ledger!$B$2:$B$1285,$A16,Ledger!$A$2:$A$1285,">="&K$1,Ledger!$A$2:$A$1285,"<"&EDATE(K$1,1)) -> 71600 | L16: =SUMIFS(Budget!$C$2:$C$145,Budget!$B$2:$B$145,$A16,Budget!$A$2:$A$145,L$1) -> 60000 | M16: =SUMIFS(Budget!$C$2:$C$145,Budget!$B$2:$B$145,$A16,Budget!$A$2:$A$145,M$1) -> 60000 | N16: =SUMIFS(Budget!$C$2:$C$145,Budget!$B$2:$B$145,$A16,Budget!$A$2:$A$145,N$1) -> 60000 | O16: =SUMIFS(Budget!$C$2:$C$145,Budget!$B$2:$B$145,$A16,Budget!$A$2:$A$145,O$1) -> 61000 | P16: =SUMIFS(Budget!$C$2:$C$145,Budget!$B$2:$B$145,$A16,Budget!$A$2:$A$145,P$1) -> 61000 | Q16: =SUMIFS(Budget!$C$2:$C$145,Budget!$B$2:$B$145,$A16,Budget!$A$2:$A$145,Q$1) -> 61000 | R16: =SUMIFS(Budget!$C$2:$C$145,Budget!$B$2:$B$145,$A16,Budget!$A$2:$A$145,R$1) -> 61000 | S16: =SUMIFS(Budget!$C$2:$C$145,Budget!$B$2:$B$145,$A16,Budget!$A$2:$A$145,S$1) -> 61000 | T16: =SUMIFS(Budget!$C$2:$C$145,Budget!$B$2:$B$145,$A16,Budget!$A$2:$A$145,T$1) -> 61000 | U16: =SUMIFS(C16:K16,$C$1:$K$1,"<="&Assumptions!$B$4) -> 605600 | V16: =SUMIFS(L16:T16,$L$1:$T$1,"<="&Assumptions!$B$4) -> 546000 | W16: =SUMIFS(C16:K16,$C$1:$K$1,Assumptions!$B$4) -> 71600 | X16: =SUMIFS(L16:T16,$L$1:$T$1,Assumptions!$B$4) -> 61000 | Y16: =IF($B16="Revenue",W16-X16,X16-W16) -> -10600 | Z16: =IFERROR(Y16/X16,0) -> -0.17377049 | AA16: =IF($B16="Revenue",U16-V16,V16-U16) -> -59600 | AB16: =IFERROR(AA16/V16,0) -> -0.10915751 | AC16: =IF(AND(ABS(Y16)>=Assumptions!$B$5,ABS(Z16)>=Assumptions!$B$6),"Material","")
A17: Repairs & maintenance | B17: Operating expense | C17: =SUMIFS(Ledger!$E$2:$E$1285,Ledger!$B$2:$B$1285,$A17,Ledger!$A$2:$A$1285,">="&C$1,Ledger!$A$2:$A$1285,"<"&EDATE(C$1,1)) -> 95100 | D17: =SUMIFS(Ledger!$E$2:$E$1285,Ledger!$B$2:$B$1285,$A17,Ledger!$A$2:$A$1285,">="&D$1,Ledger!$A$2:$A$1285,"<"&EDATE(D$1,1)) -> 106900 | E17: =SUMIFS(Ledger!$E$2:$E$1285,Ledger!$B$2:$B$1285,$A17,Ledger!$A$2:$A$1285,">="&E$1,Ledger!$A$2:$A$1285,"<"&EDATE(E$1,1)) -> 84000 | F17: =SUMIFS(Ledger!$E$2:$E$1285,Ledger!$B$2:$B$1285,$A17,Ledger!$A$2:$A$1285,">="&F$1,Ledger!$A$2:$A$1285,"<"&EDATE(F$1,1)) -> 120100 | G17: =SUMIFS(Ledger!$E$2:$E$1285,Ledger!$B$2:$B$1285,$A17,Ledger!$A$2:$A$1285,">="&G$1,Ledger!$A$2:$A$1285,"<"&EDATE(G$1,1)) -> 131900 | H17: =SUMIFS(Ledger!$E$2:$E$1285,Ledger!$B$2:$B$1285,$A17,Ledger!$A$2:$A$1285,">="&H$1,Ledger!$A$2:$A$1285,"<"&EDATE(H$1,1)) -> 108600 | I17: =SUMIFS(Ledger!$E$2:$E$1285,Ledger!$B$2:$B$1285,$A17,Ledger!$A$2:$A$1285,">="&I$1,Ledger!$A$2:$A$1285,"<"&EDATE(I$1,1)) -> 124000 | J17: =SUMIFS(Ledger!$E$2:$E$1285,Ledger!$B$2:$B$1285,$A17,Ledger!$A$2:$A$1285,">="&J$1,Ledger!$A$2:$A$1285,"<"&EDATE(J$1,1)) -> 232200 | K17: =SUMIFS(Ledger!$E$2:$E$1285,Ledger!$B$2:$B$1285,$A17,Ledger!$A$2:$A$1285,">="&K$1,Ledger!$A$2:$A$1285,"<"&EDATE(K$1,1)) -> 145400 | L17: =SUMIFS(Budget!$C$2:$C$145,Budget!$B$2:$B$145,$A17,Budget!$A$2:$A$145,L$1) -> 120000 | M17: =SUMIFS(Budget!$C$2:$C$145,Budget!$B$2:$B$145,$A17,Budget!$A$2:$A$145,M$1) -> 120000 | N17: =SUMIFS(Budget!$C$2:$C$145,Budget!$B$2:$B$145,$A17,Budget!$A$2:$A$145,N$1) -> 121000 | O17: =SUMIFS(Budget!$C$2:$C$145,Budget!$B$2:$B$145,$A17,Budget!$A$2:$A$145,O$1) -> 121000 | P17: =SUMIFS(Budget!$C$2:$C$145,Budget!$B$2:$B$145,$A17,Budget!$A$2:$A$145,P$1) -> 121000 | Q17: =SUMIFS(Budget!$C$2:$C$145,Budget!$B$2:$B$145,$A17,Budget!$A$2:$A$145,Q$1) -> 122000 | R17: =SUMIFS(Budget!$C$2:$C$145,Budget!$B$2:$B$145,$A17,Budget!$A$2:$A$145,R$1) -> 122000 | S17: =SUMIFS(Budget!$C$2:$C$145,Budget!$B$2:$B$145,$A17,Budget!$A$2:$A$145,S$1) -> 123000 | T17: =SUMIFS(Budget!$C$2:$C$145,Budget!$B$2:$B$145,$A17,Budget!$A$2:$A$145,T$1) -> 123000 | U17: =SUMIFS(C17:K17,$C$1:$K$1,"<="&Assumptions!$B$4) -> 1148200 | V17: =SUMIFS(L17:T17,$L$1:$T$1,"<="&Assumptions!$B$4) -> 1093000 | W17: =SUMIFS(C17:K17,$C$1:$K$1,Assumptions!$B$4) -> 145400 | X17: =SUMIFS(L17:T17,$L$1:$T$1,Assumptions!$B$4) -> 123000 | Y17: =IF($B17="Revenue",W17-X17,X17-W17) -> -22400 | Z17: =IFERROR(Y17/X17,0) -> -0.18211382 | AA17: =IF($B17="Revenue",U17-V17,V17-U17) -> -55200 | AB17: =IFERROR(AA17/V17,0) -> -0.050503202 | AC17: =IF(AND(ABS(Y17)>=Assumptions!$B$5,ABS(Z17)>=Assumptions!$B$6),"Material","")
A19: Total revenue | C19: =SUMIFS(C$2:C$17,$B$2:$B$17,"Revenue") -> 25538600 | D19: =SUMIFS(D$2:D$17,$B$2:$B$17,"Revenue") -> 25829500 | E19: =SUMIFS(E$2:E$17,$B$2:$B$17,"Revenue") -> 26000500 | F19: =SUMIFS(F$2:F$17,$B$2:$B$17,"Revenue") -> 26671500 | G19: =SUMIFS(G$2:G$17,$B$2:$B$17,"Revenue") -> 26577800 | H19: =SUMIFS(H$2:H$17,$B$2:$B$17,"Revenue") -> 26994200 | I19: =SUMIFS(I$2:I$17,$B$2:$B$17,"Revenue") -> 27253700 | J19: =SUMIFS(J$2:J$17,$B$2:$B$17,"Revenue") -> 26807600 | ... X19: =SUMIFS(X$2:X$17,$B$2:$B$17,"Revenue") -> 27400000
A20: Total cost of sales | C20: =SUMIFS(C$2:C$17,$B$2:$B$17,"Cost of sales") -> 20976200 | D20: =SUMIFS(D$2:D$17,$B$2:$B$17,"Cost of sales") -> 21144300 | E20: =SUMIFS(E$2:E$17,$B$2:$B$17,"Cost of sales") -> 21293000 | F20: =SUMIFS(F$2:F$17,$B$2:$B$17,"Cost of sales") -> 21939100 | G20: =SUMIFS(G$2:G$17,$B$2:$B$17,"Cost of sales") -> 21919000 | H20: =SUMIFS(H$2:H$17,$B$2:$B$17,"Cost of sales") -> 22324500 | I20: =SUMIFS(I$2:I$17,$B$2:$B$17,"Cost of sales") -> 22647700 | J20: =SUMIFS(J$2:J$17,$B$2:$B$17,"Cost of sales") -> 22323600 | ... X20: =SUMIFS(X$2:X$17,$B$2:$B$17,"Cost of sales") -> 22468000
A21: Gross profit | C21: =C19-C20 -> 4562400 | D21: =D19-D20 -> 4685200 | E21: =E19-E20 -> 4707500 | F21: =F19-F20 -> 4732400 | G21: =G19-G20 -> 4658800 | H21: =H19-H20 -> 4669700 | I21: =I19-I20 -> 4606000 | J21: =J19-J20 -> 4484000 | ... X21: =X19-X20 -> 4932000
A22: Total operating expenses | C22: =SUMIFS(C$2:C$17,$B$2:$B$17,"Operating expense") -> 3552100 | D22: =SUMIFS(D$2:D$17,$B$2:$B$17,"Operating expense") -> 3567600 | E22: =SUMIFS(E$2:E$17,$B$2:$B$17,"Operating expense") -> 3503500 | F22: =SUMIFS(F$2:F$17,$B$2:$B$17,"Operating expense") -> 3594400 | G22: =SUMIFS(G$2:G$17,$B$2:$B$17,"Operating expense") -> 3628500 | H22: =SUMIFS(H$2:H$17,$B$2:$B$17,"Operating expense") -> 3688400 | I22: =SUMIFS(I$2:I$17,$B$2:$B$17,"Operating expense") -> 3760500 | J22: =SUMIFS(J$2:J$17,$B$2:$B$17,"Operating expense") -> 3925800 | ... X22: =SUMIFS(X$2:X$17,$B$2:$B$17,"Operating expense") -> 3655000
A23: Operating profit | C23: =C21-C22 -> 1010300 | D23: =D21-D22 -> 1117600 | E23: =E21-E22 -> 1204000 | F23: =F21-F22 -> 1138000 | G23: =G21-G22 -> 1030300 | H23: =H21-H22 -> 981300 | I23: =I21-I22 -> 845500 | J23: =J21-J22 -> 558200 | ... X23: =X21-X22 -> 1277000
A24: Gross margin % | C24: =IFERROR(C21/C19,0) -> 0.17864722 | D24: =IFERROR(D21/D19,0) -> 0.1813895 | E24: =IFERROR(E21/E19,0) -> 0.18105421 | F24: =IFERROR(F21/F19,0) -> 0.17743284 | G24: =IFERROR(G21/G19,0) -> 0.17528915 | H24: =IFERROR(H21/H19,0) -> 0.17298901 | I24: =IFERROR(I21/I19,0) -> 0.16900458 | J24: =IFERROR(J21/J19,0) -> 0.167266 | ... X24: =IFERROR(X21/X19,0) -> 0.18

Sheet Accounts
A1: Account | B1: Type
A2: Sales: Cooking oil & fats | B2: Revenue
A3: Sales: Flour & grains | B3: Revenue
A4: Sales: Beverages | B4: Revenue
A5: Sales: Household goods | B5: Revenue
A6: Cost of sales: Cooking oil & fats | B6: Cost of sales
A7: Cost of sales: Flour & grains | B7: Cost of sales
A8: Cost of sales: Beverages | B8: Cost of sales
A9: Cost of sales: Household goods | B9: Cost of sales
A10: Salaries & wages | B10: Operating expense
A11: Rent | B11: Operating expense
A12: Utilities | B12: Operating expense
... A17: Repairs & maintenance | B17: Operating expense

Sheet Budget
A1: Month | B1: Account | C1: Budget (KES)
A2: 46023 | B2: Sales: Cooking oil & fats | C2: 9000000
A3: 46023 | B3: Sales: Flour & grains | C3: 7500000
A4: 46023 | B4: Sales: Beverages | C4: 5000000
A5: 46023 | B5: Sales: Household goods | C5: 3500000
A6: 46023 | B6: Cost of sales: Cooking oil & fats | C6: 7560000
A7: 46023 | B7: Cost of sales: Flour & grains | C7: 6450000
A8: 46023 | B8: Cost of sales: Beverages | C8: 3900000
A9: 46023 | B9: Cost of sales: Household goods | C9: 2590000
A10: 46023 | B10: Salaries & wages | C10: 1600000
A11: 46023 | B11: Rent | C11: 550000
A12: 46023 | B12: Utilities | C12: 150000
A13: 46023 | B13: Transport & fuel | C13: 700000
... A145: 46266 | B145: Repairs & maintenance | C145: 123000

Sheet Ledger
A1: Date | B1: Account | C1: Type | D1: Description | E1: Amount (KES)
A2: 46023 | B2: Cost of sales: Flour & grains | C2: Cost of sales | D2: Supplier invoices | E2: 673700
A3: 46023 | B3: Marketing | C3: Operating expense | D3: Payments | E3: 98100
A4: 46023 | B4: Sales: Cooking oil & fats | C4: Revenue | D4: Customer invoices | E4: 255000
A5: 46023 | B5: Sales: Flour & grains | C5: Revenue | D5: Customer invoices | E5: 262700
