Workbook

Sheet README
A1: NGO Programme M&E Dashboard – Monitoring & Evaluation Portfolio Project
A2: BZME Insights | Sector: NGO / Development | Tool: Excel (formula-driven)
A4: BUSINESS PROBLEM
A5: A donor-funded water, sanitation and hygiene programme works in six counties. The programme manager must report progress against annual targets, show which counties and indicators are lagging, and show whether spending matches delivery. Today this is assembled by hand each quarter.
A7: BUSINESS QUESTIONS
A8: 1. How much of each annual target has been delivered, compared with the share of the year that has passed?
A9: 2. Which indicators and counties are On track, on Watch or Off track?
A10: 3. Is spending ahead of or behind delivery in any county?
A11: 4. How far have outcome indicators (household survey) moved from baseline toward target?
A12: 5. What is the cost per person reached with safe water?
A14: HOW THE WORKBOOK IS BUILT
A15: Monthly_Results: 432 county-month-indicator records (Jan to Sep 2026).
... A35: Add quarterly phasing and disaggregation (gender, age, ward) when real data is available.

Sheet Dashboard
A1: NGO Programme M&E Dashboard
A2: ="Fictional water, sanitation and hygiene (WASH) programme, Western Kenya | Synthetic data | Progress as of "&TEXT(Assumptions!B4,"d mmm yyyy")&" | Prepared by BZME Insights" -> Fictional water, sanitation and hygiene (WASH) programme, Western Kenya | Synthetic data | Progress as of 30 Sep 2026 | Prepared by BZME Insights
A4: PEOPLE WITH SAFE WATER ACCESS | C4: AVG PROGRESS VS TARGET TO DATE | E4: INDICATORS ON TRACK | G4: BUDGET ABSORBED (% OF ANNUAL) | I4: COST PER PERSON WITH SAFE WATER (KES) | K4: OUTCOME PROGRESS TO TARGET
A5: =D19 -> 40401 | C5: =E27 -> 0.82990612 | E5: =COUNTIF(F19:F26,"On track")&" of "&COUNTA(F19:F26) -> 5 of 8 | G5: =D66/C66 -> 0.65327206 | I5: =IFERROR(SUM(Finance!$D$2:$D$25)/D19,0) -> 2199.0792 | K5: =E44 -> 0.47386958
A7: Key findings (update automatically)
A8: ="1. "&TEXT(Assumptions!B7,"0%")&" of the year has passed and the programme has delivered on average "&TEXT(E27,"0%")&" of its target to date; "&COUNTIF(F19:F26,"On track")&" of "&COUNTA(F19:F26)&" indicators are On track." -> 1. 75% of the year has passed and the programme has delivered on average 83% of its target to date; 5 of 8 indicators are On track.
A9: ="2. Strongest indicator: "&INDEX(A19:A26,MATCH(MAX(E19:E26),E19:E26,0))&" ("&TEXT(MAX(E19:E26),"0%")&"). Weakest: "&INDEX(A19:A26,MATCH(MIN(E19:E26),E19:E26,0))&" ("&TEXT(MIN(E19:E26),"0%")&")." -> 2. Strongest indicator: Water quality tests completed (99%). Weakest: School WASH facilities installed (39%).
A10: ="3. Lowest-performing county: "&INDEX(A31:A36,MATCH(MIN(J31:J36),J31:J36,0))&" ("&TEXT(MIN(J31:J36),"0%")&" of target to date); highest: "&INDEX(A31:A36,MATCH(MAX(J31:J36),J31:J36,0))&" ("&TEXT(MAX(J31:J36),"0%")&")." -> 3. Lowest-performing county: Bungoma (57% of target to date); highest: Kisumu (100%).
A11: =IF(COUNTIF(L31:L36,"Spend > delivery")=0,"4. No county is spending ahead of delivery.","4. "&COUNTIF(L31:L36,"Spend > delivery")&IF(COUNTIF(L31:L36,"Spend > delivery")=1," county is"," counties are")&" spending ahead of delivery: "&INDEX(A31:A36,MATCH("Spend > delivery",L31:L36,0))&IF(COUNTIF(L31:L36,"Spend > delivery")>1," and others","")&". Review its work plan and cash release.") -> 4. 1 county is spending ahead of delivery: Bungoma. Review its work plan and cash release.
A12: ="5. KES "&TEXT(SUM(Finance!$D$2:$D$25)/1000000,"#,##0.0")&"M spent to date ("&TEXT(D66/C66,"0%")&" of annual budget) at about KES "&TEXT(I5,"#,##0")&" per person with new safe water access." -> 5. KES 88.8M spent to date (65% of annual budget) at about KES 2,199 per person with new safe water access.
A13: ="6. Largest remaining gap: "&INDEX(A19:A26,MATCH(MAX(G19:G26),G19:G26,0))&" needs "&TEXT(MAX(G19:G26),"#,##0")&" more by year end to hit the annual target." -> 6. Largest remaining gap: People with access to safe water needs 19,599 more by year end to hit the annual target.
A14: ="7. Outcome survey: "&INDEX(A41:A43,MATCH(MIN(E41:E43),E41:E43,0))&" has the least progress toward target ("&TEXT(MIN(E41:E43),"0%")&" of the baseline-to-target gap closed)." -> 7. Outcome survey: Households treating drinking water has the least progress toward target (46% of the baseline-to-target gap closed).
A17: 1. Indicator progress: actual vs target to date
A18: Indicator | B18: Annual target | C18: Target to date | D18: Actual to date | E18: % of target to date | F18: Status | G18: Remaining to annual target
A19: =Indicators!B2 -> People with access to safe water | B19: =Indicators!D2 -> 60000 | C19: =Indicators!E2 -> 44876.712 | D19: =Indicators!F2 -> 40401 | E19: =Indicators!G2 -> 0.90026648 | F19: =Indicators!I2 -> On track | G19: =MAX(0,B19-D19) -> 19599
A20: =Indicators!B3 -> Water points built or rehabilitated | B20: =Indicators!D3 -> 120 | C20: =Indicators!E3 -> 89.753425 | D20: =Indicators!F3 -> 63 | E20: =Indicators!G3 -> 0.70192308 | F20: =Indicators!I3 -> Watch | G20: =MAX(0,B20-D20) -> 57
A21: =Indicators!B4 -> Households reached with hygiene education | B21: =Indicators!D4 -> 18000 | C21: =Indicators!E4 -> 13463.014 | D21: =Indicators!F4 -> 12714 | E21: =Indicators!G4 -> 0.94436508 | F21: =Indicators!I4 -> On track | G21: =MAX(0,B21-D21) -> 5286
A22: =Indicators!B5 -> Community health volunteers trained | B22: =Indicators!D5 -> 360 | C22: =Indicators!E5 -> 269.26027 | D22: =Indicators!F5 -> 252 | E22: =Indicators!G5 -> 0.93589744 | F22: =Indicators!I5 -> On track | G22: =MAX(0,B22-D22) -> 108
A23: =Indicators!B6 -> School WASH facilities installed | B23: =Indicators!D6 -> 48 | C23: =Indicators!E6 -> 35.90137 | D23: =Indicators!F6 -> 14 | E23: =Indicators!G6 -> 0.38995726 | F23: =Indicators!I6 -> Off track | G23: =MAX(0,B23-D23) -> 34
A24: =Indicators!B7 -> Water committees formed and trained | B24: =Indicators!D7 -> 90 | C24: =Indicators!E7 -> 67.315068 | D24: =Indicators!F7 -> 66 | E24: =Indicators!G7 -> 0.98046398 | F24: =Indicators!I7 -> On track | G24: =MAX(0,B24-D24) -> 24
A25: =Indicators!B8 -> Households with new handwashing station | B25: =Indicators!D8 -> 9000 | C25: =Indicators!E8 -> 6731.5068 | D25: =Indicators!F8 -> 5371 | E25: =Indicators!G8 -> 0.7978897 | F25: =Indicators!I8 -> Watch | G25: =MAX(0,B25-D25) -> 3629
A26: =Indicators!B9 -> Water quality tests completed | B26: =Indicators!D9 -> 1500 | C26: =Indicators!E9 -> 1121.9178 | D26: =Indicators!F9 -> 1109 | E26: =Indicators!G9 -> 0.98848596 | F26: =Indicators!I9 -> On track | G26: =MAX(0,B26-D26) -> 391
A27: Average across indicators | E27: =AVERAGE(E19:E26) -> 0.82990612
A29: 2. County heatmap: % of target to date, by indicator
A30: County | B30: O1 | C30: O2 | D30: O3 | E30: O4 | F30: O5 | G30: O6 | H30: O7 | I30: O8 | J30: Average | K30: Budget absorbed | L30: Spend vs delivery
A31: =County_Progress!A2 -> Kisumu | B31: =County_Progress!B2 -> 1.0414087 | C31: =County_Progress!C2 -> 0.50137363 | D31: =County_Progress!D2 -> 1.1045075 | E31: =County_Progress!E2 -> 1.2627188 | F31: =County_Progress!F2 -> 0.8021978 | G31: =County_Progress!G2 -> 1.1884412 | H31: =County_Progress!H2 -> 0.89950142 | ... J31: =County_Progress!J2 -> 1.0004307 | K31: =County_Progress!N2 -> 0.69117857 | L31: =County_Progress!P2 -> Aligned
A32: =County_Progress!A3 -> Siaya | B32: =County_Progress!B3 -> 0.93262922 | C32: =County_Progress!C3 -> 1.039886 | D32: =County_Progress!D3 -> 1.0062135 | E32: =County_Progress!E3 -> 1.0894044 | F32: =County_Progress!F3 -> 0.38199895 | G32: =County_Progress!G3 -> 1.4324961 | H32: =County_Progress!H3 -> 0.85171619 | ... J32: =County_Progress!J3 -> 0.97697824 | K32: =County_Progress!N3 -> 0.66315 | L32: =County_Progress!P3 -> Aligned
A33: =County_Progress!A4 -> Homa Bay | B33: =County_Progress!B4 -> 0.71690239 | C33: =County_Progress!C4 -> 0.60772561 | D33: =County_Progress!D4 -> 0.79765862 | E33: =County_Progress!E4 -> 0.69935193 | F33: =County_Progress!F4 -> 0.14855515 | G33: =County_Progress!G4 -> 1.0863095 | H33: =County_Progress!H4 -> 0.67179939 | ... J33: =County_Progress!J4 -> 0.67955194 | K33: =County_Progress!N4 -> 0.456625 | L33: =County_Progress!P4 -> Aligned
A34: =County_Progress!A5 -> Migori | B34: =County_Progress!B5 -> 0.92891534 | C34: =County_Progress!C5 -> 0.89133089 | D34: =County_Progress!D5 -> 0.8972731 | E34: =County_Progress!E5 -> 0.71801655 | F34: =County_Progress!F5 -> 0.57299843 | G34: =County_Progress!G5 -> 0.66849817 | H34: =County_Progress!H5 -> 0.81606295 | ... J34: =County_Progress!J5 -> 0.80919493 | K34: =County_Progress!N5 -> 0.679 | L34: =County_Progress!P5 -> Aligned
A35: =County_Progress!A6 -> Kakamega | B35: =County_Progress!B6 -> 1.0730051 | C35: =County_Progress!C6 -> 0.8021978 | D35: =County_Progress!D6 -> 1.1255237 | E35: =County_Progress!E6 -> 1.3150784 | F35: =County_Progress!F6 -> 0.16712454 | G35: =County_Progress!G6 -> 0.62393162 | H35: =County_Progress!H6 -> 0.93240202 | ... J35: =County_Progress!J6 -> 0.89909378 | K35: =County_Progress!N6 -> 0.72056522 | L35: =County_Progress!P6 -> Aligned
A36: =County_Progress!A7 -> Bungoma | B36: =County_Progress!B7 -> 0.67533171 | C36: =County_Progress!C7 -> 0.44566545 | D36: =County_Progress!D7 -> 0.68681997 | E36: =County_Progress!E7 -> 0.42090625 | F36: =County_Progress!F7 -> 0.19099948 | G36: =County_Progress!G7 -> 0.82276698 | H36: =County_Progress!H7 -> 0.58926876 | ... J36: =County_Progress!J7 -> 0.57478789 | K36: =County_Progress!N7 -> 0.7219 | L36: =County_Progress!P7 -> Spend > delivery
A37: All counties | B37: =Indicators!G2 -> 0.90026648 | C37: =Indicators!G3 -> 0.70192308 | D37: =Indicators!G4 -> 0.94436508 | E37: =Indicators!G5 -> 0.93589744 | F37: =Indicators!G6 -> 0.38995726 | G37: =Indicators!G7 -> 0.98046398 | H37: =Indicators!G8 -> 0.7978897 | I37: =Indicators!G9 -> 0.98848596 | J37: =AVERAGE(B37:I37) -> 0.82990612 | K37: =D66/C66 -> 0.65327206
A38: Indicator codes: O1 = People with access to safe water; O2 = Water points built or rehabilitated; O3 = Households reached with hygiene education; O4 = Community health volunteers trained; O5 = School WASH facilities installed; O6 = Water committees formed and trained; O7 = Households with new handwashing station; O8 = Water quality tests completed
A39: 3. Outcome indicators (household survey, baseline vs midline)
A40: Outcome | B40: Baseline | C40: Midline | D40: Target | E40: Progress to target
A41: Households treating drinking water | B41: =AVERAGEIFS(Survey_Data!$C$2:$C$19,Survey_Data!$B$2:$B$19,"OC1") -> 0.28533333 | C41: =AVERAGEIFS(Survey_Data!$D$2:$D$19,Survey_Data!$B$2:$B$19,"OC1") -> 0.43083333 | D41: =AVERAGEIFS(Survey_Data!$E$2:$E$19,Survey_Data!$B$2:$B$19,"OC1") -> 0.6 | E41: =IFERROR((C41-B41)/(D41-B41),0) -> 0.46239407
A42: Households with handwashing facility and soap | B42: =AVERAGEIFS(Survey_Data!$C$2:$C$19,Survey_Data!$B$2:$B$19,"OC2") -> 0.21683333 | C42: =AVERAGEIFS(Survey_Data!$D$2:$D$19,Survey_Data!$B$2:$B$19,"OC2") -> 0.38183333 | D42: =AVERAGEIFS(Survey_Data!$E$2:$E$19,Survey_Data!$B$2:$B$19,"OC2") -> 0.55 | E42: =IFERROR((C42-B42)/(D42-B42),0) -> 0.49524762
A43: Water points functional after 90 days | B43: =AVERAGEIFS(Survey_Data!$C$2:$C$19,Survey_Data!$B$2:$B$19,"OC3") -> 0.60716667 | C43: =AVERAGEIFS(Survey_Data!$D$2:$D$19,Survey_Data!$B$2:$B$19,"OC3") -> 0.71983333 | D43: =AVERAGEIFS(Survey_Data!$E$2:$E$19,Survey_Data!$B$2:$B$19,"OC3") -> 0.85 | E43: =IFERROR((C43-B43)/(D43-B43),0) -> 0.46396706
A44: Average | E44: =AVERAGE(E41:E43) -> 0.47386958
A46: 4. Cumulative people with safe water access: actual vs plan
...

Sheet Assumptions
A1: Assumptions & Parameters
A2: Blue cells are editable inputs. Everything else recalculates from them.
A3: Assumption | B3: Value | C3: Comment
A4: As-of date | B4: 46295 | C4: Last day of reported data.
A5: Programme year start | B5: 46023 | C5: First day of the programme year.
A6: Programme year end | B6: 46387 | C6: Last day of the programme year.
A7: Share of year elapsed | B7: =(B4-B5+1)/(B6-B5+1) -> 0.74794521 | C7: Calculated. Target-to-date = annual target x this share (straight-line phasing).
A8: On track: at or above | B8: 0.9 | C8: Share of target-to-date delivered at or above which an indicator is On track.
A9: Watch: at or above | B9: 0.7 | C9: Between this and the On-track line is Watch; below is Off track.
A10: Spend-vs-delivery gap flag | B10: 0.15 | C10: Flags a county when budget absorbed and delivery differ by more than this many points.

Sheet Indicators
A1: ID | B1: Indicator | C1: Unit | D1: Annual target | E1: Target to date | F1: Actual to date | G1: % of target to date | H1: % of annual target | I1: Status | J1: Gap to date
A2: O1 | B2: People with access to safe water | C2: people | D2: =SUMIFS(County_Targets!$C$2:$C$49,County_Targets!$A$2:$A$49,A2) -> 60000 | E2: =D2*Assumptions!$B$7 -> 44876.712 | F2: =SUMIFS(Monthly_Results!$D$2:$D$433,Monthly_Results!$C$2:$C$433,A2,Monthly_Results!$A$2:$A$433,"<="&Assumptions!$B$4) -> 40401 | G2: =IFERROR(F2/E2,0) -> 0.90026648 | H2: =IFERROR(F2/D2,0) -> 0.67335 | I2: =IF(G2>=Assumptions!$B$8,"On track",IF(G2>=Assumptions!$B$9,"Watch","Off track")) -> On track | J2: =F2-E2 -> -4475.7123
A3: O2 | B3: Water points built or rehabilitated | C3: water points | D3: =SUMIFS(County_Targets!$C$2:$C$49,County_Targets!$A$2:$A$49,A3) -> 120 | E3: =D3*Assumptions!$B$7 -> 89.753425 | F3: =SUMIFS(Monthly_Results!$D$2:$D$433,Monthly_Results!$C$2:$C$433,A3,Monthly_Results!$A$2:$A$433,"<="&Assumptions!$B$4) -> 63 | G3: =IFERROR(F3/E3,0) -> 0.70192308 | H3: =IFERROR(F3/D3,0) -> 0.525 | I3: =IF(G3>=Assumptions!$B$8,"On track",IF(G3>=Assumptions!$B$9,"Watch","Off track")) -> Watch | J3: =F3-E3 -> -26.753425
A4: O3 | B4: Households reached with hygiene education | C4: households | D4: =SUMIFS(County_Targets!$C$2:$C$49,County_Targets!$A$2:$A$49,A4) -> 18000 | E4: =D4*Assumptions!$B$7 -> 13463.014 | F4: =SUMIFS(Monthly_Results!$D$2:$D$433,Monthly_Results!$C$2:$C$433,A4,Monthly_Results!$A$2:$A$433,"<="&Assumptions!$B$4) -> 12714 | G4: =IFERROR(F4/E4,0) -> 0.94436508 | H4: =IFERROR(F4/D4,0) -> 0.70633333 | I4: =IF(G4>=Assumptions!$B$8,"On track",IF(G4>=Assumptions!$B$9,"Watch","Off track")) -> On track | J4: =F4-E4 -> -749.0137
A5: O4 | B5: Community health volunteers trained | C5: volunteers | D5: =SUMIFS(County_Targets!$C$2:$C$49,County_Targets!$A$2:$A$49,A5) -> 360 | E5: =D5*Assumptions!$B$7 -> 269.26027 | F5: =SUMIFS(Monthly_Results!$D$2:$D$433,Monthly_Results!$C$2:$C$433,A5,Monthly_Results!$A$2:$A$433,"<="&Assumptions!$B$4) -> 252 | G5: =IFERROR(F5/E5,0) -> 0.93589744 | H5: =IFERROR(F5/D5,0) -> 0.7 | I5: =IF(G5>=Assumptions!$B$8,"On track",IF(G5>=Assumptions!$B$9,"Watch","Off track")) -> On track | J5: =F5-E5 -> -17.260274
A6: O5 | B6: School WASH facilities installed | C6: facilities | D6: =SUMIFS(County_Targets!$C$2:$C$49,County_Targets!$A$2:$A$49,A6) -> 48 | E6: =D6*Assumptions!$B$7 -> 35.90137 | F6: =SUMIFS(Monthly_Results!$D$2:$D$433,Monthly_Results!$C$2:$C$433,A6,Monthly_Results!$A$2:$A$433,"<="&Assumptions!$B$4) -> 14 | G6: =IFERROR(F6/E6,0) -> 0.38995726 | H6: =IFERROR(F6/D6,0) -> 0.29166667 | I6: =IF(G6>=Assumptions!$B$8,"On track",IF(G6>=Assumptions!$B$9,"Watch","Off track")) -> Off track | J6: =F6-E6 -> -21.90137
A7: O6 | B7: Water committees formed and trained | C7: committees | D7: =SUMIFS(County_Targets!$C$2:$C$49,County_Targets!$A$2:$A$49,A7) -> 90 | E7: =D7*Assumptions!$B$7 -> 67.315068 | F7: =SUMIFS(Monthly_Results!$D$2:$D$433,Monthly_Results!$C$2:$C$433,A7,Monthly_Results!$A$2:$A$433,"<="&Assumptions!$B$4) -> 66 | G7: =IFERROR(F7/E7,0) -> 0.98046398 | H7: =IFERROR(F7/D7,0) -> 0.73333333 | I7: =IF(G7>=Assumptions!$B$8,"On track",IF(G7>=Assumptions!$B$9,"Watch","Off track")) -> On track | J7: =F7-E7 -> -1.3150685
A8: O7 | B8: Households with new handwashing station | C8: households | D8: =SUMIFS(County_Targets!$C$2:$C$49,County_Targets!$A$2:$A$49,A8) -> 9000 | E8: =D8*Assumptions!$B$7 -> 6731.5068 | F8: =SUMIFS(Monthly_Results!$D$2:$D$433,Monthly_Results!$C$2:$C$433,A8,Monthly_Results!$A$2:$A$433,"<="&Assumptions!$B$4) -> 5371 | G8: =IFERROR(F8/E8,0) -> 0.7978897 | H8: =IFERROR(F8/D8,0) -> 0.59677778 | I8: =IF(G8>=Assumptions!$B$8,"On track",IF(G8>=Assumptions!$B$9,"Watch","Off track")) -> Watch | J8: =F8-E8 -> -1360.5068
A9: O8 | B9: Water quality tests completed | C9: tests | D9: =SUMIFS(County_Targets!$C$2:$C$49,County_Targets!$A$2:$A$49,A9) -> 1500 | E9: =D9*Assumptions!$B$7 -> 1121.9178 | F9: =SUMIFS(Monthly_Results!$D$2:$D$433,Monthly_Results!$C$2:$C$433,A9,Monthly_Results!$A$2:$A$433,"<="&Assumptions!$B$4) -> 1109 | G9: =IFERROR(F9/E9,0) -> 0.98848596 | H9: =IFERROR(F9/D9,0) -> 0.73933333 | I9: =IF(G9>=Assumptions!$B$8,"On track",IF(G9>=Assumptions!$B$9,"Watch","Off track")) -> On track | J9: =F9-E9 -> -12.917808

Sheet County_Progress
A1: County | B1: O1 | C1: O2 | D1: O3 | E1: O4 | F1: O5 | G1: O6 | H1: O7 | I1: O8 | J1: Avg % of target to date | K1: Status | L1: Annual budget (KES) | M1: Spent to date (KES) | N1: Budget absorbed | O1: Absorbed minus delivery | P1: Spend vs delivery
A2: Kisumu | B2: =IFERROR(SUMIFS(Monthly_Results!$D$2:$D$433,Monthly_Results!$B$2:$B$433,$A2,Monthly_Results!$C$2:$C$433,B$1,Monthly_Results!$A$2:$A$433,"<="&Assumptions!$B$4)/(SUMIFS(County_Targets!$C$2:$C$49,County_Targets!$B$2:$B$49,$A2,County_Targets!$A$2:$A$49,B$1)*Assumptions!$B$7),0) -> 1.0414087 | C2: =IFERROR(SUMIFS(Monthly_Results!$D$2:$D$433,Monthly_Results!$B$2:$B$433,$A2,Monthly_Results!$C$2:$C$433,C$1,Monthly_Results!$A$2:$A$433,"<="&Assumptions!$B$4)/(SUMIFS(County_Targets!$C$2:$C$49,County_Targets!$B$2:$B$49,$A2,County_Targets!$A$2:$A$49,C$1)*Assumptions!$B$7),0) -> 0.50137363 | D2: =IFERROR(SUMIFS(Monthly_Results!$D$2:$D$433,Monthly_Results!$B$2:$B$433,$A2,Monthly_Results!$C$2:$C$433,D$1,Monthly_Results!$A$2:$A$433,"<="&Assumptions!$B$4)/(SUMIFS(County_Targets!$C$2:$C$49,County_Targets!$B$2:$B$49,$A2,County_Targets!$A$2:$A$49,D$1)*Assumptions!$B$7),0) -> 1.1045075 | E2: =IFERROR(SUMIFS(Monthly_Results!$D$2:$D$433,Monthly_Results!$B$2:$B$433,$A2,Monthly_Results!$C$2:$C$433,E$1,Monthly_Results!$A$2:$A$433,"<="&Assumptions!$B$4)/(SUMIFS(County_Targets!$C$2:$C$49,County_Targets!$B$2:$B$49,$A2,County_Targets!$A$2:$A$49,E$1)*Assumptions!$B$7),0) -> 1.2627188 | F2: =IFERROR(SUMIFS(Monthly_Results!$D$2:$D$433,Monthly_Results!$B$2:$B$433,$A2,Monthly_Results!$C$2:$C$433,F$1,Monthly_Results!$A$2:$A$433,"<="&Assumptions!$B$4)/(SUMIFS(County_Targets!$C$2:$C$49,County_Targets!$B$2:$B$49,$A2,County_Targets!$A$2:$A$49,F$1)*Assumptions!$B$7),0) -> 0.8021978 | G2: =IFERROR(SUMIFS(Monthly_Results!$D$2:$D$433,Monthly_Results!$B$2:$B$433,$A2,Monthly_Results!$C$2:$C$433,G$1,Monthly_Results!$A$2:$A$433,"<="&Assumptions!$B$4)/(SUMIFS(County_Targets!$C$2:$C$49,County_Targets!$B$2:$B$49,$A2,County_Targets!$A$2:$A$49,G$1)*Assumptions!$B$7),0) -> 1.1884412 | H2: =IFERROR(SUMIFS(Monthly_Results!$D$2:$D$433,Monthly_Results!$B$2:$B$433,$A2,Monthly_Results!$C$2:$C$433,H$1,Monthly_Results!$A$2:$A$433,"<="&Assumptions!$B$4)/(SUMIFS(County_Targets!$C$2:$C$49,County_Targets!$B$2:$B$49,$A2,County_Targets!$A$2:$A$49,H$1)*Assumptions!$B$7),0) -> 0.89950142 | I2: =IFERROR(SUMIFS(Monthly_Results!$D$2:$D$433,Monthly_Results!$B$2:$B$433,$A2,Monthly_Results!$C$2:$C$433,I$1,Monthly_Results!$A$2:$A$433,"<="&Assumptions!$B$4)/(SUMIFS(County_Targets!$C$2:$C$49,County_Targets!$B$2:$B$49,$A2,County_Targets!$A$2:$A$49,I$1)*Assumptions!$B$7),0) -> 1.2032967 | J2: =AVERAGE(B2:I2) -> 1.0004307 | K2: =IF(J2>=Assumptions!$B$8,"On track",IF(J2>=Assumptions!$B$9,"Watch","Off track")) -> On track | L2: =SUMIFS(Finance!$C$2:$C$25,Finance!$A$2:$A$25,A2) -> 28000000 | M2: =SUMIFS(Finance!$D$2:$D$25,Finance!$A$2:$A$25,A2) -> 19353000 | N2: =IFERROR(M2/L2,0) -> 0.69117857 | O2: =N2/Assumptions!$B$7-J2 -> -0.076327503 | P2: =IF(O2>Assumptions!$B$10,"Spend > delivery",IF(O2<-Assumptions!$B$10,"Delivery > spend","Aligned")) -> Aligned
A3: Siaya | B3: =IFERROR(SUMIFS(Monthly_Results!$D$2:$D$433,Monthly_Results!$B$2:$B$433,$A3,Monthly_Results!$C$2:$C$433,B$1,Monthly_Results!$A$2:$A$433,"<="&Assumptions!$B$4)/(SUMIFS(County_Targets!$C$2:$C$49,County_Targets!$B$2:$B$49,$A3,County_Targets!$A$2:$A$49,B$1)*Assumptions!$B$7),0) -> 0.93262922 | C3: =IFERROR(SUMIFS(Monthly_Results!$D$2:$D$433,Monthly_Results!$B$2:$B$433,$A3,Monthly_Results!$C$2:$C$433,C$1,Monthly_Results!$A$2:$A$433,"<="&Assumptions!$B$4)/(SUMIFS(County_Targets!$C$2:$C$49,County_Targets!$B$2:$B$49,$A3,County_Targets!$A$2:$A$49,C$1)*Assumptions!$B$7),0) -> 1.039886 | D3: =IFERROR(SUMIFS(Monthly_Results!$D$2:$D$433,Monthly_Results!$B$2:$B$433,$A3,Monthly_Results!$C$2:$C$433,D$1,Monthly_Results!$A$2:$A$433,"<="&Assumptions!$B$4)/(SUMIFS(County_Targets!$C$2:$C$49,County_Targets!$B$2:$B$49,$A3,County_Targets!$A$2:$A$49,D$1)*Assumptions!$B$7),0) -> 1.0062135 | E3: =IFERROR(SUMIFS(Monthly_Results!$D$2:$D$433,Monthly_Results!$B$2:$B$433,$A3,Monthly_Results!$C$2:$C$433,E$1,Monthly_Results!$A$2:$A$433,"<="&Assumptions!$B$4)/(SUMIFS(County_Targets!$C$2:$C$49,County_Targets!$B$2:$B$49,$A3,County_Targets!$A$2:$A$49,E$1)*Assumptions!$B$7),0) -> 1.0894044 | F3: =IFERROR(SUMIFS(Monthly_Results!$D$2:$D$433,Monthly_Results!$B$2:$B$433,$A3,Monthly_Results!$C$2:$C$433,F$1,Monthly_Results!$A$2:$A$433,"<="&Assumptions!$B$4)/(SUMIFS(County_Targets!$C$2:$C$49,County_Targets!$B$2:$B$49,$A3,County_Targets!$A$2:$A$49,F$1)*Assumptions!$B$7),0) -> 0.38199895 | G3: =IFERROR(SUMIFS(Monthly_Results!$D$2:$D$433,Monthly_Results!$B$2:$B$433,$A3,Monthly_Results!$C$2:$C$433,G$1,Monthly_Results!$A$2:$A$433,"<="&Assumptions!$B$4)/(SUMIFS(County_Targets!$C$2:$C$49,County_Targets!$B$2:$B$49,$A3,County_Targets!$A$2:$A$49,G$1)*Assumptions!$B$7),0) -> 1.4324961 | H3: =IFERROR(SUMIFS(Monthly_Results!$D$2:$D$433,Monthly_Results!$B$2:$B$433,$A3,Monthly_Results!$C$2:$C$433,H$1,Monthly_Results!$A$2:$A$433,"<="&Assumptions!$B$4)/(SUMIFS(County_Targets!$C$2:$C$49,County_Targets!$B$2:$B$49,$A3,County_Targets!$A$2:$A$49,H$1)*Assumptions!$B$7),0) -> 0.85171619 | I3: =IFERROR(SUMIFS(Monthly_Results!$D$2:$D$433,Monthly_Results!$B$2:$B$433,$A3,Monthly_Results!$C$2:$C$433,I$1,Monthly_Results!$A$2:$A$433,"<="&Assumptions!$B$4)/(SUMIFS(County_Targets!$C$2:$C$49,County_Targets!$B$2:$B$49,$A3,County_Targets!$A$2:$A$49,I$1)*Assumptions!$B$7),0) -> 1.0814815 | J3: =AVERAGE(B3:I3) -> 0.97697824 | K3: =IF(J3>=Assumptions!$B$8,"On track",IF(J3>=Assumptions!$B$9,"Watch","Off track")) -> On track | L3: =SUMIFS(Finance!$C$2:$C$25,Finance!$A$2:$A$25,A3) -> 20000000 | M3: =SUMIFS(Finance!$D$2:$D$25,Finance!$A$2:$A$25,A3) -> 13263000 | N3: =IFERROR(M3/L3,0) -> 0.66315 | O3: =N3/Assumptions!$B$7-J3 -> -0.090349119 | P3: =IF(O3>Assumptions!$B$10,"Spend > delivery",IF(O3<-Assumptions!$B$10,"Delivery > spend","Aligned")) -> Aligned
A4: Homa Bay | B4: =IFERROR(SUMIFS(Monthly_Results!$D$2:$D$433,Monthly_Results!$B$2:$B$433,$A4,Monthly_Results!$C$2:$C$433,B$1,Monthly_Results!$A$2:$A$433,"<="&Assumptions!$B$4)/(SUMIFS(County_Targets!$C$2:$C$49,County_Targets!$B$2:$B$49,$A4,County_Targets!$A$2:$A$49,B$1)*Assumptions!$B$7),0) -> 0.71690239 | C4: =IFERROR(SUMIFS(Monthly_Results!$D$2:$D$433,Monthly_Results!$B$2:$B$433,$A4,Monthly_Results!$C$2:$C$433,C$1,Monthly_Results!$A$2:$A$433,"<="&Assumptions!$B$4)/(SUMIFS(County_Targets!$C$2:$C$49,County_Targets!$B$2:$B$49,$A4,County_Targets!$A$2:$A$49,C$1)*Assumptions!$B$7),0) -> 0.60772561 | D4: =IFERROR(SUMIFS(Monthly_Results!$D$2:$D$433,Monthly_Results!$B$2:$B$433,$A4,Monthly_Results!$C$2:$C$433,D$1,Monthly_Results!$A$2:$A$433,"<="&Assumptions!$B$4)/(SUMIFS(County_Targets!$C$2:$C$49,County_Targets!$B$2:$B$49,$A4,County_Targets!$A$2:$A$49,D$1)*Assumptions!$B$7),0) -> 0.79765862 | E4: =IFERROR(SUMIFS(Monthly_Results!$D$2:$D$433,Monthly_Results!$B$2:$B$433,$A4,Monthly_Results!$C$2:$C$433,E$1,Monthly_Results!$A$2:$A$433,"<="&Assumptions!$B$4)/(SUMIFS(County_Targets!$C$2:$C$49,County_Targets!$B$2:$B$49,$A4,County_Targets!$A$2:$A$49,E$1)*Assumptions!$B$7),0) -> 0.69935193 | F4: =IFERROR(SUMIFS(Monthly_Results!$D$2:$D$433,Monthly_Results!$B$2:$B$433,$A4,Monthly_Results!$C$2:$C$433,F$1,Monthly_Results!$A$2:$A$433,"<="&Assumptions!$B$4)/(SUMIFS(County_Targets!$C$2:$C$49,County_Targets!$B$2:$B$49,$A4,County_Targets!$A$2:$A$49,F$1)*Assumptions!$B$7),0) -> 0.14855515 | G4: =IFERROR(SUMIFS(Monthly_Results!$D$2:$D$433,Monthly_Results!$B$2:$B$433,$A4,Monthly_Results!$C$2:$C$433,G$1,Monthly_Results!$A$2:$A$433,"<="&Assumptions!$B$4)/(SUMIFS(County_Targets!$C$2:$C$49,County_Targets!$B$2:$B$49,$A4,County_Targets!$A$2:$A$49,G$1)*Assumptions!$B$7),0) -> 1.0863095 | H4: =IFERROR(SUMIFS(Monthly_Results!$D$2:$D$433,Monthly_Results!$B$2:$B$433,$A4,Monthly_Results!$C$2:$C$433,H$1,Monthly_Results!$A$2:$A$433,"<="&Assumptions!$B$4)/(SUMIFS(County_Targets!$C$2:$C$49,County_Targets!$B$2:$B$49,$A4,County_Targets!$A$2:$A$49,H$1)*Assumptions!$B$7),0) -> 0.67179939 | I4: =IFERROR(SUMIFS(Monthly_Results!$D$2:$D$433,Monthly_Results!$B$2:$B$433,$A4,Monthly_Results!$C$2:$C$433,I$1,Monthly_Results!$A$2:$A$433,"<="&Assumptions!$B$4)/(SUMIFS(County_Targets!$C$2:$C$49,County_Targets!$B$2:$B$49,$A4,County_Targets!$A$2:$A$49,I$1)*Assumptions!$B$7),0) -> 0.70811287 | J4: =AVERAGE(B4:I4) -> 0.67955194 | K4: =IF(J4>=Assumptions!$B$8,"On track",IF(J4>=Assumptions!$B$9,"Watch","Off track")) -> Off track | L4: =SUMIFS(Finance!$C$2:$C$25,Finance!$A$2:$A$25,A4) -> 24000000 | M4: =SUMIFS(Finance!$D$2:$D$25,Finance!$A$2:$A$25,A4) -> 10959000 | N4: =IFERROR(M4/L4,0) -> 0.456625 | O4: =N4/Assumptions!$B$7-J4 -> -0.069045983 | P4: =IF(O4>Assumptions!$B$10,"Spend > delivery",IF(O4<-Assumptions!$B$10,"Delivery > spend","Aligned")) -> Aligned
A5: Migori | B5: =IFERROR(SUMIFS(Monthly_Results!$D$2:$D$433,Monthly_Results!$B$2:$B$433,$A5,Monthly_Results!$C$2:$C$433,B$1,Monthly_Results!$A$2:$A$433,"<="&Assumptions!$B$4)/(SUMIFS(County_Targets!$C$2:$C$49,County_Targets!$B$2:$B$49,$A5,County_Targets!$A$2:$A$49,B$1)*Assumptions!$B$7),0) -> 0.92891534 | C5: =IFERROR(SUMIFS(Monthly_Results!$D$2:$D$433,Monthly_Results!$B$2:$B$433,$A5,Monthly_Results!$C$2:$C$433,C$1,Monthly_Results!$A$2:$A$433,"<="&Assumptions!$B$4)/(SUMIFS(County_Targets!$C$2:$C$49,County_Targets!$B$2:$B$49,$A5,County_Targets!$A$2:$A$49,C$1)*Assumptions!$B$7),0) -> 0.89133089 | D5: =IFERROR(SUMIFS(Monthly_Results!$D$2:$D$433,Monthly_Results!$B$2:$B$433,$A5,Monthly_Results!$C$2:$C$433,D$1,Monthly_Results!$A$2:$A$433,"<="&Assumptions!$B$4)/(SUMIFS(County_Targets!$C$2:$C$49,County_Targets!$B$2:$B$49,$A5,County_Targets!$A$2:$A$49,D$1)*Assumptions!$B$7),0) -> 0.8972731 | E5: =IFERROR(SUMIFS(Monthly_Results!$D$2:$D$433,Monthly_Results!$B$2:$B$433,$A5,Monthly_Results!$C$2:$C$433,E$1,Monthly_Results!$A$2:$A$433,"<="&Assumptions!$B$4)/(SUMIFS(County_Targets!$C$2:$C$49,County_Targets!$B$2:$B$49,$A5,County_Targets!$A$2:$A$49,E$1)*Assumptions!$B$7),0) -> 0.71801655 | F5: =IFERROR(SUMIFS(Monthly_Results!$D$2:$D$433,Monthly_Results!$B$2:$B$433,$A5,Monthly_Results!$C$2:$C$433,F$1,Monthly_Results!$A$2:$A$433,"<="&Assumptions!$B$4)/(SUMIFS(County_Targets!$C$2:$C$49,County_Targets!$B$2:$B$49,$A5,County_Targets!$A$2:$A$49,F$1)*Assumptions!$B$7),0) -> 0.57299843 | G5: =IFERROR(SUMIFS(Monthly_Results!$D$2:$D$433,Monthly_Results!$B$2:$B$433,$A5,Monthly_Results!$C$2:$C$433,G$1,Monthly_Results!$A$2:$A$433,"<="&Assumptions!$B$4)/(SUMIFS(County_Targets!$C$2:$C$49,County_Targets!$B$2:$B$49,$A5,County_Targets!$A$2:$A$49,G$1)*Assumptions!$B$7),0) -> 0.66849817 | H5: =IFERROR(SUMIFS(Monthly_Results!$D$2:$D$433,Monthly_Results!$B$2:$B$433,$A5,Monthly_Results!$C$2:$C$433,H$1,Monthly_Results!$A$2:$A$433,"<="&Assumptions!$B$4)/(SUMIFS(County_Targets!$C$2:$C$49,County_Targets!$B$2:$B$49,$A5,County_Targets!$A$2:$A$49,H$1)*Assumptions!$B$7),0) -> 0.81606295 | I5: =IFERROR(SUMIFS(Monthly_Results!$D$2:$D$433,Monthly_Results!$B$2:$B$433,$A5,Monthly_Results!$C$2:$C$433,I$1,Monthly_Results!$A$2:$A$433,"<="&Assumptions!$B$4)/(SUMIFS(County_Targets!$C$2:$C$49,County_Targets!$B$2:$B$49,$A5,County_Targets!$A$2:$A$49,I$1)*Assumptions!$B$7),0) -> 0.98046398 | J5: =AVERAGE(B5:I5) -> 0.80919493 | K5: =IF(J5>=Assumptions!$B$8,"On track",IF(J5>=Assumptions!$B$9,"Watch","Off track")) -> Watch | L5: =SUMIFS(Finance!$C$2:$C$25,Finance!$A$2:$A$25,A5) -> 21000000 | M5: =SUMIFS(Finance!$D$2:$D$25,Finance!$A$2:$A$25,A5) -> 14259000 | N5: =IFERROR(M5/L5,0) -> 0.679 | O5: =N5/Assumptions!$B$7-J5 -> 0.098625586 | P5: =IF(O5>Assumptions!$B$10,"Spend > delivery",IF(O5<-Assumptions!$B$10,"Delivery > spend","Aligned")) -> Aligned
A6: Kakamega | B6: =IFERROR(SUMIFS(Monthly_Results!$D$2:$D$433,Monthly_Results!$B$2:$B$433,$A6,Monthly_Results!$C$2:$C$433,B$1,Monthly_Results!$A$2:$A$433,"<="&Assumptions!$B$4)/(SUMIFS(County_Targets!$C$2:$C$49,County_Targets!$B$2:$B$49,$A6,County_Targets!$A$2:$A$49,B$1)*Assumptions!$B$7),0) -> 1.0730051 | C6: =IFERROR(SUMIFS(Monthly_Results!$D$2:$D$433,Monthly_Results!$B$2:$B$433,$A6,Monthly_Results!$C$2:$C$433,C$1,Monthly_Results!$A$2:$A$433,"<="&Assumptions!$B$4)/(SUMIFS(County_Targets!$C$2:$C$49,County_Targets!$B$2:$B$49,$A6,County_Targets!$A$2:$A$49,C$1)*Assumptions!$B$7),0) -> 0.8021978 | D6: =IFERROR(SUMIFS(Monthly_Results!$D$2:$D$433,Monthly_Results!$B$2:$B$433,$A6,Monthly_Results!$C$2:$C$433,D$1,Monthly_Results!$A$2:$A$433,"<="&Assumptions!$B$4)/(SUMIFS(County_Targets!$C$2:$C$49,County_Targets!$B$2:$B$49,$A6,County_Targets!$A$2:$A$49,D$1)*Assumptions!$B$7),0) -> 1.1255237 | E6: =IFERROR(SUMIFS(Monthly_Results!$D$2:$D$433,Monthly_Results!$B$2:$B$433,$A6,Monthly_Results!$C$2:$C$433,E$1,Monthly_Results!$A$2:$A$433,"<="&Assumptions!$B$4)/(SUMIFS(County_Targets!$C$2:$C$49,County_Targets!$B$2:$B$49,$A6,County_Targets!$A$2:$A$49,E$1)*Assumptions!$B$7),0) -> 1.3150784 | F6: =IFERROR(SUMIFS(Monthly_Results!$D$2:$D$433,Monthly_Results!$B$2:$B$433,$A6,Monthly_Results!$C$2:$C$433,F$1,Monthly_Results!$A$2:$A$433,"<="&Assumptions!$B$4)/(SUMIFS(County_Targets!$C$2:$C$49,County_Targets!$B$2:$B$49,$A6,County_Targets!$A$2:$A$49,F$1)*Assumptions!$B$7),0) -> 0.16712454 | G6: =IFERROR(SUMIFS(Monthly_Results!$D$2:$D$433,Monthly_Results!$B$2:$B$433,$A6,Monthly_Results!$C$2:$C$433,G$1,Monthly_Results!$A$2:$A$433,"<="&Assumptions!$B$4)/(SUMIFS(County_Targets!$C$2:$C$49,County_Targets!$B$2:$B$49,$A6,County_Targets!$A$2:$A$49,G$1)*Assumptions!$B$7),0) -> 0.62393162 | H6: =IFERROR(SUMIFS(Monthly_Results!$D$2:$D$433,Monthly_Results!$B$2:$B$433,$A6,Monthly_Results!$C$2:$C$433,H$1,Monthly_Results!$A$2:$A$433,"<="&Assumptions!$B$4)/(SUMIFS(County_Targets!$C$2:$C$49,County_Targets!$B$2:$B$49,$A6,County_Targets!$A$2:$A$49,H$1)*Assumptions!$B$7),0) -> 0.93240202 | I6: =IFERROR(SUMIFS(Monthly_Results!$D$2:$D$433,Monthly_Results!$B$2:$B$433,$A6,Monthly_Results!$C$2:$C$433,I$1,Monthly_Results!$A$2:$A$433,"<="&Assumptions!$B$4)/(SUMIFS(County_Targets!$C$2:$C$49,County_Targets!$B$2:$B$49,$A6,County_Targets!$A$2:$A$49,I$1)*Assumptions!$B$7),0) -> 1.153487 | J6: =AVERAGE(B6:I6) -> 0.89909378 | K6: =IF(J6>=Assumptions!$B$8,"On track",IF(J6>=Assumptions!$B$9,"Watch","Off track")) -> Watch | L6: =SUMIFS(Finance!$C$2:$C$25,Finance!$A$2:$A$25,A6) -> 23000000 | M6: =SUMIFS(Finance!$D$2:$D$25,Finance!$A$2:$A$25,A6) -> 16573000 | N6: =IFERROR(M6/L6,0) -> 0.72056522 | O6: =N6/Assumptions!$B$7-J6 -> 0.064299281 | P6: =IF(O6>Assumptions!$B$10,"Spend > delivery",IF(O6<-Assumptions!$B$10,"Delivery > spend","Aligned")) -> Aligned
A7: Bungoma | B7: =IFERROR(SUMIFS(Monthly_Results!$D$2:$D$433,Monthly_Results!$B$2:$B$433,$A7,Monthly_Results!$C$2:$C$433,B$1,Monthly_Results!$A$2:$A$433,"<="&Assumptions!$B$4)/(SUMIFS(County_Targets!$C$2:$C$49,County_Targets!$B$2:$B$49,$A7,County_Targets!$A$2:$A$49,B$1)*Assumptions!$B$7),0) -> 0.67533171 | C7: =IFERROR(SUMIFS(Monthly_Results!$D$2:$D$433,Monthly_Results!$B$2:$B$433,$A7,Monthly_Results!$C$2:$C$433,C$1,Monthly_Results!$A$2:$A$433,"<="&Assumptions!$B$4)/(SUMIFS(County_Targets!$C$2:$C$49,County_Targets!$B$2:$B$49,$A7,County_Targets!$A$2:$A$49,C$1)*Assumptions!$B$7),0) -> 0.44566545 | D7: =IFERROR(SUMIFS(Monthly_Results!$D$2:$D$433,Monthly_Results!$B$2:$B$433,$A7,Monthly_Results!$C$2:$C$433,D$1,Monthly_Results!$A$2:$A$433,"<="&Assumptions!$B$4)/(SUMIFS(County_Targets!$C$2:$C$49,County_Targets!$B$2:$B$49,$A7,County_Targets!$A$2:$A$49,D$1)*Assumptions!$B$7),0) -> 0.68681997 | E7: =IFERROR(SUMIFS(Monthly_Results!$D$2:$D$433,Monthly_Results!$B$2:$B$433,$A7,Monthly_Results!$C$2:$C$433,E$1,Monthly_Results!$A$2:$A$433,"<="&Assumptions!$B$4)/(SUMIFS(County_Targets!$C$2:$C$49,County_Targets!$B$2:$B$49,$A7,County_Targets!$A$2:$A$49,E$1)*Assumptions!$B$7),0) -> 0.42090625 | F7: =IFERROR(SUMIFS(Monthly_Results!$D$2:$D$433,Monthly_Results!$B$2:$B$433,$A7,Monthly_Results!$C$2:$C$433,F$1,Monthly_Results!$A$2:$A$433,"<="&Assumptions!$B$4)/(SUMIFS(County_Targets!$C$2:$C$49,County_Targets!$B$2:$B$49,$A7,County_Targets!$A$2:$A$49,F$1)*Assumptions!$B$7),0) -> 0.19099948 | G7: =IFERROR(SUMIFS(Monthly_Results!$D$2:$D$433,Monthly_Results!$B$2:$B$433,$A7,Monthly_Results!$C$2:$C$433,G$1,Monthly_Results!$A$2:$A$433,"<="&Assumptions!$B$4)/(SUMIFS(County_Targets!$C$2:$C$49,County_Targets!$B$2:$B$49,$A7,County_Targets!$A$2:$A$49,G$1)*Assumptions!$B$7),0) -> 0.82276698 | H7: =IFERROR(SUMIFS(Monthly_Results!$D$2:$D$433,Monthly_Results!$B$2:$B$433,$A7,Monthly_Results!$C$2:$C$433,H$1,Monthly_Results!$A$2:$A$433,"<="&Assumptions!$B$4)/(SUMIFS(County_Targets!$C$2:$C$49,County_Targets!$B$2:$B$49,$A7,County_Targets!$A$2:$A$49,H$1)*Assumptions!$B$7),0) -> 0.58926876 | I7: =IFERROR(SUMIFS(Monthly_Results!$D$2:$D$433,Monthly_Results!$B$2:$B$433,$A7,Monthly_Results!$C$2:$C$433,I$1,Monthly_Results!$A$2:$A$433,"<="&Assumptions!$B$4)/(SUMIFS(County_Targets!$C$2:$C$49,County_Targets!$B$2:$B$49,$A7,County_Targets!$A$2:$A$49,I$1)*Assumptions!$B$7),0) -> 0.76654457 | J7: =AVERAGE(B7:I7) -> 0.57478789 | K7: =IF(J7>=Assumptions!$B$8,"On track",IF(J7>=Assumptions!$B$9,"Watch","Off track")) -> Off track | L7: =SUMIFS(Finance!$C$2:$C$25,Finance!$A$2:$A$25,A7) -> 20000000 | M7: =SUMIFS(Finance!$D$2:$D$25,Finance!$A$2:$A$25,A7) -> 14438000 | N7: =IFERROR(M7/L7,0) -> 0.7219 | O7: =N7/Assumptions!$B$7-J7 -> 0.39038976 | P7: =IF(O7>Assumptions!$B$10,"Spend > delivery",IF(O7<-Assumptions!$B$10,"Delivery > spend","Aligned")) -> Spend > delivery

Sheet Survey_Data
A1: County | B1: OutcomeID | C1: Baseline | D1: Midline | E1: Target
A2: Kisumu | B2: OC1 | C2: 0.281 | D2: 0.451 | E2: 0.6
A3: Kisumu | B3: OC2 | C3: 0.243 | D3: 0.408 | E3: 0.55
A4: Kisumu | B4: OC3 | C4: 0.61 | D4: 0.724 | E4: 0.85
A5: Siaya | B5: OC1 | C5: 0.28 | D5: 0.431 | E5: 0.6
A6: Siaya | B6: OC2 | C6: 0.197 | D6: 0.367 | E6: 0.55
A7: Siaya | B7: OC3 | C7: 0.63 | D7: 0.745 | E7: 0.85
A8: Homa Bay | B8: OC1 | C8: 0.314 | D8: 0.398 | E8: 0.6
A9: Homa Bay | B9: OC2 | C9: 0.221 | D9: 0.375 | E9: 0.55
A10: Homa Bay | B10: OC3 | C10: 0.589 | D10: 0.67 | E10: 0.85
A11: Migori | B11: OC1 | C11: 0.265 | D11: 0.431 | E11: 0.6
A12: Migori | B12: OC2 | C12: 0.223 | D12: 0.402 | E12: 0.55
A13: Migori | B13: OC3 | C13: 0.567 | D13: 0.693 | E13: 0.85
... A19: Bungoma | B19: OC3 | C19: 0.633 | D19: 0.713 | E19: 0.85

Sheet Finance
A1: County | B1: Quarter | C1: Budget (KES) | D1: Spent (KES)
A2: Kisumu | B2: Q1 | C2: 7000000 | D2: 6763000
A3: Kisumu | B3: Q2 | C3: 7000000 | D3: 6331000
A4: Kisumu | B4: Q3 | C4: 7000000 | D4: 6259000
A5: Kisumu | B5: Q4 | C5: 7000000 | D5: 0
A6: Siaya | B6: Q1 | C6: 5000000 | D6: 4373000
A7: Siaya | B7: Q2 | C7: 5000000 | D7: 4322000
A8: Siaya | B8: Q3 | C8: 5000000 | D8: 4568000
A9: Siaya | B9: Q4 | C9: 5000000 | D9: 0
A10: Homa Bay | B10: Q1 | C10: 6000000 | D10: 3544000
A11: Homa Bay | B11: Q2 | C11: 6000000 | D11: 3548000
A12: Homa Bay | B12: Q3 | C12: 6000000 | D12: 3867000
A13: Homa Bay | B13: Q4 | C13: 6000000 | D13: 0
... A25: Bungoma | B25: Q4 | C25: 5000000 | D25: 0

Sheet County_Targets
A1: IndicatorID | B1: County | C1: Annual target
A2: O1 | B2: Kisumu | C2: 12000
A3: O1 | B3: Siaya | C3: 9000
A4: O1 | B4: Homa Bay | C4: 10800
A5: O1 | B5: Migori | C5: 9000
A6: O1 | B6: Kakamega | C6: 10200
A7: O1 | B7: Bungoma | C7: 9000
A8: O2 | B8: Kisumu | C8: 24
A9: O2 | B9: Siaya | C9: 18
A10: O2 | B10: Homa Bay | C10: 22
A11: O2 | B11: Migori | C11: 18
A12: O2 | B12: Kakamega | C12: 20
A13: O2 | B13: Bungoma | C13: 18
... A49: O8 | B49: Bungoma | C49: 225

Sheet Monthly_Results
A1: Month | B1: County | C1: IndicatorID | D1: Actual
A2: 46023 | B2: Kisumu | C2: O1 | D2: 589
A3: 46054 | B3: Kisumu | C3: O1 | D3: 824
A4: 46082 | B4: Kisumu | C4: O1 | D4: 948
A5: 46113 | B5: Kisumu | C5: O1 | D5: 1050
A6: 46143 | B6: Kisumu | C6: O1 | D6: 1094
A7: 46174 | B7: Kisumu | C7: O1 | D7: 1189
A8: 46204 | B8: Kisumu | C8: O1 | D8: 1148
A9: 46235 | B9: Kisumu | C9: O1 | D9: 1207
A10: 46266 | B10: Kisumu | C10: O1 | D10: 1298
A11: 46023 | B11: Kisumu | C11: O2 | D11: 1
A12: 46054 | B12: Kisumu | C12: O2 | D12: 2
A13: 46082 | B13: Kisumu | C13: O2 | D13: 0
... A433: 46266 | B433: Bungoma | C433: O8 | D433: 13
