Workbook

Sheet README
A1: HR Workforce & Attrition Analytics
A3: Business scenario | B3: A mid-sized Kenyan company has rising staff turnover. HR needs to know the attrition rate, which departments and tenure bands lose people, why they leave, and what turnover costs.
A5: Sheets | B5: Assumptions: as-of date, 12-month window, replacement-cost multiplier, attrition and absenteeism targets.
B6: Employees: 300 synthetic staff records (inputs) plus formula columns for status, tenure, 12-month leaver flag and replacement cost.
B7: Dashboard: headcount, attrition rate, regrettable losses, cost of turnover, tables by department, tenure band and exit reason, and charts.
A9: Colour legend | B9: Blue text on yellow = editable input (Assumptions sheet).
B10: Blue header on Data sheet = raw input columns; green header = formula columns (do not overwrite).
B11: Black text = formula. Everything on the Dashboard recalculates when Assumptions or Data change.
A13: Data note | B13: All data is SYNTHETIC, generated for portfolio demonstration. Targets and thresholds are illustrative. Not client data.
A15: Skills demonstrated | B15: HR metrics (attrition, tenure, absenteeism)
B16: Date logic and helper flags
B17: AVERAGEIFS / COUNTIFS / SUMIFS
B18: Cost-of-turnover modelling
B19: Dashboard design

Sheet Dashboard
A1: HR Workforce & Attrition Dashboard
A2: Synthetic data | KES | 12-month window ending on the as-of date
A4: Key metrics
A5: Active headcount | B5: =COUNTIFS(Employees!$K$2:$K$301,"Active") -> 224
A6: Headcount at window start | B6: =SUM(Employees!$O$2:$O$301) -> 260
A7: Leavers in last 12 months | B7: =SUM(Employees!$P$2:$P$301) -> 62
A8: Annual attrition rate | B8: =IF((B5+B6)=0,0,B7/AVERAGE(B5,B6)) -> 0.25619835
A9: Attrition vs target | B9: =IF(B8<=Assumptions!$B$8,"Within target","Above target") -> Above target
A10: Regrettable leavers | B10: =SUM(Employees!$R$2:$R$301) -> 23
A11: Replacement cost of leavers (KES) | B11: =SUM(Employees!$Q$2:$Q$301) -> 34398000
A12: Annual payroll, active staff (KES) | B12: =SUMIFS(Employees!$N$2:$N$301,Employees!$K$2:$K$301,"Active") -> 239040000
A13: Avg days absent, active staff | B13: =AVERAGEIFS(Employees!$I$2:$I$301,Employees!$K$2:$K$301,"Active") -> 5.7008929
A15: Insights (auto-updating)
A16: Highest-attrition department | B16: =INDEX(A22:A27,MATCH(MAX(E22:E27),E22:E27,0)) -> IT
A17: Top exit reason | B17: =INDEX(A40:A46,MATCH(MAX(B40:B46),B40:B46,0)) -> Better pay elsewhere
A18: Share of leavers with under 1 yr tenure | B18: =D32 -> 0.12903226
A20: By department
A21: Department | B21: Active now | C21: Active at start | D21: Leavers 12m | E21: Attrition % | F21: Avg days absent | G21: Avg monthly salary (KES) | H21: Replacement cost (KES) | I21: Regrettable leavers | J21: vs target
A22: Sales | B22: =COUNTIFS(Employees!$B$2:$B$301,$A22,Employees!$K$2:$K$301,"Active") -> 50 | C22: =SUMIFS(Employees!$O$2:$O$301,Employees!$B$2:$B$301,$A22) -> 59 | D22: =SUMIFS(Employees!$P$2:$P$301,Employees!$B$2:$B$301,$A22) -> 16 | E22: =IF((B22+C22)=0,0,D22/AVERAGE(B22,C22)) -> 0.29357798 | F22: =IFERROR(AVERAGEIFS(Employees!$I$2:$I$301,Employees!$B$2:$B$301,$A22,Employees!$K$2:$K$301,"Active"),0) -> 4.88 | G22: =IFERROR(AVERAGEIFS(Employees!$H$2:$H$301,Employees!$B$2:$B$301,$A22,Employees!$K$2:$K$301,"Active"),0) -> 84880 | H22: =SUMIFS(Employees!$Q$2:$Q$301,Employees!$B$2:$B$301,$A22) -> 9540000 | I22: =SUMIFS(Employees!$R$2:$R$301,Employees!$B$2:$B$301,$A22) -> 9 | J22: =IF(E22<=Assumptions!$B$8,"OK","Above target") -> Above target
A23: Operations | B23: =COUNTIFS(Employees!$B$2:$B$301,$A23,Employees!$K$2:$K$301,"Active") -> 48 | C23: =SUMIFS(Employees!$O$2:$O$301,Employees!$B$2:$B$301,$A23) -> 53 | D23: =SUMIFS(Employees!$P$2:$P$301,Employees!$B$2:$B$301,$A23) -> 9 | E23: =IF((B23+C23)=0,0,D23/AVERAGE(B23,C23)) -> 0.17821782 | F23: =IFERROR(AVERAGEIFS(Employees!$I$2:$I$301,Employees!$B$2:$B$301,$A23,Employees!$K$2:$K$301,"Active"),0) -> 4.7291667 | G23: =IFERROR(AVERAGEIFS(Employees!$H$2:$H$301,Employees!$B$2:$B$301,$A23,Employees!$K$2:$K$301,"Active"),0) -> 83583.333 | H23: =SUMIFS(Employees!$Q$2:$Q$301,Employees!$B$2:$B$301,$A23) -> 4260000 | I23: =SUMIFS(Employees!$R$2:$R$301,Employees!$B$2:$B$301,$A23) -> 1 | J23: =IF(E23<=Assumptions!$B$8,"OK","Above target") -> Above target
A24: Finance | B24: =COUNTIFS(Employees!$B$2:$B$301,$A24,Employees!$K$2:$K$301,"Active") -> 29 | C24: =SUMIFS(Employees!$O$2:$O$301,Employees!$B$2:$B$301,$A24) -> 30 | D24: =SUMIFS(Employees!$P$2:$P$301,Employees!$B$2:$B$301,$A24) -> 4 | E24: =IF((B24+C24)=0,0,D24/AVERAGE(B24,C24)) -> 0.13559322 | F24: =IFERROR(AVERAGEIFS(Employees!$I$2:$I$301,Employees!$B$2:$B$301,$A24,Employees!$K$2:$K$301,"Active"),0) -> 5.6896552 | G24: =IFERROR(AVERAGEIFS(Employees!$H$2:$H$301,Employees!$B$2:$B$301,$A24,Employees!$K$2:$K$301,"Active"),0) -> 96655.172 | H24: =SUMIFS(Employees!$Q$2:$Q$301,Employees!$B$2:$B$301,$A24) -> 1698000 | I24: =SUMIFS(Employees!$R$2:$R$301,Employees!$B$2:$B$301,$A24) -> 1 | J24: =IF(E24<=Assumptions!$B$8,"OK","Above target") -> OK
A25: IT | B25: =COUNTIFS(Employees!$B$2:$B$301,$A25,Employees!$K$2:$K$301,"Active") -> 22 | C25: =SUMIFS(Employees!$O$2:$O$301,Employees!$B$2:$B$301,$A25) -> 35 | D25: =SUMIFS(Employees!$P$2:$P$301,Employees!$B$2:$B$301,$A25) -> 15 | E25: =IF((B25+C25)=0,0,D25/AVERAGE(B25,C25)) -> 0.52631579 | F25: =IFERROR(AVERAGEIFS(Employees!$I$2:$I$301,Employees!$B$2:$B$301,$A25,Employees!$K$2:$K$301,"Active"),0) -> 4.5454545 | G25: =IFERROR(AVERAGEIFS(Employees!$H$2:$H$301,Employees!$B$2:$B$301,$A25,Employees!$K$2:$K$301,"Active"),0) -> 91272.727 | H25: =SUMIFS(Employees!$Q$2:$Q$301,Employees!$B$2:$B$301,$A25) -> 9456000 | I25: =SUMIFS(Employees!$R$2:$R$301,Employees!$B$2:$B$301,$A25) -> 7 | J25: =IF(E25<=Assumptions!$B$8,"OK","Above target") -> Above target
A26: HR | B26: =COUNTIFS(Employees!$B$2:$B$301,$A26,Employees!$K$2:$K$301,"Active") -> 14 | C26: =SUMIFS(Employees!$O$2:$O$301,Employees!$B$2:$B$301,$A26) -> 15 | D26: =SUMIFS(Employees!$P$2:$P$301,Employees!$B$2:$B$301,$A26) -> 1 | E26: =IF((B26+C26)=0,0,D26/AVERAGE(B26,C26)) -> 0.068965517 | F26: =IFERROR(AVERAGEIFS(Employees!$I$2:$I$301,Employees!$B$2:$B$301,$A26,Employees!$K$2:$K$301,"Active"),0) -> 5.1428571 | G26: =IFERROR(AVERAGEIFS(Employees!$H$2:$H$301,Employees!$B$2:$B$301,$A26,Employees!$K$2:$K$301,"Active"),0) -> 99928.571 | H26: =SUMIFS(Employees!$Q$2:$Q$301,Employees!$B$2:$B$301,$A26) -> 996000 | I26: =SUMIFS(Employees!$R$2:$R$301,Employees!$B$2:$B$301,$A26) -> 1 | J26: =IF(E26<=Assumptions!$B$8,"OK","Above target") -> OK
A27: Customer Service | B27: =COUNTIFS(Employees!$B$2:$B$301,$A27,Employees!$K$2:$K$301,"Active") -> 61 | C27: =SUMIFS(Employees!$O$2:$O$301,Employees!$B$2:$B$301,$A27) -> 68 | D27: =SUMIFS(Employees!$P$2:$P$301,Employees!$B$2:$B$301,$A27) -> 17 | E27: =IF((B27+C27)=0,0,D27/AVERAGE(B27,C27)) -> 0.26356589 | F27: =IFERROR(AVERAGEIFS(Employees!$I$2:$I$301,Employees!$B$2:$B$301,$A27,Employees!$K$2:$K$301,"Active"),0) -> 7.6885246 | G27: =IFERROR(AVERAGEIFS(Employees!$H$2:$H$301,Employees!$B$2:$B$301,$A27,Employees!$K$2:$K$301,"Active"),0) -> 89409.836 | H27: =SUMIFS(Employees!$Q$2:$Q$301,Employees!$B$2:$B$301,$A27) -> 8448000 | I27: =SUMIFS(Employees!$R$2:$R$301,Employees!$B$2:$B$301,$A27) -> 4 | J27: =IF(E27<=Assumptions!$B$8,"OK","Above target") -> Above target
A30: Leavers by tenure band
A31: Tenure band | B31: Active now | C31: Leavers 12m | D31: Share of leavers
A32: Under 1 yr | B32: =COUNTIFS(Employees!$M$2:$M$301,$A32,Employees!$K$2:$K$301,"Active") -> 20 | C32: =COUNTIFS(Employees!$M$2:$M$301,$A32,Employees!$P$2:$P$301,1) -> 8 | D32: =IF(SUM(C$32:C$35)=0,0,C32/SUM(C$32:C$35)) -> 0.12903226
A33: 1 to 3 yrs | B33: =COUNTIFS(Employees!$M$2:$M$301,$A33,Employees!$K$2:$K$301,"Active") -> 39 | C33: =COUNTIFS(Employees!$M$2:$M$301,$A33,Employees!$P$2:$P$301,1) -> 10 | D33: =IF(SUM(C$32:C$35)=0,0,C33/SUM(C$32:C$35)) -> 0.16129032
A34: 3 to 5 yrs | B34: =COUNTIFS(Employees!$M$2:$M$301,$A34,Employees!$K$2:$K$301,"Active") -> 38 | C34: =COUNTIFS(Employees!$M$2:$M$301,$A34,Employees!$P$2:$P$301,1) -> 7 | D34: =IF(SUM(C$32:C$35)=0,0,C34/SUM(C$32:C$35)) -> 0.11290323
A35: 5+ yrs | B35: =COUNTIFS(Employees!$M$2:$M$301,$A35,Employees!$K$2:$K$301,"Active") -> 127 | C35: =COUNTIFS(Employees!$M$2:$M$301,$A35,Employees!$P$2:$P$301,1) -> 37 | D35: =IF(SUM(C$32:C$35)=0,0,C35/SUM(C$32:C$35)) -> 0.59677419
A38: Exit reasons (last 12 months)
A39: Reason | B39: Leavers | C39: Share
A40: Better pay elsewhere | B40: =COUNTIFS(Employees!$G$2:$G$301,$A40,Employees!$P$2:$P$301,1) -> 18 | C40: =IF(SUM(B$40:B$46)=0,0,B40/SUM(B$40:B$46)) -> 0.29032258
A41: Career growth | B41: =COUNTIFS(Employees!$G$2:$G$301,$A41,Employees!$P$2:$P$301,1) -> 16 | C41: =IF(SUM(B$40:B$46)=0,0,B41/SUM(B$40:B$46)) -> 0.25806452
A42: Relocation | B42: =COUNTIFS(Employees!$G$2:$G$301,$A42,Employees!$P$2:$P$301,1) -> 5 | C42: =IF(SUM(B$40:B$46)=0,0,B42/SUM(B$40:B$46)) -> 0.080645161
A43: Personal / family | B43: =COUNTIFS(Employees!$G$2:$G$301,$A43,Employees!$P$2:$P$301,1) -> 9 | C43: =IF(SUM(B$40:B$46)=0,0,B43/SUM(B$40:B$46)) -> 0.14516129
A44: Poor management | B44: =COUNTIFS(Employees!$G$2:$G$301,$A44,Employees!$P$2:$P$301,1) -> 6 | C44: =IF(SUM(B$40:B$46)=0,0,B44/SUM(B$40:B$46)) -> 0.096774194
A45: Contract ended | B45: =COUNTIFS(Employees!$G$2:$G$301,$A45,Employees!$P$2:$P$301,1) -> 7 | C45: =IF(SUM(B$40:B$46)=0,0,B45/SUM(B$40:B$46)) -> 0.11290323
A46: Dismissal | B46: =COUNTIFS(Employees!$G$2:$G$301,$A46,Employees!$P$2:$P$301,1) -> 1 | C46: =IF(SUM(B$40:B$46)=0,0,B46/SUM(B$40:B$46)) -> 0.016129032

Sheet Assumptions
A1: Assumptions (edit the yellow cells)
A4: Parameter | B4: Value | C4: Note
A5: As-of date | B5: 46295 | C5: Reporting date for headcount and tenure.
A6: 12-month window start | B6: =B5-365 -> 45930 | C6: Formula: as-of date minus 365 days.
A7: Replacement cost (% of annual salary) | B7: 0.5 | C7: Illustrative: recruitment, onboarding and lost productivity.
A8: Target annual attrition | B8: 0.15 | C8: Illustrative target.
A9: Absenteeism target (days / person / year) | B9: 6 | C9: Illustrative target.
A10: Regrettable-loss rating threshold (>=) | B10: 4 | C10: Leavers rated at or above this count as regrettable.

Sheet Employees
A1: Employee ID | B1: Department | C1: Level | D1: Gender | E1: Hire date | F1: Exit date | G1: Exit reason | H1: Monthly salary (KES) | I1: Days absent (12m) | J1: Performance rating (1-5) | K1: Status | L1: Tenure (years) | M1: Tenure band | N1: Annual salary (KES) | O1: Active at window start | P1: Left in window | Q1: Replacement cost (KES) | R1: Regrettable loss
A2: EMP2001 | B2: Customer Service | C2: Junior | D2: M | E2: 42198 | H2: 57000 | I2: 11 | J2: 4 | K2: =IF(F2="","Active","Left") -> Active | L2: =ROUND((IF(F2="",Assumptions!$B$5,F2)-E2)/365.25,1) -> 11.2 | M2: =IF(L2<1,"Under 1 yr",IF(L2<3,"1 to 3 yrs",IF(L2<5,"3 to 5 yrs","5+ yrs"))) -> 5+ yrs | N2: =H2*12 -> 684000 | O2: =IF(AND(E2<Assumptions!$B$6,OR(F2="",F2>=Assumptions!$B$6)),1,0) -> 1 | P2: =IF(F2="",0,IF(AND(F2>=Assumptions!$B$6,F2<=Assumptions!$B$5),1,0)) -> 0 | Q2: =P2*N2*Assumptions!$B$7 -> 0 | R2: =IF(AND(P2=1,J2>=Assumptions!$B$10),1,0) -> 0
A3: EMP2002 | B3: Sales | C3: Junior | D3: M | E3: 42411 | H3: 52000 | I3: 7 | J3: 4 | K3: =IF(F3="","Active","Left") -> Active | L3: =ROUND((IF(F3="",Assumptions!$B$5,F3)-E3)/365.25,1) -> 10.6 | M3: =IF(L3<1,"Under 1 yr",IF(L3<3,"1 to 3 yrs",IF(L3<5,"3 to 5 yrs","5+ yrs"))) -> 5+ yrs | N3: =H3*12 -> 624000 | O3: =IF(AND(E3<Assumptions!$B$6,OR(F3="",F3>=Assumptions!$B$6)),1,0) -> 1 | P3: =IF(F3="",0,IF(AND(F3>=Assumptions!$B$6,F3<=Assumptions!$B$5),1,0)) -> 0 | Q3: =P3*N3*Assumptions!$B$7 -> 0 | R3: =IF(AND(P3=1,J3>=Assumptions!$B$10),1,0) -> 0
A4: EMP2003 | B4: Sales | C4: Senior | D4: F | E4: 44167 | H4: 124000 | I4: 0 | J4: 4 | K4: =IF(F4="","Active","Left") -> Active | L4: =ROUND((IF(F4="",Assumptions!$B$5,F4)-E4)/365.25,1) -> 5.8 | M4: =IF(L4<1,"Under 1 yr",IF(L4<3,"1 to 3 yrs",IF(L4<5,"3 to 5 yrs","5+ yrs"))) -> 5+ yrs | N4: =H4*12 -> 1488000 | O4: =IF(AND(E4<Assumptions!$B$6,OR(F4="",F4>=Assumptions!$B$6)),1,0) -> 1 | P4: =IF(F4="",0,IF(AND(F4>=Assumptions!$B$6,F4<=Assumptions!$B$5),1,0)) -> 0 | Q4: =P4*N4*Assumptions!$B$7 -> 0 | R4: =IF(AND(P4=1,J4>=Assumptions!$B$10),1,0) -> 0
A5: EMP2004 | B5: IT | C5: Junior | D5: F | E5: 45225 | H5: 55000 | I5: 1 | J5: 3 | K5: =IF(F5="","Active","Left") -> Active | L5: =ROUND((IF(F5="",Assumptions!$B$5,F5)-E5)/365.25,1) -> 2.9 | M5: =IF(L5<1,"Under 1 yr",IF(L5<3,"1 to 3 yrs",IF(L5<5,"3 to 5 yrs","5+ yrs"))) -> 1 to 3 yrs | N5: =H5*12 -> 660000 | O5: =IF(AND(E5<Assumptions!$B$6,OR(F5="",F5>=Assumptions!$B$6)),1,0) -> 1 | P5: =IF(F5="",0,IF(AND(F5>=Assumptions!$B$6,F5<=Assumptions!$B$5),1,0)) -> 0 | Q5: =P5*N5*Assumptions!$B$7 -> 0 | R5: =IF(AND(P5=1,J5>=Assumptions!$B$10),1,0) -> 0
A6: EMP2005 | B6: Operations | C6: Officer | D6: M | E6: 45543 | F6: 46202 | G6: Contract ended | H6: 86000 | I6: 8 | J6: 3 | K6: =IF(F6="","Active","Left") -> Left | L6: =ROUND((IF(F6="",Assumptions!$B$5,F6)-E6)/365.25,1) -> 1.8 | M6: =IF(L6<1,"Under 1 yr",IF(L6<3,"1 to 3 yrs",IF(L6<5,"3 to 5 yrs","5+ yrs"))) -> 1 to 3 yrs | N6: =H6*12 -> 1032000 | O6: =IF(AND(E6<Assumptions!$B$6,OR(F6="",F6>=Assumptions!$B$6)),1,0) -> 1 | P6: =IF(F6="",0,IF(AND(F6>=Assumptions!$B$6,F6<=Assumptions!$B$5),1,0)) -> 1 | Q6: =P6*N6*Assumptions!$B$7 -> 516000 | R6: =IF(AND(P6=1,J6>=Assumptions!$B$10),1,0) -> 0
A7: EMP2006 | B7: Customer Service | C7: Junior | D7: M | E7: 45066 | F7: 45755 | G7: Personal / family | H7: 52000 | I7: 6 | J7: 4 | K7: =IF(F7="","Active","Left") -> Left | L7: =ROUND((IF(F7="",Assumptions!$B$5,F7)-E7)/365.25,1) -> 1.9 | M7: =IF(L7<1,"Under 1 yr",IF(L7<3,"1 to 3 yrs",IF(L7<5,"3 to 5 yrs","5+ yrs"))) -> 1 to 3 yrs | N7: =H7*12 -> 624000 | O7: =IF(AND(E7<Assumptions!$B$6,OR(F7="",F7>=Assumptions!$B$6)),1,0) -> 0 | P7: =IF(F7="",0,IF(AND(F7>=Assumptions!$B$6,F7<=Assumptions!$B$5),1,0)) -> 0 | Q7: =P7*N7*Assumptions!$B$7 -> 0 | R7: =IF(AND(P7=1,J7>=Assumptions!$B$10),1,0) -> 0
A8: EMP2007 | B8: Customer Service | C8: Officer | D8: F | E8: 42746 | H8: 87000 | I8: 8 | J8: 3 | K8: =IF(F8="","Active","Left") -> Active | L8: =ROUND((IF(F8="",Assumptions!$B$5,F8)-E8)/365.25,1) -> 9.7 | M8: =IF(L8<1,"Under 1 yr",IF(L8<3,"1 to 3 yrs",IF(L8<5,"3 to 5 yrs","5+ yrs"))) -> 5+ yrs | N8: =H8*12 -> 1044000 | O8: =IF(AND(E8<Assumptions!$B$6,OR(F8="",F8>=Assumptions!$B$6)),1,0) -> 1 | P8: =IF(F8="",0,IF(AND(F8>=Assumptions!$B$6,F8<=Assumptions!$B$5),1,0)) -> 0 | Q8: =P8*N8*Assumptions!$B$7 -> 0 | R8: =IF(AND(P8=1,J8>=Assumptions!$B$10),1,0) -> 0
A9: EMP2008 | B9: Operations | C9: Junior | D9: F | E9: 43589 | H9: 46000 | I9: 3 | J9: 3 | K9: =IF(F9="","Active","Left") -> Active | L9: =ROUND((IF(F9="",Assumptions!$B$5,F9)-E9)/365.25,1) -> 7.4 | M9: =IF(L9<1,"Under 1 yr",IF(L9<3,"1 to 3 yrs",IF(L9<5,"3 to 5 yrs","5+ yrs"))) -> 5+ yrs | N9: =H9*12 -> 552000 | O9: =IF(AND(E9<Assumptions!$B$6,OR(F9="",F9>=Assumptions!$B$6)),1,0) -> 1 | P9: =IF(F9="",0,IF(AND(F9>=Assumptions!$B$6,F9<=Assumptions!$B$5),1,0)) -> 0 | Q9: =P9*N9*Assumptions!$B$7 -> 0 | R9: =IF(AND(P9=1,J9>=Assumptions!$B$10),1,0) -> 0
A10: EMP2009 | B10: Operations | C10: Junior | D10: F | E10: 42307 | F10: 45998 | G10: Poor management | H10: 55000 | I10: 4 | J10: 2 | K10: =IF(F10="","Active","Left") -> Left | L10: =ROUND((IF(F10="",Assumptions!$B$5,F10)-E10)/365.25,1) -> 10.1 | M10: =IF(L10<1,"Under 1 yr",IF(L10<3,"1 to 3 yrs",IF(L10<5,"3 to 5 yrs","5+ yrs"))) -> 5+ yrs | N10: =H10*12 -> 660000 | O10: =IF(AND(E10<Assumptions!$B$6,OR(F10="",F10>=Assumptions!$B$6)),1,0) -> 1 | P10: =IF(F10="",0,IF(AND(F10>=Assumptions!$B$6,F10<=Assumptions!$B$5),1,0)) -> 1 | Q10: =P10*N10*Assumptions!$B$7 -> 330000 | R10: =IF(AND(P10=1,J10>=Assumptions!$B$10),1,0) -> 0
A11: EMP2010 | B11: Operations | C11: Senior | D11: F | E11: 45778 | F11: 45991 | G11: Career growth | H11: 177000 | I11: 0 | J11: 3 | K11: =IF(F11="","Active","Left") -> Left | L11: =ROUND((IF(F11="",Assumptions!$B$5,F11)-E11)/365.25,1) -> 0.6 | M11: =IF(L11<1,"Under 1 yr",IF(L11<3,"1 to 3 yrs",IF(L11<5,"3 to 5 yrs","5+ yrs"))) -> Under 1 yr | N11: =H11*12 -> 2124000 | O11: =IF(AND(E11<Assumptions!$B$6,OR(F11="",F11>=Assumptions!$B$6)),1,0) -> 1 | P11: =IF(F11="",0,IF(AND(F11>=Assumptions!$B$6,F11<=Assumptions!$B$5),1,0)) -> 1 | Q11: =P11*N11*Assumptions!$B$7 -> 1062000 | R11: =IF(AND(P11=1,J11>=Assumptions!$B$10),1,0) -> 0
A12: EMP2011 | B12: Customer Service | C12: Officer | D12: M | E12: 45880 | H12: 105000 | I12: 4 | J12: 5 | K12: =IF(F12="","Active","Left") -> Active | L12: =ROUND((IF(F12="",Assumptions!$B$5,F12)-E12)/365.25,1) -> 1.1 | M12: =IF(L12<1,"Under 1 yr",IF(L12<3,"1 to 3 yrs",IF(L12<5,"3 to 5 yrs","5+ yrs"))) -> 1 to 3 yrs | N12: =H12*12 -> 1260000 | O12: =IF(AND(E12<Assumptions!$B$6,OR(F12="",F12>=Assumptions!$B$6)),1,0) -> 1 | P12: =IF(F12="",0,IF(AND(F12>=Assumptions!$B$6,F12<=Assumptions!$B$5),1,0)) -> 0 | Q12: =P12*N12*Assumptions!$B$7 -> 0 | R12: =IF(AND(P12=1,J12>=Assumptions!$B$10),1,0) -> 0
A13: EMP2012 | B13: Sales | C13: Officer | D13: M | E13: 42529 | H13: 104000 | I13: 9 | J13: 4 | K13: =IF(F13="","Active","Left") -> Active | L13: =ROUND((IF(F13="",Assumptions!$B$5,F13)-E13)/365.25,1) -> 10.3 | M13: =IF(L13<1,"Under 1 yr",IF(L13<3,"1 to 3 yrs",IF(L13<5,"3 to 5 yrs","5+ yrs"))) -> 5+ yrs | N13: =H13*12 -> 1248000 | O13: =IF(AND(E13<Assumptions!$B$6,OR(F13="",F13>=Assumptions!$B$6)),1,0) -> 1 | P13: =IF(F13="",0,IF(AND(F13>=Assumptions!$B$6,F13<=Assumptions!$B$5),1,0)) -> 0 | Q13: =P13*N13*Assumptions!$B$7 -> 0 | R13: =IF(AND(P13=1,J13>=Assumptions!$B$10),1,0) -> 0
A14: EMP2013 | B14: Sales | C14: Junior | D14: F | E14: 43566 | H14: 41000 | I14: 1 | J14: 2 | K14: =IF(F14="","Active","Left") -> Active | L14: =ROUND((IF(F14="",Assumptions!$B$5,F14)-E14)/365.25,1) -> 7.5 | M14: =IF(L14<1,"Under 1 yr",IF(L14<3,"1 to 3 yrs",IF(L14<5,"3 to 5 yrs","5+ yrs"))) -> 5+ yrs | N14: =H14*12 -> 492000 | O14: =IF(AND(E14<Assumptions!$B$6,OR(F14="",F14>=Assumptions!$B$6)),1,0) -> 1 | P14: =IF(F14="",0,IF(AND(F14>=Assumptions!$B$6,F14<=Assumptions!$B$5),1,0)) -> 0 | Q14: =P14*N14*Assumptions!$B$7 -> 0 | R14: =IF(AND(P14=1,J14>=Assumptions!$B$10),1,0) -> 0
A15: EMP2014 | B15: Operations | C15: Junior | D15: F | E15: 45854 | H15: 38000 | I15: 4 | J15: 1 | K15: =IF(F15="","Active","Left") -> Active | L15: =ROUND((IF(F15="",Assumptions!$B$5,F15)-E15)/365.25,1) -> 1.2 | M15: =IF(L15<1,"Under 1 yr",IF(L15<3,"1 to 3 yrs",IF(L15<5,"3 to 5 yrs","5+ yrs"))) -> 1 to 3 yrs | N15: =H15*12 -> 456000 | O15: =IF(AND(E15<Assumptions!$B$6,OR(F15="",F15>=Assumptions!$B$6)),1,0) -> 1 | P15: =IF(F15="",0,IF(AND(F15>=Assumptions!$B$6,F15<=Assumptions!$B$5),1,0)) -> 0 | Q15: =P15*N15*Assumptions!$B$7 -> 0 | R15: =IF(AND(P15=1,J15>=Assumptions!$B$10),1,0) -> 0
A16: EMP2015 | B16: Operations | C16: Senior | D16: M | E16: 42275 | H16: 158000 | I16: 9 | J16: 3 | K16: =IF(F16="","Active","Left") -> Active | L16: =ROUND((IF(F16="",Assumptions!$B$5,F16)-E16)/365.25,1) -> 11 | M16: =IF(L16<1,"Under 1 yr",IF(L16<3,"1 to 3 yrs",IF(L16<5,"3 to 5 yrs","5+ yrs"))) -> 5+ yrs | N16: =H16*12 -> 1896000 | O16: =IF(AND(E16<Assumptions!$B$6,OR(F16="",F16>=Assumptions!$B$6)),1,0) -> 1 | P16: =IF(F16="",0,IF(AND(F16>=Assumptions!$B$6,F16<=Assumptions!$B$5),1,0)) -> 0 | Q16: =P16*N16*Assumptions!$B$7 -> 0 | R16: =IF(AND(P16=1,J16>=Assumptions!$B$10),1,0) -> 0
A17: EMP2016 | B17: Operations | C17: Junior | D17: F | E17: 44186 | H17: 53000 | I17: 6 | J17: 2 | K17: =IF(F17="","Active","Left") -> Active | L17: =ROUND((IF(F17="",Assumptions!$B$5,F17)-E17)/365.25,1) -> 5.8 | M17: =IF(L17<1,"Under 1 yr",IF(L17<3,"1 to 3 yrs",IF(L17<5,"3 to 5 yrs","5+ yrs"))) -> 5+ yrs | N17: =H17*12 -> 636000 | O17: =IF(AND(E17<Assumptions!$B$6,OR(F17="",F17>=Assumptions!$B$6)),1,0) -> 1 | P17: =IF(F17="",0,IF(AND(F17>=Assumptions!$B$6,F17<=Assumptions!$B$5),1,0)) -> 0 | Q17: =P17*N17*Assumptions!$B$7 -> 0 | R17: =IF(AND(P17=1,J17>=Assumptions!$B$10),1,0) -> 0
A18: EMP2017 | B18: Customer Service | C18: Junior | D18: M | E18: 42250 | H18: 36000 | I18: 10 | J18: 4 | K18: =IF(F18="","Active","Left") -> Active | L18: =ROUND((IF(F18="",Assumptions!$B$5,F18)-E18)/365.25,1) -> 11.1 | M18: =IF(L18<1,"Under 1 yr",IF(L18<3,"1 to 3 yrs",IF(L18<5,"3 to 5 yrs","5+ yrs"))) -> 5+ yrs | N18: =H18*12 -> 432000 | O18: =IF(AND(E18<Assumptions!$B$6,OR(F18="",F18>=Assumptions!$B$6)),1,0) -> 1 | P18: =IF(F18="",0,IF(AND(F18>=Assumptions!$B$6,F18<=Assumptions!$B$5),1,0)) -> 0 | Q18: =P18*N18*Assumptions!$B$7 -> 0 | R18: =IF(AND(P18=1,J18>=Assumptions!$B$10),1,0) -> 0
A19: EMP2018 | B19: Sales | C19: Officer | D19: M | E19: 45715 | H19: 94000 | I19: 1 | J19: 2 | K19: =IF(F19="","Active","Left") -> Active | L19: =ROUND((IF(F19="",Assumptions!$B$5,F19)-E19)/365.25,1) -> 1.6 | M19: =IF(L19<1,"Under 1 yr",IF(L19<3,"1 to 3 yrs",IF(L19<5,"3 to 5 yrs","5+ yrs"))) -> 1 to 3 yrs | N19: =H19*12 -> 1128000 | O19: =IF(AND(E19<Assumptions!$B$6,OR(F19="",F19>=Assumptions!$B$6)),1,0) -> 1 | P19: =IF(F19="",0,IF(AND(F19>=Assumptions!$B$6,F19<=Assumptions!$B$5),1,0)) -> 0 | Q19: =P19*N19*Assumptions!$B$7 -> 0 | R19: =IF(AND(P19=1,J19>=Assumptions!$B$10),1,0) -> 0
A20: EMP2019 | B20: Operations | C20: Senior | D20: M | E20: 42079 | H20: 123000 | I20: 7 | J20: 3 | K20: =IF(F20="","Active","Left") -> Active | L20: =ROUND((IF(F20="",Assumptions!$B$5,F20)-E20)/365.25,1) -> 11.5 | M20: =IF(L20<1,"Under 1 yr",IF(L20<3,"1 to 3 yrs",IF(L20<5,"3 to 5 yrs","5+ yrs"))) -> 5+ yrs | N20: =H20*12 -> 1476000 | O20: =IF(AND(E20<Assumptions!$B$6,OR(F20="",F20>=Assumptions!$B$6)),1,0) -> 1 | P20: =IF(F20="",0,IF(AND(F20>=Assumptions!$B$6,F20<=Assumptions!$B$5),1,0)) -> 0 | Q20: =P20*N20*Assumptions!$B$7 -> 0 | R20: =IF(AND(P20=1,J20>=Assumptions!$B$10),1,0) -> 0
A21: EMP2020 | B21: Customer Service | C21: Junior | D21: M | E21: 44128 | H21: 60000 | I21: 12 | J21: 4 | K21: =IF(F21="","Active","Left") -> Active | L21: =ROUND((IF(F21="",Assumptions!$B$5,F21)-E21)/365.25,1) -> 5.9 | M21: =IF(L21<1,"Under 1 yr",IF(L21<3,"1 to 3 yrs",IF(L21<5,"3 to 5 yrs","5+ yrs"))) -> 5+ yrs | N21: =H21*12 -> 720000 | O21: =IF(AND(E21<Assumptions!$B$6,OR(F21="",F21>=Assumptions!$B$6)),1,0) -> 1 | P21: =IF(F21="",0,IF(AND(F21>=Assumptions!$B$6,F21<=Assumptions!$B$5),1,0)) -> 0 | Q21: =P21*N21*Assumptions!$B$7 -> 0 | R21: =IF(AND(P21=1,J21>=Assumptions!$B$10),1,0) -> 0
A22: EMP2021 | B22: Customer Service | C22: Manager | D22: F | E22: 43565 | H22: 292000 | I22: 8 | J22: 4 | K22: =IF(F22="","Active","Left") -> Active | L22: =ROUND((IF(F22="",Assumptions!$B$5,F22)-E22)/365.25,1) -> 7.5 | M22: =IF(L22<1,"Under 1 yr",IF(L22<3,"1 to 3 yrs",IF(L22<5,"3 to 5 yrs","5+ yrs"))) -> 5+ yrs | N22: =H22*12 -> 3504000 | O22: =IF(AND(E22<Assumptions!$B$6,OR(F22="",F22>=Assumptions!$B$6)),1,0) -> 1 | P22: =IF(F22="",0,IF(AND(F22>=Assumptions!$B$6,F22<=Assumptions!$B$5),1,0)) -> 0 | Q22: =P22*N22*Assumptions!$B$7 -> 0 | R22: =IF(AND(P22=1,J22>=Assumptions!$B$10),1,0) -> 0
A23: EMP2022 | B23: Sales | C23: Senior | D23: M | E23: 44776 | F23: 46195 | G23: Relocation | H23: 135000 | I23: 2 | J23: 4 | K23: =IF(F23="","Active","Left") -> Left | L23: =ROUND((IF(F23="",Assumptions!$B$5,F23)-E23)/365.25,1) -> 3.9 | M23: =IF(L23<1,"Under 1 yr",IF(L23<3,"1 to 3 yrs",IF(L23<5,"3 to 5 yrs","5+ yrs"))) -> 3 to 5 yrs | N23: =H23*12 -> 1620000 | O23: =IF(AND(E23<Assumptions!$B$6,OR(F23="",F23>=Assumptions!$B$6)),1,0) -> 1 | P23: =IF(F23="",0,IF(AND(F23>=Assumptions!$B$6,F23<=Assumptions!$B$5),1,0)) -> 1 | Q23: =P23*N23*Assumptions!$B$7 -> 810000 | R23: =IF(AND(P23=1,J23>=Assumptions!$B$10),1,0) -> 1
A24: EMP2023 | B24: IT | C24: Officer | D24: F | E24: 42183 | F24: 46189 | G24: Personal / family | H24: 100000 | I24: 5 | J24: 5 | K24: =IF(F24="","Active","Left") -> Left | L24: =ROUND((IF(F24="",Assumptions!$B$5,F24)-E24)/365.25,1) -> 11 | M24: =IF(L24<1,"Under 1 yr",IF(L24<3,"1 to 3 yrs",IF(L24<5,"3 to 5 yrs","5+ yrs"))) -> 5+ yrs | N24: =H24*12 -> 1200000 | O24: =IF(AND(E24<Assumptions!$B$6,OR(F24="",F24>=Assumptions!$B$6)),1,0) -> 1 | P24: =IF(F24="",0,IF(AND(F24>=Assumptions!$B$6,F24<=Assumptions!$B$5),1,0)) -> 1 | Q24: =P24*N24*Assumptions!$B$7 -> 600000 | R24: =IF(AND(P24=1,J24>=Assumptions!$B$10),1,0) -> 1
A25: EMP2024 | B25: Operations | C25: Junior | D25: M | E25: 44565 | H25: 54000 | I25: 3 | J25: 3 | K25: =IF(F25="","Active","Left") -> Active | L25: =ROUND((IF(F25="",Assumptions!$B$5,F25)-E25)/365.25,1) -> 4.7 | M25: =IF(L25<1,"Under 1 yr",IF(L25<3,"1 to 3 yrs",IF(L25<5,"3 to 5 yrs","5+ yrs"))) -> 3 to 5 yrs | N25: =H25*12 -> 648000 | O25: =IF(AND(E25<Assumptions!$B$6,OR(F25="",F25>=Assumptions!$B$6)),1,0) -> 1 | P25: =IF(F25="",0,IF(AND(F25>=Assumptions!$B$6,F25<=Assumptions!$B$5),1,0)) -> 0 | Q25: =P25*N25*Assumptions!$B$7 -> 0 | R25: =IF(AND(P25=1,J25>=Assumptions!$B$10),1,0) -> 0
A26: EMP2025 | B26: HR | C26: Senior | D26: F | E26: 42433 | H26: 151000 | I26: 4 | J26: 2 | K26: =IF(F26="","Active","Left") -> Active | L26: =ROUND((IF(F26="",Assumptions!$B$5,F26)-E26)/365.25,1) -> 10.6 | M26: =IF(L26<1,"Under 1 yr",IF(L26<3,"1 to 3 yrs",IF(L26<5,"3 to 5 yrs","5+ yrs"))) -> 5+ yrs | N26: =H26*12 -> 1812000 | O26: =IF(AND(E26<Assumptions!$B$6,OR(F26="",F26>=Assumptions!$B$6)),1,0) -> 1 | P26: =IF(F26="",0,IF(AND(F26>=Assumptions!$B$6,F26<=Assumptions!$B$5),1,0)) -> 0 | Q26: =P26*N26*Assumptions!$B$7 -> 0 | R26: =IF(AND(P26=1,J26>=Assumptions!$B$10),1,0) -> 0
A27: EMP2026 | B27: Customer Service | C27: Junior | D27: M | E27: 42200 | H27: 49000 | I27: 7 | J27: 5 | K27: =IF(F27="","Active","Left") -> Active | L27: =ROUND((IF(F27="",Assumptions!$B$5,F27)-E27)/365.25,1) -> 11.2 | M27: =IF(L27<1,"Under 1 yr",IF(L27<3,"1 to 3 yrs",IF(L27<5,"3 to 5 yrs","5+ yrs"))) -> 5+ yrs | N27: =H27*12 -> 588000 | O27: =IF(AND(E27<Assumptions!$B$6,OR(F27="",F27>=Assumptions!$B$6)),1,0) -> 1 | P27: =IF(F27="",0,IF(AND(F27>=Assumptions!$B$6,F27<=Assumptions!$B$5),1,0)) -> 0 | Q27: =P27*N27*Assumptions!$B$7 -> 0 | R27: =IF(AND(P27=1,J27>=Assumptions!$B$10),1,0) -> 0
A28: EMP2027 | B28: Sales | C28: Junior | D28: M | E28: 45233 | H28: 44000 | I28: 5 | J28: 5 | K28: =IF(F28="","Active","Left") -> Active | L28: =ROUND((IF(F28="",Assumptions!$B$5,F28)-E28)/365.25,1) -> 2.9 | M28: =IF(L28<1,"Under 1 yr",IF(L28<3,"1 to 3 yrs",IF(L28<5,"3 to 5 yrs","5+ yrs"))) -> 1 to 3 yrs | N28: =H28*12 -> 528000 | O28: =IF(AND(E28<Assumptions!$B$6,OR(F28="",F28>=Assumptions!$B$6)),1,0) -> 1 | P28: =IF(F28="",0,IF(AND(F28>=Assumptions!$B$6,F28<=Assumptions!$B$5),1,0)) -> 0 | Q28: =P28*N28*Assumptions!$B$7 -> 0 | R28: =IF(AND(P28=1,J28>=Assumptions!$B$10),1,0) -> 0
A29: EMP2028 | B29: Finance | C29: Junior | D29: F | E29: 43787 | F29: 46052 | G29: Poor management | H29: 52000 | I29: 7 | J29: 3 | K29: =IF(F29="","Active","Left") -> Left | L29: =ROUND((IF(F29="",Assumptions!$B$5,F29)-E29)/365.25,1) -> 6.2 | M29: =IF(L29<1,"Under 1 yr",IF(L29<3,"1 to 3 yrs",IF(L29<5,"3 to 5 yrs","5+ yrs"))) -> 5+ yrs | N29: =H29*12 -> 624000 | O29: =IF(AND(E29<Assumptions!$B$6,OR(F29="",F29>=Assumptions!$B$6)),1,0) -> 1 | P29: =IF(F29="",0,IF(AND(F29>=Assumptions!$B$6,F29<=Assumptions!$B$5),1,0)) -> 1 | Q29: =P29*N29*Assumptions!$B$7 -> 312000 | R29: =IF(AND(P29=1,J29>=Assumptions!$B$10),1,0) -> 0
A30: EMP2029 | B30: Operations | C30: Junior | D30: M | E30: 43256 | F30: 46176 | G30: Career growth | H30: 40000 | I30: 3 | J30: 3 | K30: =IF(F30="","Active","Left") -> Left | L30: =ROUND((IF(F30="",Assumptions!$B$5,F30)-E30)/365.25,1) -> 8 | M30: =IF(L30<1,"Under 1 yr",IF(L30<3,"1 to 3 yrs",IF(L30<5,"3 to 5 yrs","5+ yrs"))) -> 5+ yrs | N30: =H30*12 -> 480000 | O30: =IF(AND(E30<Assumptions!$B$6,OR(F30="",F30>=Assumptions!$B$6)),1,0) -> 1 | P30: =IF(F30="",0,IF(AND(F30>=Assumptions!$B$6,F30<=Assumptions!$B$5),1,0)) -> 1 | Q30: =P30*N30*Assumptions!$B$7 -> 240000 | R30: =IF(AND(P30=1,J30>=Assumptions!$B$10),1,0) -> 0
A31: EMP2030 | B31: Sales | C31: Officer | D31: M | E31: 45764 | H31: 85000 | I31: 4 | J31: 4 | K31: =IF(F31="","Active","Left") -> Active | L31: =ROUND((IF(F31="",Assumptions!$B$5,F31)-E31)/365.25,1) -> 1.5 | M31: =IF(L31<1,"Under 1 yr",IF(L31<3,"1 to 3 yrs",IF(L31<5,"3 to 5 yrs","5+ yrs"))) -> 1 to 3 yrs | N31: =H31*12 -> 1020000 | O31: =IF(AND(E31<Assumptions!$B$6,OR(F31="",F31>=Assumptions!$B$6)),1,0) -> 1 | P31: =IF(F31="",0,IF(AND(F31>=Assumptions!$B$6,F31<=Assumptions!$B$5),1,0)) -> 0 | Q31: =P31*N31*Assumptions!$B$7 -> 0 | R31: =IF(AND(P31=1,J31>=Assumptions!$B$10),1,0) -> 0
A32: EMP2031 | B32: HR | C32: Junior | D32: F | E32: 44347 | H32: 38000 | I32: 6 | J32: 3 | K32: =IF(F32="","Active","Left") -> Active | L32: =ROUND((IF(F32="",Assumptions!$B$5,F32)-E32)/365.25,1) -> 5.3 | M32: =IF(L32<1,"Under 1 yr",IF(L32<3,"1 to 3 yrs",IF(L32<5,"3 to 5 yrs","5+ yrs"))) -> 5+ yrs | N32: =H32*12 -> 456000 | O32: =IF(AND(E32<Assumptions!$B$6,OR(F32="",F32>=Assumptions!$B$6)),1,0) -> 1 | P32: =IF(F32="",0,IF(AND(F32>=Assumptions!$B$6,F32<=Assumptions!$B$5),1,0)) -> 0 | Q32: =P32*N32*Assumptions!$B$7 -> 0 | R32: =IF(AND(P32=1,J32>=Assumptions!$B$10),1,0) -> 0
A33: EMP2032 | B33: Finance | C33: Officer | D33: F | E33: 43030 | F33: 46012 | G33: Personal / family | H33: 79000 | I33: 7 | J33: 3 | K33: =IF(F33="","Active","Left") -> Left | L33: =ROUND((IF(F33="",Assumptions!$B$5,F33)-E33)/365.25,1) -> 8.2 | M33: =IF(L33<1,"Under 1 yr",IF(L33<3,"1 to 3 yrs",IF(L33<5,"3 to 5 yrs","5+ yrs"))) -> 5+ yrs | N33: =H33*12 -> 948000 | O33: =IF(AND(E33<Assumptions!$B$6,OR(F33="",F33>=Assumptions!$B$6)),1,0) -> 1 | P33: =IF(F33="",0,IF(AND(F33>=Assumptions!$B$6,F33<=Assumptions!$B$5),1,0)) -> 1 | Q33: =P33*N33*Assumptions!$B$7 -> 474000 | R33: =IF(AND(P33=1,J33>=Assumptions!$B$10),1,0) -> 0
A34: EMP2033 | B34: Operations | C34: Senior | D34: M | E34: 45266 | H34: 161000 | I34: 3 | J34: 3 | K34: =IF(F34="","Active","Left") -> Active | L34: =ROUND((IF(F34="",Assumptions!$B$5,F34)-E34)/365.25,1) -> 2.8 | M34: =IF(L34<1,"Under 1 yr",IF(L34<3,"1 to 3 yrs",IF(L34<5,"3 to 5 yrs","5+ yrs"))) -> 1 to 3 yrs | N34: =H34*12 -> 1932000 | O34: =IF(AND(E34<Assumptions!$B$6,OR(F34="",F34>=Assumptions!$B$6)),1,0) -> 1 | P34: =IF(F34="",0,IF(AND(F34>=Assumptions!$B$6,F34<=Assumptions!$B$5),1,0)) -> 0 | Q34: =P34*N34*Assumptions!$B$7 -> 0 | R34: =IF(AND(P34=1,J34>=Assumptions!$B$10),1,0) -> 0
A35: EMP2034 | B35: Customer Service | C35: Senior | D35: F | E35: 43851 | H35: 147000 | I35: 5 | J35: 4 | K35: =IF(F35="","Active","Left") -> Active | L35: =ROUND((IF(F35="",Assumptions!$B$5,F35)-E35)/365.25,1) -> 6.7 | M35: =IF(L35<1,"Under 1 yr",IF(L35<3,"1 to 3 yrs",IF(L35<5,"3 to 5 yrs","5+ yrs"))) -> 5+ yrs | N35: =H35*12 -> 1764000 | O35: =IF(AND(E35<Assumptions!$B$6,OR(F35="",F35>=Assumptions!$B$6)),1,0) -> 1 | P35: =IF(F35="",0,IF(AND(F35>=Assumptions!$B$6,F35<=Assumptions!$B$5),1,0)) -> 0 | Q35: =P35*N35*Assumptions!$B$7 -> 0 | R35: =IF(AND(P35=1,J35>=Assumptions!$B$10),1,0) -> 0
A36: EMP2035 | B36: Operations | C36: Officer | D36: M | E36: 44909 | H36: 67000 | I36: 3 | J36: 3 | K36: =IF(F36="","Active","Left") -> Active | L36: =ROUND((IF(F36="",Assumptions!$B$5,F36)-E36)/365.25,1) -> 3.8 | M36: =IF(L36<1,"Under 1 yr",IF(L36<3,"1 to 3 yrs",IF(L36<5,"3 to 5 yrs","5+ yrs"))) -> 3 to 5 yrs | N36: =H36*12 -> 804000 | O36: =IF(AND(E36<Assumptions!$B$6,OR(F36="",F36>=Assumptions!$B$6)),1,0) -> 1 | P36: =IF(F36="",0,IF(AND(F36>=Assumptions!$B$6,F36<=Assumptions!$B$5),1,0)) -> 0 | Q36: =P36*N36*Assumptions!$B$7 -> 0 | R36: =IF(AND(P36=1,J36>=Assumptions!$B$10),1,0) -> 0
A37: EMP2036 | B37: Customer Service | C37: Junior | D37: F | E37: 46133 | H37: 39000 | I37: 6 | J37: 3 | K37: =IF(F37="","Active","Left") -> Active | L37: =ROUND((IF(F37="",Assumptions!$B$5,F37)-E37)/365.25,1) -> 0.4 | M37: =IF(L37<1,"Under 1 yr",IF(L37<3,"1 to 3 yrs",IF(L37<5,"3 to 5 yrs","5+ yrs"))) -> Under 1 yr | N37: =H37*12 -> 468000 | O37: =IF(AND(E37<Assumptions!$B$6,OR(F37="",F37>=Assumptions!$B$6)),1,0) -> 0 | P37: =IF(F37="",0,IF(AND(F37>=Assumptions!$B$6,F37<=Assumptions!$B$5),1,0)) -> 0 | Q37: =P37*N37*Assumptions!$B$7 -> 0 | R37: =IF(AND(P37=1,J37>=Assumptions!$B$10),1,0) -> 0
A38: EMP2037 | B38: Sales | C38: Officer | D38: F | E38: 44142 | F38: 46014 | G38: Career growth | H38: 70000 | I38: 3 | J38: 4 | K38: =IF(F38="","Active","Left") -> Left | L38: =ROUND((IF(F38="",Assumptions!$B$5,F38)-E38)/365.25,1) -> 5.1 | M38: =IF(L38<1,"Under 1 yr",IF(L38<3,"1 to 3 yrs",IF(L38<5,"3 to 5 yrs","5+ yrs"))) -> 5+ yrs | N38: =H38*12 -> 840000 | O38: =IF(AND(E38<Assumptions!$B$6,OR(F38="",F38>=Assumptions!$B$6)),1,0) -> 1 | P38: =IF(F38="",0,IF(AND(F38>=Assumptions!$B$6,F38<=Assumptions!$B$5),1,0)) -> 1 | Q38: =P38*N38*Assumptions!$B$7 -> 420000 | R38: =IF(AND(P38=1,J38>=Assumptions!$B$10),1,0) -> 1
A39: EMP2038 | B39: Operations | C39: Junior | D39: M | E39: 43397 | H39: 51000 | I39: 5 | J39: 4 | K39: =IF(F39="","Active","Left") -> Active | L39: =ROUND((IF(F39="",Assumptions!$B$5,F39)-E39)/365.25,1) -> 7.9 | M39: =IF(L39<1,"Under 1 yr",IF(L39<3,"1 to 3 yrs",IF(L39<5,"3 to 5 yrs","5+ yrs"))) -> 5+ yrs | N39: =H39*12 -> 612000 | O39: =IF(AND(E39<Assumptions!$B$6,OR(F39="",F39>=Assumptions!$B$6)),1,0) -> 1 | P39: =IF(F39="",0,IF(AND(F39>=Assumptions!$B$6,F39<=Assumptions!$B$5),1,0)) -> 0 | Q39: =P39*N39*Assumptions!$B$7 -> 0 | R39: =IF(AND(P39=1,J39>=Assumptions!$B$10),1,0) -> 0
A40: EMP2039 | B40: Finance | C40: Junior | D40: F | E40: 44643 | H40: 55000 | I40: 6 | J40: 1 | K40: =IF(F40="","Active","Left") -> Active | L40: =ROUND((IF(F40="",Assumptions!$B$5,F40)-E40)/365.25,1) -> 4.5 | M40: =IF(L40<1,"Under 1 yr",IF(L40<3,"1 to 3 yrs",IF(L40<5,"3 to 5 yrs","5+ yrs"))) -> 3 to 5 yrs | N40: =H40*12 -> 660000 | O40: =IF(AND(E40<Assumptions!$B$6,OR(F40="",F40>=Assumptions!$B$6)),1,0) -> 1 | P40: =IF(F40="",0,IF(AND(F40>=Assumptions!$B$6,F40<=Assumptions!$B$5),1,0)) -> 0 | Q40: =P40*N40*Assumptions!$B$7 -> 0 | R40: =IF(AND(P40=1,J40>=Assumptions!$B$10),1,0) -> 0
...
