Workbook

Sheet README
A1: Data Collection to Dashboard – Survey Portfolio Project
A2: BZME Insights | Sector: Research / NGO data collection | Tool: Excel (formula-driven) + KoboToolbox / XLSForm
A4: BUSINESS PROBLEM
A5: A research or NGO team wants to understand how small traders use digital payments. Field staff collect data on phones, but the team needs to know quickly whether the data can be trusted, whether fieldwork is on schedule, and what the early results say.
A7: BUSINESS QUESTIONS
A8: 1. Is fieldwork on track against the planned sample in each town?
A9: 2. Which submissions pass quality checks, and which enumerators need back-checks?
A10: 3. How many traders accept M-Pesa, and how does this vary by town, business type, sales and gender?
A11: 4. What stops non-acceptors from adopting, and who wants training?
A13: HOW THE PROJECT IS BUILT
A14: kobo/Survey_Form_XLSForm.xlsx: the data collection form in XLSForm format (survey, choices and settings sheets) that can be uploaded to KoboToolbox or ODK.
A15: Responses: 314 submissions exactly as exported from the form, with deliberate quality problems (duplicates, missing values, impossible ages, rushed interviews, inconsistent answers).
... A33: Prioritise training and fee transparency where those are the main barriers.

Sheet Dashboard
A1: Data Collection to Dashboard: Small Trader Digital Payments Survey
A2: Fictional field survey of small traders in four towns, collected on a mobile form | Synthetic data | Prepared by BZME Insights
A4: RESPONSES RECEIVED | C4: VALID AFTER QUALITY CHECKS | E4: SAMPLE TARGET COMPLETED | G4: ACCEPT M-PESA | I4: AVG M-PESA SHARE OF SALES (ACCEPTORS) | K4: INTERESTED IN TRAINING
A5: =COUNTA(Responses!$A$2:$A$315) -> 314 | C5: =SUM(Quality_Checks!$I$2:$I$315) -> 283 | E5: =SUM(Quality_Checks!$I$2:$I$315)/Assumptions!B12 -> 0.884375 | G5: =COUNTIFS(Responses!$K$2:$K$315,"Yes",Quality_Checks!$I$2:$I$315,1)/SUM(Quality_Checks!$I$2:$I$315) -> 0.80212014 | I5: =AVERAGEIFS(Responses!$L$2:$L$315,Responses!$K$2:$K$315,"Yes",Quality_Checks!$I$2:$I$315,1)/100 -> 0.42885463 | K5: =COUNTIFS(Responses!$P$2:$P$315,"Yes",Quality_Checks!$I$2:$I$315,1)/SUM(Quality_Checks!$I$2:$I$315) -> 0.42756184
A7: Key findings (update automatically)
A8: ="1. "&C5&" of "&A5&" submissions passed the quality checks ("&TEXT(C5/A5,"0%")&"); that is "&TEXT(E5,"0%")&" of the "&TEXT(Assumptions!B12,"#,##0")&"-interview target." -> 1. 283 of 314 submissions passed the quality checks (90%); that is 88% of the 320-interview target.
A9: ="2. Furthest behind target: "&INDEX(A18:A21,MATCH(MIN(E18:E21),E18:E21,0))&" ("&TEXT(MIN(E18:E21),"0%")&" of its sample); "&TEXT(SUM(F18:F22),"0")&" interviews are held back for review." -> 2. Furthest behind target: Mombasa (71% of its sample); 31 interviews are held back for review.
A10: ="3. "&TEXT(G5,"0%")&" of traders accept M-Pesa: highest in "&INDEX(A26:A32,MATCH(MAX(C26:C32),C26:C32,0))&" ("&TEXT(MAX(C26:C32),"0%")&"), lowest in "&INDEX(A26:A32,MATCH(MIN(C26:C32),C26:C32,0))&" ("&TEXT(MIN(C26:C32),"0%")&")." -> 3. 80% of traders accept M-Pesa: highest in Grocery kiosk (90%), lowest in Clothing stall (63%).
A11: ="4. By town, adoption is highest in "&INDEX(A18:A21,MATCH(MAX(G18:G21),G18:G21,0))&" ("&TEXT(MAX(G18:G21),"0%")&") and lowest in "&INDEX(A18:A21,MATCH(MIN(G18:G21),G18:G21,0))&" ("&TEXT(MIN(G18:G21),"0%")&")." -> 4. By town, adoption is highest in Nairobi (91%) and lowest in Kisumu (65%).
A12: ="5. Main barrier among non-acceptors: "&INDEX(A46:A50,MATCH(MAX(B46:B50),B46:B50,0))&" ("&TEXT(MAX(C46:C50),"0%")&"), followed by "&INDEX(A46:A50,MATCH(LARGE(B46:B50,2),B46:B50,0))&" ("&TEXT(LARGE(C46:C50,2),"0%")&")." -> 5. Main barrier among non-acceptors: Transaction fees (30%), followed by Customers prefer cash (29%).
A13: ="6. Enumerator "&INDEX(A55:A61,MATCH(MAX(D55:D61),D55:D61,0))&" has the highest flag rate ("&TEXT(MAX(D55:D61),"0%")&"); the shortest average interview is "&TEXT(MIN(E55:E61),"0.0")&" minutes ("&INDEX(A55:A61,MATCH(MIN(E55:E61),E55:E61,0))&"). Schedule back-checks before using their data." -> 6. Enumerator E05 has the highest flag rate (44%); the shortest average interview is 6.8 minutes (E05). Schedule back-checks before using their data.
A14: ="7. Training interest is "&TEXT(COUNTIFS(Responses!$K$2:$K$315,"No",Responses!$P$2:$P$315,"Yes",Quality_Checks!$I$2:$I$315,1)/COUNTIFS(Responses!$K$2:$K$315,"No",Quality_Checks!$I$2:$I$315,1),"0%")&" among non-acceptors vs "&TEXT(COUNTIFS(Responses!$K$2:$K$315,"Yes",Responses!$P$2:$P$315,"Yes",Quality_Checks!$I$2:$I$315,1)/COUNTIFS(Responses!$K$2:$K$315,"Yes",Quality_Checks!$I$2:$I$315,1),"0%")&" among acceptors." -> 7. Training interest is 57% among non-acceptors vs 39% among acceptors.
A16: 1. Fieldwork progress and M-Pesa adoption by town
A17: Town | B17: Target | C17: Received | D17: Valid | E17: Valid % of target | F17: Held for review | G17: Accept M-Pesa
A18: Nairobi | B18: =Assumptions!B8 -> 90 | C18: =COUNTIF(Responses!$D$2:$D$315,A18) -> 90 | D18: =COUNTIFS(Responses!$D$2:$D$315,A18,Quality_Checks!$I$2:$I$315,1) -> 87 | E18: =IFERROR(D18/B18,0) -> 0.96666667 | F18: =C18-D18 -> 3 | G18: =IFERROR(COUNTIFS(Responses!$D$2:$D$315,A18,Responses!$K$2:$K$315,"Yes",Quality_Checks!$I$2:$I$315,1)/D18,0) -> 0.90804598
A19: Kisumu | B19: =Assumptions!B9 -> 70 | C19: =COUNTIF(Responses!$D$2:$D$315,A19) -> 64 | D19: =COUNTIFS(Responses!$D$2:$D$315,A19,Quality_Checks!$I$2:$I$315,1) -> 60 | E19: =IFERROR(D19/B19,0) -> 0.85714286 | F19: =C19-D19 -> 4 | G19: =IFERROR(COUNTIFS(Responses!$D$2:$D$315,A19,Responses!$K$2:$K$315,"Yes",Quality_Checks!$I$2:$I$315,1)/D19,0) -> 0.65
A20: Mombasa | B20: =Assumptions!B10 -> 80 | C20: =COUNTIF(Responses!$D$2:$D$315,A20) -> 76 | D20: =COUNTIFS(Responses!$D$2:$D$315,A20,Quality_Checks!$I$2:$I$315,1) -> 57 | E20: =IFERROR(D20/B20,0) -> 0.7125 | F20: =C20-D20 -> 19 | G20: =IFERROR(COUNTIFS(Responses!$D$2:$D$315,A20,Responses!$K$2:$K$315,"Yes",Quality_Checks!$I$2:$I$315,1)/D20,0) -> 0.8245614
A21: Nakuru | B21: =Assumptions!B11 -> 80 | C21: =COUNTIF(Responses!$D$2:$D$315,A21) -> 81 | D21: =COUNTIFS(Responses!$D$2:$D$315,A21,Quality_Checks!$I$2:$I$315,1) -> 79 | E21: =IFERROR(D21/B21,0) -> 0.9875 | F21: =C21-D21 -> 2 | G21: =IFERROR(COUNTIFS(Responses!$D$2:$D$315,A21,Responses!$K$2:$K$315,"Yes",Quality_Checks!$I$2:$I$315,1)/D21,0) -> 0.78481013
A22: (town missing) | C22: =COUNTA(Responses!$A$2:$A$315)-SUM(C18:C21) -> 3 | D22: =SUM(Quality_Checks!$I$2:$I$315)-SUM(D18:D21) -> 0 | F22: =C22-D22 -> 3
A23: All towns | B23: =SUM(B18:B21) -> 320 | C23: =SUM(C18:C22) -> 314 | D23: =SUM(D18:D22) -> 283 | E23: =IFERROR(D23/B23,0) -> 0.884375 | F23: =SUM(F18:F22) -> 31 | G23: =G5 -> 0.80212014
A24: 2. M-Pesa adoption by business type (valid responses)
A25: Business type | B25: Valid n | C25: Accept M-Pesa | D25: Avg M-Pesa share of sales | E25: Pay suppliers digitally | F25: Interested in training
A26: Grocery kiosk | B26: =COUNTIFS(Responses!$E$2:$E$315,A26,Quality_Checks!$I$2:$I$315,1) -> 78 | C26: =IFERROR(COUNTIFS(Responses!$E$2:$E$315,A26,Responses!$K$2:$K$315,"Yes",Quality_Checks!$I$2:$I$315,1)/B26,0) -> 0.8974359 | D26: =IFERROR(AVERAGEIFS(Responses!$L$2:$L$315,Responses!$E$2:$E$315,A26,Responses!$K$2:$K$315,"Yes",Quality_Checks!$I$2:$I$315,1)/100,0) -> 0.44442857 | E26: =IFERROR(COUNTIFS(Responses!$E$2:$E$315,A26,Responses!$M$2:$M$315,"Yes",Quality_Checks!$I$2:$I$315,1)/B26,0) -> 0.41025641 | F26: =IFERROR(COUNTIFS(Responses!$E$2:$E$315,A26,Responses!$P$2:$P$315,"Yes",Quality_Checks!$I$2:$I$315,1)/B26,0) -> 0.44871795
A27: Food vendor | B27: =COUNTIFS(Responses!$E$2:$E$315,A27,Quality_Checks!$I$2:$I$315,1) -> 60 | C27: =IFERROR(COUNTIFS(Responses!$E$2:$E$315,A27,Responses!$K$2:$K$315,"Yes",Quality_Checks!$I$2:$I$315,1)/B27,0) -> 0.83333333 | D27: =IFERROR(AVERAGEIFS(Responses!$L$2:$L$315,Responses!$E$2:$E$315,A27,Responses!$K$2:$K$315,"Yes",Quality_Checks!$I$2:$I$315,1)/100,0) -> 0.403 | E27: =IFERROR(COUNTIFS(Responses!$E$2:$E$315,A27,Responses!$M$2:$M$315,"Yes",Quality_Checks!$I$2:$I$315,1)/B27,0) -> 0.48333333 | F27: =IFERROR(COUNTIFS(Responses!$E$2:$E$315,A27,Responses!$P$2:$P$315,"Yes",Quality_Checks!$I$2:$I$315,1)/B27,0) -> 0.48333333
A28: Clothing stall | B28: =COUNTIFS(Responses!$E$2:$E$315,A28,Quality_Checks!$I$2:$I$315,1) -> 38 | C28: =IFERROR(COUNTIFS(Responses!$E$2:$E$315,A28,Responses!$K$2:$K$315,"Yes",Quality_Checks!$I$2:$I$315,1)/B28,0) -> 0.63157895 | D28: =IFERROR(AVERAGEIFS(Responses!$L$2:$L$315,Responses!$E$2:$E$315,A28,Responses!$K$2:$K$315,"Yes",Quality_Checks!$I$2:$I$315,1)/100,0) -> 0.51166667 | E28: =IFERROR(COUNTIFS(Responses!$E$2:$E$315,A28,Responses!$M$2:$M$315,"Yes",Quality_Checks!$I$2:$I$315,1)/B28,0) -> 0.44736842 | F28: =IFERROR(COUNTIFS(Responses!$E$2:$E$315,A28,Responses!$P$2:$P$315,"Yes",Quality_Checks!$I$2:$I$315,1)/B28,0) -> 0.34210526
A29: Salon or barber | B29: =COUNTIFS(Responses!$E$2:$E$315,A29,Quality_Checks!$I$2:$I$315,1) -> 27 | C29: =IFERROR(COUNTIFS(Responses!$E$2:$E$315,A29,Responses!$K$2:$K$315,"Yes",Quality_Checks!$I$2:$I$315,1)/B29,0) -> 0.77777778 | D29: =IFERROR(AVERAGEIFS(Responses!$L$2:$L$315,Responses!$E$2:$E$315,A29,Responses!$K$2:$K$315,"Yes",Quality_Checks!$I$2:$I$315,1)/100,0) -> 0.37904762 | E29: =IFERROR(COUNTIFS(Responses!$E$2:$E$315,A29,Responses!$M$2:$M$315,"Yes",Quality_Checks!$I$2:$I$315,1)/B29,0) -> 0.48148148 | F29: =IFERROR(COUNTIFS(Responses!$E$2:$E$315,A29,Responses!$P$2:$P$315,"Yes",Quality_Checks!$I$2:$I$315,1)/B29,0) -> 0.44444444
A30: Hardware shop | B30: =COUNTIFS(Responses!$E$2:$E$315,A30,Quality_Checks!$I$2:$I$315,1) -> 27 | C30: =IFERROR(COUNTIFS(Responses!$E$2:$E$315,A30,Responses!$K$2:$K$315,"Yes",Quality_Checks!$I$2:$I$315,1)/B30,0) -> 0.85185185 | D30: =IFERROR(AVERAGEIFS(Responses!$L$2:$L$315,Responses!$E$2:$E$315,A30,Responses!$K$2:$K$315,"Yes",Quality_Checks!$I$2:$I$315,1)/100,0) -> 0.44304348 | E30: =IFERROR(COUNTIFS(Responses!$E$2:$E$315,A30,Responses!$M$2:$M$315,"Yes",Quality_Checks!$I$2:$I$315,1)/B30,0) -> 0.51851852 | F30: =IFERROR(COUNTIFS(Responses!$E$2:$E$315,A30,Responses!$P$2:$P$315,"Yes",Quality_Checks!$I$2:$I$315,1)/B30,0) -> 0.37037037
A31: Boda boda or transport | B31: =COUNTIFS(Responses!$E$2:$E$315,A31,Quality_Checks!$I$2:$I$315,1) -> 31 | C31: =IFERROR(COUNTIFS(Responses!$E$2:$E$315,A31,Responses!$K$2:$K$315,"Yes",Quality_Checks!$I$2:$I$315,1)/B31,0) -> 0.74193548 | D31: =IFERROR(AVERAGEIFS(Responses!$L$2:$L$315,Responses!$E$2:$E$315,A31,Responses!$K$2:$K$315,"Yes",Quality_Checks!$I$2:$I$315,1)/100,0) -> 0.37347826 | E31: =IFERROR(COUNTIFS(Responses!$E$2:$E$315,A31,Responses!$M$2:$M$315,"Yes",Quality_Checks!$I$2:$I$315,1)/B31,0) -> 0.48387097 | F31: =IFERROR(COUNTIFS(Responses!$E$2:$E$315,A31,Responses!$P$2:$P$315,"Yes",Quality_Checks!$I$2:$I$315,1)/B31,0) -> 0.32258065
A32: Other services | B32: =COUNTIFS(Responses!$E$2:$E$315,A32,Quality_Checks!$I$2:$I$315,1) -> 22 | C32: =IFERROR(COUNTIFS(Responses!$E$2:$E$315,A32,Responses!$K$2:$K$315,"Yes",Quality_Checks!$I$2:$I$315,1)/B32,0) -> 0.72727273 | D32: =IFERROR(AVERAGEIFS(Responses!$L$2:$L$315,Responses!$E$2:$E$315,A32,Responses!$K$2:$K$315,"Yes",Quality_Checks!$I$2:$I$315,1)/100,0) -> 0.441875 | E32: =IFERROR(COUNTIFS(Responses!$E$2:$E$315,A32,Responses!$M$2:$M$315,"Yes",Quality_Checks!$I$2:$I$315,1)/B32,0) -> 0.40909091 | F32: =IFERROR(COUNTIFS(Responses!$E$2:$E$315,A32,Responses!$P$2:$P$315,"Yes",Quality_Checks!$I$2:$I$315,1)/B32,0) -> 0.54545455
A33: All valid responses | B33: =SUM(B26:B32) -> 283 | C33: =G5 -> 0.80212014 | D33: =I5 -> 0.42885463 | E33: =COUNTIFS(Responses!$M$2:$M$315,"Yes",Quality_Checks!$I$2:$I$315,1)/SUM(Quality_Checks!$I$2:$I$315) -> 0.45583039 | F33: =K5 -> 0.42756184
A35: 3. M-Pesa adoption by monthly sales band and gender
A36: Group | B36: Valid n | C36: Accept M-Pesa
A37: Sales: KES Under 10,000 | B37: =COUNTIFS(Responses!$J$2:$J$315,"Under 10,000",Quality_Checks!$I$2:$I$315,1) -> 69 | C37: =IFERROR(COUNTIFS(Responses!$J$2:$J$315,"Under 10,000",Responses!$K$2:$K$315,"Yes",Quality_Checks!$I$2:$I$315,1)/B37,0) -> 0.71014493
A38: Sales: KES 10,000 to 30,000 | B38: =COUNTIFS(Responses!$J$2:$J$315,"10,000 to 30,000",Quality_Checks!$I$2:$I$315,1) -> 115 | C38: =IFERROR(COUNTIFS(Responses!$J$2:$J$315,"10,000 to 30,000",Responses!$K$2:$K$315,"Yes",Quality_Checks!$I$2:$I$315,1)/B38,0) -> 0.79130435
A39: Sales: KES 30,001 to 70,000 | B39: =COUNTIFS(Responses!$J$2:$J$315,"30,001 to 70,000",Quality_Checks!$I$2:$I$315,1) -> 66 | C39: =IFERROR(COUNTIFS(Responses!$J$2:$J$315,"30,001 to 70,000",Responses!$K$2:$K$315,"Yes",Quality_Checks!$I$2:$I$315,1)/B39,0) -> 0.86363636
A40: Sales: KES Over 70,000 | B40: =COUNTIFS(Responses!$J$2:$J$315,"Over 70,000",Quality_Checks!$I$2:$I$315,1) -> 33 | C40: =IFERROR(COUNTIFS(Responses!$J$2:$J$315,"Over 70,000",Responses!$K$2:$K$315,"Yes",Quality_Checks!$I$2:$I$315,1)/B40,0) -> 0.90909091
A41: Female | B41: =COUNTIFS(Responses!$H$2:$H$315,A41,Quality_Checks!$I$2:$I$315,1) -> 141 | C41: =IFERROR(COUNTIFS(Responses!$H$2:$H$315,A41,Responses!$K$2:$K$315,"Yes",Quality_Checks!$I$2:$I$315,1)/B41,0) -> 0.82269504
A42: Male | B42: =COUNTIFS(Responses!$H$2:$H$315,A42,Quality_Checks!$I$2:$I$315,1) -> 142 | C42: =IFERROR(COUNTIFS(Responses!$H$2:$H$315,A42,Responses!$K$2:$K$315,"Yes",Quality_Checks!$I$2:$I$315,1)/B42,0) -> 0.78169014
A44: 4. Main barrier among traders who do not accept M-Pesa
A45: Barrier | B45: Traders | C45: % of non-acceptors | D45: Chart label
...

Sheet Assumptions
A1: Assumptions & Parameters
A2: Blue cells are editable inputs. Everything else recalculates from them.
A3: Assumption | B3: Value | C3: Comment
A4: Minimum valid age | B4: 18 | C4: Ages below this are flagged.
A5: Maximum valid age | B5: 80 | C5: Ages above this are flagged.
A6: Minimum interview length (minutes) | B6: 6 | C6: Interviews shorter than this are flagged as too fast.
A7: Enumerator flag-rate alert | B7: 0.1 | C7: An enumerator above this share of flagged interviews is highlighted for follow-up.
A8: Target interviews: Nairobi | B8: 90 | C8: Planned sample.
A9: Target interviews: Kisumu | B9: 70 | C9: Planned sample.
A10: Target interviews: Mombasa | B10: 80 | C10: Planned sample.
A11: Target interviews: Nakuru | B11: 80 | C11: Planned sample.
A12: Total target interviews | B12: =SUM(B8:B11) -> 320 | C12: Calculated.

Sheet Quality_Checks
A1: Submission ID | B1: Duplicate | C1: Missing key field | D1: Age out of range | E1: Too fast | F1: Inconsistent answers | G1: Flags | H1: Status | I1: Include
A2: =Responses!A2 -> S0008 | B2: =IF(COUNTIF(Responses!$A$2:A2,Responses!A2)>1,1,0) -> 0 | C2: =IF(OR(Responses!D2="",Responses!E2="",Responses!J2="",Responses!K2="",Responses!I2=""),1,0) -> 0 | D2: =IF(Responses!I2="",0,IF(OR(Responses!I2<Assumptions!$B$4,Responses!I2>Assumptions!$B$5),1,0)) -> 0 | E2: =IF(Responses!Q2<Assumptions!$B$6,1,0) -> 0 | F2: =IF(OR(AND(Responses!K2="No",Responses!L2<>""),AND(Responses!K2="Yes",Responses!L2="")),1,0) -> 0 | G2: =SUM(B2:F2) -> 0 | H2: =IF(G2=0,"Valid","Review") -> Valid | I2: =IF(G2=0,1,0) -> 1
A3: =Responses!A3 -> S0027 | B3: =IF(COUNTIF(Responses!$A$2:A3,Responses!A3)>1,1,0) -> 0 | C3: =IF(OR(Responses!D3="",Responses!E3="",Responses!J3="",Responses!K3="",Responses!I3=""),1,0) -> 0 | D3: =IF(Responses!I3="",0,IF(OR(Responses!I3<Assumptions!$B$4,Responses!I3>Assumptions!$B$5),1,0)) -> 0 | E3: =IF(Responses!Q3<Assumptions!$B$6,1,0) -> 0 | F3: =IF(OR(AND(Responses!K3="No",Responses!L3<>""),AND(Responses!K3="Yes",Responses!L3="")),1,0) -> 0 | G3: =SUM(B3:F3) -> 0 | H3: =IF(G3=0,"Valid","Review") -> Valid | I3: =IF(G3=0,1,0) -> 1
A4: =Responses!A4 -> S0038 | B4: =IF(COUNTIF(Responses!$A$2:A4,Responses!A4)>1,1,0) -> 0 | C4: =IF(OR(Responses!D4="",Responses!E4="",Responses!J4="",Responses!K4="",Responses!I4=""),1,0) -> 0 | D4: =IF(Responses!I4="",0,IF(OR(Responses!I4<Assumptions!$B$4,Responses!I4>Assumptions!$B$5),1,0)) -> 0 | E4: =IF(Responses!Q4<Assumptions!$B$6,1,0) -> 0 | F4: =IF(OR(AND(Responses!K4="No",Responses!L4<>""),AND(Responses!K4="Yes",Responses!L4="")),1,0) -> 0 | G4: =SUM(B4:F4) -> 0 | H4: =IF(G4=0,"Valid","Review") -> Valid | I4: =IF(G4=0,1,0) -> 1
A5: =Responses!A5 -> S0062 | B5: =IF(COUNTIF(Responses!$A$2:A5,Responses!A5)>1,1,0) -> 0 | C5: =IF(OR(Responses!D5="",Responses!E5="",Responses!J5="",Responses!K5="",Responses!I5=""),1,0) -> 0 | D5: =IF(Responses!I5="",0,IF(OR(Responses!I5<Assumptions!$B$4,Responses!I5>Assumptions!$B$5),1,0)) -> 0 | E5: =IF(Responses!Q5<Assumptions!$B$6,1,0) -> 0 | F5: =IF(OR(AND(Responses!K5="No",Responses!L5<>""),AND(Responses!K5="Yes",Responses!L5="")),1,0) -> 0 | G5: =SUM(B5:F5) -> 0 | H5: =IF(G5=0,"Valid","Review") -> Valid | I5: =IF(G5=0,1,0) -> 1
A6: =Responses!A6 -> S0073 | B6: =IF(COUNTIF(Responses!$A$2:A6,Responses!A6)>1,1,0) -> 0 | C6: =IF(OR(Responses!D6="",Responses!E6="",Responses!J6="",Responses!K6="",Responses!I6=""),1,0) -> 0 | D6: =IF(Responses!I6="",0,IF(OR(Responses!I6<Assumptions!$B$4,Responses!I6>Assumptions!$B$5),1,0)) -> 0 | E6: =IF(Responses!Q6<Assumptions!$B$6,1,0) -> 0 | F6: =IF(OR(AND(Responses!K6="No",Responses!L6<>""),AND(Responses!K6="Yes",Responses!L6="")),1,0) -> 0 | G6: =SUM(B6:F6) -> 0 | H6: =IF(G6=0,"Valid","Review") -> Valid | I6: =IF(G6=0,1,0) -> 1
A7: =Responses!A7 -> S0074 | B7: =IF(COUNTIF(Responses!$A$2:A7,Responses!A7)>1,1,0) -> 0 | C7: =IF(OR(Responses!D7="",Responses!E7="",Responses!J7="",Responses!K7="",Responses!I7=""),1,0) -> 0 | D7: =IF(Responses!I7="",0,IF(OR(Responses!I7<Assumptions!$B$4,Responses!I7>Assumptions!$B$5),1,0)) -> 0 | E7: =IF(Responses!Q7<Assumptions!$B$6,1,0) -> 0 | F7: =IF(OR(AND(Responses!K7="No",Responses!L7<>""),AND(Responses!K7="Yes",Responses!L7="")),1,0) -> 0 | G7: =SUM(B7:F7) -> 0 | H7: =IF(G7=0,"Valid","Review") -> Valid | I7: =IF(G7=0,1,0) -> 1
A8: =Responses!A8 -> S0078 | B8: =IF(COUNTIF(Responses!$A$2:A8,Responses!A8)>1,1,0) -> 0 | C8: =IF(OR(Responses!D8="",Responses!E8="",Responses!J8="",Responses!K8="",Responses!I8=""),1,0) -> 0 | D8: =IF(Responses!I8="",0,IF(OR(Responses!I8<Assumptions!$B$4,Responses!I8>Assumptions!$B$5),1,0)) -> 0 | E8: =IF(Responses!Q8<Assumptions!$B$6,1,0) -> 0 | F8: =IF(OR(AND(Responses!K8="No",Responses!L8<>""),AND(Responses!K8="Yes",Responses!L8="")),1,0) -> 0 | G8: =SUM(B8:F8) -> 0 | H8: =IF(G8=0,"Valid","Review") -> Valid | I8: =IF(G8=0,1,0) -> 1
A9: =Responses!A9 -> S0124 | B9: =IF(COUNTIF(Responses!$A$2:A9,Responses!A9)>1,1,0) -> 0 | C9: =IF(OR(Responses!D9="",Responses!E9="",Responses!J9="",Responses!K9="",Responses!I9=""),1,0) -> 0 | D9: =IF(Responses!I9="",0,IF(OR(Responses!I9<Assumptions!$B$4,Responses!I9>Assumptions!$B$5),1,0)) -> 0 | E9: =IF(Responses!Q9<Assumptions!$B$6,1,0) -> 0 | F9: =IF(OR(AND(Responses!K9="No",Responses!L9<>""),AND(Responses!K9="Yes",Responses!L9="")),1,0) -> 0 | G9: =SUM(B9:F9) -> 0 | H9: =IF(G9=0,"Valid","Review") -> Valid | I9: =IF(G9=0,1,0) -> 1
A10: =Responses!A10 -> S0125 | B10: =IF(COUNTIF(Responses!$A$2:A10,Responses!A10)>1,1,0) -> 0 | C10: =IF(OR(Responses!D10="",Responses!E10="",Responses!J10="",Responses!K10="",Responses!I10=""),1,0) -> 0 | D10: =IF(Responses!I10="",0,IF(OR(Responses!I10<Assumptions!$B$4,Responses!I10>Assumptions!$B$5),1,0)) -> 0 | E10: =IF(Responses!Q10<Assumptions!$B$6,1,0) -> 0 | F10: =IF(OR(AND(Responses!K10="No",Responses!L10<>""),AND(Responses!K10="Yes",Responses!L10="")),1,0) -> 0 | G10: =SUM(B10:F10) -> 0 | H10: =IF(G10=0,"Valid","Review") -> Valid | I10: =IF(G10=0,1,0) -> 1
A11: =Responses!A11 -> S0127 | B11: =IF(COUNTIF(Responses!$A$2:A11,Responses!A11)>1,1,0) -> 0 | C11: =IF(OR(Responses!D11="",Responses!E11="",Responses!J11="",Responses!K11="",Responses!I11=""),1,0) -> 0 | D11: =IF(Responses!I11="",0,IF(OR(Responses!I11<Assumptions!$B$4,Responses!I11>Assumptions!$B$5),1,0)) -> 0 | E11: =IF(Responses!Q11<Assumptions!$B$6,1,0) -> 0 | F11: =IF(OR(AND(Responses!K11="No",Responses!L11<>""),AND(Responses!K11="Yes",Responses!L11="")),1,0) -> 0 | G11: =SUM(B11:F11) -> 0 | H11: =IF(G11=0,"Valid","Review") -> Valid | I11: =IF(G11=0,1,0) -> 1
A12: =Responses!A12 -> S0218 | B12: =IF(COUNTIF(Responses!$A$2:A12,Responses!A12)>1,1,0) -> 0 | C12: =IF(OR(Responses!D12="",Responses!E12="",Responses!J12="",Responses!K12="",Responses!I12=""),1,0) -> 0 | D12: =IF(Responses!I12="",0,IF(OR(Responses!I12<Assumptions!$B$4,Responses!I12>Assumptions!$B$5),1,0)) -> 0 | E12: =IF(Responses!Q12<Assumptions!$B$6,1,0) -> 1 | F12: =IF(OR(AND(Responses!K12="No",Responses!L12<>""),AND(Responses!K12="Yes",Responses!L12="")),1,0) -> 0 | G12: =SUM(B12:F12) -> 1 | H12: =IF(G12=0,"Valid","Review") -> Review | I12: =IF(G12=0,1,0) -> 0
A13: =Responses!A13 -> S0254 | B13: =IF(COUNTIF(Responses!$A$2:A13,Responses!A13)>1,1,0) -> 0 | C13: =IF(OR(Responses!D13="",Responses!E13="",Responses!J13="",Responses!K13="",Responses!I13=""),1,0) -> 0 | D13: =IF(Responses!I13="",0,IF(OR(Responses!I13<Assumptions!$B$4,Responses!I13>Assumptions!$B$5),1,0)) -> 0 | E13: =IF(Responses!Q13<Assumptions!$B$6,1,0) -> 0 | F13: =IF(OR(AND(Responses!K13="No",Responses!L13<>""),AND(Responses!K13="Yes",Responses!L13="")),1,0) -> 0 | G13: =SUM(B13:F13) -> 0 | H13: =IF(G13=0,"Valid","Review") -> Valid | I13: =IF(G13=0,1,0) -> 1
... A315: =Responses!A315 -> S0292 | B315: =IF(COUNTIF(Responses!$A$2:A315,Responses!A315)>1,1,0) -> 0 | C315: =IF(OR(Responses!D315="",Responses!E315="",Responses!J315="",Responses!K315="",Responses!I315=""),1,0) -> 0 | D315: =IF(Responses!I315="",0,IF(OR(Responses!I315<Assumptions!$B$4,Responses!I315>Assumptions!$B$5),1,0)) -> 0 | E315: =IF(Responses!Q315<Assumptions!$B$6,1,0) -> 0 | F315: =IF(OR(AND(Responses!K315="No",Responses!L315<>""),AND(Responses!K315="Yes",Responses!L315="")),1,0) -> 0 | G315: =SUM(B315:F315) -> 0 | H315: =IF(G315=0,"Valid","Review") -> Valid | I315: =IF(G315=0,1,0) -> 1

Sheet Responses
A1: Submission ID | B1: Date | C1: Enumerator | D1: County | E1: Business type | F1: Years operating | G1: Employees | H1: Gender | I1: Age | J1: Monthly sales band (KES) | K1: Accepts M-Pesa | L1: M-Pesa share of sales (%) | M1: Pays suppliers digitally | N1: Main barrier (non-acceptors) | O1: Satisfaction (1-5) | P1: Interested in training | Q1: Interview minutes
A2: S0008 | B2: 46251 | C2: E02 | D2: Nairobi | E2: Grocery kiosk | F2: 3 | G2: 1 | H2: Male | I2: 45 | J2: 10,000 to 30,000 | K2: Yes | L2: 46 | M2: No | O2: 5 | P2: Yes | Q2: 9.4
A3: S0027 | B3: 46251 | C3: E02 | D3: Nairobi | E3: Clothing stall | F3: 4 | G3: 2 | H3: Male | I3: 35 | J3: Under 10,000 | K3: Yes | L3: 90 | M3: Yes | O3: 2 | P3: No | Q3: 17
A4: S0038 | B4: 46251 | C4: E01 | D4: Nairobi | E4: Grocery kiosk | F4: 3 | G4: 2 | H4: Female | I4: 37 | J4: 10,000 to 30,000 | K4: Yes | L4: 57 | M4: Yes | O4: 4 | P4: No | Q4: 12.2
A5: S0062 | B5: 46251 | C5: E01 | D5: Nairobi | E5: Food vendor | F5: 4 | G5: 2 | H5: Female | I5: 35 | J5: Under 10,000 | K5: Yes | L5: 70 | M5: Yes | O5: 5 | P5: No | Q5: 17
A6: S0073 | B6: 46251 | C6: E01 | D6: Nairobi | E6: Boda boda or transport | F6: 0 | G6: 0 | H6: Male | I6: 27 | J6: Under 10,000 | K6: Yes | L6: 70 | M6: No | O6: 4 | P6: No | Q6: 18.7
A7: S0074 | B7: 46251 | C7: E02 | D7: Nairobi | E7: Clothing stall | F7: 11 | G7: 2 | H7: Female | I7: 40 | J7: Over 70,000 | K7: Yes | L7: 69 | M7: Yes | O7: 5 | P7: No | Q7: 12.4
A8: S0078 | B8: 46251 | C8: E02 | D8: Nairobi | E8: Grocery kiosk | F8: 12 | G8: 1 | H8: Female | I8: 38 | J8: Under 10,000 | K8: Yes | L8: 64 | M8: No | O8: 4 | P8: No | Q8: 13.1
A9: S0124 | B9: 46251 | C9: E03 | D9: Kisumu | E9: Grocery kiosk | F9: 6 | G9: 3 | H9: Female | I9: 33 | J9: Under 10,000 | K9: Yes | L9: 5 | M9: No | O9: 4 | P9: No | Q9: 13.1
A10: S0125 | B10: 46251 | C10: E03 | D10: Kisumu | E10: Grocery kiosk | F10: 8 | G10: 1 | H10: Female | I10: 32 | J10: Over 70,000 | K10: Yes | L10: 5 | M10: Yes | O10: 2 | P10: No | Q10: 11.4
A11: S0127 | B11: 46251 | C11: E03 | D11: Kisumu | E11: Hardware shop | F11: 2 | G11: 0 | H11: Male | I11: 19 | J11: Under 10,000 | K11: Yes | L11: 66 | M11: No | O11: 4 | P11: No | Q11: 13.6
A12: S0218 | B12: 46251 | C12: E05 | D12: Mombasa | E12: Other services | F12: 15 | G12: 4 | H12: Male | I12: 26 | J12: 10,000 to 30,000 | K12: Yes | L12: 43 | M12: Yes | O12: 3 | P12: No | Q12: 3
A13: S0254 | B13: 46251 | C13: E07 | D13: Nakuru | E13: Other services | F13: 9 | G13: 0 | H13: Female | I13: 21 | J13: 10,000 to 30,000 | K13: No | M13: Yes | N13: Network or float problems | P13: No | Q13: 12.8
A14: S0259 | B14: 46251 | C14: E06 | D14: Nakuru | E14: Hardware shop | F14: 2 | G14: 1 | H14: Male | I14: 27 | J14: 10,000 to 30,000 | K14: Yes | L14: 47 | M14: No | O14: 3 | P14: Yes | Q14: 18.2
A15: S0268 | B15: 46251 | C15: E07 | D15: Nakuru | E15: Grocery kiosk | F15: 4 | G15: 0 | H15: Female | I15: 35 | J15: 10,000 to 30,000 | K15: Yes | L15: 37 | M15: No | O15: 4 | P15: No | Q15: 15.9
A16: S0015 | B16: 46252 | C16: E01 | D16: Nairobi | E16: Food vendor | F16: 12 | G16: 1 | H16: Male | I16: 20 | J16: 10,000 to 30,000 | K16: Yes | L16: 86 | M16: Yes | O16: 5 | P16: No | Q16: 12.8
A17: S0031 | B17: 46252 | C17: E02 | D17: Nairobi | E17: Grocery kiosk | F17: 5 | G17: 1 | H17: Female | I17: 46 | J17: Under 10,000 | K17: No | M17: No | N17: Customers prefer cash | P17: Yes | Q17: 10.1
A18: S0054 | B18: 46252 | C18: E01 | D18: Nairobi | E18: Other services | F18: 5 | G18: 1 | H18: Female | I18: 31 | J18: 30,001 to 70,000 | K18: Yes | L18: 57 | M18: No | O18: 3 | P18: No | Q18: 10
A19: S0068 | B19: 46252 | C19: E01 | D19: Nairobi | E19: Grocery kiosk | F19: 1 | G19: 1 | H19: Female | I19: 41 | J19: 30,001 to 70,000 | K19: Yes | L19: 46 | M19: Yes | O19: 3 | P19: No | Q19: 11.4
A20: S0085 | B20: 46252 | C20: E01 | D20: Nairobi | E20: Grocery kiosk | F20: 7 | G20: 4 | H20: Male | I20: 23 | J20: 30,001 to 70,000 | K20: Yes | L20: 24 | M20: No | O20: 4 | P20: No | Q20: 17.8
A21: S0111 | B21: 46252 | C21: E03 | D21: Kisumu | E21: Food vendor | F21: 9 | G21: 0 | H21: Female | I21: 40 | J21: Over 70,000 | K21: No | M21: No | N21: Security or fraud worries | P21: Yes | Q21: 14.6
A22: S0123 | B22: 46252 | C22: E03 | D22: Kisumu | E22: Other services | F22: 6 | G22: 1 | H22: Female | I22: 42 | J22: 10,000 to 30,000 | K22: Yes | L22: 18 | M22: No | O22: 4 | P22: Yes | Q22: 10.4
A23: S0139 | B23: 46252 | C23: E03 | D23: Kisumu | E23: Grocery kiosk | F23: 1 | G23: 1 | H23: Female | I23: 34 | J23: 10,000 to 30,000 | K23: Yes | L23: 46 | M23: Yes | O23: 5 | P23: No | Q23: 14.9
A24: S0156 | B24: 46252 | C24: E05 | E24: Food vendor | F24: 4 | G24: 0 | H24: Female | I24: 48 | J24: Under 10,000 | K24: Yes | L24: 28 | M24: Yes | O24: 4 | P24: No | Q24: 5.4
A25: S0180 | B25: 46252 | C25: E05 | D25: Mombasa | E25: Grocery kiosk | F25: 14 | G25: 1 | H25: Female | I25: 19 | J25: 10,000 to 30,000 | K25: Yes | L25: 18 | M25: Yes | O25: 5 | P25: No | Q25: 2.5
A26: S0191 | B26: 46252 | C26: E05 | D26: Mombasa | E26: Salon or barber | F26: 5 | G26: 0 | H26: Female | I26: 30 | J26: 10,000 to 30,000 | K26: Yes | L26: 21 | M26: Yes | O26: 4 | P26: Yes | Q26: 6.3
A27: S0194 | B27: 46252 | C27: E05 | D27: Mombasa | E27: Hardware shop | F27: 7 | G27: 2 | H27: Male | I27: 29 | J27: 10,000 to 30,000 | K27: Yes | L27: 31 | M27: Yes | O27: 5 | P27: No | Q27: 8.4
A28: S0240 | B28: 46252 | C28: E07 | D28: Nakuru | E28: Boda boda or transport | F28: 4 | G28: 2 | H28: Male | I28: 33 | J28: 30,001 to 70,000 | K28: Yes | L28: 67 | M28: No | O28: 5 | P28: No | Q28: 11.7
A29: S0250 | B29: 46252 | C29: E06 | D29: Nakuru | E29: Grocery kiosk | F29: 8 | G29: 0 | H29: Male | I29: 52 | J29: Under 10,000 | K29: Yes | L29: 47 | M29: Yes | O29: 4 | P29: Yes | Q29: 16
A30: S0271 | B30: 46252 | C30: E07 | D30: Nakuru | E30: Boda boda or transport | F30: 3 | G30: 2 | H30: Female | I30: 38 | J30: Under 10,000 | K30: Yes | L30: 35 | M30: Yes | O30: 2 | P30: Yes | Q30: 16.7
A31: S0279 | B31: 46252 | C31: E07 | D31: Nakuru | E31: Food vendor | F31: 12 | G31: 0 | H31: Female | I31: 32 | J31: 30,001 to 70,000 | K31: Yes | L31: 54 | M31: Yes | O31: 2 | P31: No | Q31: 12.8
A32: S0307 | B32: 46252 | C32: E07 | D32: Nakuru | E32: Clothing stall | F32: 0 | G32: 1 | H32: Female | I32: 44 | J32: Over 70,000 | K32: Yes | L32: 37 | M32: Yes | O32: 4 | P32: No | Q32: 13.7
A33: S0025 | B33: 46253 | C33: E01 | D33: Nairobi | E33: Clothing stall | F33: 4 | G33: 2 | H33: Female | I33: 40 | J33: Under 10,000 | K33: Yes | L33: 31 | M33: No | O33: 5 | P33: No | Q33: 12.6
A34: S0029 | B34: 46253 | C34: E01 | D34: Nairobi | E34: Food vendor | F34: 2 | G34: 2 | H34: Male | I34: 38 | J34: 10,000 to 30,000 | K34: Yes | L34: 77 | M34: Yes | O34: 4 | P34: Yes | Q34: 17.7
A35: S0057 | B35: 46253 | C35: E01 | D35: Nairobi | E35: Other services | F35: 5 | G35: 1 | H35: Female | I35: 40 | J35: 10,000 to 30,000 | K35: No | M35: Yes | N35: Security or fraud worries | P35: No | Q35: 16.7
A36: S0060 | B36: 46253 | C36: E01 | D36: Nairobi | E36: Hardware shop | F36: 2 | G36: 1 | H36: Male | I36: 57 | J36: 30,001 to 70,000 | K36: Yes | L36: 43 | M36: No | O36: 5 | P36: Yes | Q36: 13.9
A37: S0075 | B37: 46253 | C37: E01 | D37: Nairobi | E37: Hardware shop | F37: 3 | G37: 3 | H37: Female | I37: 45 | J37: 30,001 to 70,000 | K37: Yes | L37: 75 | M37: Yes | O37: 2 | P37: No | Q37: 14.9
A38: S0090 | B38: 46253 | C38: E03 | D38: Kisumu | E38: Food vendor | F38: 0 | G38: 0 | H38: Female | I38: 7 | J38: 30,001 to 70,000 | K38: Yes | L38: 40 | M38: No | O38: 4 | P38: Yes | Q38: 16.2
A39: S0097 | B39: 46253 | C39: E03 | D39: Kisumu | E39: Other services | F39: 3 | G39: 2 | H39: Male | I39: 26 | J39: 10,000 to 30,000 | K39: No | M39: No | N39: Do not know how, need training | P39: Yes | Q39: 17.6
A40: S0117 | B40: 46253 | C40: E03 | D40: Kisumu | E40: Food vendor | F40: 5 | G40: 1 | H40: Male | I40: 56 | J40: 10,000 to 30,000 | K40: No | M40: No | N40: Transaction fees | P40: Yes | Q40: 9.3
...
