Workbook

Sheet README
A1: Digital Marketing Performance & ROI – Marketing Analytics Portfolio Project
A2: BZME Insights | Sector: Marketing / E-commerce | Tool: Excel (formula-driven)
A4: BUSINESS PROBLEM
A5: An online retailer runs 30 campaigns across six channels, but the marketing manager cannot see which channels and campaigns earn their budget, and which should be scaled, fixed or stopped. This workbook gives that decision view.
A7: BUSINESS QUESTIONS
A8: 1. What return (ROAS) does each channel and campaign deliver?
A9: 2. Where is spend not earning its keep?
A10: 3. What are the cost per order and cost per lead by channel?
A11: 4. Which campaigns overspent their budget?
A12: 5. What could reallocating budget add in revenue?
A14: HOW THE WORKBOOK IS BUILT
A15: Daily_Performance: 1,310 campaign-day records (impressions, clicks, leads, orders, revenue, spend), Jul-Sep 2026.
... A34: Set weekly budget pacing alerts to stop overspend.

Sheet Dashboard
A1: Digital Marketing Performance & ROI Dashboard
A2: ="Fictional Kenyan online home-goods retailer | Synthetic data | "&TEXT(Assumptions!B5,"d mmm yyyy")&" to "&TEXT(Assumptions!B4,"d mmm yyyy")&" | Prepared by BZME Insights" -> Fictional Kenyan online home-goods retailer | Synthetic data | 1 Jul 2026 to 30 Sep 2026 | Prepared by BZME Insights
A4: TOTAL AD SPEND (KES) | C4: REVENUE (KES) | E4: ROAS (REVENUE / SPEND) | G4: ORDERS | I4: COST PER ORDER (KES) | K4: LEADS
A5: =SUM(Daily_Performance!$H$2:$H$1311) -> 8080939 | C5: =SUM(Daily_Performance!$G$2:$G$1311) -> 35766290 | E5: =C5/A5 -> 4.4260067 | G5: =SUM(Daily_Performance!$F$2:$F$1311) -> 10681 | I5: =IFERROR(A5/G5,0) -> 756.57139 | K5: =SUM(Daily_Performance!$E$2:$E$1311) -> 21834
A7: Key findings (update automatically)
A8: ="1. KES "&TEXT(A5/1000000,"#,##0.0")&"M of ad spend generated KES "&TEXT(C5/1000000,"#,##0.0")&"M in revenue (ROAS "&TEXT(E5,"0.0")&") from "&TEXT(G5,"#,##0")&" orders at KES "&TEXT(I5,"#,##0")&" per order." -> 1. KES 8.1M of ad spend generated KES 35.8M in revenue (ROAS 4.4) from 10,681 orders at KES 757 per order.
A9: ="2. "&INDEX(A34:A39,MATCH(MAX(D34:D39),D34:D39,0))&" delivers the best return (ROAS "&TEXT(MAX(D34:D39),"0.0")&"); "&INDEX(A34:A39,MATCH(MIN(D34:D39),D34:D39,0))&" the weakest ("&TEXT(MIN(D34:D39),"0.0")&")." -> 2. Google Search Ads delivers the best return (ROAS 10.7); Influencer Partnerships the weakest (0.8).
A10: ="3. "&B62&" campaigns are flagged Pause / Rework. They absorb "&TEXT(F62,"0%")&" of spend at ROAS "&TEXT(E62,"0.0")&", against "&TEXT(E64,"0.0")&" overall." -> 3. 8 campaigns are flagged Pause / Rework. They absorb 32% of spend at ROAS 0.8, against 4.4 overall.
A11: ="4. "&INDEX(A34:A39,MATCH(MAX(H34:H39),H34:H39,0))&" takes the largest share of budget ("&TEXT(MAX(H34:H39),"0%")&") but delivers "&TEXT(INDEX(I34:I39,MATCH(MAX(H34:H39),H34:H39,0)),"0%")&" of revenue." -> 4. Facebook & Instagram Ads takes the largest share of budget (25%) but delivers 9% of revenue.
A12: ="5. Moving Pause / Rework budget into Scale campaigns could add roughly KES "&TEXT(D87/1000000,"#,##0.0")&"M of revenue, assuming moved budget earns "&TEXT(Assumptions!B9,"0%")&" of the proven ROAS." -> 5. Moving Pause / Rework budget into Scale campaigns could add roughly KES 5.5M of revenue, assuming moved budget earns 40% of the proven ROAS.
A13: ="6. "&COUNTIF(Campaigns!$T$2:$T$31,">1")&" campaigns spent over their budget; track pacing weekly to avoid overspend." -> 6. 8 campaigns spent over their budget; track pacing weekly to avoid overspend.
A14: ="7. Lead-generation campaigns produced "&TEXT(SUMIFS(Campaigns!$K$2:$K$31,Campaigns!$D$2:$D$31,"Leads"),"#,##0")&" leads at KES "&TEXT(IFERROR(SUMIFS(Campaigns!$H$2:$H$31,Campaigns!$D$2:$D$31,"Leads")/SUMIFS(Campaigns!$K$2:$K$31,Campaigns!$D$2:$D$31,"Leads"),0),"#,##0")&" per lead." -> 7. Lead-generation campaigns produced 10,850 leads at KES 184 per lead.
A16: 1. Monthly trend
A17: Month start | B17: Month | C17: Spend (KES) | D17: Revenue (KES) | E17: ROAS | F17: Orders
A18: =DATE(YEAR(Assumptions!$B$5),MONTH(Assumptions!$B$5),1) -> 46204 | B18: =TEXT(A18,"mmm") -> Jul | C18: =SUMIFS(Daily_Performance!$H$2:$H$1311,Daily_Performance!$J$2:$J$1311,A18) -> 2347897 | D18: =SUMIFS(Daily_Performance!$G$2:$G$1311,Daily_Performance!$J$2:$J$1311,A18) -> 10459780 | E18: =IFERROR(D18/C18,0) -> 4.4549569 | F18: =SUMIFS(Daily_Performance!$F$2:$F$1311,Daily_Performance!$J$2:$J$1311,A18) -> 3106
A19: =EDATE(A18,1) -> 46235 | B19: =TEXT(A19,"mmm") -> Aug | C19: =SUMIFS(Daily_Performance!$H$2:$H$1311,Daily_Performance!$J$2:$J$1311,A19) -> 3399857 | D19: =SUMIFS(Daily_Performance!$G$2:$G$1311,Daily_Performance!$J$2:$J$1311,A19) -> 15948690 | E19: =IFERROR(D19/C19,0) -> 4.6909885 | F19: =SUMIFS(Daily_Performance!$F$2:$F$1311,Daily_Performance!$J$2:$J$1311,A19) -> 4862
A20: =EDATE(A19,1) -> 46266 | B20: =TEXT(A20,"mmm") -> Sep | C20: =SUMIFS(Daily_Performance!$H$2:$H$1311,Daily_Performance!$J$2:$J$1311,A20) -> 2333185 | D20: =SUMIFS(Daily_Performance!$G$2:$G$1311,Daily_Performance!$J$2:$J$1311,A20) -> 9357820 | E20: =IFERROR(D20/C20,0) -> 4.0107493 | F20: =SUMIFS(Daily_Performance!$F$2:$F$1311,Daily_Performance!$J$2:$J$1311,A20) -> 2713
A32: 2. Channel performance
A33: Channel | B33: Spend (KES) | C33: Revenue (KES) | D33: ROAS | E33: Cost per Order (KES) | F33: CTR | G33: Conv. Rate | H33: % of Spend | I33: % of Revenue
A34: Facebook & Instagram Ads | B34: =SUMIFS(Daily_Performance!$H$2:$H$1311,Daily_Performance!$I$2:$I$1311,A34) -> 2026291 | C34: =SUMIFS(Daily_Performance!$G$2:$G$1311,Daily_Performance!$I$2:$I$1311,A34) -> 3360150 | D34: =IFERROR(C34/B34,0) -> 1.6582761 | E34: =IFERROR(B34/SUMIFS(Daily_Performance!$F$2:$F$1311,Daily_Performance!$I$2:$I$1311,A34),0) -> 1974.9425 | F34: =IFERROR(SUMIFS(Daily_Performance!$D$2:$D$1311,Daily_Performance!$I$2:$I$1311,A34)/SUMIFS(Daily_Performance!$C$2:$C$1311,Daily_Performance!$I$2:$I$1311,A34),0) -> 0.01326697 | G34: =IFERROR(SUMIFS(Daily_Performance!$F$2:$F$1311,Daily_Performance!$I$2:$I$1311,A34)/SUMIFS(Daily_Performance!$D$2:$D$1311,Daily_Performance!$I$2:$I$1311,A34),0) -> 0.0095175369 | H34: =IFERROR(B34/B$40,0) -> 0.25074945 | I34: =IFERROR(C34/C$40,0) -> 0.093947401
A35: Google Search Ads | B35: =SUMIFS(Daily_Performance!$H$2:$H$1311,Daily_Performance!$I$2:$I$1311,A35) -> 1723413 | C35: =SUMIFS(Daily_Performance!$G$2:$G$1311,Daily_Performance!$I$2:$I$1311,A35) -> 18491200 | D35: =IFERROR(C35/B35,0) -> 10.729407 | E35: =IFERROR(B35/SUMIFS(Daily_Performance!$F$2:$F$1311,Daily_Performance!$I$2:$I$1311,A35),0) -> 345.92794 | F35: =IFERROR(SUMIFS(Daily_Performance!$D$2:$D$1311,Daily_Performance!$I$2:$I$1311,A35)/SUMIFS(Daily_Performance!$C$2:$C$1311,Daily_Performance!$I$2:$I$1311,A35),0) -> 0.050304503 | G35: =IFERROR(SUMIFS(Daily_Performance!$F$2:$F$1311,Daily_Performance!$I$2:$I$1311,A35)/SUMIFS(Daily_Performance!$D$2:$D$1311,Daily_Performance!$I$2:$I$1311,A35),0) -> 0.051502057 | H35: =IFERROR(B35/B$40,0) -> 0.2132689 | I35: =IFERROR(C35/C$40,0) -> 0.51700078
A36: TikTok Ads | B36: =SUMIFS(Daily_Performance!$H$2:$H$1311,Daily_Performance!$I$2:$I$1311,A36) -> 1620716 | C36: =SUMIFS(Daily_Performance!$G$2:$G$1311,Daily_Performance!$I$2:$I$1311,A36) -> 2552380 | D36: =IFERROR(C36/B36,0) -> 1.5748472 | E36: =IFERROR(B36/SUMIFS(Daily_Performance!$F$2:$F$1311,Daily_Performance!$I$2:$I$1311,A36),0) -> 1709.616 | F36: =IFERROR(SUMIFS(Daily_Performance!$D$2:$D$1311,Daily_Performance!$I$2:$I$1311,A36)/SUMIFS(Daily_Performance!$C$2:$C$1311,Daily_Performance!$I$2:$I$1311,A36),0) -> 0.0084199315 | G36: =IFERROR(SUMIFS(Daily_Performance!$F$2:$F$1311,Daily_Performance!$I$2:$I$1311,A36)/SUMIFS(Daily_Performance!$D$2:$D$1311,Daily_Performance!$I$2:$I$1311,A36),0) -> 0.012475326 | H36: =IFERROR(B36/B$40,0) -> 0.20056036 | I36: =IFERROR(C36/C$40,0) -> 0.071362727
A37: Email | B37: =SUMIFS(Daily_Performance!$H$2:$H$1311,Daily_Performance!$I$2:$I$1311,A37) -> 610983 | C37: =SUMIFS(Daily_Performance!$G$2:$G$1311,Daily_Performance!$I$2:$I$1311,A37) -> 5667480 | D37: =IFERROR(C37/B37,0) -> 9.2760028 | E37: =IFERROR(B37/SUMIFS(Daily_Performance!$F$2:$F$1311,Daily_Performance!$I$2:$I$1311,A37),0) -> 332.4173 | F37: =IFERROR(SUMIFS(Daily_Performance!$D$2:$D$1311,Daily_Performance!$I$2:$I$1311,A37)/SUMIFS(Daily_Performance!$C$2:$C$1311,Daily_Performance!$I$2:$I$1311,A37),0) -> 0.029158619 | G37: =IFERROR(SUMIFS(Daily_Performance!$F$2:$F$1311,Daily_Performance!$I$2:$I$1311,A37)/SUMIFS(Daily_Performance!$D$2:$D$1311,Daily_Performance!$I$2:$I$1311,A37),0) -> 0.036094419 | H37: =IFERROR(B37/B$40,0) -> 0.075607921 | I37: =IFERROR(C37/C$40,0) -> 0.15845871
A38: WhatsApp Broadcast | B38: =SUMIFS(Daily_Performance!$H$2:$H$1311,Daily_Performance!$I$2:$I$1311,A38) -> 465962 | C38: =SUMIFS(Daily_Performance!$G$2:$G$1311,Daily_Performance!$I$2:$I$1311,A38) -> 4436420 | D38: =IFERROR(C38/B38,0) -> 9.520991 | E38: =IFERROR(B38/SUMIFS(Daily_Performance!$F$2:$F$1311,Daily_Performance!$I$2:$I$1311,A38),0) -> 304.3514 | F38: =IFERROR(SUMIFS(Daily_Performance!$D$2:$D$1311,Daily_Performance!$I$2:$I$1311,A38)/SUMIFS(Daily_Performance!$C$2:$C$1311,Daily_Performance!$I$2:$I$1311,A38),0) -> 0.064535141 | G38: =IFERROR(SUMIFS(Daily_Performance!$F$2:$F$1311,Daily_Performance!$I$2:$I$1311,A38)/SUMIFS(Daily_Performance!$D$2:$D$1311,Daily_Performance!$I$2:$I$1311,A38),0) -> 0.071335383 | H38: =IFERROR(B38/B$40,0) -> 0.057661863 | I38: =IFERROR(C38/C$40,0) -> 0.12403914
A39: Influencer Partnerships | B39: =SUMIFS(Daily_Performance!$H$2:$H$1311,Daily_Performance!$I$2:$I$1311,A39) -> 1633574 | C39: =SUMIFS(Daily_Performance!$G$2:$G$1311,Daily_Performance!$I$2:$I$1311,A39) -> 1258660 | D39: =IFERROR(C39/B39,0) -> 0.77049463 | E39: =IFERROR(B39/SUMIFS(Daily_Performance!$F$2:$F$1311,Daily_Performance!$I$2:$I$1311,A39),0) -> 4588.691 | F39: =IFERROR(SUMIFS(Daily_Performance!$D$2:$D$1311,Daily_Performance!$I$2:$I$1311,A39)/SUMIFS(Daily_Performance!$C$2:$C$1311,Daily_Performance!$I$2:$I$1311,A39),0) -> 0.0092192255 | G39: =IFERROR(SUMIFS(Daily_Performance!$F$2:$F$1311,Daily_Performance!$I$2:$I$1311,A39)/SUMIFS(Daily_Performance!$D$2:$D$1311,Daily_Performance!$I$2:$I$1311,A39),0) -> 0.014275975 | H39: =IFERROR(B39/B$40,0) -> 0.20215151 | I39: =IFERROR(C39/C$40,0) -> 0.035191237
A40: Total | B40: =SUM(B34:B39) -> 8080939 | C40: =SUM(C34:C39) -> 35766290 | D40: =IFERROR(C40/B40,0) -> 4.4260067 | E40: =IFERROR(B40/SUM(Daily_Performance!$F$2:$F$1311),0) -> 756.57139 | F40: =IFERROR(SUM(Daily_Performance!$D$2:$D$1311)/SUM(Daily_Performance!$C$2:$C$1311),0) -> 0.015837729 | G40: =IFERROR(SUM(Daily_Performance!$F$2:$F$1311)/SUM(Daily_Performance!$D$2:$D$1311),0) -> 0.02826813 | H40: =SUM(H34:H39) -> 1 | I40: =SUM(I34:I39) -> 1
A58: 3. Campaign actions (based on ROAS thresholds in Assumptions)
A59: Action | B59: Campaigns | C59: Spend (KES) | D59: Revenue (KES) | E59: ROAS | F59: % of Spend
A60: Scale | B60: =COUNTIF(Campaigns!$U$2:$U$31,A60) -> 11 | C60: =SUMIFS(Campaigns!$H$2:$H$31,Campaigns!$U$2:$U$31,A60) -> 2159945 | D60: =SUMIFS(Campaigns!$M$2:$M$31,Campaigns!$U$2:$U$31,A60) -> 26138040 | E60: =IFERROR(D60/C60,0) -> 12.101253 | F60: =IFERROR(C60/C$64,0) -> 0.26728886
A61: Optimise | B61: =COUNTIF(Campaigns!$U$2:$U$31,A61) -> 9 | C61: =SUMIFS(Campaigns!$H$2:$H$31,Campaigns!$U$2:$U$31,A61) -> 2341023 | D61: =SUMIFS(Campaigns!$M$2:$M$31,Campaigns!$U$2:$U$31,A61) -> 7062810 | E61: =IFERROR(D61/C61,0) -> 3.0169759 | F61: =IFERROR(C61/C$64,0) -> 0.2896969
A62: Pause / Rework | B62: =COUNTIF(Campaigns!$U$2:$U$31,A62) -> 8 | C62: =SUMIFS(Campaigns!$H$2:$H$31,Campaigns!$U$2:$U$31,A62) -> 2626096 | D62: =SUMIFS(Campaigns!$M$2:$M$31,Campaigns!$U$2:$U$31,A62) -> 2216560 | E62: =IFERROR(D62/C62,0) -> 0.8440514 | F62: =IFERROR(C62/C$64,0) -> 0.32497412
A63: Review (awareness) | B63: =COUNTIF(Campaigns!$U$2:$U$31,A63) -> 2 | C63: =SUMIFS(Campaigns!$H$2:$H$31,Campaigns!$U$2:$U$31,A63) -> 953875 | D63: =SUMIFS(Campaigns!$M$2:$M$31,Campaigns!$U$2:$U$31,A63) -> 348880 | E63: =IFERROR(D63/C63,0) -> 0.36575023 | F63: =IFERROR(C63/C$64,0) -> 0.11804012
A64: Total | B64: =SUM(B60:B63) -> 30 | C64: =SUM(C60:C63) -> 8080939 | D64: =SUM(D60:D63) -> 35766290 | E64: =IFERROR(D64/C64,0) -> 4.4260067 | F64: =SUM(F60:F63) -> 1
A67: 4. Best and worst campaigns by ROAS (excluding awareness)
A68: Top 5 by ROAS | G68: Bottom 5 by ROAS
A69: Rank | B69: Campaign | C69: Channel | D69: Spend (KES) | E69: ROAS | G69: Rank | H69: Campaign | I69: Channel | J69: Spend (KES) | K69: ROAS
A70: 1 | B70: =INDEX(Campaigns!$B$2:$B$31,MATCH(A70,Campaigns!$V$2:$V$31,0)) -> WhatsApp - Cart Recovery | C70: =INDEX(Campaigns!$C$2:$C$31,MATCH(A70,Campaigns!$V$2:$V$31,0)) -> WhatsApp Broadcast | D70: =INDEX(Campaigns!$H$2:$H$31,MATCH(A70,Campaigns!$V$2:$V$31,0)) -> 125010 | E70: =INDEX(Campaigns!$R$2:$R$31,MATCH(A70,Campaigns!$V$2:$V$31,0)) -> 19.590193 | G70: =COUNTIF(Campaigns!$D$2:$D$31,"<>Awareness")-0 -> 28 | H70: =INDEX(Campaigns!$B$2:$B$31,MATCH(G70,Campaigns!$V$2:$V$31,0)) -> Influencer - Home Makeover Guide | I70: =INDEX(Campaigns!$C$2:$C$31,MATCH(G70,Campaigns!$V$2:$V$31,0)) -> Influencer Partnerships | J70: =INDEX(Campaigns!$H$2:$H$31,MATCH(G70,Campaigns!$V$2:$V$31,0)) -> 416396 | K70: =INDEX(Campaigns!$R$2:$R$31,MATCH(G70,Campaigns!$V$2:$V$31,0)) -> 0.53766126
A71: 2 | B71: =INDEX(Campaigns!$B$2:$B$31,MATCH(A71,Campaigns!$V$2:$V$31,0)) -> Google - Back-to-School Sale | C71: =INDEX(Campaigns!$C$2:$C$31,MATCH(A71,Campaigns!$V$2:$V$31,0)) -> Google Search Ads | D71: =INDEX(Campaigns!$H$2:$H$31,MATCH(A71,Campaigns!$V$2:$V$31,0)) -> 505878 | E71: =INDEX(Campaigns!$R$2:$R$31,MATCH(A71,Campaigns!$V$2:$V$31,0)) -> 14.74312 | G71: =COUNTIF(Campaigns!$D$2:$D$31,"<>Awareness")-1 -> 27 | H71: =INDEX(Campaigns!$B$2:$B$31,MATCH(G71,Campaigns!$V$2:$V$31,0)) -> Influencer - Cart Recovery | I71: =INDEX(Campaigns!$C$2:$C$31,MATCH(G71,Campaigns!$V$2:$V$31,0)) -> Influencer Partnerships | J71: =INDEX(Campaigns!$H$2:$H$31,MATCH(G71,Campaigns!$V$2:$V$31,0)) -> 179421 | K71: =INDEX(Campaigns!$R$2:$R$31,MATCH(G71,Campaigns!$V$2:$V$31,0)) -> 0.70119997
A72: 3 | B72: =INDEX(Campaigns!$B$2:$B$31,MATCH(A72,Campaigns!$V$2:$V$31,0)) -> Email - Clearance Event | C72: =INDEX(Campaigns!$C$2:$C$31,MATCH(A72,Campaigns!$V$2:$V$31,0)) -> Email | D72: =INDEX(Campaigns!$H$2:$H$31,MATCH(A72,Campaigns!$V$2:$V$31,0)) -> 137404 | E72: =INDEX(Campaigns!$R$2:$R$31,MATCH(A72,Campaigns!$V$2:$V$31,0)) -> 13.097144 | G72: =COUNTIF(Campaigns!$D$2:$D$31,"<>Awareness")-2 -> 26 | H72: =INDEX(Campaigns!$B$2:$B$31,MATCH(G72,Campaigns!$V$2:$V$31,0)) -> TikTok - Home Makeover Guide | I72: =INDEX(Campaigns!$C$2:$C$31,MATCH(G72,Campaigns!$V$2:$V$31,0)) -> TikTok Ads | J72: =INDEX(Campaigns!$H$2:$H$31,MATCH(G72,Campaigns!$V$2:$V$31,0)) -> 117670 | K72: =INDEX(Campaigns!$R$2:$R$31,MATCH(G72,Campaigns!$V$2:$V$31,0)) -> 0.73459675
A73: 4 | B73: =INDEX(Campaigns!$B$2:$B$31,MATCH(A73,Campaigns!$V$2:$V$31,0)) -> Email - Referral Bonus | C73: =INDEX(Campaigns!$C$2:$C$31,MATCH(A73,Campaigns!$V$2:$V$31,0)) -> Email | D73: =INDEX(Campaigns!$H$2:$H$31,MATCH(A73,Campaigns!$V$2:$V$31,0)) -> 135193 | E73: =INDEX(Campaigns!$R$2:$R$31,MATCH(A73,Campaigns!$V$2:$V$31,0)) -> 12.265576 | G73: =COUNTIF(Campaigns!$D$2:$D$31,"<>Awareness")-3 -> 25 | H73: =INDEX(Campaigns!$B$2:$B$31,MATCH(G73,Campaigns!$V$2:$V$31,0)) -> Influencer - Loyalty Rewards | I73: =INDEX(Campaigns!$C$2:$C$31,MATCH(G73,Campaigns!$V$2:$V$31,0)) -> Influencer Partnerships | J73: =INDEX(Campaigns!$H$2:$H$31,MATCH(G73,Campaigns!$V$2:$V$31,0)) -> 289426 | K73: =INDEX(Campaigns!$R$2:$R$31,MATCH(G73,Campaigns!$V$2:$V$31,0)) -> 0.7944345
...

Sheet Assumptions
A1: Assumptions & Parameters
A2: Blue cells are editable inputs. Everything else recalculates from them.
A4: As-of date | B4: 46295 | C4: Last day of data.
A5: Period start | B5: 46204 | C5: First day of data.
A6: Months in period | B6: =(YEAR(B4)-YEAR(B5))*12+MONTH(B4)-MONTH(B5)+1 -> 3 | C6: Calculated.
A7: Scale: ROAS at or above | B7: 6 | C7: Return on ad spend (revenue / spend). Campaign is a candidate to scale.
A8: Pause / rework: ROAS below | B8: 2 | C8: Below this, spend is not earning its keep.
A9: Reallocation efficiency | B9: 0.4 | C9: Share of the proven (Scale + Optimise) ROAS assumed achievable on moved budget, because returns diminish as spend grows.
A11: Between the two ROAS thresholds a campaign is 'Optimise'. Awareness campaigns are reviewed on reach and cost per 1,000 impressions, not ROAS.

Sheet Campaigns
A1: CampaignID | B1: Campaign | C1: Channel | D1: Objective | E1: Start | F1: End | G1: Budget (KES) | H1: Spend (KES) | I1: Impressions | J1: Clicks | K1: Leads | L1: Orders | M1: Revenue (KES) | N1: CTR | O1: Cost per Click | P1: Cost per Lead | Q1: Cost per Order | R1: ROAS | S1: Conv. Rate | T1: Budget Used | U1: Action | V1: ROAS Rank
A2: CMP001 | B2: Google - Cart Recovery | C2: Google Search Ads | D2: Sales | E2: 46215 | F2: 46281 | G2: 420000 | H2: =SUMIFS(Daily_Performance!$H$2:$H$1311,Daily_Performance!$B$2:$B$1311,A2) -> 320522 | I2: =SUMIFS(Daily_Performance!$C$2:$C$1311,Daily_Performance!$B$2:$B$1311,A2) -> 357604 | J2: =SUMIFS(Daily_Performance!$D$2:$D$1311,Daily_Performance!$B$2:$B$1311,A2) -> 13734 | K2: =SUMIFS(Daily_Performance!$E$2:$E$1311,Daily_Performance!$B$2:$B$1311,A2) -> 528 | L2: =SUMIFS(Daily_Performance!$F$2:$F$1311,Daily_Performance!$B$2:$B$1311,A2) -> 379 | M2: =SUMIFS(Daily_Performance!$G$2:$G$1311,Daily_Performance!$B$2:$B$1311,A2) -> 1418470 | N2: =IFERROR(J2/I2,0) -> 0.038405611 | O2: =IFERROR(H2/J2,0) -> 23.337848 | P2: =IFERROR(H2/K2,0) -> 607.04924 | Q2: =IFERROR(H2/L2,0) -> 845.70449 | R2: =IFERROR(M2/H2,0) -> 4.4254997 | S2: =IFERROR(L2/J2,0) -> 0.027595748 | T2: =IFERROR(H2/G2,0) -> 0.76314762 | U2: =IF(D2="Awareness","Review (awareness)",IF(R2>=Assumptions!$B$7,"Scale",IF(R2>=Assumptions!$B$8,"Optimise","Pause / Rework"))) -> Optimise | V2: =IF(D2="Awareness","",COUNTIFS($D$2:$D$31,"<>Awareness",$R$2:$R$31,">"&R2)+COUNTIFS($D$2:D2,"<>Awareness",$R$2:R2,R2)) -> 12
A3: CMP002 | B3: Email - Clearance Event | C3: Email | D3: Sales | E3: 46218 | F3: 46275 | G3: 140000 | H3: =SUMIFS(Daily_Performance!$H$2:$H$1311,Daily_Performance!$B$2:$B$1311,A3) -> 137404 | I3: =SUMIFS(Daily_Performance!$C$2:$C$1311,Daily_Performance!$B$2:$B$1311,A3) -> 392509 | J3: =SUMIFS(Daily_Performance!$D$2:$D$1311,Daily_Performance!$B$2:$B$1311,A3) -> 12908 | K3: =SUMIFS(Daily_Performance!$E$2:$E$1311,Daily_Performance!$B$2:$B$1311,A3) -> 508 | L3: =SUMIFS(Daily_Performance!$F$2:$F$1311,Daily_Performance!$B$2:$B$1311,A3) -> 584 | M3: =SUMIFS(Daily_Performance!$G$2:$G$1311,Daily_Performance!$B$2:$B$1311,A3) -> 1799600 | N3: =IFERROR(J3/I3,0) -> 0.03288587 | O3: =IFERROR(H3/J3,0) -> 10.644871 | P3: =IFERROR(H3/K3,0) -> 270.48031 | Q3: =IFERROR(H3/L3,0) -> 235.28082 | R3: =IFERROR(M3/H3,0) -> 13.097144 | S3: =IFERROR(L3/J3,0) -> 0.04524326 | T3: =IFERROR(H3/G3,0) -> 0.98145714 | U3: =IF(D3="Awareness","Review (awareness)",IF(R3>=Assumptions!$B$7,"Scale",IF(R3>=Assumptions!$B$8,"Optimise","Pause / Rework"))) -> Scale | V3: =IF(D3="Awareness","",COUNTIFS($D$2:$D$31,"<>Awareness",$R$2:$R$31,">"&R3)+COUNTIFS($D$2:D3,"<>Awareness",$R$2:R3,R3)) -> 3
A4: CMP003 | B4: Influencer - Loyalty Rewards | C4: Influencer Partnerships | D4: Leads | E4: 46253 | F4: 46286 | G4: 365000 | H4: =SUMIFS(Daily_Performance!$H$2:$H$1311,Daily_Performance!$B$2:$B$1311,A4) -> 289426 | I4: =SUMIFS(Daily_Performance!$C$2:$C$1311,Daily_Performance!$B$2:$B$1311,A4) -> 481039 | J4: =SUMIFS(Daily_Performance!$D$2:$D$1311,Daily_Performance!$B$2:$B$1311,A4) -> 4658 | K4: =SUMIFS(Daily_Performance!$E$2:$E$1311,Daily_Performance!$B$2:$B$1311,A4) -> 638 | L4: =SUMIFS(Daily_Performance!$F$2:$F$1311,Daily_Performance!$B$2:$B$1311,A4) -> 69 | M4: =SUMIFS(Daily_Performance!$G$2:$G$1311,Daily_Performance!$B$2:$B$1311,A4) -> 229930 | N4: =IFERROR(J4/I4,0) -> 0.0096832066 | O4: =IFERROR(H4/J4,0) -> 62.135251 | P4: =IFERROR(H4/K4,0) -> 453.64577 | Q4: =IFERROR(H4/L4,0) -> 4194.5797 | R4: =IFERROR(M4/H4,0) -> 0.7944345 | S4: =IFERROR(L4/J4,0) -> 0.014813225 | T4: =IFERROR(H4/G4,0) -> 0.79294795 | U4: =IF(D4="Awareness","Review (awareness)",IF(R4>=Assumptions!$B$7,"Scale",IF(R4>=Assumptions!$B$8,"Optimise","Pause / Rework"))) -> Pause / Rework | V4: =IF(D4="Awareness","",COUNTIFS($D$2:$D$31,"<>Awareness",$R$2:$R$31,">"&R4)+COUNTIFS($D$2:D4,"<>Awareness",$R$2:R4,R4)) -> 25
A5: CMP004 | B5: WhatsApp - Payday Promo | C5: WhatsApp Broadcast | D5: Sales | E5: 46217 | F5: 46244 | G5: 40000 | H5: =SUMIFS(Daily_Performance!$H$2:$H$1311,Daily_Performance!$B$2:$B$1311,A5) -> 41887 | I5: =SUMIFS(Daily_Performance!$C$2:$C$1311,Daily_Performance!$B$2:$B$1311,A5) -> 30193 | J5: =SUMIFS(Daily_Performance!$D$2:$D$1311,Daily_Performance!$B$2:$B$1311,A5) -> 1764 | K5: =SUMIFS(Daily_Performance!$E$2:$E$1311,Daily_Performance!$B$2:$B$1311,A5) -> 69 | L5: =SUMIFS(Daily_Performance!$F$2:$F$1311,Daily_Performance!$B$2:$B$1311,A5) -> 62 | M5: =SUMIFS(Daily_Performance!$G$2:$G$1311,Daily_Performance!$B$2:$B$1311,A5) -> 162970 | N5: =IFERROR(J5/I5,0) -> 0.058424138 | O5: =IFERROR(H5/J5,0) -> 23.745465 | P5: =IFERROR(H5/K5,0) -> 607.05797 | Q5: =IFERROR(H5/L5,0) -> 675.59677 | R5: =IFERROR(M5/H5,0) -> 3.8907059 | S5: =IFERROR(L5/J5,0) -> 0.035147392 | T5: =IFERROR(H5/G5,0) -> 1.047175 | U5: =IF(D5="Awareness","Review (awareness)",IF(R5>=Assumptions!$B$7,"Scale",IF(R5>=Assumptions!$B$8,"Optimise","Pause / Rework"))) -> Optimise | V5: =IF(D5="Awareness","",COUNTIFS($D$2:$D$31,"<>Awareness",$R$2:$R$31,">"&R5)+COUNTIFS($D$2:D5,"<>Awareness",$R$2:R5,R5)) -> 13
A6: CMP005 | B6: WhatsApp - Weekend Flash Deal | C6: WhatsApp Broadcast | D6: Sales | E6: 46226 | F6: 46284 | G6: 70000 | H6: =SUMIFS(Daily_Performance!$H$2:$H$1311,Daily_Performance!$B$2:$B$1311,A6) -> 60258 | I6: =SUMIFS(Daily_Performance!$C$2:$C$1311,Daily_Performance!$B$2:$B$1311,A6) -> 42789 | J6: =SUMIFS(Daily_Performance!$D$2:$D$1311,Daily_Performance!$B$2:$B$1311,A6) -> 2521 | K6: =SUMIFS(Daily_Performance!$E$2:$E$1311,Daily_Performance!$B$2:$B$1311,A6) -> 87 | L6: =SUMIFS(Daily_Performance!$F$2:$F$1311,Daily_Performance!$B$2:$B$1311,A6) -> 132 | M6: =SUMIFS(Daily_Performance!$G$2:$G$1311,Daily_Performance!$B$2:$B$1311,A6) -> 377580 | N6: =IFERROR(J6/I6,0) -> 0.058917011 | O6: =IFERROR(H6/J6,0) -> 23.90242 | P6: =IFERROR(H6/K6,0) -> 692.62069 | Q6: =IFERROR(H6/L6,0) -> 456.5 | R6: =IFERROR(M6/H6,0) -> 6.266056 | S6: =IFERROR(L6/J6,0) -> 0.052360175 | T6: =IFERROR(H6/G6,0) -> 0.86082857 | U6: =IF(D6="Awareness","Review (awareness)",IF(R6>=Assumptions!$B$7,"Scale",IF(R6>=Assumptions!$B$8,"Optimise","Pause / Rework"))) -> Scale | V6: =IF(D6="Awareness","",COUNTIFS($D$2:$D$31,"<>Awareness",$R$2:$R$31,">"&R6)+COUNTIFS($D$2:D6,"<>Awareness",$R$2:R6,R6)) -> 11
A7: CMP006 | B7: Facebook - Brand Story | C7: Facebook & Instagram Ads | D7: Sales | E7: 46226 | F7: 46283 | G7: 310000 | H7: =SUMIFS(Daily_Performance!$H$2:$H$1311,Daily_Performance!$B$2:$B$1311,A7) -> 333608 | I7: =SUMIFS(Daily_Performance!$C$2:$C$1311,Daily_Performance!$B$2:$B$1311,A7) -> 1339560 | J7: =SUMIFS(Daily_Performance!$D$2:$D$1311,Daily_Performance!$B$2:$B$1311,A7) -> 15869 | K7: =SUMIFS(Daily_Performance!$E$2:$E$1311,Daily_Performance!$B$2:$B$1311,A7) -> 623 | L7: =SUMIFS(Daily_Performance!$F$2:$F$1311,Daily_Performance!$B$2:$B$1311,A7) -> 245 | M7: =SUMIFS(Daily_Performance!$G$2:$G$1311,Daily_Performance!$B$2:$B$1311,A7) -> 789500 | N7: =IFERROR(J7/I7,0) -> 0.011846427 | O7: =IFERROR(H7/J7,0) -> 21.022623 | P7: =IFERROR(H7/K7,0) -> 535.48636 | Q7: =IFERROR(H7/L7,0) -> 1361.6653 | R7: =IFERROR(M7/H7,0) -> 2.36655 | S7: =IFERROR(L7/J7,0) -> 0.015438906 | T7: =IFERROR(H7/G7,0) -> 1.0761548 | U7: =IF(D7="Awareness","Review (awareness)",IF(R7>=Assumptions!$B$7,"Scale",IF(R7>=Assumptions!$B$8,"Optimise","Pause / Rework"))) -> Optimise | V7: =IF(D7="Awareness","",COUNTIFS($D$2:$D$31,"<>Awareness",$R$2:$R$31,">"&R7)+COUNTIFS($D$2:D7,"<>Awareness",$R$2:R7,R7)) -> 18
A8: CMP007 | B8: Google - Referral Bonus | C8: Google Search Ads | D8: Sales | E8: 46231 | F8: 46295 | G8: 195000 | H8: =SUMIFS(Daily_Performance!$H$2:$H$1311,Daily_Performance!$B$2:$B$1311,A8) -> 168077 | I8: =SUMIFS(Daily_Performance!$C$2:$C$1311,Daily_Performance!$B$2:$B$1311,A8) -> 187625 | J8: =SUMIFS(Daily_Performance!$D$2:$D$1311,Daily_Performance!$B$2:$B$1311,A8) -> 9509 | K8: =SUMIFS(Daily_Performance!$E$2:$E$1311,Daily_Performance!$B$2:$B$1311,A8) -> 366 | L8: =SUMIFS(Daily_Performance!$F$2:$F$1311,Daily_Performance!$B$2:$B$1311,A8) -> 488 | M8: =SUMIFS(Daily_Performance!$G$2:$G$1311,Daily_Performance!$B$2:$B$1311,A8) -> 1828740 | N8: =IFERROR(J8/I8,0) -> 0.050680879 | O8: =IFERROR(H8/J8,0) -> 17.675571 | P8: =IFERROR(H8/K8,0) -> 459.22678 | Q8: =IFERROR(H8/L8,0) -> 344.42008 | R8: =IFERROR(M8/H8,0) -> 10.88037 | S8: =IFERROR(L8/J8,0) -> 0.051319802 | T8: =IFERROR(H8/G8,0) -> 0.86193333 | U8: =IF(D8="Awareness","Review (awareness)",IF(R8>=Assumptions!$B$7,"Scale",IF(R8>=Assumptions!$B$8,"Optimise","Pause / Rework"))) -> Scale | V8: =IF(D8="Awareness","",COUNTIFS($D$2:$D$31,"<>Awareness",$R$2:$R$31,">"&R8)+COUNTIFS($D$2:D8,"<>Awareness",$R$2:R8,R8)) -> 7
A9: CMP008 | B9: TikTok - Free Delivery Week | C9: TikTok Ads | D9: Sales | E9: 46209 | F9: 46235 | G9: 460000 | H9: =SUMIFS(Daily_Performance!$H$2:$H$1311,Daily_Performance!$B$2:$B$1311,A9) -> 382645 | I9: =SUMIFS(Daily_Performance!$C$2:$C$1311,Daily_Performance!$B$2:$B$1311,A9) -> 2148360 | J9: =SUMIFS(Daily_Performance!$D$2:$D$1311,Daily_Performance!$B$2:$B$1311,A9) -> 16749 | K9: =SUMIFS(Daily_Performance!$E$2:$E$1311,Daily_Performance!$B$2:$B$1311,A9) -> 686 | L9: =SUMIFS(Daily_Performance!$F$2:$F$1311,Daily_Performance!$B$2:$B$1311,A9) -> 148 | M9: =SUMIFS(Daily_Performance!$G$2:$G$1311,Daily_Performance!$B$2:$B$1311,A9) -> 409810 | N9: =IFERROR(J9/I9,0) -> 0.0077961794 | O9: =IFERROR(H9/J9,0) -> 22.845842 | P9: =IFERROR(H9/K9,0) -> 557.79155 | Q9: =IFERROR(H9/L9,0) -> 2585.4392 | R9: =IFERROR(M9/H9,0) -> 1.0709927 | S9: =IFERROR(L9/J9,0) -> 0.0088363484 | T9: =IFERROR(H9/G9,0) -> 0.83183696 | U9: =IF(D9="Awareness","Review (awareness)",IF(R9>=Assumptions!$B$7,"Scale",IF(R9>=Assumptions!$B$8,"Optimise","Pause / Rework"))) -> Pause / Rework | V9: =IF(D9="Awareness","",COUNTIFS($D$2:$D$31,"<>Awareness",$R$2:$R$31,">"&R9)+COUNTIFS($D$2:D9,"<>Awareness",$R$2:R9,R9)) -> 21
A10: CMP009 | B10: TikTok - Festive Preview | C10: TikTok Ads | D10: Sales | E10: 46224 | F10: 46244 | G10: 515000 | H10: =SUMIFS(Daily_Performance!$H$2:$H$1311,Daily_Performance!$B$2:$B$1311,A10) -> 492207 | I10: =SUMIFS(Daily_Performance!$C$2:$C$1311,Daily_Performance!$B$2:$B$1311,A10) -> 2729098 | J10: =SUMIFS(Daily_Performance!$D$2:$D$1311,Daily_Performance!$B$2:$B$1311,A10) -> 21798 | K10: =SUMIFS(Daily_Performance!$E$2:$E$1311,Daily_Performance!$B$2:$B$1311,A10) -> 860 | L10: =SUMIFS(Daily_Performance!$F$2:$F$1311,Daily_Performance!$B$2:$B$1311,A10) -> 177 | M10: =SUMIFS(Daily_Performance!$G$2:$G$1311,Daily_Performance!$B$2:$B$1311,A10) -> 461650 | N10: =IFERROR(J10/I10,0) -> 0.0079872544 | O10: =IFERROR(H10/J10,0) -> 22.580374 | P10: =IFERROR(H10/K10,0) -> 572.33372 | Q10: =IFERROR(H10/L10,0) -> 2780.8305 | R10: =IFERROR(M10/H10,0) -> 0.9379184 | S10: =IFERROR(L10/J10,0) -> 0.008120011 | T10: =IFERROR(H10/G10,0) -> 0.95574175 | U10: =IF(D10="Awareness","Review (awareness)",IF(R10>=Assumptions!$B$7,"Scale",IF(R10>=Assumptions!$B$8,"Optimise","Pause / Rework"))) -> Pause / Rework | V10: =IF(D10="Awareness","",COUNTIFS($D$2:$D$31,"<>Awareness",$R$2:$R$31,">"&R10)+COUNTIFS($D$2:D10,"<>Awareness",$R$2:R10,R10)) -> 22
A11: CMP010 | B11: Email - New Arrivals | C11: Email | D11: Sales | E11: 46216 | F11: 46283 | G11: 165000 | H11: =SUMIFS(Daily_Performance!$H$2:$H$1311,Daily_Performance!$B$2:$B$1311,A11) -> 175965 | I11: =SUMIFS(Daily_Performance!$C$2:$C$1311,Daily_Performance!$B$2:$B$1311,A11) -> 497449 | J11: =SUMIFS(Daily_Performance!$D$2:$D$1311,Daily_Performance!$B$2:$B$1311,A11) -> 11171 | K11: =SUMIFS(Daily_Performance!$E$2:$E$1311,Daily_Performance!$B$2:$B$1311,A11) -> 479 | L11: =SUMIFS(Daily_Performance!$F$2:$F$1311,Daily_Performance!$B$2:$B$1311,A11) -> 214 | M11: =SUMIFS(Daily_Performance!$G$2:$G$1311,Daily_Performance!$B$2:$B$1311,A11) -> 646040 | N11: =IFERROR(J11/I11,0) -> 0.022456573 | O11: =IFERROR(H11/J11,0) -> 15.751947 | P11: =IFERROR(H11/K11,0) -> 367.35908 | Q11: =IFERROR(H11/L11,0) -> 822.26636 | R11: =IFERROR(M11/H11,0) -> 3.6714119 | S11: =IFERROR(L11/J11,0) -> 0.019156745 | T11: =IFERROR(H11/G11,0) -> 1.0664545 | U11: =IF(D11="Awareness","Review (awareness)",IF(R11>=Assumptions!$B$7,"Scale",IF(R11>=Assumptions!$B$8,"Optimise","Pause / Rework"))) -> Optimise | V11: =IF(D11="Awareness","",COUNTIFS($D$2:$D$31,"<>Awareness",$R$2:$R$31,">"&R11)+COUNTIFS($D$2:D11,"<>Awareness",$R$2:R11,R11)) -> 14
A12: CMP011 | B12: TikTok - Home Makeover Guide | C12: TikTok Ads | D12: Sales | E12: 46224 | F12: 46266 | G12: 125000 | H12: =SUMIFS(Daily_Performance!$H$2:$H$1311,Daily_Performance!$B$2:$B$1311,A12) -> 117670 | I12: =SUMIFS(Daily_Performance!$C$2:$C$1311,Daily_Performance!$B$2:$B$1311,A12) -> 656952 | J12: =SUMIFS(Daily_Performance!$D$2:$D$1311,Daily_Performance!$B$2:$B$1311,A12) -> 4346 | K12: =SUMIFS(Daily_Performance!$E$2:$E$1311,Daily_Performance!$B$2:$B$1311,A12) -> 167 | L12: =SUMIFS(Daily_Performance!$F$2:$F$1311,Daily_Performance!$B$2:$B$1311,A12) -> 32 | M12: =SUMIFS(Daily_Performance!$G$2:$G$1311,Daily_Performance!$B$2:$B$1311,A12) -> 86440 | N12: =IFERROR(J12/I12,0) -> 0.0066153996 | O12: =IFERROR(H12/J12,0) -> 27.075472 | P12: =IFERROR(H12/K12,0) -> 704.61078 | Q12: =IFERROR(H12/L12,0) -> 3677.1875 | R12: =IFERROR(M12/H12,0) -> 0.73459675 | S12: =IFERROR(L12/J12,0) -> 0.0073630925 | T12: =IFERROR(H12/G12,0) -> 0.94136 | U12: =IF(D12="Awareness","Review (awareness)",IF(R12>=Assumptions!$B$7,"Scale",IF(R12>=Assumptions!$B$8,"Optimise","Pause / Rework"))) -> Pause / Rework | V12: =IF(D12="Awareness","",COUNTIFS($D$2:$D$31,"<>Awareness",$R$2:$R$31,">"&R12)+COUNTIFS($D$2:D12,"<>Awareness",$R$2:R12,R12)) -> 26
A13: CMP012 | B13: Google - Back-to-School Sale | C13: Google Search Ads | D13: Sales | E13: 46221 | F13: 46244 | G13: 565000 | H13: =SUMIFS(Daily_Performance!$H$2:$H$1311,Daily_Performance!$B$2:$B$1311,A13) -> 505878 | I13: =SUMIFS(Daily_Performance!$C$2:$C$1311,Daily_Performance!$B$2:$B$1311,A13) -> 563241 | J13: =SUMIFS(Daily_Performance!$D$2:$D$1311,Daily_Performance!$B$2:$B$1311,A13) -> 32192 | K13: =SUMIFS(Daily_Performance!$E$2:$E$1311,Daily_Performance!$B$2:$B$1311,A13) -> 1274 | L13: =SUMIFS(Daily_Performance!$F$2:$F$1311,Daily_Performance!$B$2:$B$1311,A13) -> 2015 | M13: =SUMIFS(Daily_Performance!$G$2:$G$1311,Daily_Performance!$B$2:$B$1311,A13) -> 7458220 | N13: =IFERROR(J13/I13,0) -> 0.05715493 | O13: =IFERROR(H13/J13,0) -> 15.714401 | P13: =IFERROR(H13/K13,0) -> 397.07849 | Q13: =IFERROR(H13/L13,0) -> 251.05608 | R13: =IFERROR(M13/H13,0) -> 14.74312 | S13: =IFERROR(L13/J13,0) -> 0.062593191 | T13: =IFERROR(H13/G13,0) -> 0.89535929 | U13: =IF(D13="Awareness","Review (awareness)",IF(R13>=Assumptions!$B$7,"Scale",IF(R13>=Assumptions!$B$8,"Optimise","Pause / Rework"))) -> Scale | V13: =IF(D13="Awareness","",COUNTIFS($D$2:$D$31,"<>Awareness",$R$2:$R$31,">"&R13)+COUNTIFS($D$2:D13,"<>Awareness",$R$2:R13,R13)) -> 2
... A31: CMP030 | B31: Email - Brand Story | C31: Email | D31: Sales | E31: 46208 | F31: 46274 | G31: 35000 | H31: =SUMIFS(Daily_Performance!$H$2:$H$1311,Daily_Performance!$B$2:$B$1311,A31) -> 34356 | I31: =SUMIFS(Daily_Performance!$C$2:$C$1311,Daily_Performance!$B$2:$B$1311,A31) -> 100007 | J31: =SUMIFS(Daily_Performance!$D$2:$D$1311,Daily_Performance!$B$2:$B$1311,A31) -> 3182 | K31: =SUMIFS(Daily_Performance!$E$2:$E$1311,Daily_Performance!$B$2:$B$1311,A31) -> 132 | L31: =SUMIFS(Daily_Performance!$F$2:$F$1311,Daily_Performance!$B$2:$B$1311,A31) -> 134 | M31: =SUMIFS(Daily_Performance!$G$2:$G$1311,Daily_Performance!$B$2:$B$1311,A31) -> 411830 | N31: =IFERROR(J31/I31,0) -> 0.031817773 | O31: =IFERROR(H31/J31,0) -> 10.796983 | P31: =IFERROR(H31/K31,0) -> 260.27273 | Q31: =IFERROR(H31/L31,0) -> 256.38806 | R31: =IFERROR(M31/H31,0) -> 11.987135 | S31: =IFERROR(L31/J31,0) -> 0.042111879 | T31: =IFERROR(H31/G31,0) -> 0.9816 | U31: =IF(D31="Awareness","Review (awareness)",IF(R31>=Assumptions!$B$7,"Scale",IF(R31>=Assumptions!$B$8,"Optimise","Pause / Rework"))) -> Scale | V31: =IF(D31="Awareness","",COUNTIFS($D$2:$D$31,"<>Awareness",$R$2:$R$31,">"&R31)+COUNTIFS($D$2:D31,"<>Awareness",$R$2:R31,R31)) -> 5

Sheet Daily_Performance
A1: Date | B1: CampaignID | C1: Impressions | D1: Clicks | E1: Leads | F1: Orders | G1: Revenue (KES) | H1: Spend (KES) | I1: Channel | J1: Month
A2: 46206 | B2: CMP023 | C2: 30145 | D2: 285 | E2: 13 | F2: 2 | G2: 8200 | H2: 19277 | I2: =INDEX(Campaigns!$C$2:$C$31,MATCH(B2,Campaigns!$A$2:$A$31,0)) -> Influencer Partnerships | J2: =DATE(YEAR(A2),MONTH(A2),1) -> 46204
A3: 46207 | B3: CMP023 | C3: 39287 | D3: 351 | E3: 9 | F3: 1 | G3: 1720 | H3: 24050 | I3: =INDEX(Campaigns!$C$2:$C$31,MATCH(B3,Campaigns!$A$2:$A$31,0)) -> Influencer Partnerships | J3: =DATE(YEAR(A3),MONTH(A3),1) -> 46204
A4: 46207 | B4: CMP028 | C4: 29093 | D4: 410 | E4: 69 | F4: 14 | G4: 53410 | H4: 6704 | I4: =INDEX(Campaigns!$C$2:$C$31,MATCH(B4,Campaigns!$A$2:$A$31,0)) -> Facebook & Instagram Ads | J4: =DATE(YEAR(A4),MONTH(A4),1) -> 46204
A5: 46208 | B5: CMP023 | C5: 37725 | D5: 293 | E5: 9 | F5: 7 | G5: 23270 | H5: 24782 | I5: =INDEX(Campaigns!$C$2:$C$31,MATCH(B5,Campaigns!$A$2:$A$31,0)) -> Influencer Partnerships | J5: =DATE(YEAR(A5),MONTH(A5),1) -> 46204
A6: 46208 | B6: CMP028 | C6: 31525 | D6: 466 | E6: 70 | F6: 7 | G6: 20790 | H6: 7743 | I6: =INDEX(Campaigns!$C$2:$C$31,MATCH(B6,Campaigns!$A$2:$A$31,0)) -> Facebook & Instagram Ads | J6: =DATE(YEAR(A6),MONTH(A6),1) -> 46204
A7: 46208 | B7: CMP030 | C7: 1829 | D7: 55 | E7: 3 | F7: 1 | G7: 2150 | H7: 630 | I7: =INDEX(Campaigns!$C$2:$C$31,MATCH(B7,Campaigns!$A$2:$A$31,0)) -> Email | J7: =DATE(YEAR(A7),MONTH(A7),1) -> 46204
A8: 46209 | B8: CMP008 | C8: 89494 | D8: 698 | E8: 28 | F8: 6 | G8: 18390 | H8: 14878 | I8: =INDEX(Campaigns!$C$2:$C$31,MATCH(B8,Campaigns!$A$2:$A$31,0)) -> TikTok Ads | J8: =DATE(YEAR(A8),MONTH(A8),1) -> 46204
A9: 46209 | B9: CMP023 | C9: 38358 | D9: 299 | E9: 11 | F9: 3 | G9: 11850 | H9: 23021 | I9: =INDEX(Campaigns!$C$2:$C$31,MATCH(B9,Campaigns!$A$2:$A$31,0)) -> Influencer Partnerships | J9: =DATE(YEAR(A9),MONTH(A9),1) -> 46204
A10: 46209 | B10: CMP028 | C10: 27163 | D10: 402 | E10: 62 | F10: 9 | G10: 26910 | H10: 6387 | I10: =INDEX(Campaigns!$C$2:$C$31,MATCH(B10,Campaigns!$A$2:$A$31,0)) -> Facebook & Instagram Ads | J10: =DATE(YEAR(A10),MONTH(A10),1) -> 46204
A11: 46209 | B11: CMP030 | C11: 1612 | D11: 46 | E11: 2 | F11: 1 | G11: 2510 | H11: 523 | I11: =INDEX(Campaigns!$C$2:$C$31,MATCH(B11,Campaigns!$A$2:$A$31,0)) -> Email | J11: =DATE(YEAR(A11),MONTH(A11),1) -> 46204
A12: 46210 | B12: CMP008 | C12: 75227 | D12: 619 | E12: 31 | F12: 3 | G12: 9350 | H12: 14909 | I12: =INDEX(Campaigns!$C$2:$C$31,MATCH(B12,Campaigns!$A$2:$A$31,0)) -> TikTok Ads | J12: =DATE(YEAR(A12),MONTH(A12),1) -> 46204
A13: 46210 | B13: CMP023 | C13: 36394 | D13: 275 | E13: 14 | F13: 4 | G13: 17830 | H13: 22430 | I13: =INDEX(Campaigns!$C$2:$C$31,MATCH(B13,Campaigns!$A$2:$A$31,0)) -> Influencer Partnerships | J13: =DATE(YEAR(A13),MONTH(A13),1) -> 46204
... A1311: 46295 | B1311: CMP024 | C1311: 7794 | D1311: 56 | E1311: 3 | F1311: 0 | G1311: 0 | H1311: 4311 | I1311: =INDEX(Campaigns!$C$2:$C$31,MATCH(B1311,Campaigns!$A$2:$A$31,0)) -> Influencer Partnerships | J1311: =DATE(YEAR(A1311),MONTH(A1311),1) -> 46266
