Workbook

Sheet README
A1: Mobile Money Revenue & Churn Intelligence – Telecom Portfolio Project
A2: BZME Insights | Sector: Telecom / Mobile Money | Tool: Excel (formula-driven)
A4: BUSINESS PROBLEM
A5: A telco's mobile money arm earns fees on every transaction, but leadership cannot see which customers drive revenue, which are drifting away, or which agents are failing to serve them. This workbook builds that visibility.
A7: BUSINESS QUESTIONS
A8: 1. Which customer segments and transaction types drive fee revenue?
A9: 2. Which active customers are slipping toward churn, and how much monthly revenue is at risk?
A10: 3. Which regions have the weakest customer health?
A11: 4. Which agents are underperforming against their tier peers?
A12: 5. Where is the cross-sell opportunity (customers using few products)?
A14: HOW THE WORKBOOK IS BUILT
A15: Customers, Agents, Transactions: synthetic raw data (600 customers, 60 agents, ~13,000 transactions, Jan–Sep 2026). No real customer data is used.
... A36: Protect the base: reward Champions and Loyal customers, since they generate a disproportionate share of revenue.

Sheet Dashboard
A1: Mobile Money Revenue & Churn Intelligence Dashboard
A2: ="Fictional East African telco | Synthetic data | "&TEXT(Assumptions!B5,"d mmm yyyy")&" to "&TEXT(Assumptions!B4,"d mmm yyyy")&" | Prepared by BZME Insights" -> Fictional East African telco | Synthetic data | 1 Jan 2026 to 30 Sep 2026 | Prepared by BZME Insights
A4: TOTAL TXN VALUE (KES) | C4: FEE REVENUE (KES) | E4: ACTIVE CUSTOMERS | G4: SLIPPING CUSTOMERS | I4: CHURNED CUSTOMERS | K4: MONTHLY REV AT RISK (KES)
A5: =SUM(Transactions!$F$2:$F$13107) -> 64420975 | C5: =SUM(Transactions!$I$2:$I$13107) -> 340787.93 | E5: =COUNTIF(Customer_Metrics!$O$2:$O$601,"Active") -> 442 | G5: =COUNTIF(Customer_Metrics!$O$2:$O$601,"Slipping") -> 94 | I5: =COUNTIF(Customer_Metrics!$O$2:$O$601,"Churned") -> 64 | K5: =SUM(Customer_Metrics!$V$2:$V$601) -> 4287.8778
A7: Key findings (update automatically)
A8: ="1. Over "&Assumptions!B6&" months the network processed KES "&TEXT(A5/1000000,"#,##0.0")&"M across "&TEXT(B40,"#,##0")&" transactions, earning KES "&TEXT(C5,"#,##0")&" in fees and commissions." -> 1. Over 9 months the network processed KES 64.4M across 13,106 transactions, earning KES 340,788 in fees and commissions.
A9: ="2. "&INDEX(A34:A39,MATCH(MAX(D34:D39),D34:D39,0))&" is the largest revenue line ("&TEXT(MAX(D34:D39)/D40,"0%")&" of fees); "&INDEX(A34:A39,MATCH(MIN(D34:D39),D34:D39,0))&" is the smallest." -> 2. Withdraw Cash is the largest revenue line (42% of fees); Deposit Cash is the smallest.
A10: ="3. "&G5&" customers are slipping ("&(Assumptions!B7+1)&"-"&Assumptions!B8&" days inactive), putting about KES "&TEXT(K5,"#,##0")&" of monthly revenue at risk. A further "&I5&" have already churned." -> 3. 94 customers are slipping (31-60 days inactive), putting about KES 4,288 of monthly revenue at risk. A further 64 have already churned.
A11: ="4. Champions and Loyal customers are "&TEXT((B61+B62)/B66,"0%")&" of the base but generate "&TEXT((C61+C62)/C66,"0%")&" of revenue." -> 4. Champions and Loyal customers are 58% of the base but generate 83% of revenue.
A12: ="5. "&COUNTIF(Customer_Metrics!$X$2:$X$601,"Yes")&" active customers use two or fewer products - the main cross-sell target group." -> 5. 26 active customers use two or fewer products - the main cross-sell target group.
A13: ="6. "&INDEX(A50:A55,MATCH(MAX(F50:F55),F50:F55,0))&" has the highest share of at-risk customers ("&TEXT(MAX(F50:F55),"0%")&" vs "&TEXT(F56,"0%")&" overall)." -> 6. Eastern has the highest share of at-risk customers (32% vs 26% overall).
A14: ="7. "&C90&" of "&B90&" agents handle under "&TEXT(Assumptions!B9,"0%")&" of their tier average volume and need float support or coaching." -> 7. 17 of 60 agents handle under 60% of their tier average volume and need float support or coaching.
A16: 1. Monthly trend – transactions and fee revenue
A17: Month start | B17: Month | C17: Transactions | D17: Revenue (KES) | E17: Value (KES)
A18: =DATE(YEAR(Assumptions!$B$5),MONTH(Assumptions!$B$5),1) -> 46023 | B18: =TEXT(A18,"mmm") -> Jan | C18: =COUNTIFS(Transactions!$G$2:$G$13107,A18) -> 1532 | D18: =SUMIFS(Transactions!$I$2:$I$13107,Transactions!$G$2:$G$13107,A18) -> 40037.43 | E18: =SUMIFS(Transactions!$F$2:$F$13107,Transactions!$G$2:$G$13107,A18) -> 7605720
A19: =EDATE(A18,1) -> 46054 | B19: =TEXT(A19,"mmm") -> Feb | C19: =COUNTIFS(Transactions!$G$2:$G$13107,A19) -> 1180 | D19: =SUMIFS(Transactions!$I$2:$I$13107,Transactions!$G$2:$G$13107,A19) -> 29684.76 | E19: =SUMIFS(Transactions!$F$2:$F$13107,Transactions!$G$2:$G$13107,A19) -> 5881892
A20: =EDATE(A19,1) -> 46082 | B20: =TEXT(A20,"mmm") -> Mar | C20: =COUNTIFS(Transactions!$G$2:$G$13107,A20) -> 1433 | D20: =SUMIFS(Transactions!$I$2:$I$13107,Transactions!$G$2:$G$13107,A20) -> 36944.93 | E20: =SUMIFS(Transactions!$F$2:$F$13107,Transactions!$G$2:$G$13107,A20) -> 7092036
A21: =EDATE(A20,1) -> 46113 | B21: =TEXT(A21,"mmm") -> Apr | C21: =COUNTIFS(Transactions!$G$2:$G$13107,A21) -> 1391 | D21: =SUMIFS(Transactions!$I$2:$I$13107,Transactions!$G$2:$G$13107,A21) -> 36076.97 | E21: =SUMIFS(Transactions!$F$2:$F$13107,Transactions!$G$2:$G$13107,A21) -> 7185432
A22: =EDATE(A21,1) -> 46143 | B22: =TEXT(A22,"mmm") -> May | C22: =COUNTIFS(Transactions!$G$2:$G$13107,A22) -> 1500 | D22: =SUMIFS(Transactions!$I$2:$I$13107,Transactions!$G$2:$G$13107,A22) -> 40346.62 | E22: =SUMIFS(Transactions!$F$2:$F$13107,Transactions!$G$2:$G$13107,A22) -> 7436840
A23: =EDATE(A22,1) -> 46174 | B23: =TEXT(A23,"mmm") -> Jun | C23: =COUNTIFS(Transactions!$G$2:$G$13107,A23) -> 1486 | D23: =SUMIFS(Transactions!$I$2:$I$13107,Transactions!$G$2:$G$13107,A23) -> 39745.72 | E23: =SUMIFS(Transactions!$F$2:$F$13107,Transactions!$G$2:$G$13107,A23) -> 7461245
A24: =EDATE(A23,1) -> 46204 | B24: =TEXT(A24,"mmm") -> Jul | C24: =COUNTIFS(Transactions!$G$2:$G$13107,A24) -> 1591 | D24: =SUMIFS(Transactions!$I$2:$I$13107,Transactions!$G$2:$G$13107,A24) -> 40512.14 | E24: =SUMIFS(Transactions!$F$2:$F$13107,Transactions!$G$2:$G$13107,A24) -> 7772204
A25: =EDATE(A24,1) -> 46235 | B25: =TEXT(A25,"mmm") -> Aug | C25: =COUNTIFS(Transactions!$G$2:$G$13107,A25) -> 1560 | D25: =SUMIFS(Transactions!$I$2:$I$13107,Transactions!$G$2:$G$13107,A25) -> 36881.71 | E25: =SUMIFS(Transactions!$F$2:$F$13107,Transactions!$G$2:$G$13107,A25) -> 6733887
A26: =EDATE(A25,1) -> 46266 | B26: =TEXT(A26,"mmm") -> Sep | C26: =COUNTIFS(Transactions!$G$2:$G$13107,A26) -> 1433 | D26: =SUMIFS(Transactions!$I$2:$I$13107,Transactions!$G$2:$G$13107,A26) -> 40557.65 | E26: =SUMIFS(Transactions!$F$2:$F$13107,Transactions!$G$2:$G$13107,A26) -> 7251719
A32: 2. Revenue by transaction type
A33: Type | B33: Transactions | C33: Value (KES) | D33: Revenue (KES) | E33: Avg Ticket (KES) | F33: % of Revenue
A34: =Assumptions!A13 -> Send Money | B34: =COUNTIFS(Transactions!$E$2:$E$13107,A34) -> 3514 | C34: =SUMIFS(Transactions!$F$2:$F$13107,Transactions!$E$2:$E$13107,A34) -> 10749800 | D34: =SUMIFS(Transactions!$I$2:$I$13107,Transactions!$E$2:$E$13107,A34) -> 93395 | E34: =IFERROR(C34/B34,0) -> 3059.1349 | F34: =IFERROR(D34/D$40,0) -> 0.27405607
A35: =Assumptions!A14 -> Withdraw Cash | B35: =COUNTIFS(Transactions!$E$2:$E$13107,A35) -> 1769 | C35: =SUMIFS(Transactions!$F$2:$F$13107,Transactions!$E$2:$E$13107,A35) -> 11878870 | D35: =SUMIFS(Transactions!$I$2:$I$13107,Transactions!$E$2:$E$13107,A35) -> 143100.2 | E35: =IFERROR(C35/B35,0) -> 6715.0198 | F35: =IFERROR(D35/D$40,0) -> 0.41990982
A36: =Assumptions!A15 -> Deposit Cash | B36: =COUNTIFS(Transactions!$E$2:$E$13107,A36) -> 1677 | C36: =SUMIFS(Transactions!$F$2:$F$13107,Transactions!$E$2:$E$13107,A36) -> 22139120 | D36: =SUMIFS(Transactions!$I$2:$I$13107,Transactions!$E$2:$E$13107,A36) -> 0 | E36: =IFERROR(C36/B36,0) -> 13201.622 | F36: =IFERROR(D36/D$40,0) -> 0
A37: =Assumptions!A16 -> Pay Bill | B37: =COUNTIFS(Transactions!$E$2:$E$13107,A37) -> 2117 | C37: =SUMIFS(Transactions!$F$2:$F$13107,Transactions!$E$2:$E$13107,A37) -> 18386370 | D37: =SUMIFS(Transactions!$I$2:$I$13107,Transactions!$E$2:$E$13107,A37) -> 44982.48 | E37: =IFERROR(C37/B37,0) -> 8685.1063 | F37: =IFERROR(D37/D$40,0) -> 0.13199552
A38: =Assumptions!A17 -> Buy Airtime | B38: =COUNTIFS(Transactions!$E$2:$E$13107,A38) -> 2126 | C38: =SUMIFS(Transactions!$F$2:$F$13107,Transactions!$E$2:$E$13107,A38) -> 403050 | D38: =SUMIFS(Transactions!$I$2:$I$13107,Transactions!$E$2:$E$13107,A38) -> 16122 | E38: =IFERROR(C38/B38,0) -> 189.58137 | F38: =IFERROR(D38/D$40,0) -> 0.047308014
A39: =Assumptions!A18 -> Buy Data | B39: =COUNTIFS(Transactions!$E$2:$E$13107,A39) -> 1903 | C39: =SUMIFS(Transactions!$F$2:$F$13107,Transactions!$E$2:$E$13107,A39) -> 863765 | D39: =SUMIFS(Transactions!$I$2:$I$13107,Transactions!$E$2:$E$13107,A39) -> 43188.25 | E39: =IFERROR(C39/B39,0) -> 453.89648 | F39: =IFERROR(D39/D$40,0) -> 0.12673057
A40: Total | B40: =SUM(B34:B39) -> 13106 | C40: =SUM(C34:C39) -> 64420975 | D40: =SUM(D34:D39) -> 340787.93 | E40: =IFERROR(C40/B40,0) -> 4915.3804 | F40: =SUM(F34:F39) -> 1
A48: 3. Regional view – customer health and revenue
A49: Region | B49: Customers | C49: Active | D49: Slipping | E49: Churned | F49: At-Risk % | G49: Revenue (KES) | H49: % of Revenue
A50: Nairobi | B50: =COUNTIF(Customer_Metrics!$B$2:$B$601,A50) -> 170 | C50: =COUNTIFS(Customer_Metrics!$B$2:$B$601,$A50,Customer_Metrics!$O$2:$O$601,"Active") -> 123 | D50: =COUNTIFS(Customer_Metrics!$B$2:$B$601,$A50,Customer_Metrics!$O$2:$O$601,"Slipping") -> 25 | E50: =COUNTIFS(Customer_Metrics!$B$2:$B$601,$A50,Customer_Metrics!$O$2:$O$601,"Churned") -> 22 | F50: =IFERROR((D50+E50)/B50,0) -> 0.27647059 | G50: =SUMIFS(Transactions!$I$2:$I$13107,Transactions!$H$2:$H$13107,A50) -> 96434.39 | H50: =IFERROR(G50/G$56,0) -> 0.28297478
A51: Central | B51: =COUNTIF(Customer_Metrics!$B$2:$B$601,A51) -> 91 | C51: =COUNTIFS(Customer_Metrics!$B$2:$B$601,$A51,Customer_Metrics!$O$2:$O$601,"Active") -> 71 | D51: =COUNTIFS(Customer_Metrics!$B$2:$B$601,$A51,Customer_Metrics!$O$2:$O$601,"Slipping") -> 12 | E51: =COUNTIFS(Customer_Metrics!$B$2:$B$601,$A51,Customer_Metrics!$O$2:$O$601,"Churned") -> 8 | F51: =IFERROR((D51+E51)/B51,0) -> 0.21978022 | G51: =SUMIFS(Transactions!$I$2:$I$13107,Transactions!$H$2:$H$13107,A51) -> 66655.24 | H51: =IFERROR(G51/G$56,0) -> 0.19559155
A52: Rift Valley | B52: =COUNTIF(Customer_Metrics!$B$2:$B$601,A52) -> 115 | C52: =COUNTIFS(Customer_Metrics!$B$2:$B$601,$A52,Customer_Metrics!$O$2:$O$601,"Active") -> 84 | D52: =COUNTIFS(Customer_Metrics!$B$2:$B$601,$A52,Customer_Metrics!$O$2:$O$601,"Slipping") -> 18 | E52: =COUNTIFS(Customer_Metrics!$B$2:$B$601,$A52,Customer_Metrics!$O$2:$O$601,"Churned") -> 13 | F52: =IFERROR((D52+E52)/B52,0) -> 0.26956522 | G52: =SUMIFS(Transactions!$I$2:$I$13107,Transactions!$H$2:$H$13107,A52) -> 58337.02 | H52: =IFERROR(G52/G$56,0) -> 0.17118276
A53: Coast | B53: =COUNTIF(Customer_Metrics!$B$2:$B$601,A53) -> 68 | C53: =COUNTIFS(Customer_Metrics!$B$2:$B$601,$A53,Customer_Metrics!$O$2:$O$601,"Active") -> 56 | D53: =COUNTIFS(Customer_Metrics!$B$2:$B$601,$A53,Customer_Metrics!$O$2:$O$601,"Slipping") -> 6 | E53: =COUNTIFS(Customer_Metrics!$B$2:$B$601,$A53,Customer_Metrics!$O$2:$O$601,"Churned") -> 6 | F53: =IFERROR((D53+E53)/B53,0) -> 0.17647059 | G53: =SUMIFS(Transactions!$I$2:$I$13107,Transactions!$H$2:$H$13107,A53) -> 43042.15 | H53: =IFERROR(G53/G$56,0) -> 0.12630186
A54: Western | B54: =COUNTIF(Customer_Metrics!$B$2:$B$601,A54) -> 79 | C54: =COUNTIFS(Customer_Metrics!$B$2:$B$601,$A54,Customer_Metrics!$O$2:$O$601,"Active") -> 56 | D54: =COUNTIFS(Customer_Metrics!$B$2:$B$601,$A54,Customer_Metrics!$O$2:$O$601,"Slipping") -> 18 | E54: =COUNTIFS(Customer_Metrics!$B$2:$B$601,$A54,Customer_Metrics!$O$2:$O$601,"Churned") -> 5 | F54: =IFERROR((D54+E54)/B54,0) -> 0.29113924 | G54: =SUMIFS(Transactions!$I$2:$I$13107,Transactions!$H$2:$H$13107,A54) -> 35878.71 | H54: =IFERROR(G54/G$56,0) -> 0.10528163
A55: Eastern | B55: =COUNTIF(Customer_Metrics!$B$2:$B$601,A55) -> 77 | C55: =COUNTIFS(Customer_Metrics!$B$2:$B$601,$A55,Customer_Metrics!$O$2:$O$601,"Active") -> 52 | D55: =COUNTIFS(Customer_Metrics!$B$2:$B$601,$A55,Customer_Metrics!$O$2:$O$601,"Slipping") -> 15 | E55: =COUNTIFS(Customer_Metrics!$B$2:$B$601,$A55,Customer_Metrics!$O$2:$O$601,"Churned") -> 10 | F55: =IFERROR((D55+E55)/B55,0) -> 0.32467532 | G55: =SUMIFS(Transactions!$I$2:$I$13107,Transactions!$H$2:$H$13107,A55) -> 40440.42 | H55: =IFERROR(G55/G$56,0) -> 0.11866741
...

Sheet Assumptions
A1: Assumptions & Parameters
A2: Blue cells are editable inputs. Everything else in the workbook recalculates from them.
A4: As-of date (analysis date) | B4: 46295 | C4: Last day of the synthetic data set.
A5: Period start | B5: 46023 | C5: First day of the synthetic data set.
A6: Months in period | B6: =(YEAR(B4)-YEAR(B5))*12+MONTH(B4)-MONTH(B5)+1 -> 9 | C6: Calculated from the two dates above.
A7: Active: max days since last transaction | B7: 30 | C7: Customer is 'Active' if last transaction is within this many days.
A8: Churned: days since last transaction above | B8: 60 | C8: Between the two thresholds the customer is 'Slipping' (churn risk).
A9: Underperforming agent threshold (% of tier average txns) | B9: 0.6 | C9: Agent flagged if transactions are below this share of their tier average.
A11: Fee / revenue schedule (ILLUSTRATIVE – not an actual operator tariff)
A12: Transaction Type | B12: Rate (% of amount) | C12: Minimum (KES) | D12: Maximum (KES) | E12: Note
A13: Send Money | B13: 0.01 | C13: 5 | D13: 105 | E13: Transfer fee
A14: Withdraw Cash | B14: 0.015 | C14: 10 | D14: 200 | E14: Cash-out fee at agent
A15: Deposit Cash | B15: 0 | C15: 0 | D15: 0 | E15: Free to customer (drives float)
A16: Pay Bill | B16: 0.004 | C16: 0 | D16: 40 | E16: Biller / merchant commission
A17: Buy Airtime | B17: 0.04 | C17: 0 | D17: 40 | E17: Airtime margin
A18: Buy Data | B18: 0.05 | C18: 0 | D18: 100 | E18: Data bundle margin
A20: RFM scoring thresholds
A21: Score | B21: Recency: max days since last txn | C21: Frequency: min txns | D21: Monetary: min revenue (KES)
A22: 5 | B22: 15 | C22: =PERCENTILE(Customer_Metrics!$J$2:$J$601,0.8) -> 31 | D22: =PERCENTILE(Customer_Metrics!$L$2:$L$601,0.8) -> 808.196
A23: 4 | B23: =B7 -> 30 | C23: =PERCENTILE(Customer_Metrics!$J$2:$J$601,0.6) -> 21.4 | D23: =PERCENTILE(Customer_Metrics!$L$2:$L$601,0.6) -> 475.72
A24: 3 | B24: =B8 -> 60 | C24: =PERCENTILE(Customer_Metrics!$J$2:$J$601,0.4) -> 14 | D24: =PERCENTILE(Customer_Metrics!$L$2:$L$601,0.4) -> 289.582
A25: 2 | B25: 90 | C25: =PERCENTILE(Customer_Metrics!$J$2:$J$601,0.2) -> 9 | D25: =PERCENTILE(Customer_Metrics!$L$2:$L$601,0.2) -> 157.36
A26: 1 | B26: otherwise | C26: otherwise | D26: otherwise
A27: Frequency and Monetary cut-offs are the 80th/60th/40th/20th percentiles of all customers (recalculated automatically).
A29: RFM segment rules (evaluated in this order)
A30: Champions: Recency score ≥ 4 AND Frequency score ≥ 4
A31: Loyal: Recency score ≥ 3 AND Frequency score ≥ 3
A32: At Risk: Recency score ≤ 2 AND Frequency score ≥ 3 (used to transact a lot, now gone quiet)
A33: Hibernating: Recency score ≤ 2 (low frequency)
A34: Potential: everyone else

Sheet Customer_Metrics
A1: CustomerID | B1: Region | C1: Plan | D1: Send Money | E1: Withdraw Cash | F1: Deposit Cash | G1: Pay Bill | H1: Buy Airtime | I1: Buy Data | J1: Total Txns | K1: Total Value (KES) | L1: Revenue (KES) | M1: Last Txn Date | N1: Days Since Last | O1: Status | P1: Products Used | Q1: R Score | R1: F Score | S1: M Score | T1: RFM Segment | U1: Avg Monthly Revenue (KES) | V1: Monthly Rev at Risk (Slipping) | W1: Monthly Rev Lost (Churned) | X1: Cross-sell Target
A2: =Customers!A2 -> C0001 | B2: =Customers!B2 -> Nairobi | C2: =Customers!C2 -> Prepaid | D2: =COUNTIFS(Transactions!$C$2:$C$13107,$A2,Transactions!$E$2:$E$13107,D$1) -> 1 | E2: =COUNTIFS(Transactions!$C$2:$C$13107,$A2,Transactions!$E$2:$E$13107,E$1) -> 0 | F2: =COUNTIFS(Transactions!$C$2:$C$13107,$A2,Transactions!$E$2:$E$13107,F$1) -> 0 | G2: =COUNTIFS(Transactions!$C$2:$C$13107,$A2,Transactions!$E$2:$E$13107,G$1) -> 0 | H2: =COUNTIFS(Transactions!$C$2:$C$13107,$A2,Transactions!$E$2:$E$13107,H$1) -> 4 | I2: =COUNTIFS(Transactions!$C$2:$C$13107,$A2,Transactions!$E$2:$E$13107,I$1) -> 4 | J2: =SUM(D2:I2) -> 9 | K2: =SUMIFS(Transactions!$F$2:$F$13107,Transactions!$C$2:$C$13107,A2) -> 2970 | L2: =SUMIFS(Transactions!$I$2:$I$13107,Transactions!$C$2:$C$13107,A2) -> 117.8 | M2: =IF(J2=0,"",_xlfn.MAXIFS(Transactions!$B$2:$B$13107,Transactions!$C$2:$C$13107,A2)) -> 46170 | N2: =IF(J2=0,999,Assumptions!$B$4-M2) -> 125 | O2: =IF(N2<=Assumptions!$B$7,"Active",IF(N2<=Assumptions!$B$8,"Slipping","Churned")) -> Churned | P2: =COUNTIF(D2:I2,">0") -> 3 | Q2: =IF(N2<=Assumptions!$B$22,5,IF(N2<=Assumptions!$B$23,4,IF(N2<=Assumptions!$B$24,3,IF(N2<=Assumptions!$B$25,2,1)))) -> 1 | R2: =1+(J2>=Assumptions!$C$25)+(J2>=Assumptions!$C$24)+(J2>=Assumptions!$C$23)+(J2>=Assumptions!$C$22) -> 2 | S2: =1+(L2>=Assumptions!$D$25)+(L2>=Assumptions!$D$24)+(L2>=Assumptions!$D$23)+(L2>=Assumptions!$D$22) -> 1 | T2: =IF(AND(Q2>=4,R2>=4),"Champions",IF(AND(Q2>=3,R2>=3),"Loyal",IF(AND(Q2<=2,R2>=3),"At Risk",IF(Q2<=2,"Hibernating","Potential")))) -> Hibernating | U2: =L2/Assumptions!$B$6 -> 13.088889 | V2: =IF(O2="Slipping",U2,0) -> 0 | W2: =IF(O2="Churned",U2,0) -> 13.088889 | X2: =IF(AND(O2="Active",P2<=2),"Yes","No") -> No
A3: =Customers!A3 -> C0002 | B3: =Customers!B3 -> Coast | C3: =Customers!C3 -> Postpaid | D3: =COUNTIFS(Transactions!$C$2:$C$13107,$A3,Transactions!$E$2:$E$13107,D$1) -> 12 | E3: =COUNTIFS(Transactions!$C$2:$C$13107,$A3,Transactions!$E$2:$E$13107,E$1) -> 0 | F3: =COUNTIFS(Transactions!$C$2:$C$13107,$A3,Transactions!$E$2:$E$13107,F$1) -> 0 | G3: =COUNTIFS(Transactions!$C$2:$C$13107,$A3,Transactions!$E$2:$E$13107,G$1) -> 0 | H3: =COUNTIFS(Transactions!$C$2:$C$13107,$A3,Transactions!$E$2:$E$13107,H$1) -> 0 | I3: =COUNTIFS(Transactions!$C$2:$C$13107,$A3,Transactions!$E$2:$E$13107,I$1) -> 7 | J3: =SUM(D3:I3) -> 19 | K3: =SUMIFS(Transactions!$F$2:$F$13107,Transactions!$C$2:$C$13107,A3) -> 37739 | L3: =SUMIFS(Transactions!$I$2:$I$13107,Transactions!$C$2:$C$13107,A3) -> 503.35 | M3: =IF(J3=0,"",_xlfn.MAXIFS(Transactions!$B$2:$B$13107,Transactions!$C$2:$C$13107,A3)) -> 46291 | N3: =IF(J3=0,999,Assumptions!$B$4-M3) -> 4 | O3: =IF(N3<=Assumptions!$B$7,"Active",IF(N3<=Assumptions!$B$8,"Slipping","Churned")) -> Active | P3: =COUNTIF(D3:I3,">0") -> 2 | Q3: =IF(N3<=Assumptions!$B$22,5,IF(N3<=Assumptions!$B$23,4,IF(N3<=Assumptions!$B$24,3,IF(N3<=Assumptions!$B$25,2,1)))) -> 5 | R3: =1+(J3>=Assumptions!$C$25)+(J3>=Assumptions!$C$24)+(J3>=Assumptions!$C$23)+(J3>=Assumptions!$C$22) -> 3 | S3: =1+(L3>=Assumptions!$D$25)+(L3>=Assumptions!$D$24)+(L3>=Assumptions!$D$23)+(L3>=Assumptions!$D$22) -> 4 | T3: =IF(AND(Q3>=4,R3>=4),"Champions",IF(AND(Q3>=3,R3>=3),"Loyal",IF(AND(Q3<=2,R3>=3),"At Risk",IF(Q3<=2,"Hibernating","Potential")))) -> Loyal | U3: =L3/Assumptions!$B$6 -> 55.927778 | V3: =IF(O3="Slipping",U3,0) -> 0 | W3: =IF(O3="Churned",U3,0) -> 0 | X3: =IF(AND(O3="Active",P3<=2),"Yes","No") -> Yes
A4: =Customers!A4 -> C0003 | B4: =Customers!B4 -> Rift Valley | C4: =Customers!C4 -> Prepaid | D4: =COUNTIFS(Transactions!$C$2:$C$13107,$A4,Transactions!$E$2:$E$13107,D$1) -> 6 | E4: =COUNTIFS(Transactions!$C$2:$C$13107,$A4,Transactions!$E$2:$E$13107,E$1) -> 27 | F4: =COUNTIFS(Transactions!$C$2:$C$13107,$A4,Transactions!$E$2:$E$13107,F$1) -> 13 | G4: =COUNTIFS(Transactions!$C$2:$C$13107,$A4,Transactions!$E$2:$E$13107,G$1) -> 11 | H4: =COUNTIFS(Transactions!$C$2:$C$13107,$A4,Transactions!$E$2:$E$13107,H$1) -> 5 | I4: =COUNTIFS(Transactions!$C$2:$C$13107,$A4,Transactions!$E$2:$E$13107,I$1) -> 14 | J4: =SUM(D4:I4) -> 76 | K4: =SUMIFS(Transactions!$F$2:$F$13107,Transactions!$C$2:$C$13107,A4) -> 269408 | L4: =SUMIFS(Transactions!$I$2:$I$13107,Transactions!$C$2:$C$13107,A4) -> 1996.33 | M4: =IF(J4=0,"",_xlfn.MAXIFS(Transactions!$B$2:$B$13107,Transactions!$C$2:$C$13107,A4)) -> 46283 | N4: =IF(J4=0,999,Assumptions!$B$4-M4) -> 12 | O4: =IF(N4<=Assumptions!$B$7,"Active",IF(N4<=Assumptions!$B$8,"Slipping","Churned")) -> Active | P4: =COUNTIF(D4:I4,">0") -> 6 | Q4: =IF(N4<=Assumptions!$B$22,5,IF(N4<=Assumptions!$B$23,4,IF(N4<=Assumptions!$B$24,3,IF(N4<=Assumptions!$B$25,2,1)))) -> 5 | R4: =1+(J4>=Assumptions!$C$25)+(J4>=Assumptions!$C$24)+(J4>=Assumptions!$C$23)+(J4>=Assumptions!$C$22) -> 5 | S4: =1+(L4>=Assumptions!$D$25)+(L4>=Assumptions!$D$24)+(L4>=Assumptions!$D$23)+(L4>=Assumptions!$D$22) -> 5 | T4: =IF(AND(Q4>=4,R4>=4),"Champions",IF(AND(Q4>=3,R4>=3),"Loyal",IF(AND(Q4<=2,R4>=3),"At Risk",IF(Q4<=2,"Hibernating","Potential")))) -> Champions | U4: =L4/Assumptions!$B$6 -> 221.81444 | V4: =IF(O4="Slipping",U4,0) -> 0 | W4: =IF(O4="Churned",U4,0) -> 0 | X4: =IF(AND(O4="Active",P4<=2),"Yes","No") -> No
A5: =Customers!A5 -> C0004 | B5: =Customers!B5 -> Central | C5: =Customers!C5 -> Prepaid | D5: =COUNTIFS(Transactions!$C$2:$C$13107,$A5,Transactions!$E$2:$E$13107,D$1) -> 2 | E5: =COUNTIFS(Transactions!$C$2:$C$13107,$A5,Transactions!$E$2:$E$13107,E$1) -> 0 | F5: =COUNTIFS(Transactions!$C$2:$C$13107,$A5,Transactions!$E$2:$E$13107,F$1) -> 0 | G5: =COUNTIFS(Transactions!$C$2:$C$13107,$A5,Transactions!$E$2:$E$13107,G$1) -> 0 | H5: =COUNTIFS(Transactions!$C$2:$C$13107,$A5,Transactions!$E$2:$E$13107,H$1) -> 3 | I5: =COUNTIFS(Transactions!$C$2:$C$13107,$A5,Transactions!$E$2:$E$13107,I$1) -> 0 | J5: =SUM(D5:I5) -> 5 | K5: =SUMIFS(Transactions!$F$2:$F$13107,Transactions!$C$2:$C$13107,A5) -> 3890 | L5: =SUMIFS(Transactions!$I$2:$I$13107,Transactions!$C$2:$C$13107,A5) -> 58.8 | M5: =IF(J5=0,"",_xlfn.MAXIFS(Transactions!$B$2:$B$13107,Transactions!$C$2:$C$13107,A5)) -> 46081 | N5: =IF(J5=0,999,Assumptions!$B$4-M5) -> 214 | O5: =IF(N5<=Assumptions!$B$7,"Active",IF(N5<=Assumptions!$B$8,"Slipping","Churned")) -> Churned | P5: =COUNTIF(D5:I5,">0") -> 2 | Q5: =IF(N5<=Assumptions!$B$22,5,IF(N5<=Assumptions!$B$23,4,IF(N5<=Assumptions!$B$24,3,IF(N5<=Assumptions!$B$25,2,1)))) -> 1 | R5: =1+(J5>=Assumptions!$C$25)+(J5>=Assumptions!$C$24)+(J5>=Assumptions!$C$23)+(J5>=Assumptions!$C$22) -> 1 | S5: =1+(L5>=Assumptions!$D$25)+(L5>=Assumptions!$D$24)+(L5>=Assumptions!$D$23)+(L5>=Assumptions!$D$22) -> 1 | T5: =IF(AND(Q5>=4,R5>=4),"Champions",IF(AND(Q5>=3,R5>=3),"Loyal",IF(AND(Q5<=2,R5>=3),"At Risk",IF(Q5<=2,"Hibernating","Potential")))) -> Hibernating | U5: =L5/Assumptions!$B$6 -> 6.5333333 | V5: =IF(O5="Slipping",U5,0) -> 0 | W5: =IF(O5="Churned",U5,0) -> 6.5333333 | X5: =IF(AND(O5="Active",P5<=2),"Yes","No") -> No
A6: =Customers!A6 -> C0005 | B6: =Customers!B6 -> Central | C6: =Customers!C6 -> Postpaid | D6: =COUNTIFS(Transactions!$C$2:$C$13107,$A6,Transactions!$E$2:$E$13107,D$1) -> 20 | E6: =COUNTIFS(Transactions!$C$2:$C$13107,$A6,Transactions!$E$2:$E$13107,E$1) -> 0 | F6: =COUNTIFS(Transactions!$C$2:$C$13107,$A6,Transactions!$E$2:$E$13107,F$1) -> 2 | G6: =COUNTIFS(Transactions!$C$2:$C$13107,$A6,Transactions!$E$2:$E$13107,G$1) -> 9 | H6: =COUNTIFS(Transactions!$C$2:$C$13107,$A6,Transactions!$E$2:$E$13107,H$1) -> 0 | I6: =COUNTIFS(Transactions!$C$2:$C$13107,$A6,Transactions!$E$2:$E$13107,I$1) -> 0 | J6: =SUM(D6:I6) -> 31 | K6: =SUMIFS(Transactions!$F$2:$F$13107,Transactions!$C$2:$C$13107,A6) -> 175090 | L6: =SUMIFS(Transactions!$I$2:$I$13107,Transactions!$C$2:$C$13107,A6) -> 1027.3 | M6: =IF(J6=0,"",_xlfn.MAXIFS(Transactions!$B$2:$B$13107,Transactions!$C$2:$C$13107,A6)) -> 46295 | N6: =IF(J6=0,999,Assumptions!$B$4-M6) -> 0 | O6: =IF(N6<=Assumptions!$B$7,"Active",IF(N6<=Assumptions!$B$8,"Slipping","Churned")) -> Active | P6: =COUNTIF(D6:I6,">0") -> 3 | Q6: =IF(N6<=Assumptions!$B$22,5,IF(N6<=Assumptions!$B$23,4,IF(N6<=Assumptions!$B$24,3,IF(N6<=Assumptions!$B$25,2,1)))) -> 5 | R6: =1+(J6>=Assumptions!$C$25)+(J6>=Assumptions!$C$24)+(J6>=Assumptions!$C$23)+(J6>=Assumptions!$C$22) -> 5 | S6: =1+(L6>=Assumptions!$D$25)+(L6>=Assumptions!$D$24)+(L6>=Assumptions!$D$23)+(L6>=Assumptions!$D$22) -> 5 | T6: =IF(AND(Q6>=4,R6>=4),"Champions",IF(AND(Q6>=3,R6>=3),"Loyal",IF(AND(Q6<=2,R6>=3),"At Risk",IF(Q6<=2,"Hibernating","Potential")))) -> Champions | U6: =L6/Assumptions!$B$6 -> 114.14444 | V6: =IF(O6="Slipping",U6,0) -> 0 | W6: =IF(O6="Churned",U6,0) -> 0 | X6: =IF(AND(O6="Active",P6<=2),"Yes","No") -> No
A7: =Customers!A7 -> C0006 | B7: =Customers!B7 -> Western | C7: =Customers!C7 -> Prepaid | D7: =COUNTIFS(Transactions!$C$2:$C$13107,$A7,Transactions!$E$2:$E$13107,D$1) -> 22 | E7: =COUNTIFS(Transactions!$C$2:$C$13107,$A7,Transactions!$E$2:$E$13107,E$1) -> 0 | F7: =COUNTIFS(Transactions!$C$2:$C$13107,$A7,Transactions!$E$2:$E$13107,F$1) -> 2 | G7: =COUNTIFS(Transactions!$C$2:$C$13107,$A7,Transactions!$E$2:$E$13107,G$1) -> 0 | H7: =COUNTIFS(Transactions!$C$2:$C$13107,$A7,Transactions!$E$2:$E$13107,H$1) -> 9 | I7: =COUNTIFS(Transactions!$C$2:$C$13107,$A7,Transactions!$E$2:$E$13107,I$1) -> 2 | J7: =SUM(D7:I7) -> 35 | K7: =SUMIFS(Transactions!$F$2:$F$13107,Transactions!$C$2:$C$13107,A7) -> 63789 | L7: =SUMIFS(Transactions!$I$2:$I$13107,Transactions!$C$2:$C$13107,A7) -> 518.05 | M7: =IF(J7=0,"",_xlfn.MAXIFS(Transactions!$B$2:$B$13107,Transactions!$C$2:$C$13107,A7)) -> 46259 | N7: =IF(J7=0,999,Assumptions!$B$4-M7) -> 36 | O7: =IF(N7<=Assumptions!$B$7,"Active",IF(N7<=Assumptions!$B$8,"Slipping","Churned")) -> Slipping | P7: =COUNTIF(D7:I7,">0") -> 4 | Q7: =IF(N7<=Assumptions!$B$22,5,IF(N7<=Assumptions!$B$23,4,IF(N7<=Assumptions!$B$24,3,IF(N7<=Assumptions!$B$25,2,1)))) -> 3 | R7: =1+(J7>=Assumptions!$C$25)+(J7>=Assumptions!$C$24)+(J7>=Assumptions!$C$23)+(J7>=Assumptions!$C$22) -> 5 | S7: =1+(L7>=Assumptions!$D$25)+(L7>=Assumptions!$D$24)+(L7>=Assumptions!$D$23)+(L7>=Assumptions!$D$22) -> 4 | T7: =IF(AND(Q7>=4,R7>=4),"Champions",IF(AND(Q7>=3,R7>=3),"Loyal",IF(AND(Q7<=2,R7>=3),"At Risk",IF(Q7<=2,"Hibernating","Potential")))) -> Loyal | U7: =L7/Assumptions!$B$6 -> 57.561111 | V7: =IF(O7="Slipping",U7,0) -> 57.561111 | W7: =IF(O7="Churned",U7,0) -> 0 | X7: =IF(AND(O7="Active",P7<=2),"Yes","No") -> No
A8: =Customers!A8 -> C0007 | B8: =Customers!B8 -> Eastern | C8: =Customers!C8 -> Business | D8: =COUNTIFS(Transactions!$C$2:$C$13107,$A8,Transactions!$E$2:$E$13107,D$1) -> 0 | E8: =COUNTIFS(Transactions!$C$2:$C$13107,$A8,Transactions!$E$2:$E$13107,E$1) -> 0 | F8: =COUNTIFS(Transactions!$C$2:$C$13107,$A8,Transactions!$E$2:$E$13107,F$1) -> 5 | G8: =COUNTIFS(Transactions!$C$2:$C$13107,$A8,Transactions!$E$2:$E$13107,G$1) -> 3 | H8: =COUNTIFS(Transactions!$C$2:$C$13107,$A8,Transactions!$E$2:$E$13107,H$1) -> 1 | I8: =COUNTIFS(Transactions!$C$2:$C$13107,$A8,Transactions!$E$2:$E$13107,I$1) -> 1 | J8: =SUM(D8:I8) -> 10 | K8: =SUMIFS(Transactions!$F$2:$F$13107,Transactions!$C$2:$C$13107,A8) -> 111970 | L8: =SUMIFS(Transactions!$I$2:$I$13107,Transactions!$C$2:$C$13107,A8) -> 196.12 | M8: =IF(J8=0,"",_xlfn.MAXIFS(Transactions!$B$2:$B$13107,Transactions!$C$2:$C$13107,A8)) -> 46285 | N8: =IF(J8=0,999,Assumptions!$B$4-M8) -> 10 | O8: =IF(N8<=Assumptions!$B$7,"Active",IF(N8<=Assumptions!$B$8,"Slipping","Churned")) -> Active | P8: =COUNTIF(D8:I8,">0") -> 4 | Q8: =IF(N8<=Assumptions!$B$22,5,IF(N8<=Assumptions!$B$23,4,IF(N8<=Assumptions!$B$24,3,IF(N8<=Assumptions!$B$25,2,1)))) -> 5 | R8: =1+(J8>=Assumptions!$C$25)+(J8>=Assumptions!$C$24)+(J8>=Assumptions!$C$23)+(J8>=Assumptions!$C$22) -> 2 | S8: =1+(L8>=Assumptions!$D$25)+(L8>=Assumptions!$D$24)+(L8>=Assumptions!$D$23)+(L8>=Assumptions!$D$22) -> 2 | T8: =IF(AND(Q8>=4,R8>=4),"Champions",IF(AND(Q8>=3,R8>=3),"Loyal",IF(AND(Q8<=2,R8>=3),"At Risk",IF(Q8<=2,"Hibernating","Potential")))) -> Potential | U8: =L8/Assumptions!$B$6 -> 21.791111 | V8: =IF(O8="Slipping",U8,0) -> 0 | W8: =IF(O8="Churned",U8,0) -> 0 | X8: =IF(AND(O8="Active",P8<=2),"Yes","No") -> No
A9: =Customers!A9 -> C0008 | B9: =Customers!B9 -> Nairobi | C9: =Customers!C9 -> Prepaid | D9: =COUNTIFS(Transactions!$C$2:$C$13107,$A9,Transactions!$E$2:$E$13107,D$1) -> 7 | E9: =COUNTIFS(Transactions!$C$2:$C$13107,$A9,Transactions!$E$2:$E$13107,E$1) -> 0 | F9: =COUNTIFS(Transactions!$C$2:$C$13107,$A9,Transactions!$E$2:$E$13107,F$1) -> 1 | G9: =COUNTIFS(Transactions!$C$2:$C$13107,$A9,Transactions!$E$2:$E$13107,G$1) -> 0 | H9: =COUNTIFS(Transactions!$C$2:$C$13107,$A9,Transactions!$E$2:$E$13107,H$1) -> 3 | I9: =COUNTIFS(Transactions!$C$2:$C$13107,$A9,Transactions!$E$2:$E$13107,I$1) -> 0 | J9: =SUM(D9:I9) -> 11 | K9: =SUMIFS(Transactions!$F$2:$F$13107,Transactions!$C$2:$C$13107,A9) -> 32700 | L9: =SUMIFS(Transactions!$I$2:$I$13107,Transactions!$C$2:$C$13107,A9) -> 164.3 | M9: =IF(J9=0,"",_xlfn.MAXIFS(Transactions!$B$2:$B$13107,Transactions!$C$2:$C$13107,A9)) -> 46294 | N9: =IF(J9=0,999,Assumptions!$B$4-M9) -> 1 | O9: =IF(N9<=Assumptions!$B$7,"Active",IF(N9<=Assumptions!$B$8,"Slipping","Churned")) -> Active | P9: =COUNTIF(D9:I9,">0") -> 3 | Q9: =IF(N9<=Assumptions!$B$22,5,IF(N9<=Assumptions!$B$23,4,IF(N9<=Assumptions!$B$24,3,IF(N9<=Assumptions!$B$25,2,1)))) -> 5 | R9: =1+(J9>=Assumptions!$C$25)+(J9>=Assumptions!$C$24)+(J9>=Assumptions!$C$23)+(J9>=Assumptions!$C$22) -> 2 | S9: =1+(L9>=Assumptions!$D$25)+(L9>=Assumptions!$D$24)+(L9>=Assumptions!$D$23)+(L9>=Assumptions!$D$22) -> 2 | T9: =IF(AND(Q9>=4,R9>=4),"Champions",IF(AND(Q9>=3,R9>=3),"Loyal",IF(AND(Q9<=2,R9>=3),"At Risk",IF(Q9<=2,"Hibernating","Potential")))) -> Potential | U9: =L9/Assumptions!$B$6 -> 18.255556 | V9: =IF(O9="Slipping",U9,0) -> 0 | W9: =IF(O9="Churned",U9,0) -> 0 | X9: =IF(AND(O9="Active",P9<=2),"Yes","No") -> No
A10: =Customers!A10 -> C0009 | B10: =Customers!B10 -> Coast | C10: =Customers!C10 -> Prepaid | D10: =COUNTIFS(Transactions!$C$2:$C$13107,$A10,Transactions!$E$2:$E$13107,D$1) -> 0 | E10: =COUNTIFS(Transactions!$C$2:$C$13107,$A10,Transactions!$E$2:$E$13107,E$1) -> 7 | F10: =COUNTIFS(Transactions!$C$2:$C$13107,$A10,Transactions!$E$2:$E$13107,F$1) -> 0 | G10: =COUNTIFS(Transactions!$C$2:$C$13107,$A10,Transactions!$E$2:$E$13107,G$1) -> 0 | H10: =COUNTIFS(Transactions!$C$2:$C$13107,$A10,Transactions!$E$2:$E$13107,H$1) -> 1 | I10: =COUNTIFS(Transactions!$C$2:$C$13107,$A10,Transactions!$E$2:$E$13107,I$1) -> 0 | J10: =SUM(D10:I10) -> 8 | K10: =SUMIFS(Transactions!$F$2:$F$13107,Transactions!$C$2:$C$13107,A10) -> 25980 | L10: =SUMIFS(Transactions!$I$2:$I$13107,Transactions!$C$2:$C$13107,A10) -> 395 | M10: =IF(J10=0,"",_xlfn.MAXIFS(Transactions!$B$2:$B$13107,Transactions!$C$2:$C$13107,A10)) -> 46270 | N10: =IF(J10=0,999,Assumptions!$B$4-M10) -> 25 | O10: =IF(N10<=Assumptions!$B$7,"Active",IF(N10<=Assumptions!$B$8,"Slipping","Churned")) -> Active | P10: =COUNTIF(D10:I10,">0") -> 2 | Q10: =IF(N10<=Assumptions!$B$22,5,IF(N10<=Assumptions!$B$23,4,IF(N10<=Assumptions!$B$24,3,IF(N10<=Assumptions!$B$25,2,1)))) -> 4 | R10: =1+(J10>=Assumptions!$C$25)+(J10>=Assumptions!$C$24)+(J10>=Assumptions!$C$23)+(J10>=Assumptions!$C$22) -> 1 | S10: =1+(L10>=Assumptions!$D$25)+(L10>=Assumptions!$D$24)+(L10>=Assumptions!$D$23)+(L10>=Assumptions!$D$22) -> 3 | T10: =IF(AND(Q10>=4,R10>=4),"Champions",IF(AND(Q10>=3,R10>=3),"Loyal",IF(AND(Q10<=2,R10>=3),"At Risk",IF(Q10<=2,"Hibernating","Potential")))) -> Potential | U10: =L10/Assumptions!$B$6 -> 43.888889 | V10: =IF(O10="Slipping",U10,0) -> 0 | W10: =IF(O10="Churned",U10,0) -> 0 | X10: =IF(AND(O10="Active",P10<=2),"Yes","No") -> Yes
A11: =Customers!A11 -> C0010 | B11: =Customers!B11 -> Nairobi | C11: =Customers!C11 -> Prepaid | D11: =COUNTIFS(Transactions!$C$2:$C$13107,$A11,Transactions!$E$2:$E$13107,D$1) -> 3 | E11: =COUNTIFS(Transactions!$C$2:$C$13107,$A11,Transactions!$E$2:$E$13107,E$1) -> 0 | F11: =COUNTIFS(Transactions!$C$2:$C$13107,$A11,Transactions!$E$2:$E$13107,F$1) -> 3 | G11: =COUNTIFS(Transactions!$C$2:$C$13107,$A11,Transactions!$E$2:$E$13107,G$1) -> 3 | H11: =COUNTIFS(Transactions!$C$2:$C$13107,$A11,Transactions!$E$2:$E$13107,H$1) -> 2 | I11: =COUNTIFS(Transactions!$C$2:$C$13107,$A11,Transactions!$E$2:$E$13107,I$1) -> 4 | J11: =SUM(D11:I11) -> 15 | K11: =SUMIFS(Transactions!$F$2:$F$13107,Transactions!$C$2:$C$13107,A11) -> 30040 | L11: =SUMIFS(Transactions!$I$2:$I$13107,Transactions!$C$2:$C$13107,A11) -> 196.9 | M11: =IF(J11=0,"",_xlfn.MAXIFS(Transactions!$B$2:$B$13107,Transactions!$C$2:$C$13107,A11)) -> 46251 | N11: =IF(J11=0,999,Assumptions!$B$4-M11) -> 44 | O11: =IF(N11<=Assumptions!$B$7,"Active",IF(N11<=Assumptions!$B$8,"Slipping","Churned")) -> Slipping | P11: =COUNTIF(D11:I11,">0") -> 5 | Q11: =IF(N11<=Assumptions!$B$22,5,IF(N11<=Assumptions!$B$23,4,IF(N11<=Assumptions!$B$24,3,IF(N11<=Assumptions!$B$25,2,1)))) -> 3 | R11: =1+(J11>=Assumptions!$C$25)+(J11>=Assumptions!$C$24)+(J11>=Assumptions!$C$23)+(J11>=Assumptions!$C$22) -> 3 | S11: =1+(L11>=Assumptions!$D$25)+(L11>=Assumptions!$D$24)+(L11>=Assumptions!$D$23)+(L11>=Assumptions!$D$22) -> 2 | T11: =IF(AND(Q11>=4,R11>=4),"Champions",IF(AND(Q11>=3,R11>=3),"Loyal",IF(AND(Q11<=2,R11>=3),"At Risk",IF(Q11<=2,"Hibernating","Potential")))) -> Loyal | U11: =L11/Assumptions!$B$6 -> 21.877778 | V11: =IF(O11="Slipping",U11,0) -> 21.877778 | W11: =IF(O11="Churned",U11,0) -> 0 | X11: =IF(AND(O11="Active",P11<=2),"Yes","No") -> No
A12: =Customers!A12 -> C0011 | B12: =Customers!B12 -> Eastern | C12: =Customers!C12 -> Business | D12: =COUNTIFS(Transactions!$C$2:$C$13107,$A12,Transactions!$E$2:$E$13107,D$1) -> 0 | E12: =COUNTIFS(Transactions!$C$2:$C$13107,$A12,Transactions!$E$2:$E$13107,E$1) -> 1 | F12: =COUNTIFS(Transactions!$C$2:$C$13107,$A12,Transactions!$E$2:$E$13107,F$1) -> 0 | G12: =COUNTIFS(Transactions!$C$2:$C$13107,$A12,Transactions!$E$2:$E$13107,G$1) -> 11 | H12: =COUNTIFS(Transactions!$C$2:$C$13107,$A12,Transactions!$E$2:$E$13107,H$1) -> 0 | I12: =COUNTIFS(Transactions!$C$2:$C$13107,$A12,Transactions!$E$2:$E$13107,I$1) -> 3 | J12: =SUM(D12:I12) -> 15 | K12: =SUMIFS(Transactions!$F$2:$F$13107,Transactions!$C$2:$C$13107,A12) -> 130120 | L12: =SUMIFS(Transactions!$I$2:$I$13107,Transactions!$C$2:$C$13107,A12) -> 562.1 | M12: =IF(J12=0,"",_xlfn.MAXIFS(Transactions!$B$2:$B$13107,Transactions!$C$2:$C$13107,A12)) -> 46253 | N12: =IF(J12=0,999,Assumptions!$B$4-M12) -> 42 | O12: =IF(N12<=Assumptions!$B$7,"Active",IF(N12<=Assumptions!$B$8,"Slipping","Churned")) -> Slipping | P12: =COUNTIF(D12:I12,">0") -> 3 | Q12: =IF(N12<=Assumptions!$B$22,5,IF(N12<=Assumptions!$B$23,4,IF(N12<=Assumptions!$B$24,3,IF(N12<=Assumptions!$B$25,2,1)))) -> 3 | R12: =1+(J12>=Assumptions!$C$25)+(J12>=Assumptions!$C$24)+(J12>=Assumptions!$C$23)+(J12>=Assumptions!$C$22) -> 3 | S12: =1+(L12>=Assumptions!$D$25)+(L12>=Assumptions!$D$24)+(L12>=Assumptions!$D$23)+(L12>=Assumptions!$D$22) -> 4 | T12: =IF(AND(Q12>=4,R12>=4),"Champions",IF(AND(Q12>=3,R12>=3),"Loyal",IF(AND(Q12<=2,R12>=3),"At Risk",IF(Q12<=2,"Hibernating","Potential")))) -> Loyal | U12: =L12/Assumptions!$B$6 -> 62.455556 | V12: =IF(O12="Slipping",U12,0) -> 62.455556 | W12: =IF(O12="Churned",U12,0) -> 0 | X12: =IF(AND(O12="Active",P12<=2),"Yes","No") -> No
A13: =Customers!A13 -> C0012 | B13: =Customers!B13 -> Eastern | C13: =Customers!C13 -> Prepaid | D13: =COUNTIFS(Transactions!$C$2:$C$13107,$A13,Transactions!$E$2:$E$13107,D$1) -> 0 | E13: =COUNTIFS(Transactions!$C$2:$C$13107,$A13,Transactions!$E$2:$E$13107,E$1) -> 0 | F13: =COUNTIFS(Transactions!$C$2:$C$13107,$A13,Transactions!$E$2:$E$13107,F$1) -> 0 | G13: =COUNTIFS(Transactions!$C$2:$C$13107,$A13,Transactions!$E$2:$E$13107,G$1) -> 1 | H13: =COUNTIFS(Transactions!$C$2:$C$13107,$A13,Transactions!$E$2:$E$13107,H$1) -> 6 | I13: =COUNTIFS(Transactions!$C$2:$C$13107,$A13,Transactions!$E$2:$E$13107,I$1) -> 11 | J13: =SUM(D13:I13) -> 18 | K13: =SUMIFS(Transactions!$F$2:$F$13107,Transactions!$C$2:$C$13107,A13) -> 16778 | L13: =SUMIFS(Transactions!$I$2:$I$13107,Transactions!$C$2:$C$13107,A13) -> 242.9 | M13: =IF(J13=0,"",_xlfn.MAXIFS(Transactions!$B$2:$B$13107,Transactions!$C$2:$C$13107,A13)) -> 46291 | N13: =IF(J13=0,999,Assumptions!$B$4-M13) -> 4 | O13: =IF(N13<=Assumptions!$B$7,"Active",IF(N13<=Assumptions!$B$8,"Slipping","Churned")) -> Active | P13: =COUNTIF(D13:I13,">0") -> 3 | Q13: =IF(N13<=Assumptions!$B$22,5,IF(N13<=Assumptions!$B$23,4,IF(N13<=Assumptions!$B$24,3,IF(N13<=Assumptions!$B$25,2,1)))) -> 5 | R13: =1+(J13>=Assumptions!$C$25)+(J13>=Assumptions!$C$24)+(J13>=Assumptions!$C$23)+(J13>=Assumptions!$C$22) -> 3 | S13: =1+(L13>=Assumptions!$D$25)+(L13>=Assumptions!$D$24)+(L13>=Assumptions!$D$23)+(L13>=Assumptions!$D$22) -> 2 | T13: =IF(AND(Q13>=4,R13>=4),"Champions",IF(AND(Q13>=3,R13>=3),"Loyal",IF(AND(Q13<=2,R13>=3),"At Risk",IF(Q13<=2,"Hibernating","Potential")))) -> Loyal | U13: =L13/Assumptions!$B$6 -> 26.988889 | V13: =IF(O13="Slipping",U13,0) -> 0 | W13: =IF(O13="Churned",U13,0) -> 0 | X13: =IF(AND(O13="Active",P13<=2),"Yes","No") -> No
... A601: =Customers!A601 -> C0600 | B601: =Customers!B601 -> Nairobi | C601: =Customers!C601 -> Prepaid | D601: =COUNTIFS(Transactions!$C$2:$C$13107,$A601,Transactions!$E$2:$E$13107,D$1) -> 1 | E601: =COUNTIFS(Transactions!$C$2:$C$13107,$A601,Transactions!$E$2:$E$13107,E$1) -> 4 | F601: =COUNTIFS(Transactions!$C$2:$C$13107,$A601,Transactions!$E$2:$E$13107,F$1) -> 1 | G601: =COUNTIFS(Transactions!$C$2:$C$13107,$A601,Transactions!$E$2:$E$13107,G$1) -> 0 | H601: =COUNTIFS(Transactions!$C$2:$C$13107,$A601,Transactions!$E$2:$E$13107,H$1) -> 0 | I601: =COUNTIFS(Transactions!$C$2:$C$13107,$A601,Transactions!$E$2:$E$13107,I$1) -> 1 | J601: =SUM(D601:I601) -> 7 | K601: =SUMIFS(Transactions!$F$2:$F$13107,Transactions!$C$2:$C$13107,A601) -> 15040 | L601: =SUMIFS(Transactions!$I$2:$I$13107,Transactions!$C$2:$C$13107,A601) -> 141 | M601: =IF(J601=0,"",_xlfn.MAXIFS(Transactions!$B$2:$B$13107,Transactions!$C$2:$C$13107,A601)) -> 46275 | N601: =IF(J601=0,999,Assumptions!$B$4-M601) -> 20 | O601: =IF(N601<=Assumptions!$B$7,"Active",IF(N601<=Assumptions!$B$8,"Slipping","Churned")) -> Active | P601: =COUNTIF(D601:I601,">0") -> 4 | Q601: =IF(N601<=Assumptions!$B$22,5,IF(N601<=Assumptions!$B$23,4,IF(N601<=Assumptions!$B$24,3,IF(N601<=Assumptions!$B$25,2,1)))) -> 4 | R601: =1+(J601>=Assumptions!$C$25)+(J601>=Assumptions!$C$24)+(J601>=Assumptions!$C$23)+(J601>=Assumptions!$C$22) -> 1 | S601: =1+(L601>=Assumptions!$D$25)+(L601>=Assumptions!$D$24)+(L601>=Assumptions!$D$23)+(L601>=Assumptions!$D$22) -> 1 | T601: =IF(AND(Q601>=4,R601>=4),"Champions",IF(AND(Q601>=3,R601>=3),"Loyal",IF(AND(Q601<=2,R601>=3),"At Risk",IF(Q601<=2,"Hibernating","Potential")))) -> Potential | U601: =L601/Assumptions!$B$6 -> 15.666667 | V601: =IF(O601="Slipping",U601,0) -> 0 | W601: =IF(O601="Churned",U601,0) -> 0 | X601: =IF(AND(O601="Active",P601<=2),"Yes","No") -> No

Sheet Agents
A1: AgentID | B1: Region | C1: Tier | D1: Transactions | E1: Cash Value Handled (KES) | F1: Revenue (KES) | G1: Tier Avg Txns | H1: % of Tier Avg | I1: Performance Flag | J1: Revenue Rank
A2: A001 | B2: Nairobi | C2: Gold | D2: =COUNTIFS(Transactions!$D$2:$D$13107,A2) -> 141 | E2: =SUMIFS(Transactions!$F$2:$F$13107,Transactions!$D$2:$D$13107,A2) -> 1228460 | F2: =SUMIFS(Transactions!$I$2:$I$13107,Transactions!$D$2:$D$13107,A2) -> 5035.75 | G2: =AVERAGEIFS($D$2:$D$61,$C$2:$C$61,C2) -> 111.83333 | H2: =IFERROR(D2/G2,0) -> 1.2608048 | I2: =IF(H2<Assumptions!$B$9,"Underperforming","OK") -> OK | J2: =RANK(F2,$F$2:$F$61)+COUNTIF($F$2:F2,F2)-1 -> 6
A3: A002 | B3: Nairobi | C3: Gold | D3: =COUNTIFS(Transactions!$D$2:$D$13107,A3) -> 251 | E3: =SUMIFS(Transactions!$F$2:$F$13107,Transactions!$D$2:$D$13107,A3) -> 2420350 | F3: =SUMIFS(Transactions!$I$2:$I$13107,Transactions!$D$2:$D$13107,A3) -> 11275.4 | G3: =AVERAGEIFS($D$2:$D$61,$C$2:$C$61,C3) -> 111.83333 | H3: =IFERROR(D3/G3,0) -> 2.2444113 | I3: =IF(H3<Assumptions!$B$9,"Underperforming","OK") -> OK | J3: =RANK(F3,$F$2:$F$61)+COUNTIF($F$2:F3,F3)-1 -> 1
A4: A003 | B4: Nairobi | C4: Gold | D4: =COUNTIFS(Transactions!$D$2:$D$13107,A4) -> 258 | E4: =SUMIFS(Transactions!$F$2:$F$13107,Transactions!$D$2:$D$13107,A4) -> 2974430 | F4: =SUMIFS(Transactions!$I$2:$I$13107,Transactions!$D$2:$D$13107,A4) -> 10245.15 | G4: =AVERAGEIFS($D$2:$D$61,$C$2:$C$61,C4) -> 111.83333 | H4: =IFERROR(D4/G4,0) -> 2.3070045 | I4: =IF(H4<Assumptions!$B$9,"Underperforming","OK") -> OK | J4: =RANK(F4,$F$2:$F$61)+COUNTIF($F$2:F4,F4)-1 -> 3
A5: A004 | B5: Nairobi | C5: Silver | D5: =COUNTIFS(Transactions!$D$2:$D$13107,A5) -> 58 | E5: =SUMIFS(Transactions!$F$2:$F$13107,Transactions!$D$2:$D$13107,A5) -> 478460 | F5: =SUMIFS(Transactions!$I$2:$I$13107,Transactions!$D$2:$D$13107,A5) -> 2340.95 | G5: =AVERAGEIFS($D$2:$D$61,$C$2:$C$61,C5) -> 42.208333 | H5: =IFERROR(D5/G5,0) -> 1.3741362 | I5: =IF(H5<Assumptions!$B$9,"Underperforming","OK") -> OK | J5: =RANK(F5,$F$2:$F$61)+COUNTIF($F$2:F5,F5)-1 -> 25
A6: A005 | B6: Nairobi | C6: Silver | D6: =COUNTIFS(Transactions!$D$2:$D$13107,A6) -> 81 | E6: =SUMIFS(Transactions!$F$2:$F$13107,Transactions!$D$2:$D$13107,A6) -> 758840 | F6: =SUMIFS(Transactions!$I$2:$I$13107,Transactions!$D$2:$D$13107,A6) -> 2969.8 | G6: =AVERAGEIFS($D$2:$D$61,$C$2:$C$61,C6) -> 42.208333 | H6: =IFERROR(D6/G6,0) -> 1.9190523 | I6: =IF(H6<Assumptions!$B$9,"Underperforming","OK") -> OK | J6: =RANK(F6,$F$2:$F$61)+COUNTIF($F$2:F6,F6)-1 -> 18
A7: A006 | B7: Nairobi | C7: Silver | D7: =COUNTIFS(Transactions!$D$2:$D$13107,A7) -> 62 | E7: =SUMIFS(Transactions!$F$2:$F$13107,Transactions!$D$2:$D$13107,A7) -> 614260 | F7: =SUMIFS(Transactions!$I$2:$I$13107,Transactions!$D$2:$D$13107,A7) -> 4200.65 | G7: =AVERAGEIFS($D$2:$D$61,$C$2:$C$61,C7) -> 42.208333 | H7: =IFERROR(D7/G7,0) -> 1.4689042 | I7: =IF(H7<Assumptions!$B$9,"Underperforming","OK") -> OK | J7: =RANK(F7,$F$2:$F$61)+COUNTIF($F$2:F7,F7)-1 -> 8
A8: A007 | B8: Nairobi | C8: Silver | D8: =COUNTIFS(Transactions!$D$2:$D$13107,A8) -> 2 | E8: =SUMIFS(Transactions!$F$2:$F$13107,Transactions!$D$2:$D$13107,A8) -> 32390 | F8: =SUMIFS(Transactions!$I$2:$I$13107,Transactions!$D$2:$D$13107,A8) -> 0 | G8: =AVERAGEIFS($D$2:$D$61,$C$2:$C$61,C8) -> 42.208333 | H8: =IFERROR(D8/G8,0) -> 0.047384008 | I8: =IF(H8<Assumptions!$B$9,"Underperforming","OK") -> Underperforming | J8: =RANK(F8,$F$2:$F$61)+COUNTIF($F$2:F8,F8)-1 -> 60
A9: A008 | B9: Nairobi | C9: Bronze | D9: =COUNTIFS(Transactions!$D$2:$D$13107,A9) -> 50 | E9: =SUMIFS(Transactions!$F$2:$F$13107,Transactions!$D$2:$D$13107,A9) -> 516330 | F9: =SUMIFS(Transactions!$I$2:$I$13107,Transactions!$D$2:$D$13107,A9) -> 1779.05 | G9: =AVERAGEIFS($D$2:$D$61,$C$2:$C$61,C9) -> 23.333333 | H9: =IFERROR(D9/G9,0) -> 2.1428571 | I9: =IF(H9<Assumptions!$B$9,"Underperforming","OK") -> OK | J9: =RANK(F9,$F$2:$F$61)+COUNTIF($F$2:F9,F9)-1 -> 29
A10: A009 | B10: Nairobi | C10: Bronze | D10: =COUNTIFS(Transactions!$D$2:$D$13107,A10) -> 27 | E10: =SUMIFS(Transactions!$F$2:$F$13107,Transactions!$D$2:$D$13107,A10) -> 199280 | F10: =SUMIFS(Transactions!$I$2:$I$13107,Transactions!$D$2:$D$13107,A10) -> 864.25 | G10: =AVERAGEIFS($D$2:$D$61,$C$2:$C$61,C10) -> 23.333333 | H10: =IFERROR(D10/G10,0) -> 1.1571429 | I10: =IF(H10<Assumptions!$B$9,"Underperforming","OK") -> OK | J10: =RANK(F10,$F$2:$F$61)+COUNTIF($F$2:F10,F10)-1 -> 44
A11: A010 | B11: Nairobi | C11: Bronze | D11: =COUNTIFS(Transactions!$D$2:$D$13107,A11) -> 48 | E11: =SUMIFS(Transactions!$F$2:$F$13107,Transactions!$D$2:$D$13107,A11) -> 431640 | F11: =SUMIFS(Transactions!$I$2:$I$13107,Transactions!$D$2:$D$13107,A11) -> 2458.7 | G11: =AVERAGEIFS($D$2:$D$61,$C$2:$C$61,C11) -> 23.333333 | H11: =IFERROR(D11/G11,0) -> 2.0571429 | I11: =IF(H11<Assumptions!$B$9,"Underperforming","OK") -> OK | J11: =RANK(F11,$F$2:$F$61)+COUNTIF($F$2:F11,F11)-1 -> 22
A12: A011 | B12: Central | C12: Gold | D12: =COUNTIFS(Transactions!$D$2:$D$13107,A12) -> 47 | E12: =SUMIFS(Transactions!$F$2:$F$13107,Transactions!$D$2:$D$13107,A12) -> 518760 | F12: =SUMIFS(Transactions!$I$2:$I$13107,Transactions!$D$2:$D$13107,A12) -> 2429.25 | G12: =AVERAGEIFS($D$2:$D$61,$C$2:$C$61,C12) -> 111.83333 | H12: =IFERROR(D12/G12,0) -> 0.42026826 | I12: =IF(H12<Assumptions!$B$9,"Underperforming","OK") -> Underperforming | J12: =RANK(F12,$F$2:$F$61)+COUNTIF($F$2:F12,F12)-1 -> 23
A13: A012 | B13: Central | C13: Gold | D13: =COUNTIFS(Transactions!$D$2:$D$13107,A13) -> 129 | E13: =SUMIFS(Transactions!$F$2:$F$13107,Transactions!$D$2:$D$13107,A13) -> 1430340 | F13: =SUMIFS(Transactions!$I$2:$I$13107,Transactions!$D$2:$D$13107,A13) -> 6130.25 | G13: =AVERAGEIFS($D$2:$D$61,$C$2:$C$61,C13) -> 111.83333 | H13: =IFERROR(D13/G13,0) -> 1.1535022 | I13: =IF(H13<Assumptions!$B$9,"Underperforming","OK") -> OK | J13: =RANK(F13,$F$2:$F$61)+COUNTIF($F$2:F13,F13)-1 -> 4
... A61: A060 | B61: Eastern | C61: Bronze | D61: =COUNTIFS(Transactions!$D$2:$D$13107,A61) -> 2 | E61: =SUMIFS(Transactions!$F$2:$F$13107,Transactions!$D$2:$D$13107,A61) -> 35000 | F61: =SUMIFS(Transactions!$I$2:$I$13107,Transactions!$D$2:$D$13107,A61) -> 248 | G61: =AVERAGEIFS($D$2:$D$61,$C$2:$C$61,C61) -> 23.333333 | H61: =IFERROR(D61/G61,0) -> 0.085714286 | I61: =IF(H61<Assumptions!$B$9,"Underperforming","OK") -> Underperforming | J61: =RANK(F61,$F$2:$F$61)+COUNTIF($F$2:F61,F61)-1 -> 56

Sheet Customers
A1: CustomerID | B1: Region | C1: Plan | D1: Age Band | E1: Join Date | F1: Tenure (months)
A2: C0001 | B2: Nairobi | C2: Prepaid | D2: 25-34 | E2: 45788 | F2: =DATEDIF(E2,Assumptions!$B$4,"m") -> 16
A3: C0002 | B3: Coast | C3: Postpaid | D3: 25-34 | E3: 45945 | F3: =DATEDIF(E3,Assumptions!$B$4,"m") -> 11
A4: C0003 | B4: Rift Valley | C4: Prepaid | D4: 55+ | E4: 44478 | F4: =DATEDIF(E4,Assumptions!$B$4,"m") -> 59
A5: C0004 | B5: Central | C5: Prepaid | D5: 35-44 | E5: 43256 | F5: =DATEDIF(E5,Assumptions!$B$4,"m") -> 99
A6: C0005 | B6: Central | C6: Postpaid | D6: 25-34 | E6: 45891 | F6: =DATEDIF(E6,Assumptions!$B$4,"m") -> 13
A7: C0006 | B7: Western | C7: Prepaid | D7: 35-44 | E7: 45433 | F7: =DATEDIF(E7,Assumptions!$B$4,"m") -> 28
A8: C0007 | B8: Eastern | C8: Business | D8: 18-24 | E8: 45155 | F8: =DATEDIF(E8,Assumptions!$B$4,"m") -> 37
A9: C0008 | B9: Nairobi | C9: Prepaid | D9: 35-44 | E9: 46199 | F9: =DATEDIF(E9,Assumptions!$B$4,"m") -> 3
A10: C0009 | B10: Coast | C10: Prepaid | D10: 25-34 | E10: 44532 | F10: =DATEDIF(E10,Assumptions!$B$4,"m") -> 57
A11: C0010 | B11: Nairobi | C11: Prepaid | D11: 35-44 | E11: 44221 | F11: =DATEDIF(E11,Assumptions!$B$4,"m") -> 68
A12: C0011 | B12: Eastern | C12: Business | D12: 55+ | E12: 46023 | F12: =DATEDIF(E12,Assumptions!$B$4,"m") -> 8
A13: C0012 | B13: Eastern | C13: Prepaid | D13: 55+ | E13: 45092 | F13: =DATEDIF(E13,Assumptions!$B$4,"m") -> 39
... A601: C0600 | B601: Nairobi | C601: Prepaid | D601: 45-54 | E601: 43591 | F601: =DATEDIF(E601,Assumptions!$B$4,"m") -> 88

Sheet Transactions
A1: TxnID | B1: Date | C1: CustomerID | D1: AgentID | E1: Type | F1: Amount (KES) | G1: Month | H1: Region | I1: Revenue (KES)
A2: T00001 | B2: 46023 | C2: C0003 | D2: A021 | E2: Deposit Cash | F2: 48360 | G2: =DATE(YEAR(B2),MONTH(B2),1) -> 46023 | H2: =INDEX(Customers!$B$2:$B$601,MATCH(C2,Customers!$A$2:$A$601,0)) -> Rift Valley | I2: =ROUND(MIN(INDEX(Assumptions!$D$13:$D$18,MATCH(E2,Assumptions!$A$13:$A$18,0)),MAX(INDEX(Assumptions!$C$13:$C$18,MATCH(E2,Assumptions!$A$13:$A$18,0)),INDEX(Assumptions!$B$13:$B$18,MATCH(E2,Assumptions!$A$13:$A$18,0))*F2)),2) -> 0
A3: T00002 | B3: 46023 | C3: C0003 | D3: Digital | E3: Buy Data | F3: 250 | G3: =DATE(YEAR(B3),MONTH(B3),1) -> 46023 | H3: =INDEX(Customers!$B$2:$B$601,MATCH(C3,Customers!$A$2:$A$601,0)) -> Rift Valley | I3: =ROUND(MIN(INDEX(Assumptions!$D$13:$D$18,MATCH(E3,Assumptions!$A$13:$A$18,0)),MAX(INDEX(Assumptions!$C$13:$C$18,MATCH(E3,Assumptions!$A$13:$A$18,0)),INDEX(Assumptions!$B$13:$B$18,MATCH(E3,Assumptions!$A$13:$A$18,0))*F3)),2) -> 12.5
A4: T00003 | B4: 46023 | C4: C0011 | D4: Digital | E4: Pay Bill | F4: 13520 | G4: =DATE(YEAR(B4),MONTH(B4),1) -> 46023 | H4: =INDEX(Customers!$B$2:$B$601,MATCH(C4,Customers!$A$2:$A$601,0)) -> Eastern | I4: =ROUND(MIN(INDEX(Assumptions!$D$13:$D$18,MATCH(E4,Assumptions!$A$13:$A$18,0)),MAX(INDEX(Assumptions!$C$13:$C$18,MATCH(E4,Assumptions!$A$13:$A$18,0)),INDEX(Assumptions!$B$13:$B$18,MATCH(E4,Assumptions!$A$13:$A$18,0))*F4)),2) -> 40
A5: T00004 | B5: 46023 | C5: C0027 | D5: Digital | E5: Send Money | F5: 360 | G5: =DATE(YEAR(B5),MONTH(B5),1) -> 46023 | H5: =INDEX(Customers!$B$2:$B$601,MATCH(C5,Customers!$A$2:$A$601,0)) -> Nairobi | I5: =ROUND(MIN(INDEX(Assumptions!$D$13:$D$18,MATCH(E5,Assumptions!$A$13:$A$18,0)),MAX(INDEX(Assumptions!$C$13:$C$18,MATCH(E5,Assumptions!$A$13:$A$18,0)),INDEX(Assumptions!$B$13:$B$18,MATCH(E5,Assumptions!$A$13:$A$18,0))*F5)),2) -> 5
A6: T00005 | B6: 46023 | C6: C0028 | D6: Digital | E6: Buy Airtime | F6: 50 | G6: =DATE(YEAR(B6),MONTH(B6),1) -> 46023 | H6: =INDEX(Customers!$B$2:$B$601,MATCH(C6,Customers!$A$2:$A$601,0)) -> Rift Valley | I6: =ROUND(MIN(INDEX(Assumptions!$D$13:$D$18,MATCH(E6,Assumptions!$A$13:$A$18,0)),MAX(INDEX(Assumptions!$C$13:$C$18,MATCH(E6,Assumptions!$A$13:$A$18,0)),INDEX(Assumptions!$B$13:$B$18,MATCH(E6,Assumptions!$A$13:$A$18,0))*F6)),2) -> 2
A7: T00006 | B7: 46023 | C7: C0036 | D7: A053 | E7: Withdraw Cash | F7: 9490 | G7: =DATE(YEAR(B7),MONTH(B7),1) -> 46023 | H7: =INDEX(Customers!$B$2:$B$601,MATCH(C7,Customers!$A$2:$A$601,0)) -> Eastern | I7: =ROUND(MIN(INDEX(Assumptions!$D$13:$D$18,MATCH(E7,Assumptions!$A$13:$A$18,0)),MAX(INDEX(Assumptions!$C$13:$C$18,MATCH(E7,Assumptions!$A$13:$A$18,0)),INDEX(Assumptions!$B$13:$B$18,MATCH(E7,Assumptions!$A$13:$A$18,0))*F7)),2) -> 142.35
A8: T00007 | B8: 46023 | C8: C0041 | D8: Digital | E8: Send Money | F8: 2000 | G8: =DATE(YEAR(B8),MONTH(B8),1) -> 46023 | H8: =INDEX(Customers!$B$2:$B$601,MATCH(C8,Customers!$A$2:$A$601,0)) -> Coast | I8: =ROUND(MIN(INDEX(Assumptions!$D$13:$D$18,MATCH(E8,Assumptions!$A$13:$A$18,0)),MAX(INDEX(Assumptions!$C$13:$C$18,MATCH(E8,Assumptions!$A$13:$A$18,0)),INDEX(Assumptions!$B$13:$B$18,MATCH(E8,Assumptions!$A$13:$A$18,0))*F8)),2) -> 20
A9: T00008 | B9: 46023 | C9: C0065 | D9: Digital | E9: Pay Bill | F9: 2820 | G9: =DATE(YEAR(B9),MONTH(B9),1) -> 46023 | H9: =INDEX(Customers!$B$2:$B$601,MATCH(C9,Customers!$A$2:$A$601,0)) -> Eastern | I9: =ROUND(MIN(INDEX(Assumptions!$D$13:$D$18,MATCH(E9,Assumptions!$A$13:$A$18,0)),MAX(INDEX(Assumptions!$C$13:$C$18,MATCH(E9,Assumptions!$A$13:$A$18,0)),INDEX(Assumptions!$B$13:$B$18,MATCH(E9,Assumptions!$A$13:$A$18,0))*F9)),2) -> 11.28
A10: T00009 | B10: 46023 | C10: C0073 | D10: Digital | E10: Buy Airtime | F10: 100 | G10: =DATE(YEAR(B10),MONTH(B10),1) -> 46023 | H10: =INDEX(Customers!$B$2:$B$601,MATCH(C10,Customers!$A$2:$A$601,0)) -> Western | I10: =ROUND(MIN(INDEX(Assumptions!$D$13:$D$18,MATCH(E10,Assumptions!$A$13:$A$18,0)),MAX(INDEX(Assumptions!$C$13:$C$18,MATCH(E10,Assumptions!$A$13:$A$18,0)),INDEX(Assumptions!$B$13:$B$18,MATCH(E10,Assumptions!$A$13:$A$18,0))*F10)),2) -> 4
A11: T00010 | B11: 46023 | C11: C0073 | D11: Digital | E11: Send Money | F11: 850 | G11: =DATE(YEAR(B11),MONTH(B11),1) -> 46023 | H11: =INDEX(Customers!$B$2:$B$601,MATCH(C11,Customers!$A$2:$A$601,0)) -> Western | I11: =ROUND(MIN(INDEX(Assumptions!$D$13:$D$18,MATCH(E11,Assumptions!$A$13:$A$18,0)),MAX(INDEX(Assumptions!$C$13:$C$18,MATCH(E11,Assumptions!$A$13:$A$18,0)),INDEX(Assumptions!$B$13:$B$18,MATCH(E11,Assumptions!$A$13:$A$18,0))*F11)),2) -> 8.5
A12: T00011 | B12: 46023 | C12: C0101 | D12: A046 | E12: Deposit Cash | F12: 9660 | G12: =DATE(YEAR(B12),MONTH(B12),1) -> 46023 | H12: =INDEX(Customers!$B$2:$B$601,MATCH(C12,Customers!$A$2:$A$601,0)) -> Western | I12: =ROUND(MIN(INDEX(Assumptions!$D$13:$D$18,MATCH(E12,Assumptions!$A$13:$A$18,0)),MAX(INDEX(Assumptions!$C$13:$C$18,MATCH(E12,Assumptions!$A$13:$A$18,0)),INDEX(Assumptions!$B$13:$B$18,MATCH(E12,Assumptions!$A$13:$A$18,0))*F12)),2) -> 0
A13: T00012 | B13: 46023 | C13: C0108 | D13: A046 | E13: Withdraw Cash | F13: 910 | G13: =DATE(YEAR(B13),MONTH(B13),1) -> 46023 | H13: =INDEX(Customers!$B$2:$B$601,MATCH(C13,Customers!$A$2:$A$601,0)) -> Western | I13: =ROUND(MIN(INDEX(Assumptions!$D$13:$D$18,MATCH(E13,Assumptions!$A$13:$A$18,0)),MAX(INDEX(Assumptions!$C$13:$C$18,MATCH(E13,Assumptions!$A$13:$A$18,0)),INDEX(Assumptions!$B$13:$B$18,MATCH(E13,Assumptions!$A$13:$A$18,0))*F13)),2) -> 13.65
... A13107: T13106 | B13107: 46295 | C13107: C0590 | D13107: Digital | E13107: Pay Bill | F13107: 250 | G13107: =DATE(YEAR(B13107),MONTH(B13107),1) -> 46266 | H13107: =INDEX(Customers!$B$2:$B$601,MATCH(C13107,Customers!$A$2:$A$601,0)) -> Central | I13107: =ROUND(MIN(INDEX(Assumptions!$D$13:$D$18,MATCH(E13107,Assumptions!$A$13:$A$18,0)),MAX(INDEX(Assumptions!$C$13:$C$18,MATCH(E13107,Assumptions!$A$13:$A$18,0)),INDEX(Assumptions!$B$13:$B$18,MATCH(E13107,Assumptions!$A$13:$A$18,0))*F13107)),2) -> 1
