Workbook

Sheet README
A1: Retail Sales, Margin & Stock Performance – BI Portfolio Project
A2: BZME Insights | Sector: Retail / FMCG | Tool: Excel (formula-driven)
A4: BUSINESS PROBLEM
A5: A supermarket chain with five branches sells thousands of units a week but cannot easily see which products drive profit, where stock-outs cost sales, and where cash is tied up in slow stock. This workbook gives management one view.
A7: BUSINESS QUESTIONS
A8: 1. Which categories, stores and SKUs drive revenue and gross profit?
A9: 2. How much revenue is lost to stock-outs, and where?
A10: 3. Which SKUs are the A-class products that must always be in stock?
A11: 4. Which store-SKU lines risk running out, and which are overstocked?
A12: 5. Which SKUs earn below the target margin?
A14: HOW THE WORKBOOK IS BUILT
A15: Sales: 6,000 weekly store-SKU records (25 weeks). Revenue, COGS (including store shrinkage), gross profit and lost revenue are formulas.
... A35: Investigate stores with the highest stock-out rates (replenishment frequency, supplier lead time).

Sheet Dashboard
A1: Retail Sales, Margin & Stock Performance Dashboard
A2: ="Fictional Kenyan supermarket chain (5 stores, 48 SKUs) | Synthetic data | "&TEXT(Assumptions!B5,"d mmm yyyy")&" to "&TEXT(Assumptions!B4,"d mmm yyyy")&" | Prepared by BZME Insights" -> Fictional Kenyan supermarket chain (5 stores, 48 SKUs) | Synthetic data | 6 Apr 2026 to 27 Sep 2026 | Prepared by BZME Insights
A4: REVENUE (KES) | C4: GROSS PROFIT (KES) | E4: GROSS MARGIN | G4: UNITS SOLD | I4: EST. LOST REVENUE (KES) | K4: LINES AT STOCK-OUT RISK
A5: =SUM(Sales!$H$2:$H$6001) -> 116534680 | C5: =SUM(Sales!$J$2:$J$6001) -> 22806110 | E5: =C5/A5 -> 0.19570234 | G5: =SUM(Sales!$D$2:$D$6001) -> 537830 | I5: =SUM(Sales!$K$2:$K$6001) -> 2173692.1 | K5: =COUNTIF(Inventory!$I$2:$I$241,"Stock-out risk") -> 11
A7: Key findings (update automatically)
A8: ="1. Over "&Assumptions!B6&" weeks the stores sold KES "&TEXT(A5/1000000,"#,##0.0")&"M and earned KES "&TEXT(C5/1000000,"#,##0.0")&"M gross profit (margin "&TEXT(E5,"0.0%")&")." -> 1. Over 25 weeks the stores sold KES 116.5M and earned KES 22.8M gross profit (margin 19.6%).
A9: ="2. "&INDEX(A34:A39,MATCH(MAX(B34:B39),B34:B39,0))&" is the biggest category ("&TEXT(MAX(E34:E39),"0%")&" of revenue); "&INDEX(A34:A39,MATCH(MAX(D34:D39),D34:D39,0))&" earns the highest margin ("&TEXT(MAX(D34:D39),"0%")&")." -> 2. Dairy & Eggs is the biggest category (29% of revenue); Personal Care earns the highest margin (30%).
A10: ="3. "&B66&" A-class SKUs ("&TEXT(B66/B69,"0%")&" of the range) produce "&TEXT(D66,"0%")&" of revenue, so these must never run out." -> 3. 21 A-class SKUs (44% of the range) produce 81% of revenue, so these must never run out.
A11: ="4. Stock-outs cost an estimated KES "&TEXT(I5/1000,"#,##0")&"K in lost revenue ("&TEXT(G55,"0.0%")&" of sales). "&INDEX(A50:A54,MATCH(MAX(E50:E54),E50:E54,0))&" has the highest stock-out rate ("&TEXT(MAX(E50:E54),"0.0%")&")." -> 4. Stock-outs cost an estimated KES 2,174K in lost revenue (1.9% of sales). Kisumu has the highest stock-out rate (2.3%).
A12: ="5. "&B74&" store-SKU lines are at stock-out risk, while "&B77&" are overstocked, tying up KES "&TEXT(C77/1000000,"#,##0.0")&"M of stock at cost." -> 5. 11 store-SKU lines are at stock-out risk, while 35 are overstocked, tying up KES 6.2M of stock at cost.
A13: ="6. "&COUNTIF(Products!$M$2:$M$49,"Below target")&" of "&COUNTA(Products!$A$2:$A$49)&" SKUs earn below the "&TEXT(Assumptions!B12,"0%")&" margin target - review pricing or supplier cost." -> 6. 24 of 48 SKUs earn below the 25% margin target - review pricing or supplier cost.
A14: ="7. "&INDEX(A50:A54,MATCH(MAX(D50:D54),D50:D54,0))&" has the best store margin ("&TEXT(MAX(D50:D54),"0.0%")&") and "&INDEX(A50:A54,MATCH(MIN(D50:D54),D50:D54,0))&" the lowest ("&TEXT(MIN(D50:D54),"0.0%")&")." -> 7. Westlands has the best store margin (20.6%) and Kisumu the lowest (18.3%).
A16: 1. Monthly trend
A17: Month start | B17: Month | C17: Weeks in month | D17: Revenue (KES) | E17: Gross Profit (KES) | F17: Margin % | G17: Revenue / week (KES)
A18: =DATE(YEAR(Assumptions!$B$5),MONTH(Assumptions!$B$5),1) -> 46113 | B18: =TEXT(A18,"mmm") -> Apr | C18: =COUNTIFS(Sales!$F$2:$F$6001,A18,Sales!$B$2:$B$6001,"Nairobi CBD",Sales!$C$2:$C$6001,"SKU001") -> 4 | D18: =SUMIFS(Sales!$H$2:$H$6001,Sales!$F$2:$F$6001,A18) -> 19496205 | E18: =SUMIFS(Sales!$J$2:$J$6001,Sales!$F$2:$F$6001,A18) -> 3830149.5 | F18: =IFERROR(E18/D18,0) -> 0.19645616 | G18: =IFERROR(D18/C18,0) -> 4874051.2
A19: =EDATE(A18,1) -> 46143 | B19: =TEXT(A19,"mmm") -> May | C19: =COUNTIFS(Sales!$F$2:$F$6001,A19,Sales!$B$2:$B$6001,"Nairobi CBD",Sales!$C$2:$C$6001,"SKU001") -> 4 | D19: =SUMIFS(Sales!$H$2:$H$6001,Sales!$F$2:$F$6001,A19) -> 19301080 | E19: =SUMIFS(Sales!$J$2:$J$6001,Sales!$F$2:$F$6001,A19) -> 3802058.4 | F19: =IFERROR(E19/D19,0) -> 0.19698682 | G19: =IFERROR(D19/C19,0) -> 4825270
A20: =EDATE(A19,1) -> 46174 | B20: =TEXT(A20,"mmm") -> Jun | C20: =COUNTIFS(Sales!$F$2:$F$6001,A20,Sales!$B$2:$B$6001,"Nairobi CBD",Sales!$C$2:$C$6001,"SKU001") -> 5 | D20: =SUMIFS(Sales!$H$2:$H$6001,Sales!$F$2:$F$6001,A20) -> 23577265 | E20: =SUMIFS(Sales!$J$2:$J$6001,Sales!$F$2:$F$6001,A20) -> 4620318.9 | F20: =IFERROR(E20/D20,0) -> 0.19596501 | G20: =IFERROR(D20/C20,0) -> 4715453
A21: =EDATE(A20,1) -> 46204 | B21: =TEXT(A21,"mmm") -> Jul | C21: =COUNTIFS(Sales!$F$2:$F$6001,A21,Sales!$B$2:$B$6001,"Nairobi CBD",Sales!$C$2:$C$6001,"SKU001") -> 4 | D21: =SUMIFS(Sales!$H$2:$H$6001,Sales!$F$2:$F$6001,A21) -> 17861485 | E21: =SUMIFS(Sales!$J$2:$J$6001,Sales!$F$2:$F$6001,A21) -> 3493163.3 | F21: =IFERROR(E21/D21,0) -> 0.19556959 | G21: =IFERROR(D21/C21,0) -> 4465371.2
A22: =EDATE(A21,1) -> 46235 | B22: =TEXT(A22,"mmm") -> Aug | C22: =COUNTIFS(Sales!$F$2:$F$6001,A22,Sales!$B$2:$B$6001,"Nairobi CBD",Sales!$C$2:$C$6001,"SKU001") -> 5 | D22: =SUMIFS(Sales!$H$2:$H$6001,Sales!$F$2:$F$6001,A22) -> 21842570 | E22: =SUMIFS(Sales!$J$2:$J$6001,Sales!$F$2:$F$6001,A22) -> 4257033.9 | F22: =IFERROR(E22/D22,0) -> 0.1948962 | G22: =IFERROR(D22/C22,0) -> 4368514
A23: =EDATE(A22,1) -> 46266 | B23: =TEXT(A23,"mmm") -> Sep | C23: =COUNTIFS(Sales!$F$2:$F$6001,A23,Sales!$B$2:$B$6001,"Nairobi CBD",Sales!$C$2:$C$6001,"SKU001") -> 3 | D23: =SUMIFS(Sales!$H$2:$H$6001,Sales!$F$2:$F$6001,A23) -> 14456075 | E23: =SUMIFS(Sales!$J$2:$J$6001,Sales!$F$2:$F$6001,A23) -> 2803386 | F23: =IFERROR(E23/D23,0) -> 0.19392442 | G23: =IFERROR(D23/C23,0) -> 4818691.7
A32: 2. Category performance
A33: Category | B33: Revenue (KES) | C33: Gross Profit (KES) | D33: Margin % | E33: % of Revenue | F33: Units Sold
A34: Grocery Staples | B34: =SUMIFS(Sales!$H$2:$H$6001,Sales!$G$2:$G$6001,A34) -> 27942570 | C34: =SUMIFS(Sales!$J$2:$J$6001,Sales!$G$2:$G$6001,A34) -> 3038531.9 | D34: =IFERROR(C34/B34,0) -> 0.10874204 | E34: =IFERROR(B34/B$40,0) -> 0.23977901 | F34: =SUMIFS(Sales!$D$2:$D$6001,Sales!$G$2:$G$6001,A34) -> 123000
A35: Dairy & Eggs | B35: =SUMIFS(Sales!$H$2:$H$6001,Sales!$G$2:$G$6001,A35) -> 33295385 | C35: =SUMIFS(Sales!$J$2:$J$6001,Sales!$G$2:$G$6001,A35) -> 5522575 | D35: =IFERROR(C35/B35,0) -> 0.16586608 | E35: =IFERROR(B35/B$40,0) -> 0.28571224 | F35: =SUMIFS(Sales!$D$2:$D$6001,Sales!$G$2:$G$6001,A35) -> 96867
A36: Beverages | B36: =SUMIFS(Sales!$H$2:$H$6001,Sales!$G$2:$G$6001,A36) -> 19475340 | C36: =SUMIFS(Sales!$J$2:$J$6001,Sales!$G$2:$G$6001,A36) -> 3960626.5 | D36: =IFERROR(C36/B36,0) -> 0.20336623 | E36: =IFERROR(B36/B$40,0) -> 0.16712055 | F36: =SUMIFS(Sales!$D$2:$D$6001,Sales!$G$2:$G$6001,A36) -> 115059
A37: Household | B37: =SUMIFS(Sales!$H$2:$H$6001,Sales!$G$2:$G$6001,A37) -> 9465030 | C37: =SUMIFS(Sales!$J$2:$J$6001,Sales!$G$2:$G$6001,A37) -> 2431157.1 | D37: =IFERROR(C37/B37,0) -> 0.25685677 | E37: =IFERROR(B37/B$40,0) -> 0.081220715 | F37: =SUMIFS(Sales!$D$2:$D$6001,Sales!$G$2:$G$6001,A37) -> 49878
A38: Personal Care | B38: =SUMIFS(Sales!$H$2:$H$6001,Sales!$G$2:$G$6001,A38) -> 14820860 | C38: =SUMIFS(Sales!$J$2:$J$6001,Sales!$G$2:$G$6001,A38) -> 4505499.8 | D38: =IFERROR(C38/B38,0) -> 0.30399719 | E38: =IFERROR(B38/B$40,0) -> 0.12717982 | F38: =SUMIFS(Sales!$D$2:$D$6001,Sales!$G$2:$G$6001,A38) -> 53706
A39: Snacks & Confectionery | B39: =SUMIFS(Sales!$H$2:$H$6001,Sales!$G$2:$G$6001,A39) -> 11535495 | C39: =SUMIFS(Sales!$J$2:$J$6001,Sales!$G$2:$G$6001,A39) -> 3347719.6 | D39: =IFERROR(C39/B39,0) -> 0.29021032 | E39: =IFERROR(B39/B$40,0) -> 0.098987658 | F39: =SUMIFS(Sales!$D$2:$D$6001,Sales!$G$2:$G$6001,A39) -> 99320
A40: Total | B40: =SUM(B34:B39) -> 116534680 | C40: =SUM(C34:C39) -> 22806110 | D40: =IFERROR(C40/B40,0) -> 0.19570234 | E40: =SUM(E34:E39) -> 1 | F40: =SUM(F34:F39) -> 537830
A48: 3. Store performance and stock-outs
A49: Store | B49: Revenue (KES) | C49: Gross Profit (KES) | D49: Margin % | E49: Stock-out Rate | F49: Est. Lost Revenue (KES) | G49: Lost % of Sales
A50: Nairobi CBD | B50: =SUMIFS(Sales!$H$2:$H$6001,Sales!$B$2:$B$6001,A50) -> 29701330 | C50: =SUMIFS(Sales!$J$2:$J$6001,Sales!$B$2:$B$6001,A50) -> 5928444.9 | D50: =IFERROR(C50/B50,0) -> 0.199602 | E50: =IFERROR(SUMIFS(Sales!$E$2:$E$6001,Sales!$B$2:$B$6001,A50)/(COUNTIFS(Sales!$B$2:$B$6001,A50)*7),0) -> 0.020714286 | F50: =SUMIFS(Sales!$K$2:$K$6001,Sales!$B$2:$B$6001,A50) -> 527266.67 | G50: =IFERROR(F50/B50,0) -> 0.017752291
A51: Westlands | B51: =SUMIFS(Sales!$H$2:$H$6001,Sales!$B$2:$B$6001,A51) -> 24975820 | C51: =SUMIFS(Sales!$J$2:$J$6001,Sales!$B$2:$B$6001,A51) -> 5141730.6 | D51: =IFERROR(C51/B51,0) -> 0.20586834 | E51: =IFERROR(SUMIFS(Sales!$E$2:$E$6001,Sales!$B$2:$B$6001,A51)/(COUNTIFS(Sales!$B$2:$B$6001,A51)*7),0) -> 0.0175 | F51: =SUMIFS(Sales!$K$2:$K$6001,Sales!$B$2:$B$6001,A51) -> 320602.33 | G51: =IFERROR(F51/B51,0) -> 0.012836509
A52: Nakuru | B52: =SUMIFS(Sales!$H$2:$H$6001,Sales!$B$2:$B$6001,A52) -> 19783130 | C52: =SUMIFS(Sales!$J$2:$J$6001,Sales!$B$2:$B$6001,A52) -> 3825875.7 | D52: =IFERROR(C52/B52,0) -> 0.19339082 | E52: =IFERROR(SUMIFS(Sales!$E$2:$E$6001,Sales!$B$2:$B$6001,A52)/(COUNTIFS(Sales!$B$2:$B$6001,A52)*7),0) -> 0.015833333 | F52: =SUMIFS(Sales!$K$2:$K$6001,Sales!$B$2:$B$6001,A52) -> 463421 | G52: =IFERROR(F52/B52,0) -> 0.02342506
A53: Kisumu | B53: =SUMIFS(Sales!$H$2:$H$6001,Sales!$B$2:$B$6001,A53) -> 19467165 | C53: =SUMIFS(Sales!$J$2:$J$6001,Sales!$B$2:$B$6001,A53) -> 3566477.6 | D53: =IFERROR(C53/B53,0) -> 0.18320478 | E53: =IFERROR(SUMIFS(Sales!$E$2:$E$6001,Sales!$B$2:$B$6001,A53)/(COUNTIFS(Sales!$B$2:$B$6001,A53)*7),0) -> 0.023095238 | F53: =SUMIFS(Sales!$K$2:$K$6001,Sales!$B$2:$B$6001,A53) -> 443301.42 | G53: =IFERROR(F53/B53,0) -> 0.02277175
A54: Mombasa | B54: =SUMIFS(Sales!$H$2:$H$6001,Sales!$B$2:$B$6001,A54) -> 22607235 | C54: =SUMIFS(Sales!$J$2:$J$6001,Sales!$B$2:$B$6001,A54) -> 4343581.1 | D54: =IFERROR(C54/B54,0) -> 0.19213235 | E54: =IFERROR(SUMIFS(Sales!$E$2:$E$6001,Sales!$B$2:$B$6001,A54)/(COUNTIFS(Sales!$B$2:$B$6001,A54)*7),0) -> 0.019285714 | F54: =SUMIFS(Sales!$K$2:$K$6001,Sales!$B$2:$B$6001,A54) -> 419100.67 | G54: =IFERROR(F54/B54,0) -> 0.018538343
A55: Total | B55: =SUM(B50:B54) -> 116534680 | C55: =SUM(C50:C54) -> 22806110 | D55: =IFERROR(C55/B55,0) -> 0.19570234 | E55: =IFERROR(SUM(Sales!$E$2:$E$6001)/(COUNTA(Sales!$B$2:$B$6001)*7),0) -> 0.019285714 | F55: =SUM(F50:F54) -> 2173692.1 | G55: =IFERROR(F55/B55,0) -> 0.018652749
A64: 4. ABC analysis (revenue concentration)
A65: Class | B65: SKUs | C65: Revenue (KES) | D65: % of Revenue | E65: Avg Margin %
A66: A | B66: =COUNTIF(Products!$L$2:$L$49,A66) -> 21 | C66: =SUMIFS(Products!$H$2:$H$49,Products!$L$2:$L$49,A66) -> 94157820 | D66: =IFERROR(C66/C$69,0) -> 0.80798111 | E66: =IFERROR(SUMIFS(Products!$I$2:$I$49,Products!$L$2:$L$49,A66)/C66,0) -> 0.18388845
...

Sheet Assumptions
A1: Assumptions & Parameters
A2: Blue cells are editable inputs. Everything else recalculates from them.
A4: As-of date | B4: 46292 | C4: Last day covered by the data.
A5: Period start | B5: 46118 | C5: First week start.
A6: Weeks in period | B6: =(B4-B5+1)/7 -> 25 | C6: Calculated.
A7: ABC class A: cumulative revenue up to | B7: 0.8 | C7: SKUs making up the first 80% of revenue.
A8: ABC class B: cumulative revenue up to | B8: 0.95 | C8: Next 15%; the rest is class C.
A9: Stock-out risk: weeks of cover below | B9: 1 | C9: Stock covers less than this many weeks of sales.
A10: Low stock: weeks of cover below | B10: 2
A11: Overstock: weeks of cover above | B11: 8 | C11: Cash tied up in slow stock.
A12: Target gross margin | B12: 0.25 | C12: SKUs below this are flagged.
A13: Demand look-back (weeks) | B13: 8 | C13: Weeks used to estimate average weekly demand.
A15: Store shrinkage & wastage (% added to cost of goods sold)
A16: Nairobi CBD | B16: 0.01
A17: Westlands | B17: 0.008
A18: Nakuru | B18: 0.016
A19: Kisumu | B19: 0.024
A20: Mombasa | B20: 0.02

Sheet Products
A1: SKU | B1: Product | C1: Category | D1: Unit Cost (KES) | E1: Unit Price (KES) | F1: Margin % | G1: Units Sold | H1: Revenue (KES) | I1: Gross Profit (KES) | J1: Revenue Rank | K1: Cum. % of Revenue | L1: ABC Class | M1: Margin Flag
A2: SKU001 | B2: Maize Flour 2kg | C2: Grocery Staples | D2: 144 | E2: 165 | F2: =(E2-D2)/E2 -> 0.12727273 | G2: =SUMIFS(Sales!$D$2:$D$6001,Sales!$C$2:$C$6001,A2) -> 18196 | H2: =SUMIFS(Sales!$H$2:$H$6001,Sales!$C$2:$C$6001,A2) -> 3002340 | I2: =SUMIFS(Sales!$J$2:$J$6001,Sales!$C$2:$C$6001,A2) -> 341675.33 | J2: =RANK(H2,$H$2:$H$49)+COUNTIF($H$2:H2,H2)-1 -> 13 | K2: =SUMIFS($H$2:$H$49,$J$2:$J$49,"<="&J2)/SUM($H$2:$H$49) -> 0.64768308 | L2: =IF(K2-H2/SUM($H$2:$H$49)<Assumptions!$B$7,"A",IF(K2-H2/SUM($H$2:$H$49)<Assumptions!$B$8,"B","C")) -> A | M2: =IF(F2<Assumptions!$B$12,"Below target","OK") -> Below target
A3: SKU002 | B3: Wheat Flour 2kg | C3: Grocery Staples | D3: 168 | E3: 190 | F3: =(E3-D3)/E3 -> 0.11578947 | G3: =SUMIFS(Sales!$D$2:$D$6001,Sales!$C$2:$C$6001,A3) -> 14557 | H3: =SUMIFS(Sales!$H$2:$H$6001,Sales!$C$2:$C$6001,A3) -> 2765830 | I3: =SUMIFS(Sales!$J$2:$J$6001,Sales!$C$2:$C$6001,A3) -> 282878.37 | J3: =RANK(H3,$H$2:$H$49)+COUNTIF($H$2:H3,H3)-1 -> 15 | K3: =SUMIFS($H$2:$H$49,$J$2:$J$49,"<="&J3)/SUM($H$2:$H$49) -> 0.69678794 | L3: =IF(K3-H3/SUM($H$2:$H$49)<Assumptions!$B$7,"A",IF(K3-H3/SUM($H$2:$H$49)<Assumptions!$B$8,"B","C")) -> A | M3: =IF(F3<Assumptions!$B$12,"Below target","OK") -> Below target
A4: SKU003 | B4: Rice Pishori 2kg | C4: Grocery Staples | D4: 376 | E4: 420 | F4: =(E4-D4)/E4 -> 0.1047619 | G4: =SUMIFS(Sales!$D$2:$D$6001,Sales!$C$2:$C$6001,A4) -> 10589 | H4: =SUMIFS(Sales!$H$2:$H$6001,Sales!$C$2:$C$6001,A4) -> 4447380 | I4: =SUMIFS(Sales!$J$2:$J$6001,Sales!$C$2:$C$6001,A4) -> 405152.14 | J4: =RANK(H4,$H$2:$H$49)+COUNTIF($H$2:H4,H4)-1 -> 7 | K4: =SUMIFS($H$2:$H$49,$J$2:$J$49,"<="&J4)/SUM($H$2:$H$49) -> 0.4596146 | L4: =IF(K4-H4/SUM($H$2:$H$49)<Assumptions!$B$7,"A",IF(K4-H4/SUM($H$2:$H$49)<Assumptions!$B$8,"B","C")) -> A | M4: =IF(F4<Assumptions!$B$12,"Below target","OK") -> Below target
A5: SKU004 | B5: Sugar 1kg | C5: Grocery Staples | D5: 161 | E5: 190 | F5: =(E5-D5)/E5 -> 0.15263158 | G5: =SUMIFS(Sales!$D$2:$D$6001,Sales!$C$2:$C$6001,A5) -> 6426 | H5: =SUMIFS(Sales!$H$2:$H$6001,Sales!$C$2:$C$6001,A5) -> 1220940 | I5: =SUMIFS(Sales!$J$2:$J$6001,Sales!$C$2:$C$6001,A5) -> 170421.12 | J5: =RANK(H5,$H$2:$H$49)+COUNTIF($H$2:H5,H5)-1 -> 27 | K5: =SUMIFS($H$2:$H$49,$J$2:$J$49,"<="&J5)/SUM($H$2:$H$49) -> 0.87936432 | L5: =IF(K5-H5/SUM($H$2:$H$49)<Assumptions!$B$7,"A",IF(K5-H5/SUM($H$2:$H$49)<Assumptions!$B$8,"B","C")) -> B | M5: =IF(F5<Assumptions!$B$12,"Below target","OK") -> Below target
A6: SKU005 | B6: Cooking Oil 1L | C6: Grocery Staples | D6: 297 | E6: 340 | F6: =(E6-D6)/E6 -> 0.12647059 | G6: =SUMIFS(Sales!$D$2:$D$6001,Sales!$C$2:$C$6001,A6) -> 27275 | H6: =SUMIFS(Sales!$H$2:$H$6001,Sales!$C$2:$C$6001,A6) -> 9273500 | I6: =SUMIFS(Sales!$J$2:$J$6001,Sales!$C$2:$C$6001,A6) -> 1048530.5 | J6: =RANK(H6,$H$2:$H$49)+COUNTIF($H$2:H6,H6)-1 -> 3 | K6: =SUMIFS($H$2:$H$49,$J$2:$J$49,"<="&J6)/SUM($H$2:$H$49) -> 0.29828597 | L6: =IF(K6-H6/SUM($H$2:$H$49)<Assumptions!$B$7,"A",IF(K6-H6/SUM($H$2:$H$49)<Assumptions!$B$8,"B","C")) -> A | M6: =IF(F6<Assumptions!$B$12,"Below target","OK") -> Below target
A7: SKU006 | B7: Salt 500g | C7: Grocery Staples | D7: 40 | E7: 45 | F7: =(E7-D7)/E7 -> 0.11111111 | G7: =SUMIFS(Sales!$D$2:$D$6001,Sales!$C$2:$C$6001,A7) -> 4530 | H7: =SUMIFS(Sales!$H$2:$H$6001,Sales!$C$2:$C$6001,A7) -> 203850 | I7: =SUMIFS(Sales!$J$2:$J$6001,Sales!$C$2:$C$6001,A7) -> 19831.76 | J7: =RANK(H7,$H$2:$H$49)+COUNTIF($H$2:H7,H7)-1 -> 48 | K7: =SUMIFS($H$2:$H$49,$J$2:$J$49,"<="&J7)/SUM($H$2:$H$49) -> 1 | L7: =IF(K7-H7/SUM($H$2:$H$49)<Assumptions!$B$7,"A",IF(K7-H7/SUM($H$2:$H$49)<Assumptions!$B$8,"B","C")) -> C | M7: =IF(F7<Assumptions!$B$12,"Below target","OK") -> Below target
A8: SKU007 | B8: Tea Leaves 250g | C8: Grocery Staples | D8: 103 | E8: 120 | F8: =(E8-D8)/E8 -> 0.14166667 | G8: =SUMIFS(Sales!$D$2:$D$6001,Sales!$C$2:$C$6001,A8) -> 18566 | H8: =SUMIFS(Sales!$H$2:$H$6001,Sales!$C$2:$C$6001,A8) -> 2227920 | I8: =SUMIFS(Sales!$J$2:$J$6001,Sales!$C$2:$C$6001,A8) -> 286100.76 | J8: =RANK(H8,$H$2:$H$49)+COUNTIF($H$2:H8,H8)-1 -> 17 | K8: =SUMIFS($H$2:$H$49,$J$2:$J$49,"<="&J8)/SUM($H$2:$H$49) -> 0.73726894 | L8: =IF(K8-H8/SUM($H$2:$H$49)<Assumptions!$B$7,"A",IF(K8-H8/SUM($H$2:$H$49)<Assumptions!$B$8,"B","C")) -> A | M8: =IF(F8<Assumptions!$B$12,"Below target","OK") -> Below target
A9: SKU008 | B9: Dry Beans 1kg | C9: Grocery Staples | D9: 186 | E9: 210 | F9: =(E9-D9)/E9 -> 0.11428571 | G9: =SUMIFS(Sales!$D$2:$D$6001,Sales!$C$2:$C$6001,A9) -> 22861 | H9: =SUMIFS(Sales!$H$2:$H$6001,Sales!$C$2:$C$6001,A9) -> 4800810 | I9: =SUMIFS(Sales!$J$2:$J$6001,Sales!$C$2:$C$6001,A9) -> 483941.95 | J9: =RANK(H9,$H$2:$H$49)+COUNTIF($H$2:H9,H9)-1 -> 5 | K9: =SUMIFS($H$2:$H$49,$J$2:$J$49,"<="&J9)/SUM($H$2:$H$49) -> 0.38200148 | L9: =IF(K9-H9/SUM($H$2:$H$49)<Assumptions!$B$7,"A",IF(K9-H9/SUM($H$2:$H$49)<Assumptions!$B$8,"B","C")) -> A | M9: =IF(F9<Assumptions!$B$12,"Below target","OK") -> Below target
A10: SKU009 | B10: Fresh Milk 500ml | C10: Dairy & Eggs | D10: 51 | E10: 65 | F10: =(E10-D10)/E10 -> 0.21538462 | G10: =SUMIFS(Sales!$D$2:$D$6001,Sales!$C$2:$C$6001,A10) -> 4101 | H10: =SUMIFS(Sales!$H$2:$H$6001,Sales!$C$2:$C$6001,A10) -> 266565 | I10: =SUMIFS(Sales!$J$2:$J$6001,Sales!$C$2:$C$6001,A10) -> 54302.286 | J10: =RANK(H10,$H$2:$H$49)+COUNTIF($H$2:H10,H10)-1 -> 47 | K10: =SUMIFS($H$2:$H$49,$J$2:$J$49,"<="&J10)/SUM($H$2:$H$49) -> 0.99825074 | L10: =IF(K10-H10/SUM($H$2:$H$49)<Assumptions!$B$7,"A",IF(K10-H10/SUM($H$2:$H$49)<Assumptions!$B$8,"B","C")) -> C | M10: =IF(F10<Assumptions!$B$12,"Below target","OK") -> Below target
A11: SKU010 | B11: Fresh Milk 1L | C11: Dairy & Eggs | D11: 104 | E11: 125 | F11: =(E11-D11)/E11 -> 0.168 | G11: =SUMIFS(Sales!$D$2:$D$6001,Sales!$C$2:$C$6001,A11) -> 8832 | H11: =SUMIFS(Sales!$H$2:$H$6001,Sales!$C$2:$C$6001,A11) -> 1104000 | I11: =SUMIFS(Sales!$J$2:$J$6001,Sales!$C$2:$C$6001,A11) -> 171639.79 | J11: =RANK(H11,$H$2:$H$49)+COUNTIF($H$2:H11,H11)-1 -> 29 | K11: =SUMIFS($H$2:$H$49,$J$2:$J$49,"<="&J11)/SUM($H$2:$H$49) -> 0.8990697 | L11: =IF(K11-H11/SUM($H$2:$H$49)<Assumptions!$B$7,"A",IF(K11-H11/SUM($H$2:$H$49)<Assumptions!$B$8,"B","C")) -> B | M11: =IF(F11<Assumptions!$B$12,"Below target","OK") -> Below target
A12: SKU011 | B12: Yoghurt 500ml | C12: Dairy & Eggs | D12: 110 | E12: 130 | F12: =(E12-D12)/E12 -> 0.15384615 | G12: =SUMIFS(Sales!$D$2:$D$6001,Sales!$C$2:$C$6001,A12) -> 4848 | H12: =SUMIFS(Sales!$H$2:$H$6001,Sales!$C$2:$C$6001,A12) -> 630240 | I12: =SUMIFS(Sales!$J$2:$J$6001,Sales!$C$2:$C$6001,A12) -> 88917.9 | J12: =RANK(H12,$H$2:$H$49)+COUNTIF($H$2:H12,H12)-1 -> 38 | K12: =SUMIFS($H$2:$H$49,$J$2:$J$49,"<="&J12)/SUM($H$2:$H$49) -> 0.96457209 | L12: =IF(K12-H12/SUM($H$2:$H$49)<Assumptions!$B$7,"A",IF(K12-H12/SUM($H$2:$H$49)<Assumptions!$B$8,"B","C")) -> C | M12: =IF(F12<Assumptions!$B$12,"Below target","OK") -> Below target
A13: SKU012 | B13: Butter 250g | C13: Dairy & Eggs | D13: 268 | E13: 320 | F13: =(E13-D13)/E13 -> 0.1625 | G13: =SUMIFS(Sales!$D$2:$D$6001,Sales!$C$2:$C$6001,A13) -> 11944 | H13: =SUMIFS(Sales!$H$2:$H$6001,Sales!$C$2:$C$6001,A13) -> 3822080 | I13: =SUMIFS(Sales!$J$2:$J$6001,Sales!$C$2:$C$6001,A13) -> 573750.09 | J13: =RANK(H13,$H$2:$H$49)+COUNTIF($H$2:H13,H13)-1 -> 10 | K13: =SUMIFS($H$2:$H$49,$J$2:$J$49,"<="&J13)/SUM($H$2:$H$49) -> 0.56631991 | L13: =IF(K13-H13/SUM($H$2:$H$49)<Assumptions!$B$7,"A",IF(K13-H13/SUM($H$2:$H$49)<Assumptions!$B$8,"B","C")) -> A | M13: =IF(F13<Assumptions!$B$12,"Below target","OK") -> Below target
... A49: SKU048 | B49: Popcorn 100g | C49: Snacks & Confectionery | D49: 47 | E49: 70 | F49: =(E49-D49)/E49 -> 0.32857143 | G49: =SUMIFS(Sales!$D$2:$D$6001,Sales!$C$2:$C$6001,A49) -> 13013 | H49: =SUMIFS(Sales!$H$2:$H$6001,Sales!$C$2:$C$6001,A49) -> 910910 | I49: =SUMIFS(Sales!$J$2:$J$6001,Sales!$C$2:$C$6001,A49) -> 290577.59 | J49: =RANK(H49,$H$2:$H$49)+COUNTIF($H$2:H49,H49)-1 -> 33 | K49: =SUMIFS($H$2:$H$49,$J$2:$J$49,"<="&J49)/SUM($H$2:$H$49) -> 0.93247066 | L49: =IF(K49-H49/SUM($H$2:$H$49)<Assumptions!$B$7,"A",IF(K49-H49/SUM($H$2:$H$49)<Assumptions!$B$8,"B","C")) -> B | M49: =IF(F49<Assumptions!$B$12,"Below target","OK") -> OK

Sheet Inventory
A1: Store | B1: SKU | C1: Product | D1: Category | E1: Stock on Hand (units) | F1: Reorder Level (units) | G1: Avg Weekly Units | H1: Weeks of Cover | I1: Stock Status | J1: Stock Value at Cost (KES) | K1: Reorder Now
A2: Nairobi CBD | B2: SKU001 | C2: =INDEX(Products!$B$2:$B$49,MATCH(B2,Products!$A$2:$A$49,0)) -> Maize Flour 2kg | D2: =INDEX(Products!$C$2:$C$49,MATCH(B2,Products!$A$2:$A$49,0)) -> Grocery Staples | E2: 395 | F2: 248 | G2: =SUMIFS(Sales!$D$2:$D$6001,Sales!$B$2:$B$6001,A2,Sales!$C$2:$C$6001,B2,Sales!$A$2:$A$6001,">="&(Assumptions!$B$4-7*Assumptions!$B$13+1))/Assumptions!$B$13 -> 165.5 | H2: =IFERROR(E2/G2,999) -> 2.3867069 | I2: =IF(H2<Assumptions!$B$9,"Stock-out risk",IF(H2<Assumptions!$B$10,"Low",IF(H2>Assumptions!$B$11,"Overstock","Healthy"))) -> Healthy | J2: =E2*INDEX(Products!$D$2:$D$49,MATCH(B2,Products!$A$2:$A$49,0)) -> 56880 | K2: =IF(E2<=F2,"Yes","No") -> No
A3: Nairobi CBD | B3: SKU002 | C3: =INDEX(Products!$B$2:$B$49,MATCH(B3,Products!$A$2:$A$49,0)) -> Wheat Flour 2kg | D3: =INDEX(Products!$C$2:$C$49,MATCH(B3,Products!$A$2:$A$49,0)) -> Grocery Staples | E3: 228 | F3: 184 | G3: =SUMIFS(Sales!$D$2:$D$6001,Sales!$B$2:$B$6001,A3,Sales!$C$2:$C$6001,B3,Sales!$A$2:$A$6001,">="&(Assumptions!$B$4-7*Assumptions!$B$13+1))/Assumptions!$B$13 -> 122.5 | H3: =IFERROR(E3/G3,999) -> 1.8612245 | I3: =IF(H3<Assumptions!$B$9,"Stock-out risk",IF(H3<Assumptions!$B$10,"Low",IF(H3>Assumptions!$B$11,"Overstock","Healthy"))) -> Low | J3: =E3*INDEX(Products!$D$2:$D$49,MATCH(B3,Products!$A$2:$A$49,0)) -> 38304 | K3: =IF(E3<=F3,"Yes","No") -> No
A4: Nairobi CBD | B4: SKU003 | C4: =INDEX(Products!$B$2:$B$49,MATCH(B4,Products!$A$2:$A$49,0)) -> Rice Pishori 2kg | D4: =INDEX(Products!$C$2:$C$49,MATCH(B4,Products!$A$2:$A$49,0)) -> Grocery Staples | E4: 1752 | F4: 169 | G4: =SUMIFS(Sales!$D$2:$D$6001,Sales!$B$2:$B$6001,A4,Sales!$C$2:$C$6001,B4,Sales!$A$2:$A$6001,">="&(Assumptions!$B$4-7*Assumptions!$B$13+1))/Assumptions!$B$13 -> 112.625 | H4: =IFERROR(E4/G4,999) -> 15.556049 | I4: =IF(H4<Assumptions!$B$9,"Stock-out risk",IF(H4<Assumptions!$B$10,"Low",IF(H4>Assumptions!$B$11,"Overstock","Healthy"))) -> Overstock | J4: =E4*INDEX(Products!$D$2:$D$49,MATCH(B4,Products!$A$2:$A$49,0)) -> 658752 | K4: =IF(E4<=F4,"Yes","No") -> No
A5: Nairobi CBD | B5: SKU004 | C5: =INDEX(Products!$B$2:$B$49,MATCH(B5,Products!$A$2:$A$49,0)) -> Sugar 1kg | D5: =INDEX(Products!$C$2:$C$49,MATCH(B5,Products!$A$2:$A$49,0)) -> Grocery Staples | E5: 474 | F5: 81 | G5: =SUMIFS(Sales!$D$2:$D$6001,Sales!$B$2:$B$6001,A5,Sales!$C$2:$C$6001,B5,Sales!$A$2:$A$6001,">="&(Assumptions!$B$4-7*Assumptions!$B$13+1))/Assumptions!$B$13 -> 54.25 | H5: =IFERROR(E5/G5,999) -> 8.7373272 | I5: =IF(H5<Assumptions!$B$9,"Stock-out risk",IF(H5<Assumptions!$B$10,"Low",IF(H5>Assumptions!$B$11,"Overstock","Healthy"))) -> Overstock | J5: =E5*INDEX(Products!$D$2:$D$49,MATCH(B5,Products!$A$2:$A$49,0)) -> 76314 | K5: =IF(E5<=F5,"Yes","No") -> No
A6: Nairobi CBD | B6: SKU005 | C6: =INDEX(Products!$B$2:$B$49,MATCH(B6,Products!$A$2:$A$49,0)) -> Cooking Oil 1L | D6: =INDEX(Products!$C$2:$C$49,MATCH(B6,Products!$A$2:$A$49,0)) -> Grocery Staples | E6: 807 | F6: 427 | G6: =SUMIFS(Sales!$D$2:$D$6001,Sales!$B$2:$B$6001,A6,Sales!$C$2:$C$6001,B6,Sales!$A$2:$A$6001,">="&(Assumptions!$B$4-7*Assumptions!$B$13+1))/Assumptions!$B$13 -> 284.375 | H6: =IFERROR(E6/G6,999) -> 2.8378022 | I6: =IF(H6<Assumptions!$B$9,"Stock-out risk",IF(H6<Assumptions!$B$10,"Low",IF(H6>Assumptions!$B$11,"Overstock","Healthy"))) -> Healthy | J6: =E6*INDEX(Products!$D$2:$D$49,MATCH(B6,Products!$A$2:$A$49,0)) -> 239679 | K6: =IF(E6<=F6,"Yes","No") -> No
A7: Nairobi CBD | B7: SKU006 | C7: =INDEX(Products!$B$2:$B$49,MATCH(B7,Products!$A$2:$A$49,0)) -> Salt 500g | D7: =INDEX(Products!$C$2:$C$49,MATCH(B7,Products!$A$2:$A$49,0)) -> Grocery Staples | E7: 33 | F7: 45 | G7: =SUMIFS(Sales!$D$2:$D$6001,Sales!$B$2:$B$6001,A7,Sales!$C$2:$C$6001,B7,Sales!$A$2:$A$6001,">="&(Assumptions!$B$4-7*Assumptions!$B$13+1))/Assumptions!$B$13 -> 29.75 | H7: =IFERROR(E7/G7,999) -> 1.1092437 | I7: =IF(H7<Assumptions!$B$9,"Stock-out risk",IF(H7<Assumptions!$B$10,"Low",IF(H7>Assumptions!$B$11,"Overstock","Healthy"))) -> Low | J7: =E7*INDEX(Products!$D$2:$D$49,MATCH(B7,Products!$A$2:$A$49,0)) -> 1320 | K7: =IF(E7<=F7,"Yes","No") -> Yes
A8: Nairobi CBD | B8: SKU007 | C8: =INDEX(Products!$B$2:$B$49,MATCH(B8,Products!$A$2:$A$49,0)) -> Tea Leaves 250g | D8: =INDEX(Products!$C$2:$C$49,MATCH(B8,Products!$A$2:$A$49,0)) -> Grocery Staples | E8: 854 | F8: 268 | G8: =SUMIFS(Sales!$D$2:$D$6001,Sales!$B$2:$B$6001,A8,Sales!$C$2:$C$6001,B8,Sales!$A$2:$A$6001,">="&(Assumptions!$B$4-7*Assumptions!$B$13+1))/Assumptions!$B$13 -> 178.5 | H8: =IFERROR(E8/G8,999) -> 4.7843137 | I8: =IF(H8<Assumptions!$B$9,"Stock-out risk",IF(H8<Assumptions!$B$10,"Low",IF(H8>Assumptions!$B$11,"Overstock","Healthy"))) -> Healthy | J8: =E8*INDEX(Products!$D$2:$D$49,MATCH(B8,Products!$A$2:$A$49,0)) -> 87962 | K8: =IF(E8<=F8,"Yes","No") -> No
A9: Nairobi CBD | B9: SKU008 | C9: =INDEX(Products!$B$2:$B$49,MATCH(B9,Products!$A$2:$A$49,0)) -> Dry Beans 1kg | D9: =INDEX(Products!$C$2:$C$49,MATCH(B9,Products!$A$2:$A$49,0)) -> Grocery Staples | E9: 384 | F9: 304 | G9: =SUMIFS(Sales!$D$2:$D$6001,Sales!$B$2:$B$6001,A9,Sales!$C$2:$C$6001,B9,Sales!$A$2:$A$6001,">="&(Assumptions!$B$4-7*Assumptions!$B$13+1))/Assumptions!$B$13 -> 203 | H9: =IFERROR(E9/G9,999) -> 1.8916256 | I9: =IF(H9<Assumptions!$B$9,"Stock-out risk",IF(H9<Assumptions!$B$10,"Low",IF(H9>Assumptions!$B$11,"Overstock","Healthy"))) -> Low | J9: =E9*INDEX(Products!$D$2:$D$49,MATCH(B9,Products!$A$2:$A$49,0)) -> 71424 | K9: =IF(E9<=F9,"Yes","No") -> No
A10: Nairobi CBD | B10: SKU009 | C10: =INDEX(Products!$B$2:$B$49,MATCH(B10,Products!$A$2:$A$49,0)) -> Fresh Milk 500ml | D10: =INDEX(Products!$C$2:$C$49,MATCH(B10,Products!$A$2:$A$49,0)) -> Dairy & Eggs | E10: 94 | F10: 63 | G10: =SUMIFS(Sales!$D$2:$D$6001,Sales!$B$2:$B$6001,A10,Sales!$C$2:$C$6001,B10,Sales!$A$2:$A$6001,">="&(Assumptions!$B$4-7*Assumptions!$B$13+1))/Assumptions!$B$13 -> 41.875 | H10: =IFERROR(E10/G10,999) -> 2.2447761 | I10: =IF(H10<Assumptions!$B$9,"Stock-out risk",IF(H10<Assumptions!$B$10,"Low",IF(H10>Assumptions!$B$11,"Overstock","Healthy"))) -> Healthy | J10: =E10*INDEX(Products!$D$2:$D$49,MATCH(B10,Products!$A$2:$A$49,0)) -> 4794 | K10: =IF(E10<=F10,"Yes","No") -> No
A11: Nairobi CBD | B11: SKU010 | C11: =INDEX(Products!$B$2:$B$49,MATCH(B11,Products!$A$2:$A$49,0)) -> Fresh Milk 1L | D11: =INDEX(Products!$C$2:$C$49,MATCH(B11,Products!$A$2:$A$49,0)) -> Dairy & Eggs | E11: 194 | F11: 130 | G11: =SUMIFS(Sales!$D$2:$D$6001,Sales!$B$2:$B$6001,A11,Sales!$C$2:$C$6001,B11,Sales!$A$2:$A$6001,">="&(Assumptions!$B$4-7*Assumptions!$B$13+1))/Assumptions!$B$13 -> 86.5 | H11: =IFERROR(E11/G11,999) -> 2.2427746 | I11: =IF(H11<Assumptions!$B$9,"Stock-out risk",IF(H11<Assumptions!$B$10,"Low",IF(H11>Assumptions!$B$11,"Overstock","Healthy"))) -> Healthy | J11: =E11*INDEX(Products!$D$2:$D$49,MATCH(B11,Products!$A$2:$A$49,0)) -> 20176 | K11: =IF(E11<=F11,"Yes","No") -> No
A12: Nairobi CBD | B12: SKU011 | C12: =INDEX(Products!$B$2:$B$49,MATCH(B12,Products!$A$2:$A$49,0)) -> Yoghurt 500ml | D12: =INDEX(Products!$C$2:$C$49,MATCH(B12,Products!$A$2:$A$49,0)) -> Dairy & Eggs | E12: 472 | F12: 69 | G12: =SUMIFS(Sales!$D$2:$D$6001,Sales!$B$2:$B$6001,A12,Sales!$C$2:$C$6001,B12,Sales!$A$2:$A$6001,">="&(Assumptions!$B$4-7*Assumptions!$B$13+1))/Assumptions!$B$13 -> 46.125 | H12: =IFERROR(E12/G12,999) -> 10.233062 | I12: =IF(H12<Assumptions!$B$9,"Stock-out risk",IF(H12<Assumptions!$B$10,"Low",IF(H12>Assumptions!$B$11,"Overstock","Healthy"))) -> Overstock | J12: =E12*INDEX(Products!$D$2:$D$49,MATCH(B12,Products!$A$2:$A$49,0)) -> 51920 | K12: =IF(E12<=F12,"Yes","No") -> No
A13: Nairobi CBD | B13: SKU012 | C13: =INDEX(Products!$B$2:$B$49,MATCH(B13,Products!$A$2:$A$49,0)) -> Butter 250g | D13: =INDEX(Products!$C$2:$C$49,MATCH(B13,Products!$A$2:$A$49,0)) -> Dairy & Eggs | E13: 448 | F13: 202 | G13: =SUMIFS(Sales!$D$2:$D$6001,Sales!$B$2:$B$6001,A13,Sales!$C$2:$C$6001,B13,Sales!$A$2:$A$6001,">="&(Assumptions!$B$4-7*Assumptions!$B$13+1))/Assumptions!$B$13 -> 134.375 | H13: =IFERROR(E13/G13,999) -> 3.3339535 | I13: =IF(H13<Assumptions!$B$9,"Stock-out risk",IF(H13<Assumptions!$B$10,"Low",IF(H13>Assumptions!$B$11,"Overstock","Healthy"))) -> Healthy | J13: =E13*INDEX(Products!$D$2:$D$49,MATCH(B13,Products!$A$2:$A$49,0)) -> 120064 | K13: =IF(E13<=F13,"Yes","No") -> No
... A241: Mombasa | B241: SKU048 | C241: =INDEX(Products!$B$2:$B$49,MATCH(B241,Products!$A$2:$A$49,0)) -> Popcorn 100g | D241: =INDEX(Products!$C$2:$C$49,MATCH(B241,Products!$A$2:$A$49,0)) -> Snacks & Confectionery | E241: 494 | F241: 126 | G241: =SUMIFS(Sales!$D$2:$D$6001,Sales!$B$2:$B$6001,A241,Sales!$C$2:$C$6001,B241,Sales!$A$2:$A$6001,">="&(Assumptions!$B$4-7*Assumptions!$B$13+1))/Assumptions!$B$13 -> 84.125 | H241: =IFERROR(E241/G241,999) -> 5.872214 | I241: =IF(H241<Assumptions!$B$9,"Stock-out risk",IF(H241<Assumptions!$B$10,"Low",IF(H241>Assumptions!$B$11,"Overstock","Healthy"))) -> Healthy | J241: =E241*INDEX(Products!$D$2:$D$49,MATCH(B241,Products!$A$2:$A$49,0)) -> 23218 | K241: =IF(E241<=F241,"Yes","No") -> No

Sheet Sales
A1: Week Start | B1: Store | C1: SKU | D1: Units Sold | E1: Days Out of Stock | F1: Month | G1: Category | H1: Revenue (KES) | I1: COGS (KES) | J1: Gross Profit (KES) | K1: Est. Lost Revenue (KES)
A2: 46118 | B2: Nairobi CBD | C2: SKU001 | D2: 172 | E2: 0 | F2: =DATE(YEAR(A2),MONTH(A2),1) -> 46113 | G2: =INDEX(Products!$C$2:$C$49,MATCH(C2,Products!$A$2:$A$49,0)) -> Grocery Staples | H2: =D2*INDEX(Products!$E$2:$E$49,MATCH(C2,Products!$A$2:$A$49,0)) -> 28380 | I2: =D2*INDEX(Products!$D$2:$D$49,MATCH(C2,Products!$A$2:$A$49,0))*(1+INDEX(Assumptions!$B$16:$B$20,MATCH(B2,Assumptions!$A$16:$A$20,0))) -> 25015.68 | J2: =H2-I2 -> 3364.32 | K2: =IF(OR(E2=0,E2>=7),0,D2/(7-E2)*E2*INDEX(Products!$E$2:$E$49,MATCH(C2,Products!$A$2:$A$49,0))) -> 0
A3: 46125 | B3: Nairobi CBD | C3: SKU001 | D3: 108 | E3: 2 | F3: =DATE(YEAR(A3),MONTH(A3),1) -> 46113 | G3: =INDEX(Products!$C$2:$C$49,MATCH(C3,Products!$A$2:$A$49,0)) -> Grocery Staples | H3: =D3*INDEX(Products!$E$2:$E$49,MATCH(C3,Products!$A$2:$A$49,0)) -> 17820 | I3: =D3*INDEX(Products!$D$2:$D$49,MATCH(C3,Products!$A$2:$A$49,0))*(1+INDEX(Assumptions!$B$16:$B$20,MATCH(B3,Assumptions!$A$16:$A$20,0))) -> 15707.52 | J3: =H3-I3 -> 2112.48 | K3: =IF(OR(E3=0,E3>=7),0,D3/(7-E3)*E3*INDEX(Products!$E$2:$E$49,MATCH(C3,Products!$A$2:$A$49,0))) -> 7128
A4: 46132 | B4: Nairobi CBD | C4: SKU001 | D4: 200 | E4: 0 | F4: =DATE(YEAR(A4),MONTH(A4),1) -> 46113 | G4: =INDEX(Products!$C$2:$C$49,MATCH(C4,Products!$A$2:$A$49,0)) -> Grocery Staples | H4: =D4*INDEX(Products!$E$2:$E$49,MATCH(C4,Products!$A$2:$A$49,0)) -> 33000 | I4: =D4*INDEX(Products!$D$2:$D$49,MATCH(C4,Products!$A$2:$A$49,0))*(1+INDEX(Assumptions!$B$16:$B$20,MATCH(B4,Assumptions!$A$16:$A$20,0))) -> 29088 | J4: =H4-I4 -> 3912 | K4: =IF(OR(E4=0,E4>=7),0,D4/(7-E4)*E4*INDEX(Products!$E$2:$E$49,MATCH(C4,Products!$A$2:$A$49,0))) -> 0
A5: 46139 | B5: Nairobi CBD | C5: SKU001 | D5: 179 | E5: 0 | F5: =DATE(YEAR(A5),MONTH(A5),1) -> 46113 | G5: =INDEX(Products!$C$2:$C$49,MATCH(C5,Products!$A$2:$A$49,0)) -> Grocery Staples | H5: =D5*INDEX(Products!$E$2:$E$49,MATCH(C5,Products!$A$2:$A$49,0)) -> 29535 | I5: =D5*INDEX(Products!$D$2:$D$49,MATCH(C5,Products!$A$2:$A$49,0))*(1+INDEX(Assumptions!$B$16:$B$20,MATCH(B5,Assumptions!$A$16:$A$20,0))) -> 26033.76 | J5: =H5-I5 -> 3501.24 | K5: =IF(OR(E5=0,E5>=7),0,D5/(7-E5)*E5*INDEX(Products!$E$2:$E$49,MATCH(C5,Products!$A$2:$A$49,0))) -> 0
A6: 46146 | B6: Nairobi CBD | C6: SKU001 | D6: 166 | E6: 0 | F6: =DATE(YEAR(A6),MONTH(A6),1) -> 46143 | G6: =INDEX(Products!$C$2:$C$49,MATCH(C6,Products!$A$2:$A$49,0)) -> Grocery Staples | H6: =D6*INDEX(Products!$E$2:$E$49,MATCH(C6,Products!$A$2:$A$49,0)) -> 27390 | I6: =D6*INDEX(Products!$D$2:$D$49,MATCH(C6,Products!$A$2:$A$49,0))*(1+INDEX(Assumptions!$B$16:$B$20,MATCH(B6,Assumptions!$A$16:$A$20,0))) -> 24143.04 | J6: =H6-I6 -> 3246.96 | K6: =IF(OR(E6=0,E6>=7),0,D6/(7-E6)*E6*INDEX(Products!$E$2:$E$49,MATCH(C6,Products!$A$2:$A$49,0))) -> 0
A7: 46153 | B7: Nairobi CBD | C7: SKU001 | D7: 180 | E7: 0 | F7: =DATE(YEAR(A7),MONTH(A7),1) -> 46143 | G7: =INDEX(Products!$C$2:$C$49,MATCH(C7,Products!$A$2:$A$49,0)) -> Grocery Staples | H7: =D7*INDEX(Products!$E$2:$E$49,MATCH(C7,Products!$A$2:$A$49,0)) -> 29700 | I7: =D7*INDEX(Products!$D$2:$D$49,MATCH(C7,Products!$A$2:$A$49,0))*(1+INDEX(Assumptions!$B$16:$B$20,MATCH(B7,Assumptions!$A$16:$A$20,0))) -> 26179.2 | J7: =H7-I7 -> 3520.8 | K7: =IF(OR(E7=0,E7>=7),0,D7/(7-E7)*E7*INDEX(Products!$E$2:$E$49,MATCH(C7,Products!$A$2:$A$49,0))) -> 0
A8: 46160 | B8: Nairobi CBD | C8: SKU001 | D8: 188 | E8: 0 | F8: =DATE(YEAR(A8),MONTH(A8),1) -> 46143 | G8: =INDEX(Products!$C$2:$C$49,MATCH(C8,Products!$A$2:$A$49,0)) -> Grocery Staples | H8: =D8*INDEX(Products!$E$2:$E$49,MATCH(C8,Products!$A$2:$A$49,0)) -> 31020 | I8: =D8*INDEX(Products!$D$2:$D$49,MATCH(C8,Products!$A$2:$A$49,0))*(1+INDEX(Assumptions!$B$16:$B$20,MATCH(B8,Assumptions!$A$16:$A$20,0))) -> 27342.72 | J8: =H8-I8 -> 3677.28 | K8: =IF(OR(E8=0,E8>=7),0,D8/(7-E8)*E8*INDEX(Products!$E$2:$E$49,MATCH(C8,Products!$A$2:$A$49,0))) -> 0
A9: 46167 | B9: Nairobi CBD | C9: SKU001 | D9: 192 | E9: 0 | F9: =DATE(YEAR(A9),MONTH(A9),1) -> 46143 | G9: =INDEX(Products!$C$2:$C$49,MATCH(C9,Products!$A$2:$A$49,0)) -> Grocery Staples | H9: =D9*INDEX(Products!$E$2:$E$49,MATCH(C9,Products!$A$2:$A$49,0)) -> 31680 | I9: =D9*INDEX(Products!$D$2:$D$49,MATCH(C9,Products!$A$2:$A$49,0))*(1+INDEX(Assumptions!$B$16:$B$20,MATCH(B9,Assumptions!$A$16:$A$20,0))) -> 27924.48 | J9: =H9-I9 -> 3755.52 | K9: =IF(OR(E9=0,E9>=7),0,D9/(7-E9)*E9*INDEX(Products!$E$2:$E$49,MATCH(C9,Products!$A$2:$A$49,0))) -> 0
A10: 46174 | B10: Nairobi CBD | C10: SKU001 | D10: 47 | E10: 5 | F10: =DATE(YEAR(A10),MONTH(A10),1) -> 46174 | G10: =INDEX(Products!$C$2:$C$49,MATCH(C10,Products!$A$2:$A$49,0)) -> Grocery Staples | H10: =D10*INDEX(Products!$E$2:$E$49,MATCH(C10,Products!$A$2:$A$49,0)) -> 7755 | I10: =D10*INDEX(Products!$D$2:$D$49,MATCH(C10,Products!$A$2:$A$49,0))*(1+INDEX(Assumptions!$B$16:$B$20,MATCH(B10,Assumptions!$A$16:$A$20,0))) -> 6835.68 | J10: =H10-I10 -> 919.32 | K10: =IF(OR(E10=0,E10>=7),0,D10/(7-E10)*E10*INDEX(Products!$E$2:$E$49,MATCH(C10,Products!$A$2:$A$49,0))) -> 19387.5
A11: 46181 | B11: Nairobi CBD | C11: SKU001 | D11: 183 | E11: 0 | F11: =DATE(YEAR(A11),MONTH(A11),1) -> 46174 | G11: =INDEX(Products!$C$2:$C$49,MATCH(C11,Products!$A$2:$A$49,0)) -> Grocery Staples | H11: =D11*INDEX(Products!$E$2:$E$49,MATCH(C11,Products!$A$2:$A$49,0)) -> 30195 | I11: =D11*INDEX(Products!$D$2:$D$49,MATCH(C11,Products!$A$2:$A$49,0))*(1+INDEX(Assumptions!$B$16:$B$20,MATCH(B11,Assumptions!$A$16:$A$20,0))) -> 26615.52 | J11: =H11-I11 -> 3579.48 | K11: =IF(OR(E11=0,E11>=7),0,D11/(7-E11)*E11*INDEX(Products!$E$2:$E$49,MATCH(C11,Products!$A$2:$A$49,0))) -> 0
A12: 46188 | B12: Nairobi CBD | C12: SKU001 | D12: 178 | E12: 0 | F12: =DATE(YEAR(A12),MONTH(A12),1) -> 46174 | G12: =INDEX(Products!$C$2:$C$49,MATCH(C12,Products!$A$2:$A$49,0)) -> Grocery Staples | H12: =D12*INDEX(Products!$E$2:$E$49,MATCH(C12,Products!$A$2:$A$49,0)) -> 29370 | I12: =D12*INDEX(Products!$D$2:$D$49,MATCH(C12,Products!$A$2:$A$49,0))*(1+INDEX(Assumptions!$B$16:$B$20,MATCH(B12,Assumptions!$A$16:$A$20,0))) -> 25888.32 | J12: =H12-I12 -> 3481.68 | K12: =IF(OR(E12=0,E12>=7),0,D12/(7-E12)*E12*INDEX(Products!$E$2:$E$49,MATCH(C12,Products!$A$2:$A$49,0))) -> 0
A13: 46195 | B13: Nairobi CBD | C13: SKU001 | D13: 191 | E13: 0 | F13: =DATE(YEAR(A13),MONTH(A13),1) -> 46174 | G13: =INDEX(Products!$C$2:$C$49,MATCH(C13,Products!$A$2:$A$49,0)) -> Grocery Staples | H13: =D13*INDEX(Products!$E$2:$E$49,MATCH(C13,Products!$A$2:$A$49,0)) -> 31515 | I13: =D13*INDEX(Products!$D$2:$D$49,MATCH(C13,Products!$A$2:$A$49,0))*(1+INDEX(Assumptions!$B$16:$B$20,MATCH(B13,Assumptions!$A$16:$A$20,0))) -> 27779.04 | J13: =H13-I13 -> 3735.96 | K13: =IF(OR(E13=0,E13>=7),0,D13/(7-E13)*E13*INDEX(Products!$E$2:$E$49,MATCH(C13,Products!$A$2:$A$49,0))) -> 0
... A6001: 46286 | B6001: Mombasa | C6001: SKU048 | D6001: 118 | E6001: 0 | F6001: =DATE(YEAR(A6001),MONTH(A6001),1) -> 46266 | G6001: =INDEX(Products!$C$2:$C$49,MATCH(C6001,Products!$A$2:$A$49,0)) -> Snacks & Confectionery | H6001: =D6001*INDEX(Products!$E$2:$E$49,MATCH(C6001,Products!$A$2:$A$49,0)) -> 8260 | I6001: =D6001*INDEX(Products!$D$2:$D$49,MATCH(C6001,Products!$A$2:$A$49,0))*(1+INDEX(Assumptions!$B$16:$B$20,MATCH(B6001,Assumptions!$A$16:$A$20,0))) -> 5656.92 | J6001: =H6001-I6001 -> 2603.08 | K6001: =IF(OR(E6001=0,E6001>=7),0,D6001/(7-E6001)*E6001*INDEX(Products!$E$2:$E$49,MATCH(C6001,Products!$A$2:$A$49,0))) -> 0
